Workbook

Sheet NASLOV
B2: URED OVLAŠTENOG ARHITEKTA – JURICA HAJDAROVIĆ m.i.a.
B4: DALMATINSKA 5, 42000 VARAŽDIN, OIB:63185340802
B9: NARUČITELJ: | C9: MINISTARSTVO RADA, MIROVINSKOGA SUSTAVA, OBITELJI I SOCIJALNE POLITIKE, VUKOVARSKA 78, ZAGREB OIB: 53969486500
B10: GRAĐEVINA: | C10: GRAĐEVINA SOCIJALNE NAMJENE - DJEČJI DOM
B11: MJESTO GRADNJE: | C11: NOVOFORMIRANA k.č. 1325/1, SASTAVLJENA OD k.č. 1325/1, 1325/2, 1344, k.o. SISAK STARI, ULICA LIPA 9, SISAK
B12: BROJ TEHN.DN: | C12: 06/23
B13: ZAJ.OZN.PROJ: | C13: JH-06/23
B14: DATUM: | C14: 07/2024
B15: VRSTA PROJEKTA: | C15: TROŠKOVNIK
B16: FAZA: | C16: -
B17: TVRTKA: | C17: URED OVLAŠTENOG ARHITEKTA, JURICA HAJDAROVIĆ m.i.a., DALMATINSKA 5, VARAŽDIN
B23: GLAVNI PROJEKTANT: | E23: POTPIS I PEČAT
B25: Jurica Hajdarović, mag.inž.arh.

Sheet OPĆE
A1: I | B1: OPĆI UVJETI UZ TROŠKOVNIK GRAĐEVINSKO-OBRTNIČKIH RADOVA
B3: Sve radove potrebno je izvesti prema opisima pojedinih stavki troškovnika, općim smjernicama iz pojedinih grupa radova, detaljima, te važećim tehničkim propisima i standardima, kao i uputstvima proizvođača materijala, te pravilima struke i građevinskim normama. Izvođač je također obavezan izraditi elaborat o zaštiti na radu na gradilištu, a prema važećem pravilniku o zaštiti na radu, izraditi privremeno prometno rješenje ukoliko je potrebno, izvjesiti tablu s podacima o građevini, Naručitelju, Izvođaču, Projektantu i Nadzoru. Građevinski dnevnik i knjigu vodi izvođač radova i svakodnevno upisuje potrebne podatke predviđene Zakonom i pravilnikom.
B4: Dopuštene tolerancije mjera izvedenih radova određene su pravilima struke, odnosno prema odluci nadzorne službe na gradilištu. Sva odstupanja od dogovorenih tolerantnih mjera dužan je izvođač otkloniti o svom trošku. Nekvalitetno izvedeni radovi neće se obračunati sve dok se ne uklone uočeni nedostaci.To vrijedi za sve vrste radova.
B5: Za izvođenje svih vrsta radova uvjetuje se rad sa stručno osposobljenom radnom snagom za pojedine vrste radova prema Zakonu o prostornom uređenju i Zakonu o gradnji, sa propisanom kvalitetom materijala koja mora odgovarati postojećim tehničkim propisima i važećim Hrvatskim standardima. Ako neke stavke imaju nejasan i nedovoljan opis, onda svaki "započeti" opis pojedine stavke znači cjelokupnu izradu te stavke, to jest nabavu, dopremu materijala, sve prijenose i prijevoze, izradu, skidanje oplate, zaštitu, njegovanje pojedinih elemenata po izradi i nakon ugradbe, odvoz viška materijala na gradski deponij, kao i ostalo.
B6: Prije započinjana i tijekom izvođenja radova, izvođač treba zaštiti sve susjedne plohe, dijelove konstrukcije i prethodno izvedene radove na prikladan način, a u skladu s pravilima, tako da ne dođe do njihovog oštećenja ili oštećenja susjednih objekata i imovine trećih lica.
B7: Troškove zaštite treba izvođač uračunati u jediničnu cijenu. Ukoliko ipak dođe do oštećenja prethodno izvedenih radova za koje je odgovoran izvođač ili njegov kooperant, dužan ih je o svom trošku dovesti u stanje prije oštećenja, ili naručiti iste radove kod drugog izvođača na svoj teret. Popravak treba izvesti u primarno određenom roku ili dogovorno.
B8: Sve elemente opreme, namještaja, konstrukcija, koje nisu tipizirane, ili nisu u standardnom programu proizvođača, tj. nemaju popratnu dokumentaciju i dokaze uporabljivosti, izvođač radova je dužan prije izrade navedenih elemenata izraditi radioničke nacrte, obavezno ih ovjeriti kod nadzornog inženjera i projektanta, a tek potom krenuti u izradu tih elemenata.
B9: Izvođač radova mora svaku promjenu u toku gradnje, kako u konstrukciji tako i u instalacijama, evidentirati putem građevinskog dnevnika, ucrtati u nacrtnu dokumenataciju i po završetku radova predati Naručitelju kao nacrt izvedenog stanja.
B10: Bez posebne nadoplate potrebno je obuhvatiti sve elemente navedene kako slijedi :
B11: a) izvođač radova dužan je prije početka radova provjeriti kote postojećeg stanja terena u odnosu na relativnu kotu (+/-0,00) kod svih ulaza i kod svih unutrašnjih podnih ploča kao i za ulazne instalacije,
B13: b) utvrditi kotu 0,00 i obilježiti je na gradilištu kao referentnu točku,
B15: c) Izvođač je dužan prije početka radova sprovesti sve pripremne radove da se izvođenje može nesmetano odvijati. U tu svrhu izvođač je dužan detaljno proučiti investiciono tehničku dokumentaciju, te izvršiti potrebne računske kontrole. Potrebno je proučiti sve tehnologije izvedbe pojedinih radova radi optimalne organizacije građenja, nabavke materijala, kalkulacije i sl.ukoliko se ukažu eventualne nejednakosti između projekta i stanja na gradilištu izvođač radova dužan je pravovremeno o tome izvjestiti nadzornog inženjera. Nadzorni inženjer je dužan o većim odstupanjima obavijestiti Naručitelja i projektanta.
B16: d) sve mjere u projektima provjeriti na gradilištu prije narudžbe materijala ili gotovih proizvoda,
... B283: Napomena:
A284: Fasadni zidovi se radi poboljšanja energetske učinkovitosti izvana oblažu certificiranim vanjskim fasadnim sustavom, s termoizolacijom od tvrde kamene vune za fasadne sustave za ugradnju lijepljenjem i mehaničkim pričvršćenjem. Debljina termoizolacije od kamene vune iznosi 15,0 cm na svim vanjskim zidovima. Prilikom izvođenja radova može se izabrati bilo koji vanjski fasadni sustav jednakih ili boljih karakteristika od prikazanih u fizici zgrade. Sva vlakna ploče moraju biti paralelna sa fasadom sa osiguranom nosivošću u cjelokupnoj debljini ploče.
A285: Izolacijske ploče debljine 15,0 cm se lijepe na prethodno očišćenu i pripremljenu podlogu građevinskim ljepilom te se OBAVEZNO dodatno učvršćuju čeličnim pričvrsnicama (tiplama). Ljepljenje je potrebno izvesti po cijelom opsegu i minimalno u W uzorku) Dužina tiple prema preporuci proizvođača, dubina sidrenja u AB konstrukciju i u opeku je minimalno 5,0 cm . Tiple moraju imati podlošku min promjera 90 mm Potrebno je ugraditi minimalno 6 kom/m2 (dupli W uzorak). Sve rubove zgrade potrebno je izvesti sa pogušćenim tiplanjem
A286: Najkasnije 14 dana od postavljanja izolacije potrebno je izvesti armaturni sloj. Armaturni sloj se izvodi gletanjem u dva premaza (dvije ruke). Prvi sloj se nanosi na pripremljenu toplinsku izolaciju, te se u njega utiskuje armaturna mrežica od staklenog voala (ugradnja odozgo prema dolje laganim pritiskom gladilicom). Na mjestima spajanja armaturne mrežice potrebno je osigurati preklop od minimalno 10 cm.
A287: Drugi sloj nanosi se u roku od 24 sata od umetanja mrežice i isti je potrebno završno zagladiti. Minimalna debljina drugog sloja iznosi 1 mm.
A288: Na uglovima otvora prozora i vrata potrebno je izvesti dijagonalno armiranje polaganjem staklene mrežice u svježi mort za armaturni sloj točno na uglovima otvora pod kutem od 45 stupnjeva i to prije nanošenja punog armaturnog sloja na toplinski izolirane površine. Minimalne dimenzije armaturnih traka iznose 20x40 cm.
A289: Sve vidljive površine toplinsko-izolacijskih materijala, uključujući špalete te donje i gornje završetke ETICS-a na kojima nisu ugrađeni prikladni profili, potrebno je obraditi armaturnim slojem i završnom žbukom.
A290: Sve spojeve kao što su spoj s prozorima i vratima, spoj s krovom, spoj s kutijom za rolete i sl. potrebno je izvesti odgovarajućim priključnim profilima ili brtvenim trakama kako bi se ETICS sustav zaštitio od prodora vlage. Na isti način potrebno je izvesti zaštitu i na svim prodorima kroz ETICS kao što su prodori za gromobransku instalaciju, odvodnju, elektroinstalacije i sl.
A291: Kod montaže klupčica na otvorima (ugradnja prije ili nakon izvedbe ETICS sustava) posebnu pažnju potrebno je posvetiti pravilnoj ugradnji klupčica i toplinskoj izolaciji – ispunjavanju svih šupljina. Ukoliko se ugradnja klupčica vrši nakon izvedbe ETICS-a potrebno je gornju stranu izolacijskog materijala zaštiti armaturnim slojem.
A292: Sve spojeve kao što su spoj s prozorima i vratima, spoj s krovom, spoj s kutijom za rolete i sl. potrebno je izvesti odgovarajućim priključnim profilima ili brtvenim trakama kako bi se ETICS sustav zaštitio od prodora vlage. Na isti način potrebno je izvesti zaštitu i na svim prodorima kroz ETICS kao što su prodori za gromobransku instalaciju, odvodnju, elektroinstalacije i sl.
A293: Kod montaže klupčica na otvorima (ugradnja prije ili nakon izvedbe ETICS sustava) posebnu pažnju potrebno je posvetiti pravilnoj ugradnji klupčica i toplinskoj izolaciji – ispunjavanju svih šupljina. Ukoliko se ugradnja klupčica vrši nakon izvedbe ETICS-a potrebno je gornju stranu izolacijskog materijala zaštiti armaturnim slojem
A295: UVJETI UZ TROŠKOVNIK STROJARSKIH INSTALACIJA OPĆI UVJETI
A297: U stavkama troškovnika potrebno je uračunati sav potrebni rad i materijal za izradu kompletne instalacije do potpune funkcionalnosti, svi potrebni prijevozi, uskladištenja, skele, unutarnje i vanjske komunikacije na gradilištu, troškove osiguranja od krađe i oštećenja, postave pomoćnih i drugih uređaja, troškove potrošnje električne i druge energije, te troškove pripreme i režijskog osoblja gradilišta. Sve eventualne promjene i odstupanja od projekta, potrebno je usuglasiti s projektantom i nadzornim inženjerom. Cijena za svaku točku ovog troškovnika mora obuhvatiti dobavu, spajanje, lukove, koljena, redukcije, potrošni materijal, izvršenje tlačne probe, punjenje sustava, ispitivanje strojeva i uređaja s povećanom opasnosti, ispitivanje buke, ateste te izradu elaborata o ispitivanjima prema važećim propisima, čišćenje i bojanje temeljnom bojom te završom lak bojom te dovođenje stavke u stanje potpune funkcionalnosti. Jedinična cijena pojedine stavke ventilacije treba sadržavati i potrebna mjerenja izlaznih/ulaznih brzina na rešetkama, zračnim ventilima te u kanalima uz fino podešavanje sustava ventilacije. Radove izvodi ovlaštena tvrtka koja izrađuje zapisnik o izvedenim mjerenjima za potrebe tehničkog pregleda. U cijenu pojedine stavke treba ukalkulirati izradu proboja koji nisu definirani troškovnikom, sav potreban spojni, montažni, pričvrsni i ostali materijal potreban za potpuno funkcioniranje pojedine stavke, predaju potvrđenih jamstva, puštanje uređaja u pogon, upoznavanje i obuka kvalificirane osobe odabrane od strane investitora za pogon i upotrebu projektiranog postrojenja te izrada zapisnika o izvršenoj edukaciji uz potpis osposobljene osobe, upute o načinu rukovanja ugrađenom opremom na hrvatskom jeziku. Prilikom izrade ponude treba imati u vidu najnovije važeće propise za pojedine vrste instalacije. Svu metalnu instalaciju potrebno je uzemljiti na uzemljivač objekta prema projektu elektoinstalacija. Prije narudžbe i ugradnje opreme i materijala sve uskladiti s nadzornim inženjerom i arhitektonskim projektom. Svi ponuđači dužni su kompletan opseg vlastite isporuke uskladiti s traženom kompletnom funkcijom, respektirajući pri tom sve predviđene i tražene parametre, uz čvrste, pismeno potvrđene garancije. Sva eventualna potrebna razrađivanja, usklađenja i slično, u opsegu su dotične isporuke, a sve pripadne troškove snosi ponuđač. Puštanje u pogon opreme izvršava izvođač radova s odabranim ovlaštenim serviserom za pojedinu vrstu opreme. Izvođač je dužan prijenos, ugradnju i svu građevinsku pripomoć izvesti o svom trošku, te sve te radove nuditi u jediničnim cijenama ovog troškovnika. Gradilište je nakon izvršenih radova potrebno očistiti te otpadni materijal odvesti na mjesni deponij. Obaveza izvođača je prikupljanje sve dokumentacije potrebne za tehnički pregled te izradu sheme spajanja opreme. Shemu ostakliti i ovjesiti na zid u toplinskoj podstanici. Cjevovode za spajanje opreme sa svom armaturom doprema, ugrađuje, ispituje i pušta u pogon izvođač. Za sve stavke opreme dozvoljeno je odstupanje navedenih tehničkih parametara u granicama ±5 % uz uvjet da se postigne jednakovrijedno učinkovit sustav.
... A318: - negorive mineralne ploče HRN.B.F2.100 ili jednakovrijedno

Sheet GRAĐEVINSKI RADOVI
A1: I GRAĐEVINSKI RADOVI
A3: rbr | B3: Opis stavke | C3: jed. mjere | D3: količina | E3: jed. cijena | F3: ukupno:
A5: 1.00 OSTALI RADOVI
A7: 1.01. | B7: Završno energetsko certificiranje građevine prije tehničkog pregleda | C7: kpl | D7: 1 | E7: 1000 | F7: =E7*D7 -> 1000
A9: 1.02. | B9: Izrada projekta izvedenog stanja od strane ovlaštene osobe koji se sastoji od arhitektonskog, hidroinstalaterskog i elektrotehničkog dijela | C9: kpl | D9: 1 | E9: 2500 | F9: =E9*D9 -> 2500
A11: 1.04. | B11: Organizacija i priprema gradilišta. Stavka obuhvaća: - uređenje, održavanje, korištenje, uklanjanje, uređenje gradilišta, organizacija i postavljanje radnih prostora, skladišta, privremene infrastrukture, natpisi, ograde, osvjetljenje, natpisi, dobava, materijala i alata, upozorenja te odvozi smeća - mobilizacija, održavanje i demobilizacija opreme, alata i strojeva - osiguranje potrebnih građevinskih priključaka (voda, el.energija, i sl), pogonske energije i pomoćnih građevina - čišćenje mjesta rada, održavanje čistoće, zaštita od prašine, redovita čišćenja i završno čišćenje gradilišta, površina i mjesta rada - osiguranje privremenih puteva, zaštita puteva i površina od oštećenja, čišćenje manipulativnih površina i osiguranje mjesta za skladištenje i deponiranje materijala - osiguranje vertikalnog i horizontalnog transporta, instalacija i korištenje naprava za vertikalni i horizontalni transport ljudi i materijala. - postava ploče kojom se označava gradilište prema Zakonu o gradnji. Ploča mora biti postavljena na vidljivom mjestu na ulazu u gradilište. Postavljanje svih oznaka upozorenja, oznaka opasnosti i zabrane, te ostalih oznaka zaštite na radu - osiguranje zaštite granica gradilišta prema okolini - izvođač je dužan osigurati gradilište i postaviti podupirače kako ne bi došlo do urušavanja građevine ili njezinog dijela - naknade za eventualno potrebno zauzimanje javne gradske površine za organizaciju gradilišta Sve vrste skele bez obzira na visinu ulaze u jediničnu cijenu pojedinog rada. Skela mora biti na vrijeme postavljena kako ne bi nastao zastoj u radu. Skele moraju biti u skladu s propisima. | C11: kpl | D11: 1 | E11: 3000 | F11: =E11*D11 -> 3000
A13: 1.05. | B13: Uklanjanje trošne građevina na parceli s propisnim zbrinjavanjem otpada, ukupne zapremnine 131,19 m3. | C13: kpl | D13: 1 | E13: 7000 | F13: =E13*D13 -> 7000
A15: 1.06. | B15: Izrada projekta zaštite građevinske jame u koji je uključena i njegova kontrola od strane nadležnog revidenta. | C15: kpl | D15: 1 | E15: 2500 | F15: =E15*D15 -> 2500
A17: 1.07. | B17: Geodetsko iskolčenje građevine | C17: kpl | D17: 1 | E17: 1500 | F17: =E17*D17 -> 1500
B19: PRIPREMNI RADOVI UKUPNO: | F19: =SUM(F7:F17) -> 17500
A21: 2.00 ZEMLJANI RADOVI
A23: 2.01. | B23: Crpljenje podzemnih voda iz građevinske jame | C23: m3 | D23: 300 | E23: 5 | F23: =E23*D23 -> 1500
A25: 2.02. | B25: Široki iskop postojećeg terena za potrebe gradnje trakastih temelja i zamjenu tla u dubini od 3,3 u odnosu na postojeći teren u zemljištu kategorije C te odlaganje zemljišta na lokaciji. U cijenu uračunati sav rad i strojeve poput pneumatskog čekića. Iskopani materijal je potrebno zbrinjavati sukladno pozitivnim propisima | C25: m3 | D25: 2213.7 | E25: 20 | F25: =E25*D25 -> 44274
A27: 2.03. | B27: Izvođenje nasipa od krupnozrnatog materijala granulacije 0-64 mm, u pojasu od 1,50 m oko građevine. U cijenu uračunati sav rad i materijal | C27: m3 | D27: 399.4 | E27: 60 | F27: =E27*D27 -> 23964
A29: 2.04. | B29: Čišćenje temeljne jame od segregiranog materijala, a otpadni materijal zbrinuti sukladno pozitivnim propisima. | C29: m3 | D29: 85 | E29: 5 | F29: =E29*D29 -> 425
A31: 2.05. | B31: Uski iskop u zemljištu kategorije C za potrebe rovova za odvodne cijevi. Sav materijal odložiti na gradilište sukladno pozitivnim propisima. U cijenu uračunati sav rad strojeva i zbrinjavanje materijala. | C31: m3 | D31: 36.5 | E31: 30 | F31: =E31*D31 -> 1095
A33: 2.06. | B33: Doprema i zasipavanje odvodnih kanala agregatom 0-16 mm. U cijenu uračunati sav rad i materijal | C33: m3 | D33: 32.9 | E33: 60 | F33: =E33*D33 -> 1974
A35: 2.07. | B35: Doprema i zasipavanje ravnog krova šljunkom granulacije 0-32 mm u sloju od 5 cm kao zaštita hidroizolacije. U cijenu uračunati sav rad i materijal. | C35: m3 | D35: 28 | E35: 60 | F35: =E35*D35 -> 1680
A37: 2.08. | B37: Nabijanje nasipanog krupnozrnatog materijala iz st. 2.03. do modula stišljivosti M=40 Mpa. U cijenu uračunati sav rad, materijal i strojeve. | C37: m2 | D37: 230.3 | E37: 10 | F37: =E37*D37 -> 2303
A39: 2.09. | B39: Nabijanje čeličnih talpi (čelik S240GP) poprečnog presjeka 75,6 m2 za potrebe zaštite građevinske jame. Talpe se nabijaju građevinskim strojevima. U cijenu je potrebno uračunati i vađenje talpi.Previđa se nabijanje talpi do 10 m dubine, postavljaju se u razmacima od 40 cm s dvostrukim stezanjem brava. | C39: m2 | D39: 100 | E39: 1.5 | F39: =E39*D39 -> 150
A41: 2.10. | B41: Zatrpavanje zdenca zemljanim nasipom na jugozapadnom rubu parcele | C41: m3 | D41: 10 | E41: 20 | F41: =E41*D41 -> 200
B43: ZEMLJANI RADOVI UKUPNO: | F43: =SUM(F23:F41) -> 77565
A45: 3.00 BETONSKI I ARMIRANOBETONSKI RADOVI:
A47: 3.01. | B47: Izvedba podložnog betona debljine 10 cm razreda tlačne čvrstoće C12/16. | C47: m3 | D47: 41.3 | E47: 200 | F47: =E47*D47 -> 8260
A49: 3.02. | B49: Izrada podložnog betona debljine 10 cm od nearmiranog betona C16/20 za potrebe odvodnih cijevi fekalne i oborinske kanalizacije. U cijenu uračunati sav rad i materijal | C49: m3 | D49: 3.5 | E49: 200 | F49: =E49*D49 -> 700
A51: 3.03. | B51: Izrada trakastih temelja dimenzija 120x60 cm od betona C30/37, granulacije agregata 0-16 mm, Za armiranje koristiti armaturu sukladno HRN.DIN.488-1 ili jednakovrijedno, a za stvaranje zaštitnog sloja sukladno projektu, plastične distancere. Oplatu je prije postavljanja potrebno premazati uljem za lako razdvajanje oplate od betona. U cijenu uračunati sav pomoćni materijal te vibriranje i njega betona
B52: a) beton | C52: m3 | D52: 183.6 | E52: 245 | F52: =E52*D52 -> 44982
B53: b) oplata | C53: m2 | D53: 429.4 | E53: 2 | F53: =E53*D53 -> 858.8
A55: 3.04. | B55: Izrada trakastih temelja dimenzija 320x60 cm od betona C30/37, granulacije agregata 0-16 mm, Za armiranje koristiti armaturu sukladno HRN.DIN.488-1 ili jednakovrijedno, a za stvaranje zaštitnog sloja sukladno projektu, plastične distancere. Oplatu je prije postavljanja potrebno premazati uljem za lako razdvajanje oplate od betona. U cijenu uračunati sav pomoćni materijal te vibriranje i njega betona
B56: a) beton | C56: m3 | D56: 84 | E56: 205 | F56: =E56*D56 -> 17220
B57: b) oplata | C57: m2 | D57: 107.7 | E57: 2 | F57: =E57*D57 -> 215.4
A59: 3.05. | B59: Izrada nadtemeljnih zidova debljine 30 cm od betona C30/37, granulacije agregata 0-16 mm, Za armiranje koristiti armaturu sukladno HRN.DIN.488-1 ili jednakovrijedno, a za stvaranje zaštitnog sloja sukladno projektu, plastične distancere. Oplatu je prije postavljanja potrebno premazati uljem za lako razdvajanje oplate od betona. U cijenu uračunati sav pomoćni materijal te vibriranje i njega betona
B60: a) beton | C60: m3 | D60: 272.6 | E60: 2 | F60: =E60*D60 -> 545.2
B61: b) oplata | C61: m2 | D61: 914.3 | E61: 70 | F61: =E61*D61 -> 64001
A63: 3.06. | B63: Izrada armiranobetonskih stupova dim, 65x35 cm od betona C25/30 granulacije agregata 0-16 mm u dvostranoj oplati. Za armiranje koristiti armaturu sukladno HRN.DIN.488-1 ili jednakovrijedno, a za stvaranje zaštitnog sloja sukladno projektu, plastične distancere. Oplatu je prije postavljanja potrebno premazati uljem za lako razdvajanje oplate od betona. U cijenu uračunati sav materijal te vibriranje i njega betona
B64: a) beton | C64: m3 | D64: 6 | E64: 200 | F64: =E64*D64 -> 1200
B65: b) oplata | C65: m2 | D65: 53.5 | E65: 60 | F65: =E65*D65 -> 3210
A67: 3.07. | B67: Izrada okruglih armiranobetonskih stupova promjera 25 cm od betona C25/30 granulacije agregata 0-16 mm u kartonskoj oplati. Za armiranje koristiti armaturu sukladno HRN.DIN.488-1 ili jednakovrijedno, a za stvaranje zaštitnog sloja sukladno projektu, plastične distancere. Oplatu je prije postavljanja potrebno premazati uljem za lako razdvajanje oplate od betona. U cijenu uračunati sav materijal te vibriranje i njega betona
B68: a) beton | C68: m3 | D68: 1.5 | E68: 500 | F68: =E68*D68 -> 750
B69: b) oplata | C69: m2 | D69: 4.3 | E69: 100 | F69: =E69*D69 -> 430
...

Sheet OBRTNIČKI RADOVI
A1: II OBRTNIČKI RADOVI
A3: rbr | B3: Opis stavke | C3: jed. mjere | D3: količina | E3: jed. cijena | F3: ukupno:
A5: 5.00 IZOLATERSKI RADOVI
A7: 5.01. | B7: Postavljanje hidroizolacije podova u prizemlju od bitumenske ljepenke kao V4 ili jednakovrijedno u jednom sloju. Izvršiti preklope od 10 cm, a na spoju s armiranobetonskim zidovima izvesti holker visine 10 cm. U cijenu uračunati sav rad i materijal. | C7: m2 | D7: 947.5 | E7: 15 | F7: =E7*D7 -> 14212.5
A9: 5.02. | B9: Postavljanje parne brane ravnog krova i bitumenske ljepenke u jednome sloju. Izvršiti preklope od 10 cm., a na spoju s zidovima atike, te krovne staklene stijene izvesti holker u visini od 80 cm. U cijenu uračunati sav rad i materijal. | C9: m2 | D9: 947.5 | E9: 1.5 | F9: =E9*D9 -> 1421.25
A11: 5.03. | B11: Postavljanje hidroizolacije ravnog krova od PE folije.. Izvesti preklope od 10 cm, a na spoju sa zidovima atike i krovne staklene stijene izvesti holker visine 20 cm. U cijenu uračunati sav rad i materijal. | C11: m2 | D11: 947.5 | E11: 1 | F11: =E11*D11 -> 947.5
A13: 5.04. | B13: Postavljanje hidroizolacijske membrane od PVC sintetičke membrane debljine 2,0 mm kao završnog pokrova kosog krova za instalacije. Izvesti preklope od 10 cm, koji se zatvaraju pomoću toplog zraka. U cijenu uračunati sav rad, materijal i pomoćna sredstva | C13: m2 | D13: 581.3 | E13: 130 | F13: =E13*D13 -> 75569
A15: 5.05. | B15: Premazivanje zidova mokrih prostorija zaštitnom poliuretanskom membranom prije polaganja keramičkih pločica. Premaz se vrši do visine spuštenog stropa. U cijenu uračunati sav rad i materijal. | C15: m2 | D15: 443.2 | E15: 20 | F15: =E15*D15 -> 8864
A17: 5.06. | B17: Premazivanje podova mokrih prostorija zaštitnom poliuretanskom membranom prije polaganja keramičkih pločica. Premaz se vrši do visine spuštenog stropa. U cijenu uračunati sav rad i materijal. | C17: m2 | D17: 121.9 | E17: 25 | F17: =E17*D17 -> 3047.5
A19: 5.07. | B19: Premazivanje podova terasa drugog kata poliuretanskom zaštitnom membranom prije polaganja keramičkih pločica. U cijenu uračunati sav rad i materijal. | C19: m2 | D19: 24 | E19: 30 | F19: =E19*D19 -> 720
A21: 5.08. | B21: Postavljanje toplinske izolacije podova u prizemlju od XPS-a debljine 14 cm. U cijenu uračunati sav rad i materijal. | C21: m2 | D21: =D7 -> 947.5 | E21: 20 | F21: =E21*D21 -> 18950
A23: 5.09. | B23: Postavljanje toplinske izolacije podgleda balkona od EPS.-a debljine 5 cm. U cijenu uračunati sav rad i materijal | C23: m2 | D23: =D19 -> 24 | E23: 20 | F23: =E23*D23 -> 480
A25: 5.10. | B25: Postavljanje toplinske izolacije nadtemeljnih zidova građevine od XPS-a debljine 15 cm. U cijenu uračunati sav rad i materijal. | C25: m2 | D25: 254.4 | E25: 20 | F25: =E25*D25 -> 5088
A27: 5.11. | B27: Postavljanje toplinske izolacije fasade građevine od mineralne vune debljine 15 cm. U stavku su uračunata sva pričvrsna sredstva, ljepilo, mrežica i impregnacijski sloj. Nakon postavljanja jednom pregletati. U cijenu u računati sav rad i materijal. | C27: m2 | D27: 1685.8 | E27: 50 | F27: =E27*D27 -> 84290
A29: 5.12. | B29: Postavljanje toplinske izolacije ravnog krova od tvrde mineralne vune u padu debljine 20-30 cm. Padove izvesti prema vodolovnim grlima. U cijenu uračunati sav rad i materijal. | C29: m2 | D29: =D9 -> 947.5 | E29: 1 | F29: =E29*D29 -> 947.5
A31: 5.13. | B31: Postavljanje toplinske izolacije od mineralne vune debljine 5 cm s unutarnje strane atike kao prekida toplinskog mosta. Površinu pripremiti za završni sloj od akrilne žbuke U cijenu uračunati sav rad i materijal. | C31: m2 | D31: 199.2 | E31: 15 | F31: =E31*D31 -> 2988
A33: 5.14. | B33: Postavljanje hidroizolacije od PE folije na spojevima betonske ploče i vodolovnog grla. U cijenu uračunati sav rad i materijal. | C33: kom | D33: 4 | E33: 200 | F33: =E33*D33 -> 800
A35: 5.15. | B35: Postavljanje zvučne izolacije od kamene vune debljine 5,00 cm koja se postavlja između zidova od gipskartonskih ploča te se pričvršćuje metalnim pričvrsnicama. U cijenu uračunati sav rad i materijal. | C35: m2 | D35: 288.4 | E35: 10 | F35: =E35*D35 -> 2884
A37: 5.16. | B37: Postavljanje zvučne izolacije od kamene vune debljine 15,00 cm koja se postavlja između zidova od gipskartonskih ploča i betonskih zidova kod kanala u kupaonama, te se pričvršćuje metalnim pričvrsnicama. U cijenu uračunati sav rad i materijal. | C37: m2 | D37: 92 | E37: 10 | F37: =E37*D37 -> 920
A39: 5.17. | B39: Dobava i postavljanje hidroizolacije nadtemeljnih zidova od bitumenske ljepenke debljine 0,8 cm. Ljepenka se varenjem lijepi na nadtemeljne zidove, a u cijenu uračunati sav rad, materijal kao i holkere na spoju s temeljnom pločom. | C39: m2 | D39: =D25 -> 254.4 | E39: 25 | F39: =E39*D39 -> 6360
A41: 5.18. | B41: Postavljanje toplinske izolacije sokla od XPS-a debljine 10 cm. U cijenu uračunati sav rad i materijal. | C41: m2 | D41: 64.1 | E41: 20 | F41: =E41*D41 -> 1282
A43: 5.19. | B43: Dobava i postavljanje hidroizolacijske brtvene trake na spoju ankera armiranobetonskih zidova u prizemlju građevine uz poštivanje preklopa od 10 cm. Prilikom postavljanja poštivate upute proizvođača. U cijenu uračunati sav rad i materijal. | C43: m' | D43: 133 | E43: 10 | F43: =E43*D43 -> 1330
A45: 5.20. | B45: Dobava i postavljanje mehaničke zaštite od čepaste folije kao zaštite izolacije nadtemeljnih zidova. U cijenu uračunati sav rad i materijal | C45: m2 | D45: =D39 -> 254.4 | E45: 5 | F45: =E45*D45 -> 1272
B47: IZOLATERSKI RADOVI UKUPNO: | F47: =SUM(F7:F45) -> 232373.25
A49: 6.00 FASADERSKI RADOVI
A51: 6.01. | B51: Dobava i postavljanje impregnacijskog i završnog fasadnog sloja od slip opeke debljine 2,00 cm na vanjske fasadne zidove lijepljenjem odgovarajućim ljepilama, sukladno uputi proizvođača. Sva predviđena opeka je crvenkaste boje, hrapavog izgleda. Prilikom izbora, uzorke je potrebno pokazati porjektantu i investitoru na uvid. Špalete otvora se sa svih eksponiranih strana također oblažu istom vrstom opeke. Kod bridova izvesti spoj na gerung U cijenu uračunati sav rad i materijal | C51: m2 | D51: 760.6 | E51: 70 | F51: =E51*D51 -> 53242
A53: 6.02. | B53: Izrada fasadnog sloja od silikatne žbuke boje po izboru projektanta s unutarnje strane zidova atike. U cijenu uračunati sav rad i materijal. | C53: m2 | D53: 259.8 | E53: 20 | F53: =E53*D53 -> 5196
A55: 6.03. | B55: Dobava, postavljanje i kasnija demontaža cijevne fasadne skele za potrebe fasaderskih radova. U cijenu uračunati sav rad i materijal. | C55: m2 | D55: 1584.5 | E55: 10 | F55: =E55*D55 -> 15845
A57: 6.04. | B57: Dobava i postavljanje sloja terapalasta na soklu građevine od uzorka po izboru projektanta. U cijenu uračunati sav rad i materijal. | C57: m2 | D57: =D41 -> 64.1 | E57: 22 | F57: =E57*D57 -> 1410.2
A59: 6.05. | B59: Dobava i postavljanje elemenata od korodirang bakra na pojedinim poizicijama pročelja. Bakreni se elementi postavljaju na podkonstrukciju od čeličnih profila 20x20x1,5mm . Dužnost izvođača je izrada radioničkih nacrta te njihov prikaz na odobrenje projektantu. U cijenu uračunati sav rad i materijal | C59: m2 | D59: 57.4 | E59: 600 | F59: =E59*D59 -> 34440
B61: FASADERSKI RADOVI UKUPNO: | F61: =SUM(F51:F60) -> 110133.2
A63: 7.00 GIPSKARTONSKI RADOVI
A65: 7.01. | B65: Izrada i postavljanje zidova od dvostrukih gipskartonskih ploča na UW i CW profile, debljine 17,5 cm u kupaonama i nužnicima kod prodora instalacija. Zidovi se bandažiraju i gletaju u dva sloja. Jedan sloj su vlagootporne ploče, a dva su vatrootporne.Spojeve zidova s konstrukcijom građevine i s drugim zidovima obraditi posebnom spojnom mrežicom.U cijenu uračunati sve potrebne radnje za ličenje zidova | C65: m2 | D65: 126 | E65: 55 | F65: =E65*D65 -> 6930
A67: 7.02. | B67: Izrada i postavljanje zidova od dvostrukih standardnih gipskartonskih ploča na UW i CW profile, debljine 10 cm. Zidovi se bandažiraju i gletaju u dva sloja. Spojeve zidova s konstrukcijom građevine i s drugim zidovima obraditi posebnom spojnom mrežicom. U cijenu uračunati sve potrebne radnje za ličenje zidova | C67: m2 | D67: =D35 -> 288.4 | E67: 50 | F67: =E67*D67 -> 14420
A69: 7.03. | B69: Izrada i postavljanje kanala instalacija od dvostrukih gipskartonskih ploča od kojih je jedan sloj dijamant ploča, a drugi vatrootporna ploča, ispunjenih mineralnom vunom. Kanali se bandažiraju i gletaju u dva sloja. Spojeve zidova s konstrukcijom građevine i s drugim zidovima obraditi posebnom spojnom mrežicom. U cijenu uračunati sve potrebne radnje za ličenje zidova | C69: m2 | D69: 27.6 | E69: 50 | F69: =E69*D69 -> 1380
A71: 7.04. | B71: Dobava i postavljanje spuštenog stropa svih unutarnjih prostorija stropom od jednostrukih gipskartonskih ploča. Koristiti visilice do visine od 60 cm. | C71: m2 | D71: 1897.3 | E71: 35 | F71: =E71*D71 -> 66405.5
A73: 7.05. | B73: Dobava i postaljanje spuštenog stropa vanjskih prostorija stropom od jednostrukih cementnih ploča. Koristiti visilice do visine od 60 cm. | C73: m2 | D73: 77.2 | E73: 80 | F73: =E73*D73 -> 6176
B75: GIPSKARTONSKI RADOVI UKUPNO: | F75: =SUM(F65:F73) -> 95311.5
A77: 8.00 SOBOSLIKARSKO-LIČILAČKI RADOVI
A79: 8.01. | B79: Bojenje u dva sloja svih zidnih i stropnih površina disperzivnim toniranim bojama po izboru projektanta | C79: m2 | D79: =D71+'GRAĐEVINSKI RADOVI'!D154+D67 -> 7100.4 | E79: 6 | F79: =E79*D79 -> 42602.4
...

Sheet DIZALO
A1: III DIZALO
A3: rbr | B3: Opis stavke | C3: jed. mjere | D3: količina | E3: jed. cijena | F3: ukupno:
A5: 14.00 DIZALO
A7: 14.01. | B7: Izrada i postavljanje dizala za suhi prostor sukladno priloženoj projektnoj dokumentaciji prema kojoj dizalo mora ispuniti tehničke uvjete, pogotovo u pogledu nosivosti i vatrootpornosti. Dizalo se sastoji od tri stanice, od kojih su svi izlazi na istim stranama, visine dizanja 7,13 m. - vozno okno dimenzija 1700x2190 mm - vatrootpornost EI 60 - vrata voznog okna su od brušenog inoxa - SF okvir - dimenzije kabine: 1600x1400x2100 - inox strop - priključak 3x400/230 V, 50 Hz - LED osvjetljenje sa svjetlosnom zavjesom na ulazu - pogon dizala je u vrhu voznog okna - ventilator - uređaj za stalnu kontrolu nosivih traka - rasvjeta voznog okna - ogledalo - rukohvati - uređaj za automatsku evakuaciju u slučaju nestanka struje Izvođač je dužan prikazati radioničku dokumentaciju nadzornom inženjeru za dizalo prije izvođenja, te je u potpunosti dužan poštivati upute proizvođača. U cijenu su uračunati sav rad i materijal | C7: kpl | D7: 1 | E7: 32000 | F7: =E7*D7 -> 32000
B10: DIZALO UKUPNO: | F10: =F7 -> 32000
C13: projektant:
C15: Jurica Hajdarović, ovl.arh.

Sheet HI - VODOVOD
A1: IV RADOVI VODOVODA
A3: rbr | B3: Opis stavke | C3: jed. mjere | D3: količina | E3: jed. cijena | F3: ukupno:
A5: 15.00 ZEMLJANI RADOVI
A7: 15.01. | B7: Iskop rova u tlu A ktg. za polaganje vodovodnih cijevi na dubinu do 2,0 m, širine 0,60m. Iskopani materijal odbacivati na udaljenost preko 1,0 m od bočne ivice rova, da se spriječi urušavanje iskopanog materijala u rov. | C7: m3 | D7: 7.9 | E7: 20 | F7: =E7*D7 -> 158
A9: 15.02. | B9: Proširenje i produbljenje rova na mjestu izvedbe vodomjernog okna. | C9: m3 | D9: 4.6 | E9: 100 | F9: =E9*D9 -> 460
A11: 15.03. | B11: Planiranje dna rova s odstupanjem ±2,0 cm. | C11: m3 | D11: 5 | E11: 100 | F11: =E11*D11 -> 500
A13: 15.04. | B13: Dobava pijeska, ubacivanje u rov te izrada pješčane posteljice ispod vodovodnih cijevi u sloju debljine d=10 cm. | C13: m3 | D13: 4.2 | E13: 100 | F13: =E13*D13 -> 420
A15: 15.05. | B15: Zatrpavanje rova prosijanim materijalom od iskopa (iz kojeg su uklonjeni veći komadi od iskopa) u slojevima od 30,0 cm, uz istovremeno obilno močenje i nabijanje materijala ručnim i strojnim nabijačima. | C15: m3 | D15: 7.2 | E15: 20 | F15: =E15*D15 -> 144
A17: 15.06. | B17: Odvoz materijala preostalog od iskopa, nakon zatrpavanja rova, na depo, kamionom do 5 km. Uključiv utovar, istovar i razastiranje. | C17: m3 | D17: 7.3 | E17: 20 | F17: =E17*D17 -> 146
B19: ZEMLJANI RADOVI UKUPNO: | F19: =SUM(F7:F18) -> 1828
A21: 16.00 BETONSKI RADOVI
A23: 16.01. | B23: Izvedba vodomjernog okna tlocrtne veličine svjetlog otvora 2,00x1,50x1,40 m. Stjenke i dno okna izvesti će se armiranim vodonepropusnim betonom C25/30, Iznad okna na dubini cca 8 cm od kote uređenog terena izvesti armirano-betonsku ploču debljine 15 cm u C25/30 s ovorom za silazak u okno vel.60x60 cm. Iznad otvora na ploči montirati ljevano-željezni poklopac za prometno opterećenje 50 KN ili adekvatan poklopac od rebrastog čeličnog lima 5/4 mm sa okvirom od čeličnog "L" profila te mogučnošću zaključavanja. Izvedba okna prema detaljnom nacrtu. | C23: kom | D23: 1 | E23: 2500 | F23: =E23*D23 -> 2500
B24: .
A25: 16.02. | B25: Izrada, dobava i ugradba penjalica, u stijenku vodomjernog okna, izrađenih iz betonskog željeza ø20 mm, razvijene dužine 125 cm. Prije ugradbe penjalice od korozije zaštiti dvostrukim premazom minija i jednostrukim premazom uljane boje. Penjalice postaviti na pločastu željeznu podlogu koja se postavlja u okno iz stavke 12.01. | C25: kom | D25: 4 | E25: 100 | F25: =E25*D25 -> 400
B27: BETONSKI RADOVI UKUPNO: | F27: =SUM(F23:F26) -> 2900
A29: 17.00 UNUTARNJI VODOVOD
A31: 17.01. | B31: Dobava i montaža PP tip3 cijevi za vodovod (fuzioterm ili sl.) komplet s PP fitinzima te spojnim i brtvenim materijalom. Cijevi montirati u podu građevine, šlicevima izvedenim u zidu građevine u prizemlju te uz armaturu zidova u suterenu, zidnim usjecima i probojima i vidljivo u kotlovnici kod bojlera.
B32: a) cijevi ø32 mm | C32: m' | D32: 38 | E32: 55 | F32: =E32*D32 -> 2090
B33: c) cijevi ø25 mm | C33: m' | D33: 1140 | E33: 18 | F33: =E33*D33 -> 20520
A35: 17.02. | B35: Izvedba zaštitne izolacije cjevovoda hladne vode u podu građevine omotom "Plastizol" trakom debljine 2,8 mm, a cjevovoda tople i hladne vode montiranog u šlicevima zida, zidnim usjecima i probojima, omotom trakama filca.
B36: a) cijevi ø32 mm | C36: m' | D36: 38 | E36: 10 | F36: =E36*D36 -> 380
B37: c) cijevi ø25 mm | C37: m' | D37: 1140 | E37: 5 | F37: =E37*D37 -> 5700
A39: 17.03. | B39: Dobava i montaža ravnih propusnih ventila za uzidanje s pripadajućom kromiranom kapom i rozetom HRN M.C5.262 Ili jednakovrijedno.
B40: ventil ø25 mm | C40: kom | D40: 20 | E40: 35 | F40: =E40*D40 -> 700
A42: 17.04. | B42: Dobava i montaža ravnih propusnih ventila HRN M.C5.260 Ili jednakovrijedno.
B43: ventil ø25 mm | C43: kom | D43: 80 | E43: 30 | F43: =E43*D43 -> 2400
A45: 17.05. | B45: Ispitivanje kompletne vodovodne mreže pod tlakom vode od 6 i 15 bara. | C45: m' | D45: =D32+D33 -> 1178 | E45: 0.5 | F45: =E45*D45 -> 589
A47: 17.06. | B47: Dobava i montaža nepovratnog ventila 5/4” za horizontalnu ugradnju. | C47: kom | D47: 4 | E47: 25 | F47: =E47*D47 -> 100
A49: 17.07. | B49: Ispiranje i dezinfekcija kompletne vodovodne mreže adekvatnim sredstvom za dezinfekciju. | C49: m' | D49: =D45 -> 1178 | E49: 1 | F49: =E49*D49 -> 1178
A51: 17.08. | B51: Bakteriološka analiza uzoraka vode iz cjevovoda nakon dezinfekcije i ponovnog ispiranja istog čistom vodom. | C51: kpl | D51: 1 | E51: 1500 | F51: =E51*D51 -> 1500
A53: 17.09. | B53: Funkcionalno ispitivanje unutrašnje hidrantske mreže, od strane nadležne ustanove koja će o tome izdati nalaz. | C53: kpl | D53: 1 | E53: 550 | F53: =E53*D53 -> 550
A55: 17.10. | B55: Izvedba priključka cjevovoda tople, hladne vode i cirkulacije na centralnu pripremu tople vode.3
B56: THVf24;Cvf25mm | C56: kom | D56: 4 | E56: 80 | F56: =E56*D56 -> 320
A58: 17.11. | B58: Dobava i montaža vodomjera priključka 15mm/ max. Opterećenje 0,80 lit/sec | C58: kom | D58: 20 | E58: 80 | F58: =E58*D58 -> 1600
A60: 17.12. | B60: Dobava i montaža kromiranih vratašca za reviziju vel. 30x30 cm, komplet s okvirom, bravicom i ključem za otvaranje. | C60: kom | D60: 20 | E60: 38 | F60: =E60*D60 -> 760
A62: 17.13. | B62: Dobava i montaža tipskog vodomjerniog ormarića za ugradnju u zid, za smještaj četiri vodomjerne garniture | C62: kom | D62: 5 | E62: 380 | F62: =E62*D62 -> 1900
B64: UNUTARNJI VODOVOD UKUPNO: | F64: =SUM(F32:F63) -> 40287
B66: RADOVI VODOVODA UKUPNO: | F66: =F64+F27+F19 -> 45015
D68: projektant:
D70: Jurica Hajdarović, ovl.arh.

Sheet HI - KANALIZACIJA
A1: V RADOVI KANALIZACIJE
A3: rbr | B3: Opis stavke | C3: jed. mjere | D3: količina | E3: jed. cijena | F3: ukupno:
A5: 18.00 ZEMLJANI RADOVI
A7: 18.01. | B7: Strojni i ručni iskop rova u tlu C ktg. za polaganje cijevi vanjske kanalizacije građevine i drenažne cijevi, širine 0,80 - 1,0m, na dubinu do 2,0m. Iskopani materijal odbacivati na udaljenost preko 1,0 m od bočne ivice rova, da se spriječi urušavanje iskopanog materijala u rov. | C7: m3 | D7: 36.6 | E7: 20 | F7: =E7*D7 -> 732
A9: 18.02. | B9: Proširenje i produbljenje rova na mjestima izvedbe oborinskih i fekalnih revizijskih okana na dubini do 2,0 m. | C9: m3 | D9: 25.5 | E9: 30 | F9: =E9*D9 -> 765
A11: 18.03. | B11: Ručno planiranje dna kanalizacijskog rova s odstupanjem ±2,0 cm. | C11: m3 | D11: 7.4 | E11: 100 | F11: =E11*D11 -> 740
A13: 18.04. | B13: Dobava pijeska, ubacivanje u rov te izrada pješčane posteljice ispod kanalizacijskih cijevi u sloju debljine d=10 cm. | C13: m3 | D13: 5 | E13: 80 | F13: =E13*D13 -> 400
A15: 18.05. | B15: Dobava pijeska, ubacivanje u rov, te zatrpavanje istim cijevi do visine 30 cm iznad tjemena cijevi. | C15: m3 | D15: 12 | E15: 80 | F15: =E15*D15 -> 960
A17: 18.06. | B17: Zatrpavanje kanalizacijskog rova materijalom od iskopa u slojevima od 30,0 cm, uz istovremeno obilno močenje i nabijanje svakog sloja nasutog materijala ručnim odnosno strojnim nabijačima. | C17: m3 | D17: =20 -> 20 | E17: 20 | F17: =E17*D17 -> 400
A19: 18.07. | B19: Razastiranje preostalog materijala na predmetnoj parceli prema posebnom projektu. U cijenu uračunati sav rad i materijal. | C19: m3 | D19: 20 | E19: 20 | F19: =E19*D19 -> 400
B21: ZEMLJANI RADOVI UKUPNO: | F21: =SUM(F7:F20) -> 4397
A23: 19.00 BETONSKI RADOVI
A25: 19.01. | B25: Izvedba revizijskog okna na vanjskoj kanalizaciji građevine, armiranim vodonepropusnim betonom C25/30 u dvostranoj oplati debljine bočnih stijenki i dna 15 cm. Na dnu okna izvesti kinete prema podacima o niveleti okna i obraditi ih cementnom glazurom 1:2 zaglađenom do crnog sjaja. Stijenke okna ožbukati cementnom žbukom 1:2 zaglađenom do crnog sjaja. Iznad okna na dubini cca 10 cm od kote uređenog terena izvesti armirano-betonsku ploču debljine 15 cm u C25/30 s otvorom za silazak u okno, vel. 60x60 cm. Iznad otvora na ploči montirati četvrtasti lijevano željezni poklopac s okvirom vel. 600x600 mm za prometno opterećenje od 400 KN ako se okna izvode ispod prometnih površina. Izvedba okna prema priloženom detaljnom nacrtu. | C25: kom | D25: 8 | E25: 1200 | F25: =E25*D25 -> 9600
A27: 19.02. | B27: Izrada tesarskih prodora za kanalizacijske cijevi dimenzija 20x20 od dasaka. U cijenu uračunati sav rad i materijal. | C27: kom | D27: 39 | E27: 20 | F27: =E27*D27 -> 780
A29: 19.03. | B29: Izrada prodora za vertikale ravnog krova od drvenih dasaka za potrebe vertikala ravnog krova. U cijenu uračunati sav rad i materijal. | C29: kom | D29: 4 | E29: 50 | F29: =E29*D29 -> 200
B31: BETONSKI RADOVI UKUPNO: | F31: =SUM(F25:F30) -> 10580
A33: 20.00 MONTAŽNI RADOVI KANALIZACIJSKOG CJEVOVODA
A35: 20.01. | B35: Dobava i montaža tvrdih PVC cijevi za uličnu kanalizaciju tip UKC HRN G.C6.501-3 ili jednakovrijedno, razred čvrstoće SN8. Cijevi će se montirati za temeljne odvode krovnih vertikala u oborinsko reviziono okno, te odvoda fekalne kanalizacije u gradsku kanalizaciju. Spajanje cijevi izvoditi gumenim prstenima.
B36: PVC cijev UKC
B37: DN 160 mm | C37: m' | D37: 65.2 | E37: 35 | F37: =E37*D37 -> 2282
A39: 20.02. | B39: Dobava i montaža tvrdih PVC cijevi za kućnu kanalizaciju HRN G.C6.501-3. Spajanje cijevi izvoditi pomoću natičnih naglavaka, a brtvljenje spojeva standardiziranim gumenim brtvama.
B40: DN 110 mm | C40: m' | D40: 95.2 | E40: 10 | F40: =E40*D40 -> 952
B41: DN 70 mm | C41: m' | D41: 119 | E41: 8 | F41: =E41*D41 -> 952
B42: DN 50 mm | C42: m' | D42: 40.1 | E42: 7 | F42: =E42*D42 -> 280.7
A44: 20.03. | B44: Dobava i montaža fazonskih (spojnih) komada iz tvrdog PVC-a za kućnu kanalizaciju. Spajanje komada izvoditi prema opisu u stavci 3.03.
B45: a) koljeno 87º30’,
B46: RC 87º30’
B47: DN 110 mm | C47: kom | D47: 20 | E47: 14 | F47: =E47*D47 -> 280
B48: DN 50 mm | C48: kom | D48: 20 | E48: 7 | F48: =E48*D48 -> 140
B49: b) koljeno 45º,
B50: RC 45º
B51: DN 50 mm | C51: kom | D51: 20 | E51: 14 | F51: =E51*D51 -> 280
B52: DN 110 mm | C52: kom | D52: 9 | E52: 7 | F52: =E52*D52 -> 63
B53: c) jednostruki ogranak RT 87º30‘
B54: DN 70/50 mm | C54: kom | D54: 16 | E54: 8 | F54: =E54*D54 -> 128
B55: DN 50/50 mm | C55: kom | D55: 20 | E55: 7 | F55: =E55*D55 -> 140
B56: e) jednostruki ogranak RG 45º
B57: DN 110/110 mm | C57: kom | D57: 5 | E57: 14 | F57: =E57*D57 -> 70
B58: DN 70/50 mm | C58: kom | D58: 20 | E58: 8 | F58: =E58*D58 -> 160
B59: DN 50/50 mm | C59: kom | D59: 25 | E59: 7 | F59: =E59*D59 -> 175
...

Sheet HI - HIDRANTSKA MREŽA
A1: VI RADOVI HIDRANTSKE MREŽE
A3: rbr | B3: Opis stavke | C3: jed. mjere | D3: količina | E3: jed. cijena | F3: ukupno:
A5: 22.00 ZEMLJANI RADOVI
A7: 22.01. | B7: Iskop rova u tlu C ktg. za polaganje vodovodnih cijevi na dubinu do 2,0 m, širine 0,60m. Iskopani materijal odbacivati na udaljenost preko 1,0 m od bočne ivice rova, da se spriječi urušavanje iskopanog materijala u rov. | C7: m3 | D7: 4 | E7: 50 | F7: =E7*D7 -> 200
A9: 22.02. | B9: Planiranje dna rova s odstupanjem ±2,0 cm. | C9: m3 | D9: 0.5 | E9: 100 | F9: =E9*D9 -> 50
A11: 22.03. | B11: Dobava pijeska, ubacivanje u rov te izrada pješčane posteljice ispod hidrantskih cijevi u sloju debljine d=10 cm. | C11: m3 | D11: 0.5 | E11: 100 | F11: =E11*D11 -> 50
A13: 22.04. | B13: Zatrpavanje rova prosijanim materijalom od iskopa (iz kojeg su uklonjeni veći komadi od iskopa) u slojevima od 30,0 cm, uz istovremeno obilno močenje i nabijanje materijala ručnim i strojnim nabijačima. | C13: m3 | D13: 3 | E13: 100 | F13: =E13*D13 -> 300
B15: ZEMLJANI RADOVI UKUPNO: | F15: =SUM(F7:F14) -> 600
A17: 23.00 CIJEVNI RAZVOD I OPREMA
A19: 23.01. | B19: Dobava i montaža čeličnih cijevi za vodovod (fuzioterm ili sl.) komplet s čečičnim fitinzima te spojnim i brtvenim materijalom. Cijevi montirati u podu građevine, šlicevima izvedenim u zidu građevine u prizemlju te uz armaturu zidova u suterenu, zidnim usjecima i probojima i vidljivo u kotlovnici kod bojlera.
B20: a) cijevi ø50 mm | C20: m' | D20: 55.9 | E20: 55 | F20: =E20*D20 -> 3074.5
A22: 23.02. | B22: Izvedba zaštitne izolacije (debljina izolacije 2,8 mm) cjevovoda hladne vode u podu građevine omotom "Plastizol" trakom, a cjevovoda tople i hladne vode montiranog u šlicevima zida, zidnim usjecima i probojima, omotom trakama filca.
B23: a) cijevi ø50 mm | C23: m' | D23: 55.9 | E23: 10 | F23: =E23*D23 -> 559
A25: 23.03. | B25: Dobava i montaža ravnih propusnih ventila za uzidanje s odgovarajućom kapom i rozetom HRN M.C5.262 ili jednakovrijedno
B26: ventil ø50 mm | C26: kom | D26: 5 | E26: 88 | F26: =E26*D26 -> 440
A28: 23.04. | B28: Ispitivanje kompletne vodovodne mreže pod tlakom vode od 6 i 15 bara. | C28: m' | D28: 55.9 | E28: 1 | F28: =E28*D28 -> 55.9
A30: 23.05. | B30: Dobava i montaža ormarića s bubnjem za ugradbu u zid, veličine 500x500x120 mm sa limenim vratima i oznakom "H", komplet sa hidrantskim ventilom ø52 mm i spojnicom. | C30: kom | D30: 5 | E30: 198 | F30: =E30*D30 -> 990
A32: 23.06. | B32: Dobava i postava vatrogasnog pribora u hidrantski ormarić
B33: -vatrogasno tlačno trevira crijevo tip "C" dužine 15m HRN Z.C6.011 ili jednakovrijedno | C33: kom | D33: 5 | E33: 50 | F33: =E33*D33 -> 250
B34: -univerzalna mlaznica sa
B35: slavinom i univerzal-
B36: nom glavom tip "C",
B37: HRN Z.C1.066 ili jednakovrijedno | C37: kom | D37: 5 | E37: 35 | F37: =E37*D37 -> 175
A39: 23.07. | B39: Dobava i montaža vatrogasnih aparata za gašenje požara prahom HRN Z.C2.035 ili jednakovrijedno
B40: S-9 | C40: kom | D40: 5 | E40: 80 | F40: =E40*D40 -> 400
B42: CIJEVNI RAZVOD I OPREMA UKUPNO: | F42: =SUM(F19:F41) -> 5944.4
B44: HIDRANTSKA MREŽA UKUPNO: | F44: =F42+F15 -> 6544.4
D47: projektant:
D49: Jurica Hajdarović, ovl.arh.

Sheet STROJARSTVO
A3: red.br. | C3: OPIS | D3: jed.mj. | E3: količina | F3: jed. cijena (€) | G3: ukupna cijena (€)
C5: TROŠKOVNIK RADOVA, MATERIJALA I USLUGA - STROJARSKI DIO
B7: NARUČITELJ | D7: MINISTARSTVO RADA, MIROVINSKOGA SUSTAVA, OBITELJI I SOCIJALNE POLITIKE
D8: VUKOVARSKA 78
D9: HR-10000 Zagreb
D10: OIB: 53969486500
B11: GRAĐEVINA: | D11: GRAĐEVINA SOCIJALNE NAMJENE - DJEČJI DOM
B12: LOKACIJA: | D12: ULICA LIPA 9
D13: HR-44000 SISAK
D14: NOVOFORMIRANA k.č. 1325/1, k.o. SISAK STARI
B15: ZAHVAT: | D15: IZGRADNJA
B16: Z.O.P.: | D16: JH-06/23
B17: Mapa 3: | D17: PROJEKT STROJARSKIH INSTALACIJA
D18: INSTALACIJA ZEMNOG PLINA, TOPLOVODNOG GRIJANJA, INSTALACIJA HLAĐENJA I VENTILACIJE
B19: BROJ PROJEKTA: | D19: TD 1199/24
C21: OPĆA NAPOMENA:
C22: Materijal, oprema i proizvodi specificirani u stavkama, kao i kompletni sustavi mogu biti zamijenjeni jednakovrijednim materijalima, opremom, proizvodima i sistemima drugih proizvođača.
C23: U slučaju da ponuditelj nudi jednakovrijedne materijale, opremu i proizvode obavezno upisuje podatke o proizvođaču i tipu proizvoda u predviđeno mjesto troškovnika. Jednakovrijednost dokazuje dostavom dokumentacije, ispitivanja, proračuna i sl. za ponuđene jednakovrijedne proizvode ili opremu.
C24: U stavkama troškovnika potrebno je uračunati sav potrebni rad i materijal za izradu kompletne instalacije do potpune funkcionalnosti, spajanje, svi potrebni prijevozi, uskladištenja, skele te unutarnje i vanjske komunikacije na gradilištu. Sve eventualne promjene i odstupanja od projekta, potrebno je usuglasiti s projektantom i nadzornim inženjerom. Prilikom izrade ponude treba imati u vidu najnovije važeće propise za pojedine vrste instalacije.
C25: Potvrdu narudžbe prije definitivne isporuke specificirane opreme izvođač radova obavezno je dužan provjeriti kod projektanta. Izmjena pojedinih dijelova opreme “zamjenskim dijelovima” bez prethodne pismene suglasnosti projektanta isključuje odgovornost projektanta za predviđenu funkcionalnost postrojenja.
C26: Svi ponuđači dužni su kompletan opseg vlastite isporuke uskladiti s traženom kompletnom funkcijom, uvažavajući pritom sve predviđene i tražene parametre, uz čvrste, pismeno potvrđene garancije. Sva eventualna potrebna razrađivanja, usklađenja i slično, u opsegu su dotične isporuke, a sve pripadne troškove snosi ponuđač.
C27: Izvođač je dužan prijenos, ugradnju i svu građevinsku pripomoć izvesti o svom trošku, te sve te radove nuditi u jediničnim cijenama ovog troškovnika.
F28: PROJEKTANT:
E30: Nino Valinčić, dipl.ing.stroj.
C33: 24. , 25. PLINSKA INSTALACIJA - plinski priključak
C35: 24.00. STROJARSKI DIO
A37: 24.01. | C37: Dobava i ugradnja - PE sedlo za navarivanje na plinovod i bušenje pod plinom. Sedlo je izrađeno iz polietilena PE 100 SDR 11 kvalitete prema DIN 8075 ili jednakovrijedno i dimenzija prema DIN 8074 ili jednakovrijedno ili ISO 4437 ili jednakovrijedno
C38: d 63/ d 32 | D38: kom | E38: 1 | F38: 150 | G38: =F38*E38 -> 150
A40: 24.02. | C40: Dobava i ugradnja - Podzemna uvarna slavina s PE krajevima i s vretenom i lijevanoželjeznom kapom s natpisom PLIN
C41: NO 25 | D41: kom | E41: 1 | F41: 100 | G41: =F41*E41 -> 100
A43: 24.03. | C43: Dobava i ugradnja - Polietilenska cijev iz koluta serije PE 100 SDR 11 kvalitete prema DIN 8075 ili jednakovrijedno i dimenzija prema DIN 8074 ili jednakovrijedno ili ISO 4437 ili jednakovrijedno. Cijev se spaja elektrospojnicom.
C44: d 32 | D44: m | E44: 30 | F44: 50 | G44: =F44*E44 -> 1500
A46: 24.04. | C46: Dobava i ugradnja - Plastična traka upozorenja širine 6 – 8 cm žute boje s natpisom PLIN ili POZOR PLIN. Traka mora biti položena tako da natpis bude okrenut prema gore. Polaže se na dubini 50 cm ispod nivelete terena. | D46: m | E46: 35 | F46: 1 | G46: =F46*E46 -> 35
A48: 24.05. | C48: Dobava i ugradnja - PE traka s dvije žice od nehrđajućeg čelika (valovito ugrađene) za otkrivanje PE plinovoda. Žicu na krajevima međusobno spajati tako da se ostvari trajna i kvalitetna električna veza. Žicu spojiti zajedno s žicom za detekciju uličnog ST plinovoda d110 PE 100, te jedan kraj izvući u nazidni ormarić. Krajevi žice moraju biti dostupni za priključenje detektora. Nakon ugradnje izvršiti kontrolu električne veze i o tome dati pismeni nalaz. | D48: m | E48: 35 | F48: 2 | G48: =F48*E48 -> 70
A50: 24.06. | C50: Dobava i ugradnja - Elektrospojnica, PE 100, SDR 11 kvalitete prema DIN 8075 ili jednakovrijedno, dimenzija prema DIN 8074 ili jednakovrijedno ili ISO 4437 ili jednakovrijedno.
C51: d 32 | D51: kom | E51: 4 | F51: 150 | G51: =F51*E51 -> 600
A53: 24.07. | C53: Dobava i ugradnja prijelaznog komada polietilen / čelik s elektrozavojnicom, PE 100 SDR 11.
C54: PE/ČE - d 32/DN 25 | D54: kom | E54: 1 | F54: 150 | G54: =F54*E54 -> 150
A56: 24.08. | C56: Dobava i ugradnja - Čelična cijev dimenzija prema DIN 2448 (C.B5.122) ili jednakovrijedno, izrađena od materijala Č.1212. Cijev se ugrađuje na podzemnom dijelu nemjerenog priključka i antikorozivno zaštićuje primerom i plastizol trakom.
C57: ø 33,7 x 2,6 mm ( DN 25 ) | D57: m | E57: 3 | F57: 50 | G57: =F57*E57 -> 150
...

Sheet ELEKTRO
E1: BR. PROJEKTA | F1: 113-23
B2: GRAĐEVINA | C2: GRAĐEVINA SOCIJALNE NAMJENE - DJEČJI DOM
B3: NARUČITELJ | C3: MINISTARSTVO RADA, MIROVINSKOGA SUSTAVA,
C4: OBITELJI I SOCIJALNE POLITIKE
B5: FAZA PROJEKTA | C5: GLAVNI PROJEKT | E5: DATUM | F5: srpanj 2024.
A8: Rbr. | B8: Opis stavke | C8: Jed. mjera | D8: Količina | E8: Jed. cijena | F8: Ukupno cijena | G8: Napomena
A11: A | B11: ELEKTRO RADOVI
B13: Cijena za svaku stavku ovog troškovnika mora obuhvatiti dobavu, montažu, spajanje, te po potrebi uzemljenje. U cijenu je potrebno ukalkulirati sav potreban spojni, montažni, ovjesni i pridržni materijal potreban za potpuno funkcioniranje pojedine stavke. U jedinstvenoj cijeni svih stavki sadržani su svi troškovi i materijali potrebni za besprijekornu izvedbu i kompletnu izvedbu. Prije davanja konačne ponude obvezno izvršiti upoznavanje sa predmetnom projektnom dokumentacijom (tehnički opis, nacrti) te tražiti eventualna pojašnjenja prije zaključivanja ponude. Izvođač je dužan uskladiti projektnu dokumentaciju sa stvarno izvedenim stanjem, te istu s izmjenama isporučiti Investitoru u jednom primjerku. Rezanje kabela izvoditi na licu mjesta nakon izmjere stvarnih dužina trase, naročito u slučajevima kabela većih presjeka. Tekstove natpisnih pločica usuglasiti sa tehnologom i projektantom. Sve kabele označiti odgovarajućim oznakama na oba kraja.
B14: Instalacijske cijevi moraju biti otpornosti 750N, te sve cijevi moraju biti samogasive.
B15: Prije narudžbe materijala na licu mjesta provjeriti stvarno potrebne dužine i komade.
A17: 34.00. | B17: PRIPREMNI RADOVI
A19: 34.01. | B19: Priprema gradilišta i odlaganje otpada
B20: Priprema gradilišta, donošenje potrebne opreme i alata na gradilište. Tokom izvedbe svih radova elektroinstalacija, sav materijal nastao kao posljedica izvedebe elektroinstalaterskih radova potrebno je na parceli sortirati u zasebnim kontejnerima prema vrsti materijala. Posebno je odvojiti ambalažni otpad (papir, plastika, drvo i sl.) te višak i otpadci materijala izvedbe (metal, toplinska izolacija i sl.). Sav otpadni materijal potrebno je učestalo odvoziti sa lokacije na mjesta predviđena za odlaganje pojedine vrste otpada i u reciklažna dvorišta. Zabranjeno je odvoziti otpad na mjesta koja za to nisu dozvoljena. Sve stavke podrazumijevaju odvoz i uklanjanje nakon ugradnje i usitnjavanja na gradilištu, uključivo i transport kompletnog viška materijala na deponij i reciklažna dvorišta udaljena do 25km od gradilišta, sa plaćanjem svih pristojbi za zbrinjavanje otpada. Sav otpad prevozi se i odlaže sukladno propisima o otpadu i komunalnom redu. Investitoru je obavezno dostaviti Prateći list za otpad | C20: kom | D20: 1 | E20: 1000 | F20: =D20*E20 -> 1000
A23: 34.00. | B23: =B17 -> PRIPREMNI RADOVI | C23: UKUPNO | F23: =SUM(F19:F22) -> 1000
A26: B | B26: JAKA STRUJA
B28: Sve stavke uključuju kompletno ožičene, ispitane razdjelnike, dopremljene, montirane i spojene na mjestu ugradnje. _x005F_x000D_Stavka uključuje sav potrebam spojni i montažni materijal koji je potreban za dovođenje razdjelnika do pune funkcijonalnosti. Svaki razdjelnik opremljen je ladicom za smještaj jednopolne sheme u koju obvezno treba uložiti jednopolnu shemu izvedenog stanja svakog pripadajućeg razdjelnika. Svaki razdjelni mora biti ispitan i isporučen sa izjavama o sukladnosti za ormar i svu ugrađenu opremu.
B29: Svi razdjelnici moraju biti isporučeni u kompletu sa svim montažnim i spojnim priborom, vodičima unutrašnjih veza, rednim stezaljkama, brtvenim gumama, kabelskim uvodnicama, naljepnicama, vrećicom za umetanje sheme, faznim, N i PE sabirnicama.
B30: U svakome razdjelniku ostaviti 25% rezerve za naknadnu ugradnju opeme.
A32: 35.00. | B32: DISTRIBUCIJSKI RAZDJELNICI
A34: 35.01. | B34: GRO
B35: Dobava, montaža i spajanje razvodnog ormara oznake +GRO dimenzija [(600+600)x(2048+100)x250mm], tipski testiran prema IEC 60439-1/IEC 61439-1-2 do 250A. Ormar je slobodnostojeći, metalni, sa prozirnim vratima, sa stupnjem zaštite IP43. Potrebno predvidjeti 20% rezervnog prostora u svrhu budućih nadogradnji. Stavka uključuje sav potreban montažni materijal za potpunu funkcionalnost.
B36: ORMAR:
B37: Nosači za zid kom 1
B38: Aparatno polje š=600mm v=2000mm kom 1
B39: Ext: aparatno polje + kit za produljenje š=600mm v=2000mm kom 1
B40: Krov/dno TZ-flange š=600mm kom 1
B41: TL flange, metalne, š=600mm kom 1
B42: Upora za medjusobne povezivanje ormara serije L-M kom 1 i
B43: Krov/dno otvoreno, dimnezija š=600mm kom 2
B44: Puna ploča za dno ormara š=600mm kom 2
B45: Staklena vrata š=600mm v=2000mm kom 2
B46: Podnožje ormara v=100 mm širine š=600mm kom 2
... B107: Doprema, unošenje i povezivanje ormara s kablovima na objektu, sa ispitivanjem i izdavanjem atesta kpl 1
B108: Obračun po kompletu ugrađenog i spojenog ormara | C108: kompl | D108: 1 | E108: 10000 | F108: =D108*E108 -> 10000
A110: 35.02. | B110: KOMP
B111: Dobava, montaža i spajanje razvodnog ormara oznake +RO_KOMP, dimenzija [800x1200x300mm], tipski testiran prema IEC 60439-1/IEC 61439-1-2 ili jednkovrijedno ______________________________.Ormar je zidni, metalni, s punim metalnim vratima, sa stupnjem zaštite IP65. Potrebno predvidjeti 20% rezervnog prostora u svrhu budućih nadogradnji. Stavka uključuje sav potreban montažni materijal za potpunu funkcionalnost.
B112: ORMAR:
B113: Zidni ormar dimenzija 800x1200x300mm, stupanj zaštite IP65, kom 1
B115: Džep za dokumentaciju A4, kom 1
B116: OPREMA:
...

Sheet VANJSKO
A2: IX | B2: RADOVI VANJSKOG UREĐENJA
B4: OPIS STAVKE | C4: JED.MJ. | D4: KOLIČINA | E4: J.CIJENA | F4: UKUPNO
A5: 54.00 | B5: PRIPREMNI RADOVI
A6: 54.01 | B6: Horizontalno i visinsko iskolčenje trase sa izradom elaborata iskolčenja. Iskolčenje obuhvaća sva geodetska mjerenja kojima se podaci iz projekta prenose na teren, osiguranje osi iskolčene trase, profiliranje, obnavljanje i održavanje iskolčenih oznaka na terenu za sve vrijeme građenja, odnosno do predaje radova Investitoru. Rad se obračunava i mjeri po kvadratnom metru trase. Napomena: ukupna površina zahvata uređenja okoliša (bez zgrade) iznosi 1.806,00 m2.
C7: m2 | D7: 2479 | E7: 0.5 | F7: =SUM(D7*E7) -> 1239.5
A8: 54.02. | B8: Provedba mjera osiguranja gradilišta prije početka i u tijeku izvođenja radova, obavlja se postavom prometnih znakova, rampi i svjetlosnih signala noću, zaštitnih ograda i drugih oznaka. Prema stavkama 0-24. i 0-35.2.14 OTU-a za radove na cestama, knjiga I.
C9: kom. | D9: 1 | E9: 500 | F9: =SUM(D9*E9) -> 500
A10: 54.03. | B10: Ručni iskop materijala C kategorije (šlicanje) za točno utvrđivanje položaja postojećih podzemnih instalacija. Predviđena je širina rova 0.40 m, dubina rova 0.8 m u dužini od 2.0 m, a sve prema posebnim uvjetima građenja nadležnih poduzeća za pojedinu vrstu instalacije. U cijenu stavke uključeno je i zatrpavanje istih. Obračun prema stvarno izvršenim količinama po kubnom metru iskopanog materijala.
C11: m3 | D11: 4 | E11: 200 | F11: =SUM(D11*E11) -> 800
A12: 54.04. | B12: Rezanje rubova postojećeg asfaltnog zastora radi osiguranja kvalitete spoja starog i novog asfalta (Širina rezanog asfalta je min. 25cm). U cijenu uključiti razbijanje, utovar i odvoz na deponiju udaljenu do 10km. Obračun po dužnom metru izrezanog asfalta.
C13: m' | D13: 60.7 | E13: 10 | F13: =SUM(D13*E13) -> 607
A14: 54.05. | B14: Demontaža postojećih prometnih znakova s skladištenjem na gradilištu do ponvnog postavljanja istih. U cijenu uključiti izvedbu temelja, i sve ostale radove za postavljanje prometnog znaka. Rad se mjeri i obračunava po komadu demontiranog znaka i ponovno postavljenog prometnog znaka.
C15: kom. | D15: 1 | E15: 500 | F15: =SUM(D15*E15) -> 500
A16: 54.06. | B16: Zaštita postojećih podzemnih instalacija. Na mjestima gdje postojeće ili premještene podzemne instalacije prolaze ispod kolničke konstrukcije, potrebno je izvršiti mehaničku zaštitu vodova prema posebnim uvjetima nadležnih poduzeća. Obračun se vrši po dužnom metru stvarno izvedene zaštite.
B17: a.) Elektro instalacije | C17: m' | D17: 80.1 | E17: 10 | F17: =SUM(D17*E17) -> 801
B18: b.) Plinskih instalacija | C18: m' | D18: 20 | E18: 10 | F18: =SUM(D18*E18) -> 200
B19: c.) Telefonskih instalacija | C19: m' | D19: 16 | E19: 10 | F19: =SUM(D19*E19) -> 160
B20: d.) Vodovodnih instalacija | C20: m' | D20: 80.1 | E20: 10 | F20: =SUM(D20*E20) -> 801
A22: 54.07. | B22: Izrada geodetskog snimka izvedenog stanja sa provedbom na katastru. Obračun po kvadratnom metru snimljene i u katastru provedene situacije izvedenog stanja.
C23: m2 | D23: 2894.3 | E23: 0.5 | F23: =SUM(D23*E23) -> 1447.15
A25: 54.08. | B25: Izmještanje elektroenergetskog stupa. Rad se mjeri i obračunava prema komadu izmještenog stupa. (Prema posebnim uvjetima HEP-a u slučaju potrebe zaštite ili izmještanja instalacija - obveza je Inverstitora prije početka radova izraditi projekt zaštite ili izmještanja elektroenergetskih instalacija). Ovaj rad izvodi ovlaštena organizacija, prema komadu (kompletno sa svim radovima) izmještenog stupa.
B26: RADOVE IZVODI ISKLJUČIVO DISTRIBUTER EL. ENERGIJE! NE NUDITI! | C26: kpl | D26: 1 | E26: 1 | F26: =SUM(D26*E26) -> 1
B29: PRIPREMNI RADOVI UKUPNO: | F29: =SUM(F6:F26) -> 7056.65
A31: 55.00 | B31: ZEMLJANI RADOVI
A32: 55.00. | B32: Strojni i ručni iskop materijala (materijal "B" kategorije) s utovarom i odvozom na deponij (udaljen do 10km). Iskop se obavlja prema profilima i visinskim kotama iz projekta, te propisanim nagibima kosina. Rad se obračunava po m3 stvarno iskopanog, utovarenog i odveženog materijala. Predviđa se 98 % strojnog i 2 % ručnog iskopa.
B33: a) RUČNO - 2% | C33: m3 | D33: 23.7 | E33: 40 | F33: =SUM(D33*E33) -> 948
B34: B) STROJNO - 98% | C34: m3 | D34: 1160.8 | E34: 20 | F34: =SUM(D34*E34) -> 23216
A35: 55.02. | B35: Uređenje temeljnog tla. Radovi na uređenju temeljnog tla obuhvaćaju planiranje, eventualno potrebno prosušivanje ili vlaženje materijala i zbijanje do propisanog modula stišljivosti za izvedbu ceste, parkirališta, travnih ploča i pješačke staze, Ms=25MN/m2. Rad se mjeri i obračunava po kvadratnom metru stvarno uređene i zbijenog temeljnog tla.
C36: m2 | D36: 1050 | E36: 35 | F36: =SUM(D36*E36) -> 36750
A37: 55.03. | B37: Izrada nasipa od šljunkovitog materijala, granulacije 32 mm. U stavku uključiti dobavu, ugradnju i sabijanje materijala za nasip prema projektu, zbijanje do Ms=50MN/m2. Rad se mjeri i obračunava po kubnom metru ugrađenog materijala.
C38: m3 | D38: 1270 | E38: 2 | F38: =SUM(D38*E38) -> 2540
