Workbook
Name __xlfn_ANCHORARRAY: NA()
Name _1Excel_BuiltIn_Print_Area_1: #REF!
Name _1Excel_BuiltIn_Print_Area_1: #REF!
Name _1Excel_BuiltIn_Print_Area_1: #REF!
Name _rbr: #REF!
Name _rbr2: #REF!
Name _Toc322533491: STROJ!#REF!
Name _Toc322533491: VIK!#REF!
Name all: #REF!
Name all: #REF!
Name all: #REF!
Name aluminijska: #REF!
Name aluminijska: #REF!
Name aluminijska: #REF!
Name ASD: #REF!
Name AVD: #REF!
Name BE_Price: #REF!
Name betonska: #REF!
Name BETONSKI_I_ARM.BETONSKI_RADOVI: #REF!
Name BOD: ELEKTRO!#REF!
Name BOD: #REF!
Name BOD: #REF!
Name BOD: #REF!
Name BOD: #REF!
Name BOD: #REF!
Name BOD: #REF!
Name BODIC: #REF!
Name BODIC: #REF!
Name BODIC: #REF!
Name BODICA: #REF!
Name BODICA: #REF!
Name BRAVARIJA_SKLONIŠTA: #REF!
Name Countr.: #REF!
Name Countr.no: #REF!
Name Country: #REF!
Name CRNA_BRAVARIJA: #REF!
Name č: #REF!
Name ČELIČNA_KONSTRUKCIJA: #REF!
Name D: #REF!
Name Data_base_result: #REF!
Name dfgdfgdfgdfgydf: [1]POMOĆNI!$B$56:$B$69
Name DIMNJACI: #REF!
Name DIMNJACI: #REF!
Name DIZALA: #REF!
Name DIZALA: #REF!
Name EODB: #REF!
Name EODB: #REF!
Name euro: #REF!
Name euronew: #REF!
Name EXCEG: #REF!
Name Excel_BuiltIn_Print_Area_1: #REF!
Name Excel_BuiltIn_Print_Area_1_1: #REF!
Name Excel_BuiltIn_Print_Area_2: #REF!
Name Excel_BuiltIn_Print_Area_3: #REF!
Name Excel_BuiltIn_Print_Area_4: #REF!
Name Excel_BuiltIn_Print_Area_5: #REF!
Name Excel_BuiltIn_Print_Titles: #REF!
Name Excel_BuiltIn_Print_Titles_1: #REF!
Name Excel_BuiltIn_Print_Titles_1_1: #REF!
Name Excel_BuiltIn_Print_Titles_2: #REF!

Sheet NASL
A2: rc-proing | B2: d.o.o. za projektiranje i usluge
A3: a. | B3: Ćire Truhelke 33a
A4: o. | B4: 1669597821
A5: e. | B5: fcvitak@rc-proing.hr
A6: m. | B6: 0989065414
A8: naručitelj | B8: Općina Orle
B9: Orle 5
B10: 10 411 Orle
A14: građevina | B14: Dječji vrtić Bukevje
A17: predmet | B17: Troškovnik radova
A22: k.č. | B22: 1419/9
A23: k.o. | B23: Bukevje
A24: adresa | B24: Bukevje, Orle
A35: izradio | B35: Filip Cvitak, dia
A40: direktor | B40: Filip Cvitak, dia
A42: datum | B42: 07/2024.

Sheet REKAP SVEUK
A2: REKAPITULACIJA
A4: GRAĐEVINSKO OBRTNIČKI RADOVI | F4: ='REKAP-GOR'!E50 -> 3111797
A5: OPREMA | F5: =OPREMA!F392 -> 209022.4
A6: VODOVOD I ODVODNJA | F6: =VIK!F544 -> 382095
A7: STROJARSKI | F7: =STROJ!F29 -> 492313
A8: ELEKTROTEHNIČKI | F8: =ELEKTRO!E509 -> 282527.15
A9: VATRODOJAVA | F9: =VATRODOJAVA!F47 -> 26255.6
A10: SOLARNA ELEKTRANA | F10: =SE!E157 -> 71951.59
B15: UKUPNO | F15: =SUM(F4:F10) -> 4575961.7
B16: PDV 25% | F16: =F15*0.25 -> 1143990.4
B17: UKUPNO S PDV-OM | F17: =SUM(F15:F16) -> 5719952.2

Sheet OPĆI UVJETI
A1: OPĆI UVJETI UZ TROŠKOVNIK GRAĐEVINSKO-OBRTNIČKIH RADOVA
B3: Prije pristupanja svim radovima (kao skidanje oštećenih dijelova konstrukcije, pročelja, završnih obrada površina, demontaže opreme i slično) potrebno je obaviti prethodni pregled s nadzornim inženjerom i unaprijed dogovoriti potreban obim posla.
B6: Prilikom izrade ponude potrebno je poštivati trenutno važeći Zakon o javnoj nabavi i sve ostale prateće zakone i pravilnike.
B7: Sva rušenja i demontaže pojedinih dijelova građevine izvoditi pažljivo. Kod izvođenja pojedinih vrsta radova zabranjena je upotreba teških alata, kompresora ili sličnih uređaja koji mogu posredno prouzročiti štetu na konstruktivnim dijelovima građevine. Rušenja izvoditi tek kada su izvršena sva potrebna rasterećenja, podupiranja, osiguranja i isključivanja instalacija od nadležnih institucija. Prilikom rušenja potrebno je razvrstavati otpad te ga sukcesivno odvoziti na za to predviđene gradske deponije, a elemente koji će se ponovno ugrađivati, demontirati što pažljivije, te ih skladištiti na gradilištu odnosno na suho i sigurno mjesto za popravak i ponovnu ugradnju. Ako se prilikom rušenja i demontaže naiđe na nepredviđene detalje ili se uoče opasnosti od rušenja ili ugrožavanja okolnih elemenata građevine, izvođač je dužan o tome odmah obavjestiti nadzornog inženjera i investitora. Prije početka rušenja i demontaža kvalificirana i stručna osoba mora odpojiti sve instalacije i osigurati gradilište.
B8: Sve radove izvesti prema opisima pojedinih stavki troškovnika, općim smjernicama iz pojedinih grupa radova, detaljima, i svim važećim tehničkim propisima i standardima, kao i uputstvima proizvođača materijala, te pravilima struke i građevinskim normama. Za izvođenje svih radova uvjetuje se rad sa stručno osposobljenom radnom snagom za pojedine vrste radova prema Zakonu o gradnji, sa propisanom kvalitetom materijala koja mora odgovarati postojećim tehničkim propisima i važećim standardima. Ako neke stavke imaju nejasan i nedovoljan opis, onda svaki "započeti" opis pojedine stavke znači cjelokupnu izradu te stavke, to jest nabavu, dopremu materijala, sve prijenose i prijevoze, izradu, skidanje oplate, zaštitu, njegovanje pojedinih elemenata po izradi i nakon ugradbe, odvoz viška materijala na gradski deponij, kao i ostalo. Bez posebne nadoplate potrebno je obuhvatiti sve elemente navedene kako slijedi:
B15: a) izvođač radova dužan je prije početka radova provjeriti kote postojećeg stanja terena u odnosu na relativnu kotu (+/-0,00) kod svih ulaza i kod svih unutrašnjih podnih ploča kao i za ulazne instalacije,
B17: b) utvrditi kotu 0,00 i obilježiti je na gradilištu kao referentnu točku,
B18: c) ukoliko se ukažu eventualne nejednakosti između projekta i stanja na gradilištu izvođač radova dužan je pravovremeno o tome izvjestiti investitora, projektanta i nadzornog inženjera te shodno tome zatražiti potrebna objašnjenja,
B20: d) sve mjere u projektima provjeriti na gradilištu prije narudžbe materijala ili gotovih proizvoda.
B21: e) provjera količina troškovnika obaveza je Izvođača radova, kao i izrada dokaznice izvedenih radova unutar građevinske knjige
B24: MATERIJAL
B25: Pod stavkom materijal podrazumijeva se dobavna cijena materijala, to jest cijena glavnih i pomoćnih materijala potrebnog za ugradnju do kompletne gotovosti. U tu cijenu potrebno je uključiti i cijenu prijevoza bez obzira na vrstu prijevoznog sredstva, udaljenost, te eventualne potrebne utovare, istovare i prijenose do skladišta i do mjesta ugradbe. U cijeni materijala je i cijena čuvanja, zaštite i skladištenja materijala do ugradnje. Prema važećim propisima potrebno je uzimanje uzoraka - probnih kocki - za beton, te ugradnja samo onih materijala koji imaju važeće potvrde o sukladnosti. Svu dokumentaciju o dokazu kvalitete materijala prikuplja izvođač radova i po završetku predaje Investitoru.
B31: RAD
... B179: U slučaju nastanka opravdanih nepredviđenih radova, potrebno je napraviti aneks ugovora.

Sheet I PRIPR
A2: I | B2: PRIPREMNI RADOVI I UREĐENJE GRADILIŠTA
B5: OPĆI NAPUTCI
B7: Radove treba izvesti točno prema opisu troškovnika, a u stavkama gdje nije objašnjen način rada i posebne osobine finalnog produkta, izvođač je dužan pridržavati se uobičajenog načina rada, uvažavajući odredbe važećih standarda, uz obvezu izvedbe kvalitetnog proizvoda.
B8: Osim toga, izvođač je obvezan pridržavati se uputa projektanta/nadzora u svim pitanjima koja se odnose na izbor i obradu materijala i način izvedbe pojedinih detalja, ukoliko to nije već detaljno opisano troškovnikom, a naročito u slučajevima kada se zahtjeva izvedba van propisanih standarda. Sav materijal za izgradnju mora biti kvalitetan i mora odgovarati opisu troškovnika i postojećim građevinskim propisima. U slučaju da opis pojedine stavke nije dovoljno jasan, mjerodavna je samo uputa i tumačenje projektanta/nadzora. O tome se izvođač treba informirati već prilikom sastavljanja jedinične cijene. Cijene pojedinih radova moraju sadržavati sve elemente koji određuju cijenu gotovog proizvoda, a u skladu sa odredbama troškovnika. Ako izvođač sumnja u valjanost ili kvalitetu nekog propisanog materijala i drži da za takvu izvedbu ne bi mogao preuzeti odgovornost, dužan je o tome obavijestiti projektanta s obrazloženjem i dokumentacijom. Konačnu odluku donosi projektant u suglasnosti s nadzornim inženjerom, nakon proučenog prijedloga izvođača.
B11: POSEBNI NAPUTCI ZA UREĐENJE GRADILIŠTA
A13: 1. | B13: Prethodne odredbe i odobrenje gradnje
B14: Investitor stavlja, sukladno projektnoj dokumentaciji i pravomoćnoj građevnoj dozvoli, glavnom izvođaču radova bez naknade privremeno na raspolaganje teren za uređenje gradilišta u potrebnom obimu ili shodno lokalnim uvjetima.
A16: 2. | B16: Odstranjivanje otpada
B17: Vlastiti preostali materijal i materijal od rušenja treba izvođač besplatno ukloniti. Moraju se poštivati odnosni propisi o zbrinjavanju posebnog otpada. Ukopavanje ili spaljivanje na gradilištu je zabranjeno. Zbrinjavanje otpada, mase od rušenja ili građevinskog otpada obuhvaća ponovno iskorištavanje sukladno propisima odnosno potrebnim mjerama skupljanja, transporta, obrade i skladištenja prema propisima i nalozima organa.
B18: Investitor može zahtijevati dokaz o urednom zbrinjavanju otpada.
A20: 3. | B20: Spoj s drugim cjelinama
B21: U Posebnim tehničkim ugovornim uvjetima utvrdit će se kako će pojedini izvođači koristiti dijelove uređenja gradilišta u odnosu na građevinski pothvat. Građevinske puteve koristit će svi sudionici izgradnje besplatno.
A23: 4. | B23: Opći podaci o izvedbi
B24: Na zahtjev treba prije uređenja gradilišta napraviti plan uređenja gradilišta i predočiti Investitoru na odobrenje. Pri tom treba uzeti u obzir da se ne sprečavaju eventualni radovi izmjere, posebice iskolčavanja i provjere granica ulica, puteva i građevine. U nacrtu uređenja treba uzeti u obzir i skladištenje zemljane mase. Površine, skladišne površine, slobodne površine i slično, koje će se koristiti za uređenje gradilišta, trebaju se umetnuti u nacrt uređenja gradilišta s podatkom svrhe korištenja. Uređenje gradilišta na tratini ili humusu nije dopušteno. Prije uređenja gradilišta treba izvođač utvrditi stanje učvršćenja pločnika i kolnika, koji graniče s građevinskom parcelom kao i susjedne površine gradilišta, u prisustvu vlasnika. O tome treba voditi zapisnik i obje ga strane moraju potvrditi. Uređenje gradilišta treba izvršiti tako da se vodovi napajanja i odvođenja za građevinske mjere mogu položiti pravodobno i bez smetnji.
B25: Postojeći graničnici (kamenje) i oznake izmjera moraju se osigurati s početkom radova u sklopu uređenja gradilišta do pospremanja uređenja gradilišta. Prije početka radova mora se izvođač informirati o prolazu vodova, kablove itd. (nadzemno i podzemno). Potrebna premještanja mora izvođač pravodobno zatražiti. U slučaju dvojbe dat će izvođač nalogodavcu uputu, po potrebi će se provesti utvrđivanje.
B26: Kod micanja uređenja gradilišta treba paziti: - Investitora treba informirati o namjeravanom micanju uređenja gradilišta ili bitnih dijelova istog - Dijelove, koji više nisu potrebni, treba brzo maknuti - Nakon skidanja uređenja gradilišta treba teren, koji je za isto bio korišten odnosno korištene građevinske uređaje i građevine vratiti u prvobitno stanje, ako nije drugačije utanačeno.
A28: 5. | B28: Posebni zahtjevi za korištenje
B29: Izvođač mora postavit zahtjeve kod nadležnih organa za uređenje i uklanjanje postrojenja bez Sudjelovanja nalogodavca. Struja, koju uzimaju druge tvrtke, Zaračunat će se njima direktno.
B31: UREĐENJE GRADILIŠTA, KOMPLETNA POZICIJA
A33: 1. | B33: Uređenje gradilišta Glavna pozicija
B34: Urediti, održavati za dogovoren rok trajanja radova kao i uređivati gradilište i ponovno uspostavljanje terena u prijašnje stanje uključujući uklanjanje nečistoće, sa sljedećim radovima, koji moraju biti uračunati u paušalnu cijenu: - mjesto za skladištenje i rad - uređaj za signalizaciju prometa uključujući rad na osiguranju prometa - rasvjeta gradilišta - građevinska struja, građevinska voda, građevinska otpadna voda uklj. razvod i priključni vod - komunikacijski uređaj - dnevni boravak i stanovanje uklj. sanitarni uređaj (prostor), - skladišni prostor, radionica, spremište, natkriveni prostor - ograda gradnje, zaštitni zid, zaštitni krov - strojevi, uređaji Za cijelo vrijeme gradnje prema vremenskom planu projekta. Cijena uključuje ishođenje dozvole za zauzimanje javne površine uz objekat u površini prema rješenju nadležnog tijela vlasti. Gradilište mora biti uređeno sukladno odredbama Zakona o zaštiti na radu sukladno elaboratu uređenja gradilišta.
B35: Glavna pozicija | C35: kompl | D35: 1 | E35: 15000 | F35: =D35*E35 -> 15000
A37: 2. | B37: Ispitivanje temeljnog tla
B38: Izrada geomehaničkog elaborata i ispitivanje nosivosti temeljnog tla.
C39: kompl | D39: 1 | E39: 2500 | F39: =D39*E39 -> 2500
A41: =A2 -> I | B41: UREĐENJE RADILIŠTA I PRIPREMNI RADOVI | C41: UKUPNO | F41: =SUM(F34:F40) -> 17500

Sheet II ZEM
A2: II | B2: ZEMLJANI RADOVI
B4: POSEBNI NAPUTCI ZA ZEMLJANE RADOVE
B6: Investitor stavlja na raspolaganje teren, koji je potreban za zemljane radove, s izuzetkom deponije za otpad. Izvođač se prije izvođenja radova mora informirati o točnom smještaju prepreka, kao vodova, kablova, kanala, oznaka i sl.
B7: Cijenama je pokriveno između ostalog: - poteškoće zbog mokrog iskopanog materijala - poteškoće, koje su uvjetovane godišnjim dobom ili nepovoljnim vremenom i s kojima se normalno mora računati - uklanjanje normalnih padalina - mjere zaštite od normalnih padalina - prebacivanje strojeva i uređaja na području gradilišta, ukoliko za to nije zadužen Nalogodavac - osiguranje prometa i tekuće čišćenje korištenih javnih ulica i puteva, ukoliko su prouzročene zemljanim radovima i ukoliko se izričito ne radi o Posebnim odredbama - zaštita od prašine pri transportima - međuskladištenje na zahtjev Izvođača
B8: S cijenama nije pokriveno: - radovi držanja vode, ukoliko se ne radi o uklanjanju padalina - vrijeme zastoja pri prekidu zbog pronalaženja zaostalih streljiva i povijesno značajnih iskapanja
B9: Iskopani materijal mora načelno odvesti Izvođač na deponiju po svom izboru, radijusa maksimalno 30 km. Iskopan materijal, koji je potreban za ponovno punjenje, skladištit će se privremeno u dogovoru s Nalogodavcem, ukoliko ne može ostati na mjestu ugradnje. Ako Nalogodavac kao privremeno skladištenje ili deponiju odredi odlagalište, onda je to obvezatno za predaju ponude. U okviru izvođenja gradnje može se dogovoriti nešto drugo.
B10: Već postojeće okolčavanje, graničnike, fiksne točke, oznake visina itd. za zgradu ili za vođenje cesta i puteva, mora izvođač osigurati prije početka radova. Ako je potrebno, izvođač i investitor će zajednički izvršiti mjerenje postojećeg terena prije izvedbe radova u pogledu položaja i visine i rezultat utvrditi zapisnički. Buseni trave i iskopan gornji sloj skladištit će se prema dogovoru s Investitorom na prikladnom mjestu i na prikladnu površinu. Ako se pri iskapanju naiđe na svojstva tla, koja odstupaju od opisa radova, ili nastupe okolnosti, zbog kojih se propisani radovi iskapanja ne mogu provesti. izvođač je dužan o navedenom bez odgađanja obavijestiti investitora. Ovisno o konkretnim okolnostima, investitor i izvođač će se dogovoriti o načinu daljnjeg postupanja.
B11: Ako se na relativno nepropusnom tlu - ili na kamenim slojevima pojave podzemne ili procjedne vode, treba odmah izvijestiti nadzornog inženjera. Treba izbjegavati omekšavanje dna temelja.
B12: Kod zemljanih radova i zatrpavanja izvođač je dužan u skladu s pravilima struke ugraditi prikladan odnosno odgovarajući materijal - zemlju ili kamen, ovisno o specifičnim okolnostima terena. Ako postoje opravdane sumnje u sposobnost sabijanja, izvođač je dužan o navedenom obavijestiti Investitora ili njegovog voditelja gradnje.
B13: Izvođač je dužan prije zatrpavanja jarkova provjeriti da u prostoru, koji treba zatrpati, nema građevinskog otpada, smeća i sl., Ako se nakon provjere utvrdi da u prostoru postoji građevinski otpad, smeće i sl. izvođač je dužan o navedenom odmah izvijestiti Nalogodavca.
B14: Prije zatrpavanja ili zasipanja materijala, koji je dobiven pri kopanju na gradilištu (reciklirani materijal) odnosno materijala, koji je nabavio Izvođač, potrebno je ishoditi odobrenje Investora za njegovo korištenje.
A16: 1. | B16: Iskop zemlje C kategorije i skidanje humusa na neizgrađenom dijelu parcele
B17: Iskop u tlu C ( Pod materijalom C kategorije podrazumijevaju se svi materijali koje nije potrebno minirati, nego se mogu kopati izravno, upotrebom pogodnih strojeva. Ovdje bi spadali vezani zemljani materijali: sve gline visoke do niske plastičnosti, prašinasto tlo; kao i nevezani materijali: pijesci, pjeskoviti šljunci, prirodne kamene drobine i slični materijali. ) ktg. dubine prema projektu za potrebe pripreme i izvedbe pristupnih rampi na prilazu i ulazu u objekt . Iskopani materijal zbrinuti, uklj. pristojbu za deponiju, ili deponirati za ponovnu ugradnju u potrebnom obimu za zatrpavanje a sve u dogovoru sa nadzornim inžinjerom. Deponij se može nalaziti u krugu radijusa maksimalno 30 km
B18: Količine iskopanih materijala veće od projektiranih ili količine neodobrene od nadzornog inženjera, tj. nastale pogreškom izvođača, ne plaćaju se.
B19: U jediničnu cijenu ukalkulirati iskop u prirodno sraslom stanju bez obzira na kategoriju zemljišta, utovar iskopanog materijala u prevozno sredstvo te odvoz iskopanog materijala na privremenu gradilišnu deponiju ili nasip u krugu autokampa. U jediničnoj cijeni također je sadržano čišćenje pokosa od labilnih blokova i rastresitog materijala, planiranje iskopanih susjednih površina te izvođač nema pravo zahtjevati bilo kakvu naknadu za taj rad. Stavka uključuje strojni iskop.
B20: - strojno skidanje humusa, sloj debljine 30-40 cm | C20: m3 | D20: 2996 | E20: 0.1 | F20: =D20*E20 -> 299.6
B21: - široki iskop ispod zgrade | C21: m3 | D21: 4829 | E21: 0.1 | F21: =D21*E21 -> 482.9
B22: - iskop ispod kolno pješačkih površina | C22: m3 | D22: 1835 | E22: 16 | F22: =D22*E22 -> 29360
B23: - iskop za trakaste temelje parapeta ograde | C23: m3 | D23: 285 | E23: 20 | F23: =D23*E23 -> 5700
B24: - iskop za temelje igrala za djecu | C24: m3 | D24: 35 | E24: 100 | F24: =D24*E24 -> 3500
A26: 2. | B26: Uređenje temeljnog tla mehaničkim zbijanjem
B27: Rad obuhvaća sve aktivnosti potrebne za osposobljavanje temeljnog tla za izradu nasipa ili mršavog betona iznad njega, a obuhvaća mehaničko zbijanje na Ms≥30 MN/m2, planiranje i postizanje optimalne vlažnosti vlaženjem ili sušenjem. Uređuje se temeljno tlo ispod trakastih temelja, podnih ploča građevina, kolnih i kolnopješačkih površina. Rad obuhvaća planiranje temeljnog tla na projektom predviđene kote s točnošću ±2,00cm, privremeno rješenje odvodnje temeljnog tla i drenažnog jarka. Obračunato po m2 uređenog temeljnog tla / posteljice, za izradu razdjelnog sloja i nasipa/tamponskog sloja iznad njega.
B28: - uređenje tla ispod građevina | C28: m2 | D28: 2156 | E28: 45 | F28: =D28*E28 -> 97020
B29: - uređenje tla ispod kolno-pješačkih površina | C29: m2 | D29: 2782 | E29: 2 | F29: =D29*E29 -> 5564
A31: 3. | B31: Izrada razdjelnog sloja
B32: Dobava i ugradnja geotekstila na spoju između prirodnog tla i nasipa , mase >300 g/m2, kao sloja čistoće na planumu min preklop 20 cm. Obračun prema tlocrtnoj površini , bez dodataka na preklop.
B33: - ispod građevina | C33: m2 | D33: 2156 | E33: 40 | F33: =D33*E33 -> 86240
B34: - ispod kolno-pješačkih površina | C34: m2 | D34: 2782 | E34: 4 | F34: =D34*E34 -> 11128
A36: 4. | B36: Izrada tamponskog sloja ( sloj ispod objekta )
B37: Dobava, doprema, nabijanje i ugradnja tamponskog sloja šljunka granulacije 0-32 mm, debljine 30cm, ispod poda objekta, a između nadtemeljnih greda. Slojeve šljunka u debljini od 15 cm zbiti do zbijenosti Ms=60MN/m2. U cijenu uključeno i planiranje na projektiranu kotu. Nasipavanjem oblikovati posteljicu za temeljnu ploču sa svim zadebljanjima - vidjeti plan oplate. Obračun po m3 izvedenog tampona u zbijenom stanju. Ispitivanje zbijenosti u cijeni stavke.
B38: Obračun po m3 | C38: m3 | D38: 4937 | E38: 0.1 | F38: =D38*E38 -> 493.7
A40: 5. | B40: Zatrpavanje temelja oko zgrade
B41: Zatrpavanje temelja oko zgrade materijalom iz iskopa. Prilikom nasipavanje potrebno je izvesti grubo planiranje terena. Količina je iskazana u zbijenom stanju zemlje.
B42: Obračun po m3 u zbijenom stanju | C42: m3 | D42: 794 | E42: 12 | F42: =D42*E42 -> 9528
A44: 6. | B44: Nasipavanje zemlje na neizgrađenom dijelu parcele
B45: Nasipavanje plodne zemlje iz iskopa na neizgrađenom dijelu parcele. Prilikom nasipavanje potrebno je izvesti grubo planiranje terena. Količina je iskazana u zbijenom stanju zemlje.
B46: Obračun po m3 u zbijenom stanju | C46: m3 | D46: 1123 | E46: 12 | F46: =D46*E46 -> 13476
A48: 7. | B48: Odvoz iskopanog materijala
B49: Utovar na kamion i odvoz viška iskopanog materijala na deponij. U cijeni utovar, istovar, transport te sve manipulativne radnje tijekom procesa. Deponij se nalazi u krugu radijusa do 30 km.
B50: Obračun po m3 odvezene zemlje u sraslom stanju | C50: m3 | D50: 8063 | E50: 1 | F50: =D50*E50 -> 8063
...

Sheet III OPL_KOLNIK
A2: III | B2: PJEŠAČKO KOLNIČKA KONSTRUKCIJA
A4: 1. | B4: Izrada posteljice od zrnatog kamenog materijala bez veziva debljine, zbijenosti Ms=40MN/m2
B5: Nakon preuzimanja ispitanog planuma u pogledu zabijenosti, ravnosti projektiranih nagiba, a sve prema važećim normama, pristupa se izradi nosivog sloja od zrnatog kamenog materijala. Za izradu ovog sloja treba upotrijebiti zrnati kameni materijal za koji je pribavljen atest o njegovoj podobnosti za izradu nosivog sloja. Kameni materijal se mora navoziti (navlačiti) tako da se ne ošteti izvedeni profil posteljice. Zahtjevana zbijenost za kolnik sa asfaltnim zastorom i sve ostale kolnopješačke površine iznosi Ms = 40 MN/m2. Sve nepravilnosti utvrđene za vrijeme zbijanja mora izvođač o svom trošku ukloniti. Sva tekuća i kontrolna ispitivanja treba vršiti prema važećim standardima i propisima u toku građenja. Ova stavka obuhvaća: a) pribavljanje atesta za kameni materijal prije početka radova Za prometnice i pješačke staze materijal 0/32. b) dopremu, razgrtanje, planiranje i profiliranje tamponskog sloja c) kontrola ravnine i visine izvedenog sloja d) sve radove na ispitivanju koji su potrebni za pravilno izveden sloj prema HRN U9.020. ili jednakovrijedno ___________. Obračunato po m3 ugrađenog sloja u zbijenom stanju, prema poprečnim profilima do potpune pogonske gotovosti.
B6: - drobljenac ispod asfalta frakcije 0/64mm d=50cm | C6: m3 | D6: 498 | E6: 50 | F6: =D6*E6 -> 24900
B7: - drobljenac ispod travnih rešetki frakcije 0/64mm d=50cm | C7: m3 | D7: 514 | E7: 50 | F7: =D7*E7 -> 25700
B8: - drobljenac ispod betonskih opločnika frakcije 0/64mm d=50cm | C8: m3 | D8: 281 | E8: 50 | F8: =D8*E8 -> 14050
B9: - drobljenac ispod gumene podloge frakcije 0/64mm d=50cm | C9: m3 | D9: 115 | E9: 50 | F9: =D9*E9 -> 5750
A11: 2. | B11: Izrada nosivog sloja od zrnatog kamenog materijala bez veziva debljine, zbijenosti Ms=100MN/m2
B12: Nakon preuzimanja ispitanog planuma u pogledu zabijenosti, ravnosti projektiranih nagiba, a sve prema važećim normama, pristupa se izradi nosivog sloja od zrnatog kamenog materijala. Za izradu ovog sloja treba upotrijebiti zrnati kameni materijal za koji je pribavljen atest o njegovoj podobnosti za izradu nosivog sloja. Kameni materijal se mora navoziti (navlačiti) tako da se ne ošteti izvedeni profil posteljice. Zahtjevana zbijenost za kolnik sa asfaltnim zastorom i sve ostale kolnopješačke površine iznosi Ms = 100 MN/m2. Sve nepravilnosti utvrđene za vrijeme zbijanja mora izvođač o svom trošku ukloniti. Sva tekuća i kontrolna ispitivanja treba vršiti prema važećim standardima i propisima u toku građenja. Ova stavka obuhvaća: a) pribavljanje atesta za kameni materijal prije početka radova Za prometnice i pješačke staze materijal 0/32. b) dopremu, razgrtanje, planiranje i profiliranje tamponskog sloja c) kontrola ravnine i visine izvedenog sloja d) sve radove na ispitivanju koji su potrebni za pravilno izveden sloj prema HRN U9.020. ili jednakovrijedno ___________. Obračunato po m3 ugrađenog sloja u zbijenom stanju, prema poprečnim profilima do potpune pogonske gotovosti.
B13: - drobljenac ispod asfalta frakcije 0/64mm d=40cm | C13: m3 | D13: 398 | E13: 50 | F13: =D13*E13 -> 19900
B14: - drobljenac ispod travnih rešetki frakcije 0/64mm d=40cm | C14: m3 | D14: 411 | E14: 50 | F14: =D14*E14 -> 20550
B15: - drobljenac ispod betonskih opločnika frakcije 0/64mm d=40cm | C15: m3 | D15: 224 | E15: 50 | F15: =D15*E15 -> 11200
B16: - drobljenac ispod gumene podloge frakcije 0/64mm d=40cm | C16: m3 | D16: 92 | E16: 50 | F16: =D16*E16 -> 4600
A18: 3. | B18: Izvedba kolničkih rubnjaka 18/24 i pješačkih rubnjaka 10/22
B19: Ova stavka obuhvaća: *dobavu gotovih betonskih rubnjaka iz betona C 40/50 te razvoz rubnjaka po gradilištu, *pripremu podloge, čišćenje, otkop ili nasipavanje sa nabijanjem kod podloge od kamena, * izrada i ugradnja betona C 12/15 vel. temelja 20/30 cm, za rubnjak 10/22 i veličine 30/40 za rubnjak 18/24 - podloge i zaloge, *polaganje rubnjaka u beton po pravcu i niveleti sa razmakom (spojnicom) do 0,50 cm, *svi prijevozi i prijenosti betona i pomoćnog materijala, *zalijevanje spojnica cementnim mortom omjera 1:2, *njega betona, *ispitivanje kvalitete rubnjaka sa pribavljanjem atesta. Izvedba radova, obračun radova i kontrola kvalitete prema OTU 3-04.7.1. ili jednakovrijedno. Rubnjake koji se izvode u radiusu izvesti od komada proizvedenih u projektiranom radiusu. Obračun po m1 ugrađenog rubnjaka uzdignuto i upušteno do potpune pogonske gotovosti.
B20: - rubnjaci 18/24 cm uz kolnik, temelj 0,12m3/m' (beton C12/15) uzdignuti i upušteni | C20: m1 | D20: 340 | E20: 30 | F20: =D20*E20 -> 10200
B21: - rubnjaci 10/22 cm uz uređene površine, temelj 0,07m3/m' (beton C12/15) uzdignuti i upušteni | C21: m1 | D21: 1045 | E21: 20 | F21: =D21*E21 -> 20900
B23: OPĆA NAPOMENA ZA IZRADU SVIH VRSTA ASFALTERSKIH RADOVA
B24: U cijenu mora biti uračunato: a) sva potrebna odsijecanja asfalta kao i prskanja podloge b) tekuća i kontrolna ispitivanja, te pribavljanje atesta od ovlaštenog poduzeća.
A26: 4. | B26: Izvedba AC 32 base, BIT 50/70 AG6 M 2E, debljine d=8cm
B27: Izvedbi donjeg nosivog sloja može se prići nakon ispitanog i po nadzornom inženjeru preuzetom donjem nosivom sloju. Ova stavka obuhvaća: - dobavu i dopremu asfaltne mješavine d=8cm - čišćenje i prskanje podloge za AC 32 base - razastiranje, valjanje i njega AC 32 base. Obuhvaćen je sav materijal, rad i alat na izradi sloja kao i sva potrebna tekuća i kontrolna ispitivanja s izradom atesta za dokaz kvalitete ugrađenog sloja. Asfaltiranje se vrši strojno i ručno. Obračunato po m2 ugrađenog sloja, sve do potpune pogonske gotovosti.
C28: m2 | D28: 994 | E28: 30 | F28: =D28*E28 -> 29820
A30: 5. | B30: Izvedba završnog sloja kolnika od asfaltbetona AC 11 surf, BIT50/70, AG3 M 3E, debljine d= 4 cm
B31: Izradi ovog sloja može se prići nakon propisno izvedenog i po nadzornom inženjeru preuzetom AC base. Ova stavka obuhvaća: - dobavu i dopremu asfaltne mješavine, - čišćenje i prskanje podloge za asfaltbeton, - razastiranje, valjanje i njega asfaltbetona. Obuhvaćen je sav materijal, rad i alat na izradi sloja kao i sva potrebna tekuća i kontrolna ispitivanja s izradom atesta za dokaz kvalitete ugrađenog sloja. Asfaltiranje se vrši strojno i ručno. Obračunato po m2 ugrađenog sloja, debljine d=4cm, sve do potpune pogonske gotovosti.
C32: m2 | D32: 994 | E32: 25 | F32: =D32*E32 -> 24850
A34: 6. | B34: Izvedba travne rešetke s ispunom supstratom
B35: Dobava i ugradnja travnih rešetki od recikliranog polietilena HDPE, dimenzija 620x620x100mm za parkirališta teretnih vozila i protupožarne puteve, atestiranih za vatrogasni pristup (100 kN/osovina). Površina po kom: 0,403 m2/kom.
B36: Stavka obuhvaća izradu, dobavu potrebnih materijala i ugradnju svih slojeva završne podne obloge travnim rešetkama na nosivi sloj drobljenog kamenog materijala.
B37: Postava travnih rešetki se vrši na dobro uvaljani sloj pijeska za poravnanje granulacije 0/4mm debljine sloja 5 cm i geotekstil 300g/m2. Uključeno u jediničnu cijenu stavke.
B38: Elementi travne rešetke se polažu s minimalnom širinom reške uz dilataciju od 1cm do rubnjaka.
B39: Izrezivanje rubnih elemenata radi upasivanja do izvedenog rubnjaka i sl. uključeno je u cijenu.
B40: Travne rešetke se pune supstratom, mješavinom kvalitetne vrtne zemlje i mješavinom komposta i treseta (mješavina 50% kvalitetna vrtna zemlja, 25% kompost, 25% treset). Zemlja u travnim rešetkama se nabija mlazom minivoša.
B41: Kada nivo zemlje padne za 2cm, sije otporna travna mješavina (1 kg za 15 m2), te se dodaje sporootpuštajuće gnojivo kao npr. tip Osmocote Maintenance ili jednakovrijedan proizvod, doza prema uputi proizvođača.
B42: Nakon toga se sjeme prekrije u sloju 2 cm sa supstratom, mješavinom kvalitetne vrtne zemlje te mješavinom komposta i treseta (mješavina 50% kvalitetna vrtna zemlja, 25% kompost, 25% treset)
B43: U cijenu uključeni materijal i radovi.
B44: Sastav travne mješavine za travne rešetke:
B45: Poa pratensis 40%, Festuca nigrescens 30%, Festuca ovina 15%, Festuca rubra ssp.rubra 15%
B46: Tijekom klijanja, trava se treba redovno navodnjavati. Preko netom posijane trave tijekom klijanja ne smije se voziti.
... B48: Sve uključeno u jediničnu cijenu stavke.
B49: Obračunato po m2 do potpune gotovosti. | C49: m2 | D49: 1029 | E49: 55 | F49: =D49*E49 -> 56595
...

Sheet IV AB RADOVI
A2: IV | B2: BETONSKI I ARMIRANOBETONSKI RADOVI
A4: 1. | B4: Trakasti temelji
B5: Dobava materijala, transport i betoniranje AB trakastih temelja objekta poprečnog presjeka 60x50 cm, 80x50 cm 130x50 cm, 150x50 cm, 195x50 cm, u potrebnoj oplati Izvesti betonom C25/30 sa maximalnim V/C faktorom 0,6 , sa dodatkom za vodonepropusnost kvalitete VDP 2. Beton srednjeg presjeka, armirati sa armaturom kvalitete B500B. Svi distanceri i držači armature u cijeni. Zaštitni sloj betona prema armaturi izvesti prema statičkom izračunu i uvjetima djelovanja okoline-XC2 ( vlažna okolina rijeđe suha ). Obračun za kompletan rad i materijal iz opisa po m3 ugrađenog betona, m2 oplate. U cijenu je uključena dobava i ugradba betona, njega betona, te dobava i postava oplate, uključujuću skidanje i čišćenje oplate, a sve prema pravilima struke.
B6: - beton C25/30 | C6: m3 | D6: 243 | E6: 900 | F6: =D6*E6 -> 218700
B7: - oplata | C7: m2 | D7: 715 | E7: 50 | F7: =D7*E7 -> 35750
A9: 2. | B9: AB podna ploča prizemlja
B10: Dobava materijala, transport i betoniranje AB podne ploče prizemlja debljine 15 cm, u potrebnoj oplati Izvesti betonom C25/30 sa maximalnim V/C faktorom 0,6 , sa dodatkom za vodonepropusnost kvalitete VDP 2. Ploče se izvode ravne ili u padu prema planu oplate. Beton srednjeg presjeka, armirati sa armaturom kvalitete B500B. Svi distanceri i držači armature u cijeni. Zaštitni sloj betona prema armaturi izvesti prema statičkom izračunu i uvjetima djelovanja okoline-XC2 ( vlažna okolina rijeđe suha ). Obračun za kompletan rad i materijal iz opisa po m3 ugrađenog betona, m2 oplate. U cijenu je uključena dobava i ugradba betona, njega betona, te dobava i postava oplate, uključujuću skidanje i čišćenje oplate, a sve prema pravilima struke.
B11: beton C25/30 | C11: m3 | D11: 308 | E11: 180 | F11: =D11*E11 -> 55440
B12: oplata | C12: m2 | D12: 78 | E12: 50 | F12: =D12*E12 -> 3900
A14: 3. | B14: Armirano betonski nadtemeljni zidovi
B15: Betoniranje armirano betonskih nadtemeljnih zidova u dvostranoj glatkoj oplati, debljine 20-25 cm, betonom C25/30 sa maximalnim V/C faktorom 0,6 , sa dodatkom za vodonepropusnost kvalitete VDP 2. Beton srednjeg presjeka, armirati sa armaturom kvalitete B500B. Svi distanceri i držači armature u cijeni. Zaštitni sloj betona prema armaturi izvesti prema statičkom izračunu i uvjetima djelovanja okoline-XC2 ( vlažna okolina rijeđe suha ). Betoniranje zidova izvesti sukladno Programu kontrole i kvalitete, u pripremljenu dvostranu glatku oplatu uz obavezno pervibriranje. U oplati zida predvidjeti sva oslabljenja i otvore, te ugraditi sve potrebne instalacije. Razred konzistencije S3. Razred sadržaja klorida Cl 0.2. Razred maksimalnog zrna agregata Dmax16. Nakon ugradnje betona potrebno je obavezno njegovati beton sukladno Programu kontrole i kvalitete. Cijena stavke uključuje nabavu i dopremu na gradilište betona klase C25/30, spravljenog u betonari, te sav potreban osnovni i pomoćni materijal, te rad ljudi i strojeva pri ugradnji.
B16: - beton C25/30 | C16: m3 | D16: 615 | E16: 1 | F16: =D16*E16 -> 615
B17: - oplata | C17: m2 | D17: 4438 | E17: 0.1 | F17: =D17*E17 -> 443.8
A19: 4. | B19: Krovna ploča
B20: Dobava materijala, transport i betoniranje krovnih ravnih AB ploča sa i bez konzolnog prepusta na krajevima sa uključenim pripadnim gredama ispod ili iznad ploče. Izvesti sa betonom srednjeg presjeka ( d= 20 cm) C25/30. Ploče izvesti bez neravnina i gnijezda. Prilikom betoniranja ugraditi sve elemente predviđene za ugradbu (prodori kroz ploču, ventilacijski otvori i sl.) Visina podupiranja do max. 7,0 m. Ploče armirati prema statičkom računu i planu armature sa armaturom kvalitete B500B. Zaštitni sloj betona prema armaturi izvesti prema statičkom izračunu i uvjetima djelovanja okoline-XC1. Svi distanceri i držači armature u cijeni. Izvedbu uskladiti sa betoniranjem osnovne nosive AB konstrukcije zidova, stupova i greda. Obračun za kompletan rad i materijal iz opisa po m3 ugrađenog betona, m2 oplate.
B21: U cijenu je uključena dobava i ugradba betona, njega betona, te dobava i postava oplate, uključujuću skidanje i čišćenje oplate, dobava i ugradnja armature, te po m1 oplate visine 20 i 25 cm za rubove. Izvođač je dužan u potpunosti izvoditi glatke i ravne betone u skladu sa HRN ili jednakovrijedno ___________________.
B22: U oplati izvesti prodore za rešetke za ozračivanje - detalji u strojarskom projektu.
B23: Ploča ravnog krova d=20 cm
B24: - beton C25/30 | C24: m3 | D24: 391 | E24: 180 | F24: =D24*E24 -> 70380
B25: - oplata horizontalna | C25: m2 | D25: 1923 | E25: 50 | F25: =D25*E25 -> 96150
B26: - oplata vertikalna | C26: m2 | D26: 112 | E26: 50 | F26: =D26*E26 -> 5600
A28: 5. | B28: Armirano betonski zidovi
B29: Betoniranje armirano betonskih nosivih zidova u glatkoj oplati završno spremno za soboslikarsku obradu ili keramičarske radove, debljine 20-25 cm, betonom klase C25/30 pripremljenim u betonari. Betoniranje zidova izvesti sukladno Programu kontrole i kvalitete, u pripremljenu dvostranu glatku oplatu uz obavezno pervibriranje. U oplati zida predvidjeti sva oslabljenja i otvore, te ugraditi sve potrebne instalacije. Razred čvrstoće betona C25/30. Razred izloženosti XC2. Razred konzistencije S3. Razred sadržaja klorida Cl 0.2. Razred maksimalnog zrna agregata Dmax16. Nakon ugradnje betona potrebno je obavezno njegovati beton sukladno Programu kontrole i kvalitete. Cijena stavke uključuje nabavu i dopremu na gradilište betona klase C25/30, spravljenog u betonari, te sav potreban osnovni i pomoćni materijal, te rad ljudi i strojeva pri ugradnji.
B30: zidovi vanjski, atika krova i odušnici
B31: - beton C25/30 | C31: m3 | D31: 73 | E31: 180 | F31: =D31*E31 -> 13140
B32: - oplata | C32: m2 | D32: 589 | E32: 50 | F32: =D32*E32 -> 29450
A34: 6. | B34: Armirano betonski stupovi i vertikalni serklaži
B35: Betoniranje armirano betonskih stupova i vertikalnih serklaža u glatkoj oplati završno spremno za soboslikarsku obradu ili keramičarske radove, betonom klase C25/30 pripremljenim u betonari. Stupovi su sastavni djelovi strukture nosivie konstrukcije. Betoniranje stupova izvesti sukladno Programu kontrole i kvalitete, u pripremljenu četverostranu glatku oplatu uz obavezno pervibriranje. U oplati zida predvidjeti sva oslabljenja i otvore, te ugraditi sve potrebne instalacije. Razred čvrstoće betona C25/30. Razred izloženosti XC2. Razred konzistencije S3. Razred sadržaja klorida Cl 0.2. Razred maksimalnog zrna agregata Dmax16. Cijena stavke uključuje nabavu i dopremu na gradilište betona klase C25/30, spravljenog u betonari, te sav potreban osnovni i pomoćni materijal, te rad ljudi i strojeva pri ugradnji.
B36: - beton C25/30 | C36: m3 | D36: 47 | E36: 250 | F36: =D36*E36 -> 11750
B37: - oplata | C37: m2 | D37: 404 | E37: 60 | F37: =D37*E37 -> 24240
A40: 7. | B40: Armirano betonske grede, nadvoji i horizontalni serklaži
B41: Betoniranje armirano betonskih greda, nadvoja i horizontalnih serklaža u glatkoj oplati završno spremno za soboslikarsku obradu ili keramičarske radove, betonom klase C25/30 pripremljenim u betonari. Grede su sastavni djelovi strukture nosive konstrukcije. Betoniranje greda izvesti sukladno Programu kontrole i kvalitete, u pripremljenu trostranu glatku oplatu uz obavezno pervibriranje. U oplati zida predvidjeti sva oslabljenja i otvore, te ugraditi sve potrebne instalacije. Razred čvrstoće betona C25/30. Razred izloženosti XC2. Razred konzistencije S3. Razred sadržaja klorida Cl 0.2. Razred maksimalnog zrna agregata Dmax16. Nakon ugradnje betona potrebno je obavezno njegovati beton sukladno Programu kontriole i kvalitete. Cijena stavke uključuje nabavu i dopremu na gradilište betona klase C25/30, spravljenog u betonari, te sav potreban osnovni i pomoćni materijal, te rad ljudi i strojeva pri ugradnji.
B42: - beton C25/30 | C42: m3 | D42: 36 | E42: 250 | F42: =D42*E42 -> 9000
B43: - oplata | C43: m2 | D43: 145 | E43: 70 | F43: =D43*E43 -> 10150
A45: 8. | B45: Armirano betonska stubišta na tlu
B46: Dobava materijala, transport i betoniranje AB stubišta betonom C25/30 u potrebnoj glatkoj oplati. Ploče izvesti bez neravnina i gnijezda. Stubište armirati prema statičkom računu i planu armature sa armaturom kvalitete B500B. Zaštitni sloj betona prema armaturi izvesti prema statičkom izračunu i uvjetima djelovanja okoline XC2. Svi distanceri i držači armature u cijeni. Izvedbu uskladiti sa betoniranjem osnovne nosive AB konstrukcije zidova, stupova i greda. Obračun za kompletan rad i materijal iz opisa po m3 ugrađenog betona, m2 oplate. U cijenu je uključena dobava i ugradba betona, njega betona, te dobava i postava oplate, uključujuću skidanje i čišćenje oplate, dobava i ugradnja armature.
B47: - beton | C47: m3 | D47: 6 | E47: 300 | F47: =D47*E47 -> 1800
B48: - oplata | C48: m2 | D48: 30 | E48: 100 | F48: =D48*E48 -> 3000
A50: 9. | B50: Podložni beton
B51: Dobava materijala, transport i betoniranje podložne betonske podloge C12/15 debljine 10 cm ispod temeljnih ploča i drugih elemenata na mjestu denivelacije i drugih lokacija u i oko objekta. U cijenu je uključena dobava i ugradba betona, njega betona, sve prema pravilima struke.
...

Sheet V ZIDARSKI
A2: V | B2: ZIDARSKI RADOVI
A4: 1. | B4: Zidanje zidova blok opekom
B5: Dobava i zidanje zidova prema grafičkim prilozima. Zidanje se izvodi zidanim elementima skupine 2 (njega uranjanjem u vodu) debljine 25 cm u jednom sloju, srednje tlačne čvrstoće 10 N/mm2 i mortom opće namjene minimalne marke M7,5. Prvi red blokova potrebno je postaviti na idealno ravan u oba smjera sloj cemetnog morta 1:2 debljine 2-5 cm ovisno o točnosti izvedene podloge. Sve ostale horizontalne i vertikalne sljubnice (fuge) potrebno je ispuniti po cijeloj površini mortom max. debljine 15 mm. Prilikom zidanja nije dozvoljeno preklapanje vertikalnih sljubnica. Min. razmak između vertikalnih sljubnica dva susjedna reda smije biti 10 cm. Obračun po m3 zida.
C6: m3 | D6: 394 | E6: 250 | F6: =D6*E6 -> 98500
A8: 2. | B8: Žbukanje zidova
B9: Dobava i izrada grube i fine žbuke unutrašnjih i vanjskih površina zidova od blok opeke produžnom vapneno-cementnim mortom M 2,5 debljine 2 cm. Površine prethodno pripremiti za žbukanje špricom cementnim mlijekom. U cijeni stavke je i rabitiziranje spojeva različitih materijala. Potrebna radna skela je u cijeni stavke. Otvori nisu odbijani, te je cijena izrade špaleta u cijeni stavke. Obračun po m2 zida.
C10: m2 | D10: 2997 | E10: 15 | F10: =D10*E10 -> 44955
A12: 3. | B12: Cementni estrih s plivajućim podom
B13: Dobava i ugradba plivajućeg cementnog estriha (2200 kg/m3), debljine 4-7,5 cm u slojevima poda prizemlja i kata armiranog rabitz pletivom. Na spoju sa zidovima ugraditi traku elasticificiranog polistirena (eEPS), debljine d=2cm, visine od podložne toplinske /zvučne izolacije, do 1cm iznad razine završenog i poravnatog estriha. U stavku je uključena i nabava materijala i postavljanje zaštitne PE folije, koja se postavlja na podložnu toplinsku/zvučnu izolaciju, te podiže uz rubnu traku EPS-a, a sve prije ugradnje estriha. Obračun po m2 izvedenog estriha.
B14: Glazuru , minimalne čvrstoće na tlak od 25 N/mm2 ,rabicirati pocinčanim, punktiranim pletivom Φ 5 mm sa oknima max 10x10 cm ( ili polikarbonatnim vlaknima).
B15: Izvoditi radne reške rezanjem u 2/3 debljine sloja. Izvoditi ih da ni jedna dimenzije polja estriha nije veća od 10 m te ih izvoditi ispod svih vratiju. ( U slučaju uskih i dugih prosotrija postaviti radne reške svakih 10 m, tj, ravnomjerno ih rasporediti po duljoj stranici tog prostora). Izvedba radnih reški na način da je max površina plivajućeg poda unutar radnih reški 30 m2.
B16: Gornju površinu zagladiti do crnog sjaja strojnom obradom. Izvesti rubne reške koje trajno razdvajaju glazuru i zidove, a načinjene su od polistirena debljine min 1 cm. Obračun po m2 izvedene glazure zajedno sa PVC folijom i "rabic" pletivom
B17: - plivajući pod s estrihom 6 cm | C17: m2 | D17: 1015 | E17: 16 | F17: =D17*E17 -> 16240
B18: - plivajući pod s estrihom 7 cm | C18: m2 | D18: 374 | E18: 16 | F18: =D18*E18 -> 5984
B19: - plivajući pod s estrihom u padu na terasama 5-10 cm | C19: m2 | D19: 412 | E19: 18 | F19: =D19*E19 -> 7416
A22: 4. | B22: Dobava i ugradba aluminijskih pragova
B23: Dobava i ugradba aluminijskih pragova od kutnog profila L 30 x 30 mm na mjestima gdje je razlika u podu po visini ili vrsti materijala. U jediničnoj cijeni učvršćenje aluminijskog kutnog profila za drveni ili aluminijski dovratnik. Obračun po komadu ugrađenog praga i po m1ugrađenog profila na razdjeljivanim površinama.
B24: prag dužine do 1 m | C24: kom | D24: 40 | E24: 40 | F24: =D24*E24 -> 1600
A26: 5. | B26: Zatvaranje naknadno izvedenih šliceva.
B27: Zatvaranje naknadno izvedenih šliceva izvedbom grube i fine žbuke i rabiciranjem spoja sa okolnom površinom što ulazi u cijenu. Širina rabica cca 20 cm. Izvodi se nakon položene instalacije ili druge ugrađene opreme.
C28: m1 | D28: 250 | E28: 20 | F28: =D28*E28 -> 5000
A30: 6. | B30: Zatvaranje prodora u zidu i podu
B31: Dobava i doprema materijala i zatvaranje prodora u zidu i podu nakon postave instalacija. U cijenu uključiti sve potrebne predradnje, čišćenje, otprašivanje, povezivanje s postojećim konstrukcijama. Izvesti špricanje cijele površine prodora rijetkim cementnim mortom i zapunjavanje prodora betonom. Zidni prodori dimenztija 30/30 cm, podni prodori dimenzija 20/20 cm.
B32: - zidni prodori | C32: kom | D32: 15 | E32: 50 | F32: =D32*E32 -> 750
B33: - podni prodori | C33: kom | D33: 35 | E33: 50 | F33: =D33*E33 -> 1750
A35: 7. | B35: Šljunak
B36: Dobava oblutaka granulacije 30-50 mm. Sloj oblutaka je predviđen na ravnom krovu u debljini od 5,0 cm. U stavku uključen sav potreban materijal i pribor. Obračun po m3 izvedene šljunčane površine.
C37: m3 | D37: 95 | E37: 250 | F37: =D37*E37 -> 23750
A39: =A2 -> V | B39: =B2 -> ZIDARSKI RADOVI | C39: UKUPNO | F39: =SUM(F1:F38) -> 205945

Sheet VI IZOLAT
A2: VI | B2: IZOLATERSKI RADOVI
A4: 1. | B4: Hidroizolacija podne ploče i zidova u tlu
B5: Dobava i izvedba horizontalne i vertikalne HI ploče na tlu i zidova u tlu. Hidroizolacija se izvodi iz dva sloja fleksibilne polimer bitumenske trake (2x5 mm) uz predhodni hladan premaz resitolom. Sve izvesti prema uputi proizvođača HI. Staklena tkanina impregnirana i obostrano obložena fleksibilnom polimer bitumenskom masom. Traka je zaštićena obostrano folijom. Trake se izvode na prethodno izvedene nadtemlne zidove i donju betonsku podlogu Uključen kompletan rad, materijal i pribor. Obračun po m² izvedene HI.
B6: - horizontalna hidroizolacija | C6: m² | D6: 1596 | E6: 27 | F6: =D6*E6 -> 43092
A8: 2. | B8: Izvedba tekuće hidroizolacije poda i zidova u sanitarijama i vanjskih površina podova
B9: Dvokomponentni visokoelastični cementni mort za hidroizolaciju + armirna alkalno-otporna mrežica od staklenih vlakana. Izvodi se na podove i na zidove do visine od 2,2 m. Izvedba hidroizolacijskog sustava dvokomponentnim visoko fleksibilnim cementnim mortom. . Hidroizolacija mora zadovoljiti normu EN 14891 ili jednakovrijedno _________________________ te premostiti pokotinu ≥ 0,75 mm pri temperaturama od -20°C i +23°C. Izvedba u 2 sloja ukupne debljine min. 2 mm, s tim da se u prvi sloj utisne mrežica od alkalno otpornih staklenih vlakana. Na mjestima dilatacijskih fuga, spojeva između vodoravnih i okomitih površina te odvoda, potrebno je ugraditi gumiranu poliestersku traku s alkalno otpornim filcem, kutne elemente i manžete. Trake se međusobno lijepe super ljepilom za spajanje PVC cijevi. Ljepilo nakon sušenja mora biti otporno na hladnu i vruću vodu. Otpornost na smrzavanje do -15°C, a otpornost na grijanje +100°C.
B10: Za sve ostalo prema uputama proizvođača
B11: Obračun po m2 izvedene hidroizolacije
B12: - podovi | C12: m2 | D12: 145 | E12: 26 | F12: =D12*E12 -> 3770
B13: - zidovi do visine od 2,2 m | C13: m2 | D13: 196 | E13: 26 | F13: =D13*E13 -> 5096
B14: - vanjske površine podova | C14: m2 | D14: 392 | E14: 26 | F14: =D14*E14 -> 10192
A16: 3. | B16: Toplinska izolacija ploča i zidova u zemlji
B17: Dobava i ugradnja tvrdih izolacijskih ploča iz ekstrudiranog, pjenjenog polistirena, pjenjene s CO2, bez freona obostrano strukturirane površine ili jednakovrijedan. Izvodi se kao vanjska toplinska izolacija ploča i zidova u tlu debljine 10 cm.
B18: Tehničke osobine Nazivna vrijednost toplinske provodljivosti (λD ) 0,034 - 0,038 W(m·K) HRN EN 13164 ili jednakovrijedno ___________________________ Tlačno opterećenje kod 10 % deformacije 0,30 CS(10\Y)300 N/mm 2 HRN EN 826 ili jednakovrijedno ________________________ Dugotrajno upijanje vlage (cijele ploče) ≤ 0,7 WL(T)0,7 % HRN EN 12087 ili jednakovrijedno ______________________________ Difuzijsko upijanje vlage (cijele ploče) WD(V)3 HRN EN 12088 ili jednakovrijedno ___________________________ Otpornost protiv naizmjeničnog smrzavanja– odmrzavanja (maksimalno upijanje vlage) ≤ 1,0 FT2 % HRN EN 12087 ili jednakovrijedno ___________________________ Dimenzijska promjena pri 90 % relativnoj vlažnosti zraka i 70 °C ≤ 5 DS(TH) % HRN EN 1604 ili jednakovrijedno ____________________________ Dimenzijska promjena pri opterećenju 0,04 N/mm 2 i 70 °C ≤ 5 DLT(2)5 % HRN EN 1605 ili jednakovrijedno ___________________________ Požarna otpornost po EN (euro klasifikacija) E HRN EN 13501-1 ili jednakovrijedno ______________________________ Difuzijska otpornost vodenoj pari (μ) 80-250 HRN EN 12086 ili jednakovrijedno ___________________________ Kapilarnost 0 Granične temperature upotrebe -50 do + 70 °C °C
B20: Obračun po m2 izvedene toplinske izolacije
B21: - zidovi u tlu d=10 cm | C21: m2 | D21: 227 | E21: 20 | F21: =D21*E21 -> 4540
B22: - izolacija iznad podne ploče d=10 cm | C22: m2 | D22: 1268 | E22: 16 | F22: =D22*E22 -> 20288
A24: 4. | B24: Izolacija od udarnog zvuka s EPS-T
B25: Dobava i postava sloja izolacije protiv udarnog zvuka: pjenaste folije od ekspandiranog ekstrudiranog polistirena, na armirano betonsku ploču. Izolacija se postavlja u dva sloja, s izmaknutim preklopima, ukupne debljine 1+1 cm. Sve prodore vertikalnih instalacijskih cijevi kroz međukatnu konstrukciju i plivajući pod treba izolirati omatanjem zvučnoizolacijskom folijom kako bi se spriječio izravan dodir cijevi i tvrdog cementnog estriha ili betona. Zvučna izolacija polaže se s preklopima po punoj površini podne ploče (min. 10 cm), a uza zid se povija do visine postavljanja rubne trake EPS-a. U stavku uključen sav potrebni rad, osnovni i pomoćni materijal.
C26: m2 | D26: 1268 | E26: 3.5 | F26: =D26*E26 -> 4438
A28: 5. | B28: Geotekstil
B29: Dobava materijala i izvedba geotekstila 300g/m2 kao razdjelni sloj između AB podne ploče i temoizolacije podova na tlu. Obračun po m2.
C30: m2 | D30: 1268 | E30: 3.5 | F30: =D30*E30 -> 4438
A32: 6. | B32: Čepasta folija
B33: Zaštita vertikalne hidroizolacije zidova i XPSa plastičnom zaštitnom folijom (čepasta folija) s kvržicama u rolama. Kvržice visine 7-8 mm. Stazu učvrstiti tipskim čavlićima s odgovarajućim podlošcima. Širina preklopa staze 10 cm. Po m2.
C34: m2 | D34: 294 | E34: 6 | F34: =D34*E34 -> 1764
A36: =A2 -> VI | B36: =B2 -> IZOLATERSKI RADOVI | C36: UKUPNO | F36: =SUM(F5:F34) -> 97618

Sheet VII KROV
A2: VII | B2: KROV
A5: 1. | B5: Ravni krov
B6: Dobava i ugradba parne brane na ravnom/kosom krovu; fleksibilne polimerbitumenske trake, uložak Al folija. (HRN U.M3.230 ili jednakovrijedno), polagati na razdijelni sloj, geotekstil min. 300g/m2. Istu vrstu geotekstila poloižiit na TPO kao razdijelni sloj prema šljunku koji se postavlja iznad. U stavku uključiti oba sloja geotekstila.
B7: Dobava i postava ploča od mineralne vune (MW), kaširane s gornje strane, polutvrde, hidrofobirane (prema HRN EN 13163 ili jednakovrijedno), d=10-20 cm, na ravni krov. Ugradnja u dva sloja, s međusobno izmaknutim sudarnicama (za MW homogene gustoće), ili jednoslojno (za MW dvoslojne gustoće), na prethodno postavljenu parnu branu (obračunato posebno). Klasa negorivosti min. A1, λ ≤ 0,036 W/m2K. Tlačna čvrstoća σ10 ≤ 70 kPa (prema HRN EN 826), delaminacijska čvrstoća σmt = 15 kPa (prema HRN EN 1607 ili jednakovrijedno), točkasto opterećenje Fp ≥ 550 N (prema HRN EN 12430 ili jednakovrijedno). Sav materijal, pomoćni materijal, ugradna i pričvrsna sredstva odrediti prema uputama proizvođača i pravilima struke. U stavku uključen sav potrebni rad, materijal i pomoćni materijal.
B8: Nadozid krova / atiku obložiti s pločama istih karakteristika kao i za ravni krov. Debljina ploča za zid je 5 cm. Dok se na gornju plohu nadozida postavljaju iste ploče debljine 5 cm.
B9: Dobava i postava hidroizolacije sa TPO sintetičkom hidroizolacijskom folijom kao, debljine 1.5mm, mase 1,5 kg/m2 (EN 1849-2 ili jednakovrijedno), paropropusnost 150.000 u (EN 1931 ili jednakovrijedno), vlačne čvrstoće ≥ 9 N/mm2 (EN 12311-2 ili jednakovrijedno), izduženja ≥ 550% (EN 12311-2 ili jednakovrijedno), UV otporna, otporna na prodiranje korijenja (EN 13948 - test FLL ili jednakovrijedno), otpornost na trganje ≥ 150 N (EN 12310-1 ili jednakovrijedno), pregibljivost pri niskim temperaturama ≤ -40°C sa signalnim slojem koja se vari strojevima s toplim zrakom, uz preklop od 10cm. Folija je slobodno položena, učvršćena pri rubovima objekta specijalnim tiplama za beton. TPO hidroizolacija se podiže uz nadozid visine 76 cm te se pričvršćuje na gornjoj plohi nadozida. U stavkz uključen sloj geotekstila 300g/m2; služi kao razdjelni sloj između TPO i šljunka. Sav materijal, pomoćni materijal, ugradna i pričvrsna sredstva odrediti prema uputama proizvođača i pravilima struke. U stavku uključen sav potrebni rad, materijal i pomoćni materijal.
B10: - obračun po m2 kompletno izvedenog ravnog krova MW 20 cm | C10: m2 | D10: 1615 | E10: 75 | F10: =D10*E10 -> 121125
B11: - obračun po m2 kompletno izvedenog ravnog krova MW 10 cm | C11: m2 | D11: 35 | E11: 60 | F11: =D11*E11 -> 2100
B12: - vertikala nadozida MW= 5 cm | C12: m2 | D12: 142 | E12: 100 | F12: =D12*E12 -> 14200
B13: - horizontala nadozida MW= 5 cm | C13: m2 | D13: 193 | E13: 100 | F13: =D13*E13 -> 19300
A15: =A2 -> VII | B15: =B2 -> KROV | C15: UKUPNO | F15: =SUM(F4:F14) -> 156725

Sheet VIII FASADA
A2: VIII | B2: FASADERSKI RADOVI
A4: 1. | B4: Fasadni ETICS sustav
B5: Dobava materijala i izvođenje topl. izol. fasadnog sustava sa termoizolacijskim pločama od ploča KAMENE VUNE specifične mase 100-110 kg/m3, λ=0,035 proizvedenog za fasadne sustave, sa tankoslojnom silikonskom završnom, fasadnom žbukom granulacije do 3 mm, koja se nanosi na toplinsku izolaciju. Na zidove se izvodi ljepljenjem spec.ljepilom na zidove. Termoizolacijske ploče se dodatno sidre sa 8-9 komada sidra po m2. Sidra moraju biti otporna na koroziju. Bušenje rupa i sidrenje izvoditi nakon ljepljenja ploča. Na učvršćene izol. ploče se nanosi prvi zaštitni sloj spec. mortom-ljepilom debljine 2-3 mm, po čitavoj površini. U takav svježi sloj morta se utiskuje staklena mrežica. Drugi zaštitni sloj spec. morta-ljepila se nanosi nakon 24 sata, također u debljini 2-3 mm uz završno zaglađivanje. Stavka uključuje i obradu svih uglova, špaleta i sokla limenim i plast. kutnim profilima kao zaštite od mehaničkog oštećenja. - nakon min. 5-7 dana sušenja, premazivanje impregnacijskim premazom i nanošenje završnog sloja , minimalne debljine zrna od 1,5 mm ( max do 3 mm ).
B6: Dobava i postava ostalog pribora (kutni i okapni profili, špaletni elementi ploča debljine 2 cm,..). Sve radove izvesti prema uputama proizvođača komponenti sustava. Završna obrada fasade u boji po izboru projektanta. Obračun po m2 izvedenog pročelja do pune gotovosti, uključivo silikonska žbuka, izolacijske ploče, mortovi-ljepila, staklena mrežica, kutnici, okapnici i sidra te sav ostali potrebni pribor.
B7: - fasadni sustav debljine 15cm | C7: m2 | D7: 1710 | E7: 65 | F7: =D7*E7 -> 111150
B8: - fasadni sustav debljine 5cm | C8: m2 | D8: 93 | E8: 60 | F8: =D8*E8 -> 5580
B9: - fasadni sustav debljine 5cm podgled | C9: m2 | D9: 359 | E9: 60 | F9: =D9*E9 -> 21540
A11: 2. | B11: Donji dio fasade - sokl
B12: Dobava materijala i izvedba DONJEG DIJELA pročelja-sokl v=cca 30 cm. Podloga je ploča iz XPSa kao fasadna ploča debljine 14 ( 1 cm manje od fasadne ploče), λ ≤ 0,035 W/mK, tlačna čvrstoća ≤ 300 kPa. Naslanja se na donju čvrstu betonsku podlogu ( na istu podlogu se mora nasloniti i završna obloga iz kamena). Izvoditi prema uputstvima proizvođača. Završni sloj je vodoodbojna žbuka kao teraplast prebojana sa silikonskom bojom u tonu RGB 245, 231, 180
B13: Tehničke osobine Nazivna vrijednost toplinske provodljivosti (λD ) 0,034 - 0,038 W(m·K) HRN EN 13164 ili jednakovrijedan proizvod ___________________________ Tlačno opterećenje kod 10 % deformacije 0,30 CS(10\Y)300 N/mm 2 HRN EN 826 ili jednakovrijedan proizvod _________________________ Dugotrajno upijanje vlage (cijele ploče) ≤ 0,7 WL(T)0,7 % HRN EN 12087 ili jednakovrijedan proizvod ______________________________ Difuzijsko upijanje vlage (cijele ploče) WD(V)3 HRN EN 12088 ili jednakovrijedan proizvod _____________________________ Otpornost protiv naizmjeničnog smrzavanja– odmrzavanja (maksimalno upijanje vlage) ≤ 1,0 FT2 % HRN EN 12087 ili jednakovrijedan proizvod ____________________ Dimenzijska promjena pri 90 % relativnoj vlažnosti zraka i 70 °C ≤ 5 DS(TH) % HRN EN 1604 ili jednakovrijedan proizvod ________________________ Dimenzijska promjena pri opterećenju 0,04 N/mm 2 i 70 °C ≤ 5 DLT(2)5 % HRN EN 1605 ili jednakovrijedan proizvod _______________________________ Požarna otpornost po EN (euro klasifikacija) E HRN EN 13501-1 ili jednakovrijedan proizvod ____________________________- Difuzijska otpornost vodenoj pari (μ) 80-250 HRN EN 12086 ili jednakovrijedan proizvod _____________________________ Kapilarnost 0 Granične temperature upotrebe -50 do + 70 °C °C
B14: Obračun po m2.postavljene i pripremljene podloge. | C14: m2 | D14: 138 | E14: 70 | F14: =D14*E14 -> 9660
A17: 3. | B17: Fasadna skela
B18: Dobava, izrada i postava lake fasadne skele od cijevnih profila i mosnica, zajedno sa svim potrebnim ukrućenjima vezanim za objekt, potrebnom ogradom, prilazima i radnim podovima. U jediničnu cijenu ulazi montaža i demontaža sa sortiranjem i transportom. Obračun po m2 izvedene skele. (vertikalna projekcija)
B19: fasadna skela | C19: m2 | D19: 1710 | E19: 10 | F19: =D19*E19 -> 17100
A21: =A2 -> VIII | B21: =B2 -> FASADERSKI RADOVI | C21: UKUPNO | F21: =SUM(F5:F19) -> 165030

Sheet IX BRAV
A2: IX | B2: BRAVARSKI RADOVI
B4: ANTIKOROZIVNA ZAŠTITA ČELIČNIH KONSTRUKCIJA OBUHVAĆA slj. faze: Priprema čelika za antikorozivnu zaštitu: * čiščenje * odmašćivanje, otprašivanje * pjeskarenje do stupnja čistoće 2,5 s prethodnom zaštitom sredstvima za ispiranje i primerom ili vruće pocinčavanje. * zaštita temeljnim adekvatnim premaznim sredstvima - prvi sloj deblj. min 40 µ. - drugi sloj deblj. min 40µ. * zaštita kvalitetnim pokrovnim premaznim sredstvima u boji RAL 7016. - prvi sloj deblj. min 40 µ. - drugi sloj deblj. min 40 µ. * Kod vidljivih, izloženih ČN konstrukcija pokrovni premazi trebaju biti visokokvalitetni poliuretanski
B5: U cijeni kompletan spojni i pričvrsni pribor uključivo zaobljenja u unutarnjim i vanjskim kutevima - koljena , prelazi i sl. Ostali detalji prema izvedbenoj dokumentaciji i uputama glavnog projektanta.
A7: 1. | B7: Čelične ljestve
B8: Dobava i ugradnja čeličnih ljestvi za izlaz na krov zgrade. Čelične ljestve su smještene na pročelju. Ljestve moraju imati leđobrane od visine 2,2 m pa do vrha. Izrađene su od kvadratičnih čeličnih cijevi 30 mm x 30 mm x 5 mm. Gazišta su izrađena od punih čeličnih profila fi 10 mm. Ljestve su pričvršćene u zid vijcima. Čelik je zaštičen kao u općim uvjetima ove grupe radova. Nisu vruće cinčani. U stavku uključiti radioničke nacrte i sav potreban materijal i pribor za ugradnju ljestvi do pune gotovosti uključujući i završnu boju - RAL 7016.
B9: NAPOMENA: Shema prema izvedbenom projektu.
B10: Obračun po kom ugrađene i isporučene pozicije.
B11: - ljestve visine 475 cm | C11: kom | D11: 1 | E11: 2500 | F11: =D11*E11 -> 2500
B12: - ljestve visine 250 cm | C12: kom | D12: 1 | E12: 2000 | F12: =D12*E12 -> 2000
A14: 2. | B14: Klizna vrata na kolnom ulazu
B15: Izrada, dopremanje i ugradnja kliznih, dvodijelnih metalnih vrata, na kolnom ulazu na parcelu. Vrata se ugrađuju između nosivih čeličnih stupova, postavljenih na prethodno izvedene AB temeljne stope. Kolni ulaz je horizontalan, te se vrata izvode u horizontalnoj ravnini, te kližu po donjoj vodilici. Okvirna konstrukcija će se izvesti od čeličnih profila sandučastog presjeka prema zahtjevima proračuna, a ispuna se izvodi od vertikalnih čeličnih šipki manjeg presjeka, na osnom razmaku od max. 130mm. Kako se vrata nalaze na kosini bitno je postaviti stopere i graničnike. U prethodno izvedeni betonski kanal polaže se čelična vodilica - utor. U cijenu stavke uključiti sav rad i materijal potreban za izvedbu i ugradnju vrata, sve do konačne gotovosti, uključivo elektromotor, brave s ključem, kvake, sve potrebno za daljinsko otvaranje i sl. Sve čelične elemente obraditi protiv hrđe pocinčavanjem, te bojati u ton i boju RAL 7016. U stavku su uključena sva osnovna i pomoćna sredstva, rad i transport, sve do potpune gotovosti proizvoda, uključivo i izrada radioničkih nacrta koje, zajedno s uzorcima, obavezno treba dati na odobrenje projektantu. Obračun po komadu gotovog proizvoda.
B16: dim. 650x140 cm | C16: kom | D16: 1 | E16: 5000 | F16: =D16*E16 -> 5000
A18: 3. | B18: Zaokretna vrata na pješačkom ulazu
B19: Izrada, dopremanje i ugradnja zaokretnih, jednodijelnih metalnih vrata, na pješačkom ulazu na parcelu. Vrata se ugrađuju između nosivih čeličnih stupova, postavljenih na prethodno izvedene AB temeljne stope. Pješački ulaz je horizontalan, te se vrata izvode u horizontalnoj ravnini. Okvirna konstrukcija će se izvesti od čeličnih profila sandučastog presjeka prema zahtjevima proračuna, a ispuna se izvodi od vertikalnih čeličnih šipki manjeg presjeka, na osnom razmaku od max. 130mm. U cijenu stavke uključiti sav rad i materijal potreban za izvedbu i ugradnju vrata, sve do konačne gotovosti, uključivo brave s ključem, kvake, sve potrebno za daljinsko otvaranje i sl. Sve čelične elemente obraditi protiv hrđe pocinčavanjem, te bojati u ton i boju RAL 7016. U stavku su uključena sva osnovna i pomoćna sredstva, rad i transport, sve do potpune gotovosti proizvoda, uključivo i izrada radioničkih nacrta koje, zajedno s uzorcima, obavezno treba dati na odobrenje projektantu. Obračun po komadu gotovog proizvoda.
B20: dim. 120x140 cm | C20: kom | D20: 1 | E20: 1500 | F20: =D20*E20 -> 1500
A22: 4. | B22: Zaokretna vrata na gospodarskom ulazu
