Workbook
Name __xlnm.Print_Area_5: #REF!
Name __xlnm.Print_Area_5: #REF!
Name __xlnm.Print_Titles_5: #REF!
Name __xlnm.Print_Titles_5: #REF!
Name beton: [1]AB!#REF!
Name beton: [1]AB!#REF!
Name beton: [1]AB!#REF!
Name beton: [1]AB!#REF!
Name OLE_LINK1: '4.Strojarstvo'!#REF!
Name OLE_LINK3: '4.Strojarstvo'!#REF!
Name OLE_LINK5: '4.Strojarstvo'!#REF!
Name OLE_LINK7: '4.Strojarstvo'!#REF!
Name pausal: #REF!
Name pausal: #REF!
Name pausal: #REF!
Name pausal: #REF!
Name rbr: #REF!
Name rbr: #REF!
Name rbr: #REF!
Name tekuci: '4.Strojarstvo'!#REF!
Name ž: #REF!
Name ž: #REF!
Name ž: #REF!

Sheet naslovnica
A1: GRADIR d.o.o. Zagreb, Solinska 19, ured: Ilica 124/1, tel./faks.: +385(0)13760383, e-pošta: info@gradir.com, OIB: 02776388180
B6: GRAĐEVINA I LOKACIJA:
B7: DJEČJI VRTIĆ LEKENIK
B8: HR-44272 Lekenik, Zagrebačka 25A
B9: k.o. Lekenik; k.č.br. 2232/1, 2232/2, 2231/1
B10: (novoformirana k.č.br. 2231/1); z.k.ul. 2529, 2533, 2210
B12: INVESTITOR:
B13: OPĆINA LEKENIK
B14: HR-44272 Lekenik
B15: Zagrebačka 44
B20: ZOP:
B21: GRAD-4/24
B23: ZOP:
... B32: TROŠKOVNIK PROJEKTIRANIH RADOVA
A35: 1. | B35: GRAĐEVINSKO OBRTNIČKI RADOVI
A36: 2. | B36: KRAJOBRAZNO UREĐENJE
A37: 3. | B37: VODOVOD I ODVODNJA
A38: 4. | B38: STROJARSKE INSTALACIJE
A39: 5. | B39: ELEKTROINSTALACIJE
A40: 6. | B40: SUSTAV ZA DOJAVU POŽARA
A41: 7. | B41: DIZALO
A42: 8. | B42: KUHINJA I PRAONICA
A43: 9. | B43: OPREMANJE
B49: GLAVNI PROJEKTANT:
B50: Damir Petric, dipl. ing. arh.
B53: MJESTO:
B54: Zagreb
B56: DATUM:
B57: kolovoz 2024.
A60: SADRŽAJ TROŠKOVNIKA:
B62: SVEUKUPNA REKAPITULACIJA
B64: OPĆI UVJETI TROŠKOVNIKA
A66: 1. | B66: GRAĐEVINSKO OBRTNIČKI RADOVI
B67: RADOVI IZ: | C67: GLAVNI PROJEKT
C68: Gradir d.o.o.; broj projekta: 4/24/a
C69: Gradir d.o.o.; broj projekta: 4/24/k
C70: IZVEDBENI PROJEKT
C71: Gradir d.o.o.; broj projekta: 4/24/a-iz
C72: Gradir d.o.o.; broj projekta: 4/24/k-iz
B73: IZRADIO: | C73: Gradir d.o.o., Damir Petric, dipl. ing. arh.
...

Sheet rekapitulacija
A1: GRADIR d.o.o. Zagreb, Solinska 19, ured: Ilica 124/1, tel./faks.: +385(0)13760383, e-pošta: info@gradir.com, OIB: 02776388180
B5: TROŠKOVNIK - DJEČJI VRTIĆ LEKENIK
B7: SVEUKUPNA REKAPITULACIJA
A9: 1. | B9: =naslovnica!B35 -> GRAĐEVINSKO OBRTNIČKI RADOVI | F9: ='1.GOR'!F2026 -> 2680252
A10: 2. | B10: =naslovnica!B36 -> KRAJOBRAZNO UREĐENJE | F10: ='2.Krajobraz'!F106 -> 50449.5
A11: 3. | B11: =naslovnica!B37 -> VODOVOD I ODVODNJA | F11: ='3.ViO'!F477 -> 255212.6
A12: 4. | B12: =naslovnica!B38 -> STROJARSKE INSTALACIJE | F12: ='4.Strojarstvo'!F1018 -> 481194.5
A13: 5. | B13: =naslovnica!B39 -> ELEKTROINSTALACIJE | F13: ='5.Elektro'!F786 -> 263710.57
A14: 6. | B14: =naslovnica!B40 -> SUSTAV ZA DOJAVU POŽARA | F14: ='6.Vatrodojava'!F178 -> 41826
A15: 7. | B15: =naslovnica!B41 -> DIZALO | F15: ='7.Dizalo'!F34 -> 38600
A16: 8. | B16: =naslovnica!B42 -> KUHINJA I PRAONICA | F16: ='8.Kuhinja-praonica'!F271 -> 104570
A17: 9. | B17: =naslovnica!B43 -> OPREMANJE | F17: ='9.Opremanje'!F1423 -> 263108.57
B22: RADOVI SVEUKUPNO: | F22: =SUM(F9:F21) -> 4178923.8
B23: pdv (25%) | F23: =0.25*F22 -> 1044730.9
B24: RADOVI SVEUKUPNO s pdv-om: | F24: =SUM(F22:F23) -> 5223654.7

Sheet OUT
A1: GRADIR d.o.o. Zagreb, Solinska 19, ured: Ilica 124/1, tel./faks.: +385(0)13760383, e-pošta: info@gradir.com, OIB: 02776388180
B5: OPĆI UVJETI TROŠKOVNIKA
B7: VAŽNA NAPOMENA UZ TROŠKOVNIKE (odnosi se na sve troškovnike): IMENA PROIZVOĐAČA OPREME, ODREĐENIH MATERIJALA I DIJELOVA KONSTRUKCIJE KOJA SU NAVEDENA U TROŠKOVNIKU NE OBVEZUJU PONUĐAČA DA ISTE I NUDI, VEĆ JE POTREBNO PONUDITI OPREMU, MATERIJALE I DIJELOVE KONSTRUKCIJE JEDNAKOVRIJEDNE (JEDNAKIH SVOJSTAVA I TEHNIČKIH KARAKTERISTIKA) KAO ŠTO SU IMENOVANI U TROŠKOVNIKU. Kriteriji mjerodavni za ocjenu jednakovrijednosti navedeni su u tehničkim specifikacijama u opisu troškovničke stavke. Dokaz jednakovrijednosti mora podnijeti ponuditelj. Proizvodi koji su u dokumentaciji za nadmetanje navedeni kao primjer smatraju se ponuđenima ako ponuditelj ne navede nikakve druge proizvode na za to predviđenom mjestu troškovnika predmeta nabave.
B8: VAŽNE NAPOMENE UZ TROŠKOVNIK:
B9: PREDMET OVE DOKUMENTACIJE JE IZGRADNJA DJEČJEG VRTIĆA LEKENIK. Prije davanja ponude ponuđač može obići i detaljno izvršiti pregled lokacije, kako bi kod formiranja cijene obuhvatio sve potrebne radove i troškove na pripremnim radovima. PRIJE PREDAJE PONUDE, U SLUČAJU KAKVIH NEJASNOĆA ILI OCJENE PONUĐAČA DA JE NEKO OD RJEŠENJA NEPRIHVATLJIVO POSTAVITI UPIT NARUČITELJU KOJI ĆE KONTAKTIRATI PROJEKTANTA RADI RAZRJEŠENJA DETALJA. U PROTIVNOM OD IZVOĐAČA ĆE SE ZAHTIJEVATI IZVOĐENJE DETALJA KAO ŠTO JE PROJEKTANT PREDLOŽIO.
B10: Trošak pribavljanja sve atestne dokumentacije uključiti u cijenu nuđenih stavaka, jer se posebni troškovi neće priznati.
B11: Za pojedine elemente dani su normativi važeči na dan pisanja ovog troškovnika. U slučaju da isti u razdoblju do početka realizacije ovih radova ili u njihovom tijeku budu izmijenjeni, primjenjuju se normativi važeći u vrijeme izvođenja radova.
B12: Sav ugrađeni materijal treba odgovarati uvjetima iz opisa troškovnika i nacrta, te odgovarajućim Hrvatskim normama ili tehničkim uvjetima za izvođenje istih radova, a ukoliko se to posebno traži opisom i drugim propisima.
B13: Izvođač treba kvalitetu ugrađenih materijala i stručnosti radnika dokazati odgovarajućim atestima i uvjerenjima izdanim od strane za to ovlaštene organizacije i to uračunati u cijenu pojedinih stavaka.
B14: Imena proizvođača određenih materijala i dijelova konstrukcije koja su navedena u troškovniku NE OBAVEZUJU ponuđača da iste i nudi, već je potrebno ponuditi materijale i dijelove konstrukcije jednakovrijedne (jednakih svojstava i tehničkih karakteristika) kao što su imenovani u troškovniku. Kriteriji mjerodavni za ocjenu jednakovrijednosti navedeni su u tehničkim specifikacijama u opisu troškovničke stavke. Dokaz jednakovrijednosti mora podnijeti ponuditelj. Proizvodi koji su u dokumentaciji za nadmetanje navedeni kao primjer smatraju se ponuđenima ako ponuditelj ne navede nikakve druge proizvode na za to predviđenom mjestu troškovnika predmeta nabave.
B15: Ponuđena cijena je konačna cijena za realizaciju pojedine troškovničke stavka te obuhvaća i sve radnje koje u stavci nisu posebno navedene, a nužne su za izvedbu pojedine stavke do potpune funkcionalne i uporabne gotovosti.
B16: Stavke troškovnika uključuju i sve radove i predradnje potrebne kod primjene zaštite na radu, zaštitne skele oko zgrade i gradilišta, privremene ograde i zaštitne konstrukcije do kompletnog završetka izgradnje, a sve uzimajući u obzir da je gradilište u izgrađenom okolišu okruženo zgradama koje se koriste.
B19: OPĆI UVJETI GRAĐENJA
... B27: Izvođač je dužan pridržavati se važećih zakona i propisa i to naročito:
B28: ► | C28: Zakona o gradnji,
B29: ► | C29: Zakona o prostornom uređenju,
B30: ► | C30: Zakona o građevnim proizvodima,
B31: ► | C31: Zakona o zaštiti na radu (ZNR),
B32: ► | C32: Hrvatskih normi (HRN),
B33: ► | C33: Općih tehničkih uvjeta (OTU).
B34: ► | C34: Uredbe i odluke EU
B35: koji su i dio ugovorne dokumentacije. Izvođač je dužan pridržavati se svih navedenih zakona i uvjeta, osim ako
B36: projektom nije drugačije navedeno. Svi radovi moraju se izvesti solidno i stručno prema važećim propisima i
B37: pravilima dobrog zanata. Na gradilištu Izvođač radova, u skladu sa Zakonom o gradnji mora imati Glavnog inženjera
B38: gradilišta kvalificiranog za dotične vrste poslova i koji će stalno boraviti na gradilištu.
B40: Izvođač je dužan prilikom uvođenja u posao, u okviru ugovorene cijene, preuzeti parcelu, te obavijestiti nadležne
B41: službe o otvaranju gradilišta. Od tog trenutka pa do primopredaje zgrade izvođač je odgovoran za stvari i osobe
B42: koje se nalaze unutar gradilišta. Od ulaska na gradilište izvođač je dužan voditi građevinski dnevnik i građevinsku
B43: knjigu. U građevinski dnevnik se unose svi bitni podaci i događaji tijekom građenja (npr. meteorološke prilike,
B44: temperatura zraka, eventualne nepogode i sl.), upisuju se primjedbe Projektanta, nalozi nadzornog inženjera i
B45: građevinske inspekcije. Tako registrirani zahtjevi obavezni su za Izvođača radova, s tim da je za svaku nepredviđenu
B46: višu radnju, koja bi povećala ukupne troškove predviđene za izgradnju po ovom troškovniku, potrebna pisana
B47: suglasnost investitora. U građevinsku knjigu bilježe se i dokumentiraju mjerenja i kalkulacije svih faza izvršenih
... B70: Za sve naknadne radove izvođač je dužan izraditi analize cijena koje moraju sadržavati:
B71: a) | C71: sav materijal fco radilište (A)
B72: b) | C72: sve brutto plaće na izvedbi radova date po grupama i kvalifikacijama (B)
B73: c) | C73: razradu faktora poduzeća (opravdanje veličina) (F)
B74: d) | C74: važeće normative za izvedbu radova
B76: Sav rad i materijal vezan za organizaciju građevinske proizvodnje: ograde, vrata gradilišta, putevi na gradilištu,
B77: prilazi do gradilišta s lokalnih prometnica, privremena regulacija prometa, uredi, blagovaonice, svlačionice,
...

Sheet 1.GOR
A1: GRADIR d.o.o. Zagreb, Solinska 19, ured: Ilica 124/1, tel./faks.: +385(0)13760383, e-pošta: info@gradir.com, OIB: 02776388180
A2: stavka | B2: opis stavke | C2: jed.mj. | D2: količina | E2: jedinična cijena | F2: ukupna cijena
A3: 1 | B3: 2 | C3: 3 | D3: 4 | E3: 5 | F3: 4x5=6
A5: 1. | B5: GRAĐEVINSKO OBRTNIČKI RADOVI
A7: A. | B7: GRAĐEVINSKI RADOVI
B9: Napomena:
B10: Kod svih radova izvođač je dužan držati se Općih Uvjeta Troškovnika (OUT), važećih zakona i propisa iz pojedine grupe radova, tehničkih uputstava pojedinih proizvođača, koji moraju biti u skladu sa HRN i EU normama.
B11: Kod kalkuliranja cijena za pojedine radove izvođač mora uzeti u obzir sve faze radova, sve potebne elemente i radnje koji čine tehnološku cijelinu izvedbe, jer se VTR neće priznavati zbog 'nepotpune' kalkulacije cijene.
B12: U okviru pripremnih radova potrebno je funkcionalno organizirati gradilište. Izvođač mora osigurati prostor za održavanje koordinacija, privremene priključke komunalne infrastrukture za potrebe gradilišta, privremeni deponij materijala i sl., osigurati ili izvesti sve pristupne putove. Shemu gradilišta i dinamički plan izvođenja radova izvođač će dostaviti stručnom nadzoru i investitoru 8 dana prije početka radova.
A15: A.1. | B15: PRIPREMNI RADOVI
A17: * | B17: iskolčenje građevine:
A19: A.1.1. | B19: Geodetsko iskolčenje radova. Elaborat o iskolčenju izrađuje osoba registrirana za obavljanje te djelatnosti. Geodetsko iskolčenje radova provodi se prema elaboratu iskolčenja, a sve u skladu s izvedbenim projektom.
B20: Prije početka radova provodi se iskolčenje. Osnovna iskolčenja i poligonske točke i pomoćne točke moraju se na odgovarajući način osigurati od uništenja i biti jasno označeni cijelo vrijeme radova. Iskolčenje trase i objekata obuhvaća sva geodetska mjerenja i geodetska praćenja, kojima se podaci iz projekta prenose na teren ili s terena u projekte, osiguranje osi iskolčene potporne konstrukcije, profiliranje, obnavljanje i održavanje iskolčenih oznaka na terenu za sve vrijeme građenja, odnosno do predaje radova investitoru.
B21: Rad uključuje sva potrebna mjerenja u vezi prijenosa podataka iz projekta na teren i obrnuto: - preuzimanje podataka u nadležnom katastru o stalnim geodetskim točkama i njihova obrada, - provjera međe na terenu, - iskolčenje građevine prema izvedbenom projektu, - postavljanje i održavanje iskolčenih oznaka na terenu od početka radova do predaje svih radova investitoru - izrada i ovjera geodetskog elaborata iskolčenja sa skicom iskolčenja, - iskolčenje nanosne skele i glavnih visinskih točaka
B22: Izvedba, kontrola kakvoće i obračun prema OTU.
A23: a) | B23: iskolčenje građevine u skladu s elaboratom iskolčenja i projektom | C23: kpl | D23: 1 | E23: 1000 | F23: =IF(OR(OR(E23=0,E23=" "),OR(D23=0,D23=" "))," ",D23*E23) -> 1000
A24: b) | B24: iskolčenje ostalih planiranih građevina i zahvata (ogradnih zidova, elemenata uređenja okoliša, infrastrukturnih trasa) unutar obuhvata u skladu s elaboratom iskolčenja i projektom | C24: kpl | D24: 1 | E24: 1000 | F24: =IF(OR(OR(E24=0,E24=" "),OR(D24=0,D24=" "))," ",D24*E24) -> 1000
A26: * | B26: geodetski elaborat:
A27: A.1.2. | B27: Izrada geodetskog elaborata potrebnog za evidentiranje podataka o katastarskim česticama i podataka o novo izgrađenim građevinama, te predaja i ovjera elaborata u područnom katastarskom i zemljišno-knjižnom uredu.
A28: a) | B28: izrada geodetskog elaborata za građevine (sa snimkom izvedenog stanja), obveza izvođača | C28: kpl | D28: 1 | E28: 1000 | F28: =IF(OR(OR(E28=0,E28=" "),OR(D28=0,D28=" "))," ",D28*E28) -> 1000
A29: b) | B29: izrada geodetskog elaborata instalacija (sa snimkom izvedenog stanja), obveza izvođača | C29: kpl | D29: 1 | E29: 1000 | F29: =IF(OR(OR(E29=0,E29=" "),OR(D29=0,D29=" "))," ",D29*E29) -> 1000
A31: * | B31: čišćenje terena:
A33: A.1.3. | B33: Strojno i ručno sječenje stabala i vađenje panjeva i korijenja. Stabla posjeći i ispiliti na dužine pogodne za transport. Promjer stabla do 50 cm, koji se mjeri na visini cca 1,30 m od terena. Stavka obuhvaća slijedeće radove:
B34: sječenje, odnosno piljenje stabala, strojno ili ručno, kresanje grana, strojno vađenju panjeva, utovar na kamion, odvoz i zbrinjavanje sukladno važećem Zakonu o gospodarenju otpadom i pripadajućim podzakonskim aktima. Obračun po komadu.
A35: a) | B35: strojno i ručno sječenje stabala, te strojno čupanje i vađenje korijenja, prijenos na deponiju, panj promjera 50-100 cm, stabla u granicama obuhvata. | C35: kom | D35: 8 | E35: 300 | F35: =IF(OR(OR(E35=0,E35=" "),OR(D35=0,D35=" "))," ",D35*E35) -> 2400
A36: b) | B36: strojno i ručno sječenje stabala, te strojno čupanje i vađenje korijenja, prijenos na deponiju, panj promjera 25-50 cm, stabla u granicama obuhvata. | C36: kom | D36: 11 | E36: 200 | F36: =IF(OR(OR(E36=0,E36=" "),OR(D36=0,D36=" "))," ",D36*E36) -> 2200
A38: A.1.4. | B38: Strojno i ručno čišćenje terena u granicama obuhvata od grmlja, šiblja, raslinja, korjenja i raznih žičanih ograda, smeća i manjih prepreka. Raslinje je promjera do 10 cm. Stavka obuhvaća i utovar na kamion, odvoz i zbrinjavanje otpada sukladno važećem Zakonu o gospodarenju otpadom i pripadajućim podzakonskim aktima. Obračun po m2 očišćene površine odnosno m1 ograde.
A39: a) | B39: čišćenje terena od raslinja, šiblja, korijenja u granicama obuhvata. | C39: m2 | D39: 1000 | E39: 1 | F39: =IF(OR(OR(E39=0,E39=" "),OR(D39=0,D39=" "))," ",D39*E39) -> 1000
A40: b) | B40: čišćenje žičanih ograda uključivo metalne i betonske stupove ohrade i vađenje temelja stupova | C40: m1 | D40: 155 | E40: 10 | F40: =IF(OR(OR(E40=0,E40=" "),OR(D40=0,D40=" "))," ",D40*E40) -> 1550
A42: * | B42: zaštita i izmještanje infrastrukture:
A43: A.1.5. | B43: Zaštita postojeće komunalne i ostale infrastrukture unutar obuhvata i u kontaktnoj zoni obuhvata (elektroinstalacije, telekomunikacije, vodovod, odvodnja), a sve prema uvjetima i uz suglasnost vlasnika/upravitelja infrastrukture. Obračun komplet.
A44: a) | B44: zaštita postojeće infrastrukture | C44: kpl | D44: 1 | E44: 500 | F44: =IF(OR(OR(E44=0,E44=" "),OR(D44=0,D44=" "))," ",D44*E44) -> 500
A46: A.1.6. | B46: Zahvati (denivelacije poklopaca i sl.) na postojećoj komunalnoj i ostaloj infrastrukture unutar obuhvata i u kontaktnoj zoni obuhvata (elektroinstalacije, telekomunikacije, vodovod, odvodnja).
B47: - 1 poklopac - rešetka cestovne oborinske odvodnje (cestovni slivnik)
B48: Radove izvodi ovlašteno poduzeće prema uvjetima i pod nadzorom vlasnika/upravitelja infrastrukture. Obveza je izvođača radova zatražiti uvjete, nadzor i radove od strane vlasnika/upravitelja infrastrukture i prema tim uvjetima postupiti. Sve radnje izvode ovlaštene osobe, prema uvjetima i uz suglasnost i nadzor vlasnika/upravitelja infrastrukture. Stavka obuhvaća sve radove do pune funkcionalnosti. Obračun komplet.
A49: a) | B49: zahvati na postojećoj infrastrukturi | C49: kpl | D49: 1 | E49: 500 | F49: =IF(OR(OR(E49=0,E49=" "),OR(D49=0,D49=" "))," ",D49*E49) -> 500
A51: A.1.7. | B51: Izmještanje odnosno uklanjanje betonskog uličnog stupa rasvjete/elektroinstalacij/telekomunikacija zajedno sa svim vodovima koji su na njega spojeni (rasvjeta, elektoinstalacije, telekomunikacije). Stupovi koji se izmještaju/uklanjaju:
B52: - Ulični stup smješten uz sjeverni rub čestice, uz prometnicu, u zoni planiranog intervencijskog ulaza. Stup se izmješta južnije uz rub čestice u planiranu zelenu površinu. - Ulični stupovi smješteni uz istočni rub čestice, uz prometnicu, u zoni planiranih parkirnih mjesta. Stupi se izmještaju zapadnije bliže rubu čestice. - Stup smješten uz zapadni rub čestice. Stup se uklanja.
B53: Radove izvodti prema uvjetima i pod nadzorom vlasnika/upravitelja infrastrukture. Obveza je izvođača radova zatražiti uvjete, nadzor i radove na izmještanju stupa od strane vlasnika/upravitelja infrastrukture i prema tim uvjetima postupiti. Sve radnje izvode ovlaštene osobe, prema uvjetima i uz suglasnost i nadzor vlasnika/upravitelja infrastrukture. Stavka obuhvaća i utovar na kamion, odvoz i zbrinjavanje nastalog otpada sukladno važećem Zakonu o gospodarenju otpadom i pripadajućim podzakonskim aktima, te izvedbu nove (izmještene) infrastrukture, sve do pune funkcionalnosti.
A54: a) | B54: izmještanje infrastrukture - stup uz sjeverni i sjeveroistočni rub čestice | C54: kpl | D54: 5 | E54: 500 | F54: =IF(OR(OR(E54=0,E54=" "),OR(D54=0,D54=" "))," ",D54*E54) -> 2500
...

Sheet 2.Krajobraz
A1: GRADIR d.o.o. Zagreb, Solinska 19, ured: Ilica 124/1, tel./faks.: +385(0)13760383, e-pošta: info@gradir.com, OIB: 02776388180
A2: stavka | B2: opis stavke | C2: jed.mj. | D2: količina | E2: jedinična cijena | F2: ukupna cijena
A3: 1 | B3: 2 | C3: 3 | D3: 4 | E3: 5 | F3: 4x5=6
A5: 2. | B5: KRAJOBRAZNO UREĐENJE
B8: OPĆI TEHNIČKI UVJETI
B9: Prije početka radova na hortikulturnom uređenju i oblikovanju potrebno je završiti sve građevinske radove, očistiti površine, te završiti radove na infrastrukturi vezano na zelene površine kao i radove na izgradnji ogradnog zida. Biljni materijal planiran za sadnju mora odgovarati standardima i imati certifikate. Sve sadnice moraju imati kvalitetno razvijen nadzemni dio i dobro razvijen korijenov sistem. Drveća trebaju biti školovana u rasadnicima, s formiranom krošnjom, pravilnom provodnicom debla i standardnih opsega debla za sadnju u odnosu na pojedinu vrstu.
B10: Od voćaka treba odabrati domaće sorte koje također trebaju biti uzgojene u rasadniku. Odabrane vrste drveća trebaju biti starosti 4-5 godina, s pravilnom produljnicom debla. Ukrasno grmlje i grmlje bobičastog voća treba biti starosti 3 godine, kvalitetnog rasadničkog uzgoja. Sav biljni materijal mora biti dopremljen na radlište sa zaštićenim korijenovim sistemom, s certifikatom i označen etiketom vrste. Stavke uključuju sve radove i predradnje potrebne kod primjene zaštite na rad, zaštitne i radne skele. Izvođač radova obvezan je dati garanciju od jedne godine. Održavanje nakon izvedbe mora biti osigurano.
B11: UVJETI ODRŽAVANJA
B12: Nakon sjetve i sadnje izvođač je dužan njegovati travnjak i sadnice do primopredaje krajnjem korisniku: - redovito zalijevanje u sušno doba - okopavanje i plijevljenje te zamjenska sadnja ukoliko se biljka posušila - fitosanitetska zaštita tijekom jedogodišnjeg razdoblja nakon sadnje - izvođač je dužan na vlastiti trošak ispraviti loše izvedene radove
A15: 1. | B15: PRIPREMNI RADOVI
A17: 1.1. | B17: Čiščenje zelenih površina nakon završetka svih radova, a prije izvođenja radova krajobraznog uređenja. Stavka obuhvaća čišćenje zelenih površina od otpada i zaostalog građevinskog materijala, utovar na kamion, odvoz i zbrinjavanje nastalog otpada na propisanu gradsku deponiju.
B18: Obračun radova po m2 očišćene površine.
A19: a) | B19: čišćenje zelenih površina | C19: m2 | D19: 3970 | E19: 1 | F19: =IF((D19*E19)=0,"",(D19*E19)) -> 3970
A21: 1. | B21: PRIPREMNI RADOVI UKUPNO | F21: =SUM(F17:F20) -> 3970
A24: 2. | B24: ZEMLJANI RADOVI
A26: 2.1. | B26: Izvedba sloja plodnog tla (humusa) na površine parcele koja je predviđena za sadnju. Plodno tlo nanositi na površine namjenjene sijanju i razastirati, strojno ukopavati u tlo (frezom). Stavka se odnosi na dopremu i razastiranje prethodno uklonjenog i deponiranog humusa sa čestice (stavka A.3.1. građevinsko-obrtničkih radova). U cijenu uračunati i pripremu posteljice, planiranje na kotu predviđenu projektom, te zbijanje i fino planiranje zemljane površine prije sijanja trave.
B27: Zasijana površina cca: 2759 m2, količina: 0,2 m3/m2
B28: Obračun po m2, prema stvarno izvršenim radovima uključujući sve radnje prema opisu.
A29: a) | B29: doprema i razastiranje plodno tlo (humus) za sadnju debljine d=20 cm | C29: m2 | D29: 2759 | E29: 2 | F29: =IF((D29*E29)=0,"",(D29*E29)) -> 5518
A32: 2. | B32: ZEMLJANI RADOVI UKUPNO | F32: =SUM(F26:F31) -> 5518
A35: 3. | B35: RADOVI S BILJNIM MATERIJALOM
A37: * | B37: SADNJA DRVEĆA
A39: 3.1. | B39: Nabava i doprema sadnica do mjesta sadnje. Sav biljni materijal treba biti starosti 4-5 godina, promjera debla cca 8 cm, s pravilnom produljnicom debla, kvalitetnog rasadničkog uzgoja. Sadnice za drvorednu sadnju. Sadnice moraju biti dopremljene na radilište sa zaštićenim korijenovim sistemom, balirane ili u kontejnerima te čitljive oznake (etikete) vrste sadnice. Obračun po komadu dobavljene sadnice.
A40: a) | B40: Fraxinus augustifolia - poljski jasen, (visina grananja od 2m), [H.1.1.] | C40: kom | D40: 8 | E40: 70 | F40: =IF((D40*E40)=0,"",(D40*E40)) -> 560
A41: b) | B41: Fraxinus augustifolia Raywood - ukrasni jasen, (visina grananje od 2m), [H.1.2.] | C41: kom | D41: 12 | E41: 70 | F41: =IF((D41*E41)=0,"",(D41*E41)) -> 840
A42: c) | B42: Carpinus petulus Pyramidalis - grab piramidalni (visina grananje od 2,5-3m), [H.1.3.] | C42: kom | D42: 9 | E42: 70 | F42: =IF((D42*E42)=0,"",(D42*E42)) -> 630
A43: d) | B43: Gleditsia triacanthos "Sunburst", (visina grananja od 2m), [H.1.4.] | C43: kom | D43: 4 | E43: 70 | F43: =IF((D43*E43)=0,"",(D43*E43)) -> 280
A44: e) | B44: Prunus serrulata "Pink Perfection" - ukrasna trešnja, (visina grananja 2m), [H.1.5.] | C44: kom | D44: 2 | E44: 70 | F44: =IF((D44*E44)=0,"",(D44*E44)) -> 140
A45: f) | B45: Sorbus aucuparia - Jarebika, (visina grananja 2m), [H.1.5.] | C45: kom | D45: 2 | E45: 70 | F45: =IF((D45*E45)=0,"",(D45*E45)) -> 140
A47: 3.2. | B47: Iskop jama za sadnju i sadnja drveća. Stavka obuhvaća: - Iskop kružne jame za sadnju drveća i sadnja. Dimenzije jame su 100 x 100 x 100 cm, odnosno dimenzija jame prilagođena veličini korjenove grude-bale. - Rahljenje dna jame, zatrpavanje jame do polovice, bez nabijanja, gnojenje "Humovitom" ili kompostom (20 litara po jami), sadnju sadnice, zatrpavanje jame, učvšćivanje s tri kolca od bagrema ili kestena, formiranje zdjelice, vezivanje jutenom trakom te jednokratno zalijevanje. Obračun po komadu sadnice sa svim pripadajućim radovima. | F47: =IF((D47*E47)=0,"",(D47*E47))
A48: a) | B48: iskop jama za sadnju i sadnja drveća | C48: kom | D48: 37 | E48: 80 | F48: =IF((D48*E48)=0,"",(D48*E48)) -> 2960
A50: * | B50: SADNJA VOĆKI - JABUKA
B51: NAPOMENA
B52: Treba nabavljati kultivirane domaće sorte koje su dostupne u rasadnicima. U slučaju da navedene odabrane sorte nisu dostupne, mogu se nabaviti i druge domaće sorte.
A54: 3.3. | B54: Nabava i doprema sadnica jabuka do mjesta sadnje. Sav biljni materijal treba biti starosti 4-5 godina, s pravilnom provodnicom debla, kvalitetnog rasadničkog uzgoja. Sadnice moraju biti dopremljene na radilište sa zaštićenim korijenovim sistemom, balirane ili u kontejnerima te čitljive oznake (etikete) vrste sadnice. Obračun po komadu dobavljene sadnice.
A55: a) | B55: Božićnica (dozrijeva u listopadu), [H.2.1.] | C55: kom | D55: 1 | E55: 100 | F55: =IF((D55*E55)=0,"",(D55*E55)) -> 100
A56: b) | B56: Zlatna zimska parmenka (dozrijeva u rujnu), [H.2.2.] | C56: kom | D56: 2 | E56: 100 | F56: =IF((D56*E56)=0,"",(D56*E56)) -> 200
A57: c) | B57: Idared (dozrijeva u listopadu), [H.2.3.] | C57: kom | D57: 2 | E57: 100 | F57: =IF((D57*E57)=0,"",(D57*E57)) -> 200
A59: 3.4. | B59: Iskop jama za sadnju jabuka i sadnja. Stavka obuhvaća: - Iskop jama za sadnju jabuka. Dimenzija jame je 60 x 60 x 80 cm, odnosno dimenzija jame prilagođena veličini korjenove grude-bale. - Rahljenje dna jame, zatrpavanje jame do polovice, bez nabijanja, gnojenje "Humovitom" ili kompostom (20 litara po jami), sadnju sadnice, zatrpavanje jame, učvšćivanje s tri kolca od bagrema ili kestena, formiranje zdjelice, vezivanje jutenom trakom te jednokratno zalijevanje. Obračun po komadu sadnice sa svim pripadajućim radovima. | F59: =IF((D59*E59)=0,"",(D59*E59))
A60: a) | B60: iskop jama za sadnju jabuka i sadnja | C60: kom | D60: 5 | E60: 80 | F60: =IF((D60*E60)=0,"",(D60*E60)) -> 400
...

Sheet 3.ViO
A1: GRADIR d.o.o. Zagreb, Solinska 19, ured: Ilica 124/1, tel./faks.: +385(0)13760383, e-pošta: info@gradir.com, OIB: 02776388180
A2: stavka | B2: opis stavke | C2: jed.mj. | D2: količina | E2: jedinična cijena | F2: ukupna cijena
A3: 1 | B3: 2 | C3: 3 | D3: 4 | E3: 5 | F3: 4x5=6
A5: 3. | B5: VODOVOD I ODVODNJA
A8: 1. | B8: PRIPREMNI RADOVI
A10: 1.1. | B10: Detaljno iskolčenje trase temeljnog razvoda vodovoda, oborinske i fekalne odvodnje, označavanje pozicija revizijskih okana.
B11: Obračun po m1 iskolčene trase. | C11: m1 | D11: 615 | E11: 2 | F11: =IF((D11*E11)=0,"",(D11*E11)) -> 1230
A14: 1. | B14: PRIPREMNI RADOVI UKUPNO: | F14: =SUM(F10:F13) -> 1230
A17: 2. | B17: ZEMLJANI RADOVI
A19: 2.1. | B19: Strojni iskop (cca. 90%) rova za kanale širine prema detaljnom nacrtu, dubine prema kotama prikazanim u situaciji, uključivo pravilno odsjecanje bočnih strana i dna, odbacivanje iskopanog materijala na najmanje 1,0 metar od rubova iskopa. Komplet sa iskopom za cjevovode i kontrolna okna.
B20: Kategorija zemljišta odrediti će se prilikom iskopa, a predviđa se "B" kategorija. Obračun po m3 izvedenog iskopa u sraslom tlu. | C20: m3 | D20: 466 | E20: 20 | F20: =IF((D20*E20)=0,"",(D20*E20)) -> 9320
A22: 2.2. | B22: Strojni iskop (cca. 95%) građevinske jame za izvedbu sabirne jame V=103m3, dubine prema kotama na detalju, sa skošenjem stranica iskopa 1:2, odbacivanje iskopanog materijala na plohu dovoljno udaljenu od građevinske jame.
B23: Kategorija zemljišta odrediti će se prilikom iskopa, a predviđa se "B" kategorija. Obračun po m3 izvedenog iskopa u sraslom tlu. | C23: m3 | D23: 403 | E23: 20 | F23: =IF((D23*E23)=0,"",(D23*E23)) -> 8060
A25: 2.3. | B25: Strojni iskop (cca. 95%) građevinske jame za izvedbu vodomjernog okna, dimenzija prema kotama na detalju, sa skošenjem stranica iskopa 1:2, odbacivanje iskopanog materijala na plohu dovoljno udaljenu od građevinske jame.
B26: Kategorija zemljišta odrediti će se prilikom iskopa, a predviđa se "B" kategorija. Obračun po m3 izvedenog iskopa u sraslom tlu. | C26: m3 | D26: 59 | E26: 20 | F26: =IF((D26*E26)=0,"",(D26*E26)) -> 1180
A28: 2.4. | B28: Ručni iskop rova za kanal na mjestima gdje strojni iskop nije moguć (cca 10%), a prema odobrenju nadzornog inženjera. Obračun po m3. | C28: m3 | D28: 75 | E28: 50 | F28: =IF((D28*E28)=0,"",(D28*E28)) -> 3750
A30: 2.5. | B30: Ručni iskop jame sabirne jame i vodomjernog okna na mjestima gdje strojni iskop nije moguć (cca. 5%), a prema odobrenju nadzornog inženjera. Obračun po m3. | C30: m3 | D30: 24 | E30: 50 | F30: =IF((D30*E30)=0,"",(D30*E30)) -> 1200
A32: 2.6. | B32: Planiranje dna rova kanala s točnošću ±1cm . Obračun po m2. | C32: m2 | D32: 509 | E32: 1 | F32: =IF((D32*E32)=0,"",(D32*E32)) -> 509
A34: 2.7. | B34: Izrada pješčane posteljice granulacije 4-8 mm za vodovodne cijevi i cjevovod odvodnje, visina posteljice 10 cm.
B35: Stavka uključuje nabavu i dopremu pijeska granulacije 4-8 mm, te sav potreban rad za izvedbu posteljice. Obračun po m3. | C35: m3 | D35: 57 | E35: 45 | F35: =IF((D35*E35)=0,"",(D35*E35)) -> 2565
A37: 2.8. | B37: Zatrpavanje rova nakon izvedbe kanala i revizijskih okana i provedenog ispitivanja vodonepropusnosti. Rov zatrpavati pijeskom granulacije 8-16 mm do visine 30 cm od tjemena cijevi uz ručno nabijanje.
B38: Stavka uključuje nabavu i dopremu pijeska granulacije 8-16 mm, te sav potreban rad. Obračun po m3. | C38: m3 | D38: 188 | E38: 45 | F38: =IF((D38*E38)=0,"",(D38*E38)) -> 8460
A40: 2.9. | B40: Zatrpavanje preostale visine rova materijalom iz iskopa uz strojno nabijanje u slojevima od 30cm. Obračun po m3. | C40: m3 | D40: 256 | E40: 15 | F40: =IF((D40*E40)=0,"",(D40*E40)) -> 3840
A42: 2.10. | B42: Zatrpavanje zemlje materijalom iz iskopa oko izvedene sabirne jame uz strojno nabijanje u slojevima od 30 cm. Obračun po m3. | C42: m3 | D42: 219 | E42: 20 | F42: =IF((D42*E42)=0,"",(D42*E42)) -> 4380
A44: 2.11. | B44: Zatrpavanje zemlje materijalom iz iskopa oko izvedene vodomjernog okna uz strojno nabijanje u slojevima od 30 cm. Obračun po m3. | C44: m3 | D44: 42 | E44: 20 | F44: =IF((D44*E44)=0,"",(D44*E44)) -> 840
A46: 2.12. | B46: Odvoz suvišnog i neupotrebljivog materijala iz iskopa. Stavka obuhvaća utovar, prijevoz do 15 km, istovar i zbrinjavanje na propisanom gradskom deponiju. Obračun po m3. | C46: m3 | D46: 486 | E46: 15 | F46: =IF((D46*E46)=0,"",(D46*E46)) -> 7290
A48: 2. | B48: ZEMLJANI RADOVI UKUPNO: | F48: =SUM(F19:F47) -> 51394
A51: 3. | B51: TESARSKI RADOVI
A53: 3.1. | B53: Razupiranje bočnih strana rova. U stavku je uračunata dobava, doprema i ugradnja čelične oplate te demontaža. Razupiranje izvesti prema propisima zaštite na radu, tako da se osigura i omogući siguran rad u rovu i van rova.
B54: Predviđeno je 50% - tno razupiranje.
B55: Stvarnu količinu razupiranja odrediti će nadzorni inženjer prema stvarnim prilikama na terenu. Obračun po m2. | C55: m2 | D55: 619 | E55: 1 | F55: =IF((D55*E55)=0,"",(D55*E55)) -> 619
A57: 3. | B57: TESARSKI RADOVI UKUPNO: | F57: =SUM(F53:F56) -> 619
A60: 4. | B60: BETONSKI I ARMIRANO BETONSKI RADOVI
A62: 4.1. | B62: Izrada armirano-betonske sabirne jame V=103 m3, svijetlih tlocrtnih dimenzija 825 x 500 cm i dubine 250 cm, betonom klase C25/30 s dodatkom aditiva za vodonepropusnost i otpornost prema agresivnim vodama.
B63: Stavka uključuje nabavu i dopremu sveg potrebnog materijala, pripremu, dovoz i ugradnju betonske smjese, zbijanje pervibratorima, zaštitu betona poslije ugradnje od utjecaja atmosfere, te održavanje betona vlažnim za vrijeme procesa vezivanja.
B64: Unutarnje površine zidova i dna sabirne jame ožbukati cementnim mortom omjera smjese 1:2, upotrebom čistog prosijanog pijeska bez organskih primjesa s dodatkom sredstva za postizanje vodonepropusnosti prema odredbi nadzornog inženjera, uključivo nabavu i dopremu sveg potrebnog materijala, čišćenje i močenje zidova i dna , popunjavanje rupa eventualno zaostalih nakon betoniranja, izradu morta, donos na mjesto žbukanja, dodavanje i nabacivanje te zaglađivanje uz posipanje cementom, ali ne do crnog sjaja.
B65: U jamu se ugrađuju penjalice od rebrastog željeza na međusobnom razmaku od 30 cm. Stavka uključuje nabavu, dopremu bušenje rupa za ugrađivanje, potrebni cementni mort omjera smjese 1:2, pripremu i donos morta, učvršćivanje penjalica te nabavu i dopremu sveg potrebnog materijala.
B66: Na ulazu se ugrađuje ljevano željezni poklopac veličine 60x60 cm, nosivosti 25 t. Stavka uključuje nabavu, dopremu, ugradnju poklopaca uključivo podložni sloj cementnog morta omjera smjese 1:2, pripremu i dopremu morta.
B67: Okno je predviđeno armirati armaturom B 500 B, prema statičkom proračunu i planu armature.
B68: Armatura: RA: 2487 kg; MA: 4324 kg. Oplata: 250 m2 Beton: 51,2 m3
...

Sheet 4.Strojarstvo
A1: GRADIR d.o.o. Zagreb, Solinska 19, ured: Ilica 124/1, tel./faks.: +385(0)13760383, e-pošta: info@gradir.com, OIB: 02776388180
A2: stavka | B2: opis stavke | C2: jed.mj. | D2: količina | E2: jedinična cijena | F2: ukupna cijena
A3: 1 | B3: 2 | C3: 3 | D3: 4 | E3: 5 | F3: 4x5=6
A5: 4. | B5: STROJARSKE INSTALACIJE
B8: Napomena: sve stavke uključuju dobavu na mjesto ugradnje, montažu i puštanje u pogon do pune funkcionalnosti. Sve stavke se mogu zamijeniti jednakovrijednim proizvodima samo uz odobrenje projektanta i garanciju funkcionalnosti, te zadovoljavanja svih projektnih parametara.
B10: Sve građevinske prodore u podovima, stropovima i zidovima za instalacije treba obuhvatiti građevinskim radovima, dok prodori za prolaze cjevovoda (osim kroz armirano-betonske konstrukcije), kao i ugradnja proturnih cijevi u istim, obuhvaćeni su ovom specifikacijom.
B12: Potvrdu narudžbe prije definitivne isporuke specificirane opreme izvođač radova obvezatno je dužan ovjeriti kod projektanta. Izmjena pojedinih dijelova predviđene opreme "zamjenskim dijelovima" bez prethodne pismene suglasnosti projektanta isključuje odgovornost projektanta za predviđenu funkcionalnost postrojenja.
B14: Svi ponuđači dužni su kompletan opseg vlastite isporuke uskladiti s traženom kompletnom funkcijom, respektirajući pri tom sve predviđene i tražene parametre, uz čvrste pisano potvrđene garancije. Sva eventualno potrebna razrađivanja, usklađenja i slično, u opsegu su dotične isporuke, a sve pripadne troškove snosi ponuđač.
A16: 1. | B16: ENERGETSKO POSTROJENJE
A18: 1.1. | B18: Inverterska reverzibilna dizalica toplina sa stapnim kompresorima.
B19: Koristi prirodni radnim medij R290 (propan) s iznimno niskim GWP=3 i smanjenim utjecajem na okoliš. Uređaji mogu proizvoditi toplu vodu do 63 ° C i raditi s vanjskom temperaturom do -20 ° C.
B20: Struktura jedinice izrađena je od pocinčanog lima presvučenog poliesterskim prahom RAL 5017/7035 na 180 ° C, što je čini visoko otpornom na vremenske uvjete. Konstrukcija je nosivi okvir s uklonjivim oplatama obloženim prostirkom od poliuretana koja apsorbira zvuk. Svi vijci su od nehrđajućeg čelika.
B21: Kompresori su polu-hermetički klipni s dva kruga, frekventnim pretvaračem za svaki kompresor koji modulira radnu frekvenciju prema zahtjevu opterećenja. Inverterski kompresori promjenjive brzine povećavaju sezonsku učinkovitost i postižu stabilnu termodinamičku regulaciju u svim uvjetima opterećenja.
B22: Optimizirani su za upotrebu s propanom. Svi kompresori opremljeni su grijačem kućišta radilice, usisnim i dovodnim servisnim ventilima. Kompresori imaju ATEX certifikat.
B23: Brzina modulirajućeg kompresora varira, ovisno o ukupnom toplinskom opterećenju između 30 i 105 o / min. 30Hz i 65Hz.
B24: Zrakom hlađeni i grijani toplinski izmjenjivač uređaja napravljen je od bakrenih cijevi te aluminijskih mikro kanala koji povećavaju površinu izmjene zraka. Izmjenivač je optimiziran za rad uređaja u grijanju te ima povećanu širinu i nagib lamela kako bi se smanjilo stvaranje leda i olakšao odljev kondenzirane vode tijekom odmrzavanja. Bakrene cijevi su povećane debljine kako bi se osigurala veća pouzdanost i trajnost tijekom radnog vijeka.
B25: Na dnu zrakom hlađenog i grijanog izmjenivača se nalazi posuda za sakupljanje kondenzata koja olakšava odvod kondenzata tijekom odmrzavanja. Uređaj je standardno opremljen grijaćim kabelom montiranim na dno posude za kondenzat kako bi se spriječilo stvaranje leda.
B26: Za jedinice opremljene EC ventilatorima (opcija) ista se funkcija izvodi pomoću elektronički komutiranog motora ventilatora.
B27: Vodeni izmjenjivač je također opremljen termostatom grijačem protiv smrzavanja koji ga štiti od stvaranja leda kada uređaj ne radi. Rad uređaja optimiziran je u načinu grijanja, gdje se voda i tekućine rashladnog sredstva izmjenjuju u protustruji unutar pločastog izmjenjivača topline.
B28: Svaki krug rashladnog sredstva osnovne jedinice sadrži: elektromagnetni ventil na dovodu tekuće faze, 4-smjerni prekretni ventil, servisni ventili prije i nakon kompresora, reciever tekuće faze radnog medija, priključci za punjenje radnog medija, kontrolno staklo, filter za isušivanje, elektronski ekspanzijski ventil, prekidači visokog i niskog tlaka te separator usisne tekućine.
B29: Rashladni krug zatvoren je u odjeljak koji sadrži ATEX-certificirani osjetnik propuštanja i ventilacijski ventilator s ATEX-ovim certifikatom. Hidraulični modul, ako je prisutan, također je zatvoren u odjeljak koji sadrži ATEX certificirani osjetnik propuštanja i ATEX certificirani ventilator za usisavanje.
B30: Električna upravljačka ploča izrađena je u obojenoj pocinčanoj kutiji od lima sa prisilnom ventilacijom i zaštitom IP54. Električna ploča izrađena je prema standardu EN60204-1. Električna ploča odvojena je od odjeljka kompresora.
... B85: - maksimalne dimenzije uređaja
B86: - navedena dodatna oprema uređaja s karakteristikama | C86: kom | D86: 1 | E86: 70000 | F86: =D86*E86 -> 70000
A88: 1.2. | B88: Podkonstrukcija za smještaj modula dizalice topline. Stavka uključuje betonske blokete, čeličnu podkonstrukciju i antivibracijske nosače. | C88: kpl | D88: 1 | E88: 500 | F88: =D88*E88 -> 500
A90: 1.3. | B90: Gumeni prirubnički kompenzator za ublažavanje vibracija, te aksijalnih i lateralnih dilatacija, PN 10, uključivo protuprirubnice, brtve i vijci slijedeće dimenzije:
B91: DN 80 | C91: kom | D91: 2 | E91: 59 | F91: =D91*E91 -> 118
A93: 1.4. | B93: Probni rad instalacije (topla proba) dizalice topline od strane ovlaštenih servisera na području RH te puštanje u redovan pogon do potpune funkcionalnosti postrojenja, uključivo mjerenje projektiranih parametara. | C93: kpl | D93: 1 | E93: 200 | F93: =D93*E93 -> 200
A95: 1.5. | B95: Vanjska jedinica u izvedbi dizalice topline zrak/zrak, odnosno zrak/voda u ovisnosti o tipu priključenih unutarnjih jedinica. Kod jedinica iz više modula osiguran je parcijalni defrost, a samim time i kontinuirano grijanje za vrijeme defrosta.
B96: Simultana i automatska promjena temperature isparavanja radnog medija prema temperaturi okoliša omogućuje dodatne uštede energije i veći komfor zbog viših temperatura istrujanog zraka. Jedinica je opremljena sa pločastim izmjenjivačem topline [intercooler] koji omogućuje značajno poboljšanje efikasnosti kako u hlađenju tako i u grijanju. Uređaj je opremljen s "pump out/down" funkcijom koja omogućuje jednostavno servisiranje pojedinih dijelova sustava. Uređaji su EUROVENT certificirani.
B97: Maksimalno dozvoljena udaljenosti: ukupno cijevni razvod do 1000 metara; najudaljenija dionica cjevovoda je 220 m; visinska razlika između vanjske i unutarnje jedinice iznosi 110 m, visinska razlika između pojedinih unutarnjih jedinica iznosi 50 m.
B98: Konstrukcija: Jedinice su modularne izvedbe sa osnovnim nosivim okvirom i galvaniziranim čeličnim panelima sa odgovarajućom zaštitom za vanjsku i unutarnju ugradnju. Do veličine 26HP jedinice mogu biti u izvedbi 1 modula, dok su veće sastavljene od dva, ili tri modula. Jedinica se standardno isporučuje sa zaštitnom mrežom izmjenjivača. Ventilatori su niskošumne izvedbe s DC kontinuiranom regulacijom brzine vrtnje. Raspoloživi eksterni statički tlak ventilatora je 110 Pa. Svi kompresori u uređaju su inverterski, zvučno izolirani SSC-tip hermetički scroll izvedbe s radnim područjem 15-150 Hz.
B99: Za vanjsku jedinicu potrebno je izraditi postolje minimalne visine 30cm od kote ravnog terena.
B100: Jedinica je sastavljena iz jednog modula sljedećih tehničkih karakteristika:
B101: Tehničke karakteristike:
B102: Qh ukupno = 22,4 kW
B103: Priključna snaga:
B104: N ukupno = 5,6 kW / 380 - 415 V - 50 Hz
B105: EER: 4 (100% opterećenja)
B106: Tv = 35°C ST
...

Sheet 5.Elektro
A1: GRADIR d.o.o. Zagreb, Solinska 19, ured: Ilica 124/1, tel./faks.: +385(0)13760383, e-pošta: info@gradir.com, OIB: 02776388180
A2: stavka | B2: opis stavke | C2: jed.mj. | D2: količina | E2: jedinična cijena | F2: ukupna cijena
A3: 1 | B3: 2 | C3: 3 | D3: 4 | E3: 5 | F3: 4x5=6
A5: 5. | B5: ELEKTROINSTALACIJE
B7: OPĆE ODREDBE TROŠKOVNIKA:
B8: Svi radovi iz ovog troškovnika moraju biti izvedeni stručno, precizno i veoma savjesno prema danom troškovničkom opisu i projektu, te moraju odgovarati važećim tehničkim propisima i normativima.
B9: U cijeni pojedinih stavaka obuhvaćeni su svi troškovi za puno dovršenje stavke, sav rad, materijal, sve zidarske pripomoći, svi prijevozi i prijenosi, razni doprinosi, dodaci i režijski troškovi, sva potrebna ispitivanja i funkcionalne probe do potpune funkcionalnosti, čišćenje, ispiranje i dezinfekcije cjevovoda, izdavanje atesta, izrada svih projekata izvedenog stanja, izrada katastra svih vanjskih instalacija, obučavanja korisnika opreme, sitni spojni, montažni i brtveni materijal, tehnička dokumentacija sustava, tehnički listovi i certifikati ugrađene opreme, dokumentacija za rukovanje i održavanje sustava, certifikati o protokolarnim mjerenjima, te svi ini troškovi izvoditelja vezani na organizaciju gradilišta.
B10: Svi radovi iz troškovnika obračunat će se prema "Prosječnim normama u graditeljstvu" ukoliko u pojedinim stavkama nije drugačije označeno.
B11: Sav upotrijebljeni materijal mora biti kvalitetan i odgovarati odredbama odgovarajućih standarda i propisa. Nekvalitetan materijal ne smije se upotrebljavati. Za sav materijal koji će se upotrijebiti za građenje, izvoditelj radova mora pribaviti uvjerenje o kvaliteti materijala koji se mora priložiti primopredaji izvedenih radova. Radovi moraju biti izvedeni prema projektu, te izvoditelj ne smije vršiti nikakve promjene ili odstupanja od projekta bez odobrenja stručnog nadzora, investitora i projektanta. Sva eventualna odstupanja od projekta moraju se upisati u građevinski dnevnik od strane nadzornog inženjera i moraju biti usuglašena od strane investitora. Bez odobrenja investitora , izvoditelj ne smije upotrebljavati materijale koji nisu predviđeni projektom. Za čitavo vrijeme građenja izvoditelj je dužan održavati potrebnu čistoću na gradilištu.
B12: Ukoliko investitor utvrdi da neki materijal ne odgovara kvaliteti i važećim propisima izvoditelj je dužan isti materijal ukloniti sa gradilišta o svom trošku i zamijeniti ga sa propisanim.
B13: Za sve nuđene proizvode potrebno je prije njihove narudžbe odnosno ugradnje dostaviti kataloške podatke (i/ili montažna uputstva), kopije traženih certifikata, izjave proizvođača, svjetlotehničke izračune istovjetnima onima u projektu (samo za svjetiljke) kojima se dokazuje zadovoljavanje tehničkih uvjeta definiranim u troškovniku i projektu. Dokumenti moraju biti izrađeni od strane akreditiranih neovisnih ustanova (certifikati i ispitna izvješća) ili proizvođača (tehničke brošure). Nije dozvoljeno prilaganje izjava, brošura, kataloških podataka i dokumentacije izdanih od strane uvoznika, distributera, zastupnika i sl..
B14: U slučaju prilaganja drugih tipova certifikata od navedenih ovim troškovnikom potrebno je priložiti dokumentaciju za dokazivanje njihove jednakovrijednosti sa traženima (osim kada se radi o novijim izdanjima certifikata/normi). Traženu dokumentaciju potrebno je dostaviti nadzornom inženjeru i/ili projektantu na uvid, te je potrebno ishoditi pismeno odobrenje za ugradnju opreme koja je ponuđena (Zapisnik o ocjenjivanju nominirane opreme ili upisom u Građevinski dnevnik). Nadzorni inženjer/projektant prilikom tehničke evalulacije opreme imaju pravo zatražiti izvorne oblike (el. oblik) proračuna, svjetlotehničke krivulje, web adrese proizvođača/proizvoda ukoliko to smatraju potrebnim za ocjenjivanje kvalitete.
B15: Ukoliko ponuđena oprema ne zadovoljava uvjete propisane troškovnikom/projektom nadzorni inženjer i/ili projektant dužni su u Građevinski dnevnijk ili Zapisnik o ocjenjivanju navesti utvrđene nepravilnosti. Ponuditelj ima obvezu u što kraćem roku predložiti zamjensku opremu koja zadovoljava uvjete troškovnika i natječaja. Odobrenje za ugradnju zamjenske opreme potrebno je dobiti istim postupcima kako je navedeno ranije. Dobava i ugradnja zamjenske opreme ne smije negativno utjecati na ugovorene iznose prema troškovniku niti na produljenje roka izvođenja, odnosno za sav eventualni trošak odgovoran je Ponuditelj.
B16: Obračun radova vršiti će se prema odredbama iz ugovora između izvoditelja i investitora. Nakon završetka izgradnje odnosno primopredaje radova, izvoditelj je dužan s gradilišta ukloniti o svom trošku sve privremene objekte, deponije materijala i sl. Za vrijeme izvođenja radova izvoditelj mora primjenjivati sva potrebna sredstva zaštite na radu kako bi osigurao izvođenje radova na siguran način, a u svrhu zaštite života i zdravlja svojih i inih djelatnika, slučajnih prolaznika i sl., te osiguranja uvjeta da ne dođe do oštećenja susjednih objekata. Izvoditelj se u tijeku gradnje mora pridržavati odredaba zakona o gradnji, Zakona o zaštiti na radu i drugih važećih pozitivnih propisa RH.
B17: Ukoliko je u određenim stavkama naveden tip proizvoda/proizvođača koji je korišten kao referentni proizvod u projektu, njegovo imenovanje ima samo značenje tehničko - tehnoloških i približno oblikovnih osobitosti proizvoda koji trebaju ugraditi, a nikako naredbodavnu obaveznu dobavu i ugradbu imenovanog proizvoda. Dozvoljava se ugradnja drugog proizvoda uz obavezno dokazivanje jednakovrijednosti s navedenim tehničkim karakteristikama u troškovniku.
B18: Prije narudžbe odnosno isporuke i ugradnje opreme potrebno je dobiti pismeno odobrenje od nadzornog inženjera/projektanta za ugradnju nuđenih proizvoda na način da se dostave tehnički listovi i certifikati kojima se dokazuje zadovoljavanje tehničkih karakteristika i certifikata koje su navedene u troškovniku. Za stavke u kojima se nude rasvjetna tijela (svjetiljke) potrebno je izraditi kontrolne proračune rasvjete (istovjetne onima u projektu) kojima se dokazuje postizanje potrebnih razina rasvijetljenosti, te dostaviti LDT krivulje svjetiljaka korištenih u proračunima.
... B22: Nacrti, detalji i napomene na nacrtima, tehnički opis i program kontrole i osiguranja kvalitete, kao i opisi radova u pojedinim stavkama obavezni su kod izvođenja radova.
A26: 1. | B26: INSTALACIJA ENERGETSKOG RAZVODA
A29: 1.1. | B29: Izvedba privremenog priključka, komplet sa građevinskim elektro ormarom koji je prethodno ispitan od ovlaštene tvrtke. | C29: kpl | D29: 1 | E29: 1500 | F29: =IF(OR(OR(E29=0,E29=" "),OR(D29=0,D29=" "))," ",D29*E29) -> 1500
B31: SPMO
A32: 1.2. | B32: Dobava, ugradnja i spajanje kućnog priključno mjernog ormara SPMO opremljen s osigurač-rastavnom sklopkom NH (NV)2C 250A, poveznicom i mogućnost priključka Al/Cu s dva kabela 4x50-150mm2 u dolazu i dva kabela do 4x150mm2 u odlazu, za nazivni napon 3x230v/400V, 400A. Klasa zaštite II, mehanička zaštite IP54, za ugradnju ili montažu na fasadu, iz prešanog poliestera boje RAL 7016 ili jednakovrijedna boja________________________, otporan na UV zrake i gorenje, pripremljen za ugradnju polucilindar bravice i zatvaranje u tri točke. (HEP) | C32: kom | D32: 1 | E32: 1406 | F32: =IF(OR(OR(E32=0,E32=" "),OR(D32=0,D32=" "))," ",D32*E32) -> 1406
A34: 1.3. | B34: GRO
B35: Dobava montaža i spajanje samostojećeg tipski testiranog niskonaponskog sklopnog bloka prema shemi "GRO", u skladu sa standardom IEC 61439-1 i IEC 61439-2 ili jednako vrijedne norme, nazivnog napona izolacije glavnih sabirnica do 1000 V, stupnja zaštite IP31, Forma 2b, zaštićen sa polimer epoxy zaštitom u boji RAL 9001, sa metalnim vratima, sastavljen od; 1 aparatna polja širine 650mm, 1 aparatno-sabirničkog polje širine 800 (650+150) mm te 1 kabelskog polje širine 300mm; ukupnih dimenzija 1750x2107x450 mm ( Š x V x D ), uvod kabela s gornje strane. Razdjelnik je s postoljem od 100 mm. Razdjelnik opremiti bravicama na vratima, nosačem za dokumentaciju, nosačima i pokrovnim pločama komponenata, stranicama i ostalim potrebnim mehaničkim priborom. Predviđene su vertikalne i horizontalne sabirnce za napajanje aparata. kom 1
B36: U razdjelnik ugraditi slijedeću opremu prema jednopolnoj shemi:
B37: MREŽNO POLJE
A38: - | B38: odvodnik prenapona 3P+N, maksimalne struje odvoda Imax= 40kA, tip 2, izvedbe s ulošcima i indikacijom dotrajalosti kom 1
A39: - | B39: minijaturni automatski prekidač sa Vfunkcionalnošću indikacijom sigurnog položaja kontakta i trenutnom identifikacijom kvara, prekidne moći Icu=15kA kod 415V AC prema IEC/EN 60947-2, četveropolni 4P, 40A, C krivulje kom 1
A41: - | B41: Niskonaponski kompaktni zaštitni prekidač, nazivne struje tijela prekidača 400A, nazivnog napona Ue=690V, tropolni 3P, fiksne izvedbe, nazivne granične prekidne moći Icu=25kA kod 415V AC prema IEC/EN 60947-2, sa termo-magnetskom zaštitnom jedinicom In=250A, podesiva Ir=(0.7-1.0) x In, sa naponskim okidačem MX (230 V AC); kom 1
A42: - | B42: minijaturni automatski prekidač sa funkcionalnošću indikacijom sigurnog položaja kontakta i trenutnom identifikacijom kvara, prekidne moći Icu=10kA kod 415V AC prema IEC/EN 60947-2 ili jednako vrijedna norma, tropolni 3P, 6A, C krivulje kom 1
A43: - | B43: minijaturni automatski prekidač sa funkcionalnošću indikacijom sigurnog položaja kontakta i trenutnom identifikacijom kvara, prekidne moći Icu=10kA kod 415V AC prema IEC/EN 60947-2 ili jednakovrijedna norma, tropolni 1P, 6A, C krivulje kom 3
A44: - | B44: signalna svjetiljka za indikaciju prisutnosti napona, LED, zelene boje, jednostruka, nazivni napon 110-230V AC, kom 1
A46: - | B46: Niskonaponski kompaktni zaštitni prekidač, nazivne struje tijela prekidača 125A, nazivnog napona Ue=690V, tropolni 3P, fiksne izvedbe, nazivne granične prekidne moći Icu=25kA kod 415V AC prema IEC/EN 60947-2, sa termo-magnetskom zaštitnom jedinicom In=100A, podesiva Ir=(0.7-1.0) x In kom 2
A47: - | B47: Niskonaponski kompaktni zaštitni prekidač, nazivne struje tijela prekidača 125A, nazivnog napona Ue=690V, tropolni 3P, fiksne izvedbe, nazivne granične prekidne moći Icu=25kA kod 415V AC prema IEC/EN 60947-2, sa termo-magnetskom zaštitnom jedinicom In=63A, podesiva Ir=(0.7-1.0) x In kom 4
A48: - | B48: Niskonaponski kompaktni zaštitni prekidač, nazivne struje tijela prekidača 63A, nazivnog napona Ue=690V, tropolni 3P, fiksne izvedbe, nazivne granične prekidne moći Icu=25kA kod 415V AC prema IEC/EN 60947-2, sa termo-magnetskom zaštitnom jedinicom In=40A, podesiva Ir=(0.7-1.0) x In kom 2
A49: - | B49: Niskonaponski kompaktni zaštitni prekidač, nazivne struje tijela prekidača 63A, nazivnog napona Ue=690V, tropolni 3P, fiksne izvedbe, nazivne granične prekidne moći Icu=25kA kod 415V AC prema IEC/EN 60947-2, sa termo-magnetskom zaštitnom jedinicom In=32A, podesiva Ir=(0.7-1.0) x In kom 3
A50: - | B50: Niskonaponski kompaktni zaštitni prekidač, nazivne struje tijela prekidača 63A, nazivnog napona Ue=690V, tropolni 3P, fiksne izvedbe, nazivne granične prekidne moći Icu=25kA kod 415V AC prema IEC/EN 60947-2, sa termo-magnetskom zaštitnom jedinicom In=16A, podesiva Ir=(0.7-1.0) x In kom 4
A52: - | B52: diferencijalna zaštitna sklopka, četveropolna 4P , nazivne struje 40A, osjetljivosti 30mA, tip A kom 8
... A61: - | B61: sva potrebna montažna i spojna oprema potrebna za ugradnju specificirane opreme u ormar do njegove pune fukcionalnosti; Powerclip sabirnice, igličaste sabirnice, redne stezaljke, sabirnice nule i zemlje, spojni vodovi, plastične kanalice, označavanje, funkcionalno ispitivanje prije isporuke, atesti, ispitni protokol, korisnička dokumentacija te ostali potrebni sitni spojni i montažni materijal i pribor do pune funkcionalnosti ormara. kpl 1
C62: kpl | D62: 1 | E62: 12100 | F62: =IF(OR(OR(E62=0,E62=" "),OR(D62=0,D62=" "))," ",D62*E62) -> 12100
A64: 1.4. | B64: RO1
...

Sheet 6.Vatrodojava
A1: GRADIR d.o.o. Zagreb, Solinska 19, ured: Ilica 124/1, tel./faks.: +385(0)13760383, e-pošta: info@gradir.com, OIB: 02776388180
A2: stavka | B2: opis stavke | C2: jed.mj. | D2: količina | E2: jedinična cijena | F2: ukupna cijena
A3: 1 | B3: 2 | C3: 3 | D3: 4 | E3: 5 | F3: 4x5=6
A5: 6. | B5: SUSTAV ZA DOJAVU POŽARA
B8: OPĆE ODREDBE TROŠKOVNIKA:
B9: Svi radovi iz ovog troškovnika moraju biti izvedeni stručno, precizno i veoma savjesno prema danom troškovničkom opisu i projektu, te moraju odgovarati važećim tehničkim propisima i normativima.
B10: U cijeni pojedinih stavaka obuhvaćeni su svi troškovi za puno dovršenje stavke, sav rad, materijal, sve zidarske pripomoći, svi prijevozi i prijenosi, razni doprinosi, dodaci i režijski troškovi, sva potrebna ispitivanja i funkcionalne probe do potpune funkcionalnosti, čišćenje, ispiranje i dezinfekcije cjevovoda, izdavanje atesta, izrada svih projekata izvedenog stanja, izrada katastra svih vanjskih instalacija, obučavanja korisnika opreme, sitni spojni, montažni i brtveni materijal, tehnička dokumentacija sustava, tehnički listovi i certifikati ugrađene opreme, dokumentacija za rukovanje i održavanje sustava, certifikati o protokolarnim mjerenjima, te svi ini troškovi izvoditelja vezani na organizaciju gradilišta.
B11: Svi radovi iz troškovnika obračunat će se prema "Prosječnim normama u graditeljstvu" ukoliko u pojedinim stavkama nije drugačije označeno.
B12: Sav upotrijebljeni materijal mora biti kvalitetan i odgovarati odredbama odgovarajućih standarda i propisa. Nekvalitetan materijal ne smije se upotrebljavati. Za sav materijal koji će se upotrijebiti za građenje, izvoditelj radova mora pribaviti uvjerenje o kvaliteti materijala koji se mora priložiti primopredaji izvedenih radova. Radovi moraju biti izvedeni prema projektu, te izvoditelj ne smije vršiti nikakve promjene ili odstupanja od projekta bez odobrenja stručnog nadzora, investitora i projektanta. Sva eventualna odstupanja od projekta moraju se upisati u građevinski dnevnik od strane nadzornog inženjera i moraju biti usuglašena od strane investitora. Bez odobrenja investitora , izvoditelj ne smije upotrebljavati materijale koji nisu predviđeni projektom. Za čitavo vrijeme građenja izvoditelj je dužan održavati potrebnu čistoću na gradilištu.
B13: Ukoliko investitor utvrdi da neki materijal ne odgovara kvaliteti i važećim propisima izvoditelj je dužan isti materijal ukloniti sa gradilišta o svom trošku i zamijeniti ga sa propisanim.
B14: Obračun radova vršiti će se prema odredbama iz ugovora između izvoditelja i investitora. Nakon završetka izgradnje odnosno primopredaje radova, izvoditelj je dužan s gradilišta ukloniti o svom trošku sve privremene objekte, deponije materijala i sl. Za vrijeme izvođenja radova izvoditelj mora primjenjivati sva potrebna sredstva zaštite na radu kako bi osigurao izvođenje radova na siguran način, a u svrhu zaštite života i zdravlja svojih i inih djelatnika, slučajnih prolaznika i sl., te osiguranja uvjeta da ne dođe do oštećenja susjednih objekata. Izvoditelj se u tijeku gradnje mora pridržavati odredaba zakona o gradnji, Zakona o zaštiti na radu i drugih važećih pozitivnih propisa RH.
B15: Ukoliko je u određenim stavkama naveden tip proizvoda/proizvođača koji je korišten kao referentni proizvod u projektu, njegovo imenovanje ima samo značenje tehničko - tehnoloških i približno oblikovnih osobitosti proizvoda koji trebaju ugraditi, a nikako naredbodavnu obaveznu dobavu i ugradbu imenovanog proizvoda. Dozvoljava se ugradnja drugog proizvoda uz obavezno dokazivanje jednakovrijednosti s navedenim tehničkim karakteristikama u troškovniku.
B16: Prije narudžbe odnosno isporuke i ugradnje opreme potrebno je dobiti pismeno odobrenje od nadzornog inženjera/projektanta za ugradnju nuđenih proizvoda na način da se dostave tehnički listovi i certifikati kojima se dokazuje zadovoljavanje tehničkih karakteristika i certifikata koje su navedene u troškovniku. Za stavke u kojima se nude rasvjetna tijela (svjetiljke) potrebno je izraditi kontrolne proračune rasvjete (istovjetne onima u projektu) kojima se dokazuje postizanje potrebnih razina rasvijetljenosti, te dostaviti LDT krivulje svjetiljaka korištenih u proračunima.
B17: U slučaju da nuđeni proizvodi ne zadovoljavaju uvjete troškovnika, ponuditelj je obavezan pronaći alternativne proizvode koji zadovoljavaju tražene karakteristike. Ukoliko alternativni proizvodi imaju veću cijenu od ponuđenih, ponuditelj mora snositi razliku na svoju štetu, odnosno ne dozvoljava se povećanje ugovorne cijene nuđenih stavki.
B18: U slučaju da nuđeni proizvodi ne zadovoljavaju uvjete troškovnika, ponuditelj je obavezan pronaći alternativne proizvode koji zadovoljavaju tražene karakteristike. Ukoliko alternativni proizvodi imaju veću cijenu od ponuđenih, ponuditelj mora snositi razliku na svoju štetu, odnosno ne dozvoljava se povećanje ugovorne cijene nuđenih stavki.
B19: Imenovanje pojedinog proizvoda i proizvođača ima samo značenje tehničko - tehnoloških i približno oblikovnih osobitosti proizvoda koji će se ugraditi, a nikako naredbodavnu obaveznu dobavu, proizvodnju i ugradbu imenovanog proizvoda
B20: Nacrti, detalji i napomene na nacrtima, tehnički opis i program kontrole i osiguranja kvalitete, kao i opisi radova u pojedinim stavkama obavezni su kod izvođenja radova.
A24: 1. | B24: OPREMA, MATERIJAL I SPECIJALISTIČKI RADOVI
A27: 1.1. | B27: Dobava, ugradnja i spajanje adresabilne vatrodojavne centrale s mikro procesorom i 2 petlje svaka s 128 adresa, proširivo do 4 petlje sa ukupno 512 adresa, digitalna komunikacija, sa zaslonom, programabilna putem tipkovnice i računala (USB priključak), 1000 memorijskih događaja, mogućnost povezivanja daljinskog upravljača, izlaz 2A, omogućuje kompenzaciju prašine, BUS komunikacija s detektorima i sučeljima, jednostavna zamjena natpisa na glavnoj ploči, omogućena centralna kontrola sa sustavom Iperview, jednostavno praćenje i resetiranje senzora. Sa slijedećim karakteristikama: - 2-4 adresabilne petlje za do 512 adresa - integrirani zaslonn s alfanumeričkom tipkovnicoma, navigacijskim tipkama i LED indikatorima - RS232/RS485 sučelje - USB + USB (host) - Ethernet sučelje - Modem PSTN/GSM - Konektor za PS2 tipkovnicu - USB veza, serijska veza, Ethernet hub - terminal za spajanje udaljenog panela - sukladno s HRN EN 54-2:1997 + A1:2006 - EN 54-4:1997 + A2:2006 ili jednakovrijedne norme ___________________. | C27: kom | D27: 1 | E27: 1033 | F27: =IF(OR(OR(E27=0,E27=" "),OR(D27=0,D27=" "))," ",D27*E27) -> 1033
A29: 1.2. | B29: Dobava programskog seta za hrvatski jezik. | C29: kom | D29: 1 | E29: 50 | F29: =IF(OR(OR(E29=0,E29=" "),OR(D29=0,D29=" "))," ",D29*E29) -> 50
A31: 1.3. | B31: Dobava, ugradnja i spajanje vatrootpornog ormarića za vatrodojavnu centralu u izvedbi sa protupožarnim staklom, zaštite F30, certificiran u RH. | C31: kom | D31: 1 | E31: 1581 | F31: =IF(OR(OR(E31=0,E31=" "),OR(D31=0,D31=" "))," ",D31*E31) -> 1581
A33: 1.4. | B33: Dobava, ugradnja i spajanje dodatanog napajanja 24Vdc/4.5A, u željeznom kućištu, omogućava punjenje baterija, relejni izlaz za signalizaciju statusa napajanja, stanja baterije, prostor za dvije baterije, IP30, priključak na 230Vac/50Hz, LED indikacija, dimenzije: H 220 x Š 300 x D 175 mm, EN 54-4 (A2), EN12101-10. | C33: kom | D33: 2 | E33: 350 | F33: =IF(OR(OR(E33=0,E33=" "),OR(D33=0,D33=" "))," ",D33*E33) -> 700
A35: 1.5. | B35: Dobava, ugradnja i spajanje akumulatora 12V / 18 Ah. | C35: kom | D35: 6 | E35: 55 | F35: =IF(OR(OR(E35=0,E35=" "),OR(D35=0,D35=" "))," ",D35*E35) -> 330
A37: 1.6. | B37: Dobava, ugradnja i spajanje adresibilnog ulazno izlaznog modula sa dvostrukim izolatorom petlje sastavljen od 2 nadzirane fizičke/logičke jedinice: 1 ulaz i 1 izlaz, koje sustav pojedinačno identificira i zauzimaju do 2 adrese, u kućištu. | C37: kom | D37: 10 | E37: 66 | F37: =IF(OR(OR(E37=0,E37=" "),OR(D37=0,D37=" "))," ",D37*E37) -> 660
A39: 1.7. | B39: Dobava, ugradnja i spajanje adresibilnog ulazno izlaznog modula sa dvostrukim izolatorom petlje sastavljen od 4 nadzirane fizičke/logičke jedinice: 4 relejna izlaza (30Vdc/1A (NC / NO), 4 električna izlaza, 4 električna ulaza, u kućištu. | C39: kom | D39: 5 | E39: 189 | F39: =IF(OR(OR(E39=0,E39=" "),OR(D39=0,D39=" "))," ",D39*E39) -> 945
A41: 1.8. | B41: Dobava, ugradnja i spajanje IP sučeljA za pripadnu centralu; omogućuje spajanje centrala na Internet mrežu putem Ethernet ili WI-FI veze te upravljanje sustavom putem mobilne aplikacije My Elkron Family; sučelje je instalirano izravno u centralu; 100 Mbps (ethernet); 150 Mbps (WI-FI); IEEE 802.3; IEEE 802.11 b/g/n; prema EN54-21. | C41: kom | D41: 1 | E41: 520 | F41: =IF(OR(OR(E41=0,E41=" "),OR(D41=0,D41=" "))," ",D41*E41) -> 520
