Workbook
Name __xlnm.Print_Area_1: #REF!
Name __xlnm.Print_Area_2: #REF!
Name __xlnm.Print_Area_3: #REF!
Name __xlnm.Print_Area_4: #REF!
Name __xlnm.Print_Area_5: #REF!
Name __xlnm.Print_Titles_1: #REF!
Name __xlnm.Print_Titles_2: #REF!
Name __xlnm.Print_Titles_3: #REF!
Name __xlnm.Print_Titles_4: #REF!
Name d: #REF!
Name dadsada: #REF!
Name dasdasdasdsad: #REF!
Name dsadsadasdsadsadsadasd: #REF!
Name dsadsadsa: #REF!
Name OLE_LINK1_2: #REF!
Name OLE_LINK1_2: #REF!
Name OLE_LINK1_2: #REF!
Name OLE_LINK1_2_1: "#REF!"
Name OLE_LINK1_2_3: "#REF!"
Name OLE_LINK1_2_4: "#REF!"
Name OLE_LINK1_2_5: "#REF!"
Name OLE_LINK1_3: #REF!
Name OLE_LINK1_3: #REF!
Name OLE_LINK1_3: #REF!
Name OLE_LINK1_3_1: "#REF!"
Name OLE_LINK1_3_3: "#REF!"
Name OLE_LINK1_3_4: "#REF!"
Name OLE_LINK1_3_5: "#REF!"

Sheet I. GRAĐEVINSKO OBRTNIČKI
A1: Redni broj: | B1: OPIS STAVKE: | C1: Jedinica mjere: | D1: Količina: | E1: Jedinična cijena: | F1: Ukupno:
B4: IZGRADNJA DJEČJEG VRTIĆA POKUPSKA TROŠKOVNIK SVIH VRSTA RADOVA
B6: OPĆI UVJETI UZ TROŠKOVNIK
B7: Izvedba radova treba biti prema nacrtima, općim uvjetima i opisu radova, detaljima i prema pravilima zanata. Eventualna odstupanja treba prethodno dogovoriti s nadzornim inženjerom i projektantom za svaki pojedini slučaj.
B8: Sve mjere u planovima provjeriti u naravi. Svu kontrolu vršiti bez posebne naplate. Tolerancije mjera izvedenih radova određene su uzancama zanata, odnosno prema odluci projektanta i nadzorne službe.
B9: Sva odstupanja od dogovorenih tolerantnih mjera dužan je izvođač otkloniti o svom trošku. To vrijedi za sve vrste radova, kao što su građevinski, obrtnički i montažerski, opremanje i ostali radovi.
B10: Izrada tipskih primjeraka i uzoraka svih ugrađenih materijala ( npr. ograde, pregradne stijene, bravarija, opločenja i sl.), te ovjera istih kod glavnog projektanta u cijeni je stavki i u obvezi je izvođača.
B11: PRIPREMNI RADOVI
B12: Izvođač je dužan prije početka radova sprovesti sve pripremne radove da se izvođenje može nesmetano odvijati. U tu svrhu izvođač je dužan detaljno proučiti investiciono tehničku dokumentaciju, te izvršiti potrebne računske kontrole.
B13: Potrebno je proučiti sve tehnologije izvedbe pojedinih radova radi optimalne organizacije građenja, nabavke materijala, kalkulacije i sl. Nepoznavanje crtanog dijela projekta i tehničkog opisa neće se prihvatiti kao razlog za povišenje jediničnih cijena ili greške u izvedbi.
B14: Izvođač i njegovi kooperanti dužni su svaki dio investiciono tehničke dokumentacije pregledati, te dati primjedbe na eventualne tehničke probleme koji bi mogli prouzročiti slabiji kvalitet, postojnost ugrađenih elemenata ili druge štete. U protivnom biti će dužan ovakve štete sanirati o svom trošku.
B15: Naročitu pažnju kod toga treba posvetiti usaglašavanju građevinskih i instalaterskih nacrta. Ako ustanovi neke razlike u mjerama, nedostatke ili pogreške u podlogama, dužan je pravovremeno obavijestiti nadzornog inženjera i odgovornog projektanta, te zatražiti rješenja.
B16: Radove treba izvesti točno prema opisu troškovnika, a u stavkama gdje nije objašnjen način rada i posebne osobine finalnog produkta, izvođač je dužan pridržavati se uobičajenog načina rada, uvažavajući odredbe važećih standarda, uz obvezu izvedbe kvalitetnog proizvoda.
... B26: Na gradilištu moraju biti poduzete sve HTZ mjere prema postojećim propisima. Izvođač je dužan po završetku radova gradilište kompletno očistiti, skinuti i odvesti sve nasipe, betonske podloge, temelje strojeva, radnih i pomoćnih prostorija i drugo do zdrave zemlje da se može pristupiti hortikulturnom uređenju.
A27: A/ | B27: MATERIJAL
B28: Pod tim nazivom se podrazumjeva cijena materijala tj. dobavna cijena i to kako glavnog materijala, tako i pomoćnog, veznog materijala i sl.
B29: U cijenu materijala uključena je i cijena transportnih troškova bez obzira na prijevozno sredstvo sa svim prijenosima, utovarima i istovarima, te uskladištenje i čuvanje na gradilištu od unošenja (prebacivanje, zaštita i sl.), kao i davanje potrebnih uzoraka.
B30: Uskladištenje materijala treba provesti tako da materijal bude osiguran od vlaženja i lomova, jer se samo neoštećen i kvalitetan smije ugrađivati. Ovo se odnosi na sve gotove prefabrikate, obrtničke proizvode i materijal za obrtničke radove. Vezna sredstva također moraju biti prvorazredna. Cement, opeka, kameni agregat, pijesak, bitumen i sl. treba ispitati prema važećim tehničkim propisima i atesete predočiti nadzornom inženjeru.
A31: B/ | B31: RAD
B33: Ujedno treba uključiti sav rad oko zaštite gotovih konstrukcija i dijelova objekta od štetnog utjecaja vrućine, hladnoće i sl.
A34: C/ | B34: SKELE
B35: Sve vrste skele bez obzira na visinu ulaze u jediničnu cijenu pojedinog rada.
B36: Skela mora biti na vrijeme postavljena kako ne bi nastao zastoj u radu. Skele moraju biti u skladu s propisima HTZ. Iskopane rovove treba u načelu podupirati ako su dubine preko jednog metra. Osim toga, treba ukalkulirati sve potrebne zaštitne ograde, te rampe i mostove za prijevoz materijala po gradnji.
A37: D/ | B37: OPLATA
B38: Kod izrade oplate predviđeno je podupiranje, uklještenja, te postave i skidanje iste. U cijenu ulazi kvašenje oplate prije betoniranja, kao i mazanje limenih kalupa i sl.
B39: Po završetku betoniranja, sva se oplata nakon određenog vremena mora očistiti i sortirati.
A40: E/ | B40: OBRAČUN
B41: Ukoliko nije u pojedinoj stavci dat način obračuna radova, treba se u svemu pridržavati prosječnih normi u građevinarstvu.
A42: F/ | B42: ZIMSKI I LJETNI RAD
B43: Ukoliko je u ugovoreni termin izvršenja objekta uključen i zimski odnosno ljetni period, to se neće posebno izvoditelju priznavati na ime naknade, već sve mora biti uključeno u jediničnu cijenu. Za vrijeme zime građevina se mora zaštititi. Svi eventualno smrznuti dijelovi moraju se ukloniti i izvesti ponovno bez bilo kakve naplate.
B44: Ukoliko je temperatura niža od temperature, pri kojoj je dozvoljen određeni rad, a investitor ipak traži da se radovi izvode, izvoditelj ima pravo računati naknadu po važećoj normi ali u tom slučaju izvoditelj snosi punu odgovornost za ispravnost i kvalitetu izvedenih radova.
B45: To isto vrijedi i za zaštitu radova tokom ljeta od prebrzog sušenja uslijed visoke temperature. Ukoliko dođe do kašnjenja u dinamici krivnjom izvoditelja, dodatne troškove pri radu na niskim temperaturama snosi izvoditelj.
A46: G/ | B46: FAKTORI
B47: Na jediničnu cijenu radne snage izvoditelj ima pravo zaračunati faktor prema postojećim gospodarskim instrumentima na osnovu zakonskih propisa.
B48: Povrh toga izvođač će faktorom obuhvatiti i sljedeće radove, koji se neće zasebno obračunavati kao naknadni rad, i to:
B49: * kompletnu režiju gradilišta, uključujući dizalice, mostove, svu potrebnu mehanizaciju i sl.
B50: * izvedbu privremenih pristupnih puteva u okviru gradilišta
B51: * sva ispitivanja materijala,
B52: * uskladištenje materijala i elemenata za obrtničke i instalaterske radove do njihove ugradbe,
B53: * uređenje gradilišta po završetku rada, sa otklanjanjem svih otpadaka, šute, ostataka građevnog materijala, inventara, pomoćnih objekata, itd.
...

Sheet II. NAMJEŠTAJ
A1: Redni broj: | B1: OPIS STAVKE: | C1: Jedinica mjere: | D1: Količina: | E1: Jedinična cijena: | F1: Ukupno:
A4: II. | B4: OPREMA I NAMJEŠTAJ
B6: OPĆI UVJETI I NAPOMENE:
B8: Prilikom dopreme i ugradnje mora se pridržavati svih važećih normativa i propisa za iste, opisa u stavkama troškovnika i projekta. Sav upotrebljeni materijal mora odgovarati svim važećim propisima i standardima.
B9: Za svu opremu stavkom se određuju dimenzije. Ukoliko se ne radi o ugradbenoj opremi koja mora imati točno određene i zadane mjere koje prozlaze iz prostornog ili nekog drugog ograničenja (dužina zida,dubina niše i sl.), dimenzije dane stavkom su okvirne te mogu varirati, ovisno o proizvođaču. Ukoliko u pojedinoj stavci nije drugačije navedeno, ili ako dimenzije opreme u pojedinoj stavci nisu navedenu po principu od ___ cm do ___ cm, za navedene dimenzije dozvoljava odstupanje od ± 3cm. Svako veće, eventualno moguće odstupanje mora biti striktno navedeno u opisu stavke koja se odnosi na točno određeni komad opreme. Također je obavezno poštivati dimenzije namještaja (stolice, stolovi i sl.) uvjetovane uzrastom djece pojedinih vrtičkih skupina.
B10: Ponuđena oprema mora biti ispitana i certificirana prema HRN EN normama ili jednakovrijednim od strane akreditirane kontrolne ustanove, te sukladno tome ponuditelj mora za određeni namještaj raspolagati sa sljedećim dokumentima koje je potrebno dostaviti prilikom isporuke / ugradnje opreme:
B11: - certifikat/izjavu o sukladnosti proizvođača za ponuđene stolove i stolce za dječje vrtiće sukladno normama: HRN EN 1729-1:2016/Ispr.1, HRN EN 1729-1:2016, HRN EN 1729-2:2016,HRN EN 1728:2012/Ispr.1:2013, HRN EN 1728:2012. | C11: ili jednakovrijedno normi ________________
B12: - certifikat/izjavu o sukladnosti proizvođača za ponuđeni namještaj za dječje vrtiće sukladno normama: HRN EN 16121:2017, HRN EN 14073-2:2008, HRN EN 14073-3:2008, HRN EN 14749:2016, HRN EN 12221-1:2013, HRN EN 1727:2001. | C12: ili jednakovrijedno normi ________________
B13: - certifikat/izjavu o sukladnosti proizvođača za ponuđeni namještaj za odgajatelje sukladno normama: HRN EN 527-1:2011, HRN EN 527-2:2016, HRN EN 527-3:2003, HRN EN 14073-1:2008, HRN EN 14074:2008, HRN EN 14749:2016. | C13: ili jednakovrijedno normi ________________
B14: - certifikt/izjavu o sukladnosti proizvođača za ponuđene garderobe i ostali namještaj za odgojne skupine sukladno normama: HRN EN 16121:2017, HRN EN 14073-1:2008 HRN EN 14073-2:2008, HRN EN 14073-3:2008, HRN EN 14074:2008, HRN EN 14749:2016. | C14: ili jednakovrijedno normi ________________
B15: - certifikat/izjavu o sukladnosti proizvođača za ponuđene dječje garniture za sjedenje sukladno normama: HRN EN 1729-2:2016 (EN 1729:2015). | C15: ili jednakovrijedno normi ________________
B16: - certifikat/izjavu o sukladnosti proizvođača za ponuđeni program arhivskih i garderobnih ormara sukladno normama: HRI CEN/TR 14073-01:2008, HRN EN 14073-2:2008, HRN EN 14073-3:2008, HRN EN 14074:2008, HRN EN 16139:2013, 16121:2017. | C16: ili jednakovrijedno normi ________________
B17: - cerifikat/ozjavu o sukladnosti proizvođača za ponuđene dječje madrace i krevete za odmor sukladno normama: EN 16890:2017(16890:2017). | C17: ili jednakovrijedno normi ________________
B18: - certifikat/izjavu o sukladnosti proizvođača za ponuđeni program metalnih regala sukladno normama: HRI CEN/TR 14073-01:2008, HRN EN 14073-2:2008, HRN EN 14073-3:2008, HRN EN 16121:2017. | C18: ili jednakovrijedno normi ________________
B20: PRIZEMLJE
A21: II.1. | B21: VJETROBRAN
A22: II.1.01 | B22: Kanta za kišobrane, promjera 23, visine 50 cm; tipske proizvodnje, metalna plastificirana ili lakirana u boji po izboru naručitelja. | C22: kom | D22: 1 | E22: 30 | F22: =D22*E22 -> 30
A23: II.1.02 | B23: Zidni pano pluto u metalnom plastificiranom okviru sa zaobljenim rubovima 80x120 cm | C23: kom | D23: 1 | E23: 68 | F23: =D23*E23 -> 68
A24: II.1.03 | B24: Zidni pano magnetni u metalnom plastificiranom okviru sa zaobljenim rubovima 80x120 cm | C24: kom | D24: 2 | E24: 131 | F24: =D24*E24 -> 262
A25: II.1.04 | B25: Stojeća vješalica, metalna, u boji po izboru naručitelja, visine minimalno 170 cm. | C25: kom | D25: 1 | E25: 57 | F25: =D25*E25 -> 57
A26: II.1. | B26: VJETROBRAN - UKUPNO | C26: kom | F26: =SUM(F22:F25) -> 417
A28: II.2. | B28: ULAZNI HALL I STUBIŠTE:
A29: II.2.01 | B29: Sat u obliku kamena Materijal: MDF vlaknatica, bukova šperploča. Dimenzije: Š 58 x V 38 cm. Ovi ukrasni zidni satovi praktičan su dodatak za sve vrste interijera. | C29: kom | D29: 2 | E29: 203 | F29: =D29*E29 -> 406
A30: II.2.02 | B30: Zidni nosači za izlaganje likovnih radova, sastoji se od užadi, kvačica i 2 držača s motivom kamena. Svaka figura ima dimenzije 38 x 88 cm, izrađena od mediapana, a međusobno su povezane s četiri užeta, svako duljine 5 metra. Užad služi za vješanje/izlaganje likovnih radova.Moguće izvjesiti 32 komada papira formata A4 . | C30: kom | D30: 2 | E30: 325 | F30: =D30*E30 -> 650
A31: II.2.03 | B31: Plutena ploča s motivom kamena Plutene ploče služe za postavljanje informacija i nastavnih materijala te dječjih radova. Okvirna ploča u boji pomaže u tematskom usklađivanju razreda, svlačionice ili cijelog odjela. U izradi se koristi kvalitetno zrnasto pluto debljine 6 mm koje je natopljeno lanenim uljem. Zahvaljujući sastavu materijala ploče su vrlo čvrste i dimenzijski stabilne. Materijal: Materijal: a) 6 mm šperploča – podloga, b) 10 mm MDF - sloj podloge, c) 6 mm meko pluto - gornji sloj, d) 18 mm MDF - ukrasni okvir. Dimenzije: Š 118 x V 116 cm | C31: kom | D31: 1 | E31: 687 | F31: =D31*E31 -> 687
A32: II.2. | B32: ULAZNI HALL I STUBIŠTE UKUPNO: | F32: =SUM(F29:F31) -> 1743
A34: II.3. | B34: PROSTOR ZA VIŠE NAMJENA
A35: II.3.01 | B35: Psihomotorna kolica dimenzija ŠDV 106x53,5x111,5 cm, u potpunosti su izrađena od šperploče breze debljine 18 mm, obojana netoksičnim bojama topljivim u vodi koje propuštaju zrno drva. Isporučuje se u kompletu s maxi asortimanom za psihomotoriku od oko 110 komada. Opremljen s 4 čvrsta zakretna kotača, od kojih 2 imaju graničnik. Svi uglovi i rubovi su zaobljeni kako bi se izbjegle traume u slučaju sudara. Isporučuje se s jednostavnim uputama za sastavljanje. Uključuje: 1 kolica zajedno sa: 24 čunjeva za razgraničenje, 2 bloka staze, 12 krugova različitih promjera, 8 štapova u 2 duljine, 8 univerzalnih konektora, 4 čunja s 8 rupa, 24 otiska stopala, 12 šalova, 6 mekanih lopti, 4 glatka prstena , 2 lopte. | C35: kom | D35: 1 | E35: 859 | F35: =D35*E35 -> 859
A36: II.3.02 | B36: Strunjača dim. 200x100x6 cm izrađena od čvrste spužve prekrivena vinilnim materijalom,antialergiskim , sa specijalnom protukliznom , antimufa podlogom, nezapaljiva klase 1, s ručkama | C36: kom | D36: 7 | E36: 140 | F36: =D36*E36 -> 980
A37: II.3.03 | B37: Kombinirani toranj - poligon za igru djece - izrađen od punog svijetlog drva, glatko brušen i lakiran - sastoji se od : a)četverostranog tornja konusnog oblika dim 160x160x160 cm pri dnu i 80x80 cm pri vrhu. Jedna strana puna kao stijena za penjanje sa otvorima za noge. Otvori su okrugli profila 10 cm, i četvrtasti dim 10x10 cm.Na ostale tri strane ima ljestve za penjanje koje su postavljene između kosih nosivih stranica tornja. b) manjeg trokutastog tornja dim 120x85x100 cm kod kojeg dvije strane imaju po četiri letve za penjanje ,a treća ima tri letve za penjanje. c) posebnih ljestvi dim 220x48cm za 17 letvi za penjanje koje na kraju imaju metalne zakrivljene zakačke s kojima se ljestve povezuju za niže i više horizontalne letve tornjeva. | C37: kom | D37: 1 | E37: 2065 | F37: =D37*E37 -> 2065
A38: II.3.04 | B38: Klizeća rampa dim 220 x48 cm koja se također zakači za letve tornja i služi za sklizanje.Okvir je od masivnog drva kao i svi ostali elementi - klizeća ispuna je od šperploče. | C38: kom | D38: 1 | E38: 419 | F38: =D38*E38 -> 419
A39: II.3.05 | B39: Konstrukcija s dvojakom funkcijom: mališani je mogu koristiti kao ljuljačku, dok je za one starije dodatak za penjanje. Izrađena od drva, premazana bojom na bazi vode za udobnu igru ​​i jednostavno čišćenje.Ovo je dio staze koja uključuje niz međusobno kompatibilnih modula za stvaranje novih i složenijih staza. Spajanje nekoliko elemenata stvara pravo igralište, dizajnirano kako želite. Promijenite položaj luka kako biste stvorili nove i jedinstvene staze s preprekama. Izrađeno od održivog drva bukve i breze. Najveća podržana težina 60 kg. Dimenzije: 78x50x32 cm | C39: kom | D39: 1 | E39: 156 | F39: =D39*E39 -> 156
A40: II.3.06 | B40: Švedska klupa dužine 250 cm, sa prihvatom za švedske ljestve i švedski sanduk. Okrenuta naopako može se koristiti kao greda širine 10 cm. Neklizajuća podloga. Materijal: drvo. Dužina: 250 cm. Širina: 22 cm. Visina: 30 cm. | C40: kom | D40: 4 | E40: 275 | F40: =D40*E40 -> 1100
A41: II.3.07 | B41: Široka platforma s različitim stranama za skakanje, za stvaranje ravnih ili kosih staza. Sastoji se od 4 lica: ploča za penjanje s otvorom za prolaz; 3 šipkasta elementa na različitim visinama za penjanje i za fiksiranje spojnih elemenata s drugim elementima konstrukcije. Izrađena od masiva breze i bora, omogućuje višestruke kombinacije i brojne motoričke aktivnosti. Ove se aktivnosti lako mogu prilagoditi razini sklonosti djece i postavljenim ciljevima. Struktura izgrađena u skladu sa sigurnosnim standardom NES 54 300 za obrazovni materijal za motoričke vještine. Isporučuje se u kompletu s ključem, uputama za sastavljanje i prijedlozima za obrazovnu upotrebu. Dimenzije: 74x74x59 cm | C41: kom | D41: 1 | E41: 365 | F41: =D41*E41 -> 365
A42: II.3.08 | B42: Kompletan psihomotorni set u 3 dimenzije. Svaka platforma izrađena je od čvrstog plastičnog materijala i ima neklizajuće gumene umetke na vrhu i dnu. Oblik i širina elemenata dizajnirani su tako da djetetu pružaju stabilnost i prate ergonomski oblik stopala, dok reljefi nude različite ugodne osjećaje. Prikladno od 3 godine. Uključuje: 6 platformi (2 velike od fi 40 cm, 2 srednje od 30 cm i 2 male od 25 cm), 8 brežuljaka dim: 53x18 cm, 6 spojnica, 4 platforme u obliku oblaka dim: 23,7x31,5x4,5 cm i 1 vodič. Materijal: plastika s taktilnom stimulacijom na površinama. Edukacijski cilj: poticati taktilni osjet stopala, ravnotežu, mišiće nogu i skočnog zgloba. | C42: kom | D42: 2 | E42: 599 | F42: =D42*E42 -> 1198
A43: II.3.09 | B43: Set od 4 luka, u 4 boje, izrađena od polikarbonata, laganog ali vrlo otpornog plastičnog materijala, s gumenom podlogom. Njihovim postavljanjem uzastopno moguće je stvoriti tunel u kojem djeca mogu iskusiti koordinaciju u prostoru, sposobnost žongliranja i interakcije s drugom djecom. Dimenzije:55x70 cm | C43: kom | D43: 2 | E43: 75 | F43: =D43*E43 -> 150
A44: II.3.10 | B44: Kolica za lopte napravljena od čelične konstrukcije, premazana prahom za veću izdržljivost tijekom vremena i otpornost na habanje. Opremljen s 4 kotača (od kojih su 2 zakretna) i poklopcem s zatvaračem (lokot nije uključen) idealan je za pohranu lopti i sportske opreme. Može se koristiti i u zatvorenom i na otvorenom. Uključuje: 1 kolica s loptom. Dimenzija ŠDV: 103x70x81 cm | C44: kom | D44: 1 | E44: 280 | F44: =D44*E44 -> 280
A45: II.3.11 | B45: Lopte rukometne, veličine 1 | C45: kom | D45: 4 | E45: 13 | F45: =D45*E45 -> 52
A46: II.3.12 | B46: Lopte s ventilima Ø 22 cm, košarkaške | C46: kom | D46: 4 | E46: 16 | F46: =D46*E46 -> 64
... A62: II.3.28 | B62: Ljestve za penjanje - 2 komada dimenzije: 180x256 cm, sa 17 prečki debljine 30mm materijal: masivno drvo - smreka, bor, ariš prečke 30x80mm - materijal jasen | C62: kom | D62: 2 | E62: 490 | F62: =D62*E62 -> 980
...

Sheet III. VODOOPSKRBA I ODVODNJA
A1: Redni broj: | B1: OPIS STAVKE: | C1: Jedinica mjere: | D1: Količina: | E1: Jedinična cijena: | F1: Ukupno:
A4: III. | B4: RADOVI VODOOPSKRBE I ODVODNJE
A6: III.01. | B6: VANJSKA VODOVODNA INSTALACIJA
A7: III.01.01 | B7: Iskolčenje trase cjevovoda.
B8: Iskolčenje osi projektirane trase vodovoda. Rad obuhvaća iskolčenje prema projektu, i sva geodetska mjerenja kojima se podaci sa projekta prenose na teren, osiguranje osi iskolčene trase i održavanje iskolčenih oznaka na terenu za sve vrijeme građenja, odnosno do predaje radova Investitoru.Obračun se vrši po m' iskolčene osi prema projektnoj dokumentaciji. | C8: m' | D8: 146 | E8: 2 | F8: =D8*E8 -> 292
A9: III.01.02 | B9: Iskop jarka na dionici vodovoda.
B10: na dionici vodovoda. Strojni odnosno ručni iskop zemlje III-V kategorije za izradu jarka prosječne širine 80 cm i prosječne dubine 80 cm u koji se polažu vodovodne cijevi. U jediničnoj cijeni obuhvaćene su sve potrebne aktivnosti (iskop, utovar i odvoz viška materijala na privremenu deponiju). Obračun se vrši po m3 iskopa u sraslom stanju. Jediničnom cijenom obuhvaćene su slijedeće aktivnosti: • iskop (strojni i prema potrebi ručni) zemlje III-V kategorije • iskopani materijal odložit će se na privremeni deponij kako bi s mogao koristiti za zasipanje cjevovoda, a sve prema odluci nadzornog inženjera • iskop (strojni i prema potrebi ručni) zemlje III-V kategorije - sve ostalo potrebno za funkcionalnu izvedbu. Obračun po m3 iskopanog materijala.
B11: ručni iskop | C11: m3 | D11: 26 | E11: 50 | F11: =D11*E11 -> 1300
B12: strojni iskop | C12: m3 | D12: 60 | E12: 30 | F12: =D12*E12 -> 1800
B13: strojni iskopa rova u nasipu ceste s odlaganjem na privremenu deponiju | C13: m3 | D13: 8 | E13: 100 | F13: =D13*E13 -> 800
A14: III.01.03 | B14: Planiranje i valjanje posteljice za polaganje cjevovoda
B15: od miješanih materijala prosječne širine 60 cm na dionici trase vodovoda. Normativ U.B1.010, U.B1.012, U.B1.014, U.B1.016, U.B1.018, U.B1.020, U.B1.022, U.B1.024, U.B1.038, U.B1.042, U.B1.046, U.E8.010. Poprečni nagib i kote posteljice definirane su projektom. Rad obuhvaća uređenje posteljice, nasipavanje i razastiranje izravnavajućeg sloja od čistog sitnijeg materijala, obračunatog u drugoj stavci, grubo i fino planiranje. Posteljicu treba zbiti tako da bez oštećenja može preuzeti opterećenja od konstrukcije prema kotama definiranim projektom. Obračun se vrši po m2 potpuno uređene i zbijene posteljice. | C15: m2 | D15: 70 | E15: 2 | F15: =D15*E15 -> 140
B16: Normativ U.B1.010, U.B1.012, U.B1.014, U.B1.016, U.B1.018, U.B1.020, U.B1.022, U.B1.024, U.B1.038, U.B1.042, U.B1.046, U.E8.010. ili jednakovrijedno______________________________
A17: III.01.04 | B17: Izvedba posteljice
B18: Izvedba posteljice debljine 10 cm i nasipa debljine 15 cm iznad PP vodovodnih cijevi kamenim materijalom 4-8 mm. Obračun po m3 uključujući sav potrebni rad , dobavu i ugradnju materijala. Varijanta ako se vodovod izvodi od PEHD cijevi, ukoliko se izvodi od PEHD cijevi sa zaštitnom ovojnicom stavka se ne izvodi. Obračun po m3 ugrađenog materijala. | C18: m3 | D18: 35 | E18: 40 | F18: =D18*E18 -> 1400
A19: III.01.05 | B19: Zatrpavanje rovova
B20: materijalom iz iskopa u sloju 30 cm sa nabijanjem. Prosječna dubina nasipa je 24 cm i širina 0,80 cm. Najprije upotrijebiti sitni materijal. U cijenu uračunato nabijanje i kvašenje. Obračun po m3 ugrađenog materijala. | C20: m3 | D20: 37 | E20: 25 | F20: =D20*E20 -> 925
A21: III.01.06 | B21: Izrada/popravak tampona
B22: Izrada/popravak sloja tampona cestovne konstrukcije na mjestima iskopa rovova materijalom iz iskopa. IZRADA NOSIVOG SLOJA OD ZRNATOG KAMENOG MATERIJALA Nabava, dovoz i ugradnja kamenog agregata s privremene deponije, tampona 0-31.5 mm s finim planiranjem i valjanjem do potrebne zbijenosti od Ms=100 MN/m2. Debljina tampona je 30 cm. Normativ U.B1.012, U.B1.016, U.B1.018, U.B1.024, U.B1.038, U.B1.042, U.B1.046, U.B8.039, U.E9.020. Rad obuhvaća dobavu i ugradnju zrnatog kamenog materijala u nosivi sloj kolničke konstrukcije. Ovaj sloj se može izvoditi tek nakon što je nadzorni inženjer primio posteljicu. | C22: m3 | D22: 39 | E22: 50 | F22: =D22*E22 -> 1950
B23: Normativ U.B1.012, U.B1.016, U.B1.018, U.B1.024, U.B1.038, U.B1.042, U.B1.046, U.B8.039, U.E9.020. ili jednakovrijedno ________________________________
A24: III.01.07 | B24: Odvoz viška materijala
B25: kamionom na deponij sa utovarom, odvozom , istovarom i taksama za odlaganje. Obračun po m3 odvezenog i zbrinutog materijala. | C25: m3 | D25: 18 | E25: 20 | F25: =D25*E25 -> 360
A26: III.01.08 | B26: Vanjske trase vodovoda od polietilenskih cijevi sa zaštitnom ovojnicom
B27: Dobava i ugradnja vodovodnih polietilenskih cijevi sa zaštitnom ovojnicom, prema DIN 8074/8075, DIN EN 12201, izrađen od PE 100-RC prema PAS 1075, SDR 17, s najvećom otpornosti na spor rast pukotine; ovjereno u skladu s DIN 8075 kao i DIN Certco u skladu s ZP 14.3.1, obilježen s DIN Certco DINplus oznakom sukladnosti, s kontinuiranim ekstrudiranim zaštitnim slojem izrađenim od modificiranog polietilena PEplus, sa plavom prugom. Cijev je kalibrirana i označena prema EN 12201-2. Izvedba cjevovoda prema PAS 1075 Tip 3, cijev s dimenzijama prema DIN 8074 s vanjskim zaštitnim slojem. Sučeono zavarivanje bez uklanjanja zaštitnog sloja, zavarivanje prema relevantnim uputama. Koljena i fazonske komade uračunati u m1 postavljene trase cijevi, ne obračunavaju se zasebno. Obračun se vrši po m' funkcionalno ugrađenih cijevi.
B28: DN 40 | C28: m' | D28: 92 | E28: 15 | F28: =D28*E28 -> 1380
B29: DN 50 | C29: m' | D29: 114 | E29: 21 | F29: =D29*E29 -> 2394
B30: DN 110 | C30: m' | D30: 13 | E30: 40 | F30: =D30*E30 -> 520
B31: - cijevi sa zaštitnom ovojnicom, prema DIN 8074/8075, DIN EN 12201 izrađen od PE 100-RC prema PAS 1075, SDR 17, s najvećom otpornosti na spor rast pukotine; ovjereno u skladu s DIN 8075 ili jednakovrijedno ____________________________________________
B32: DIN Certco u skladu s. s ZP 14.3.1, obilježen s DIN Certco DINplus oznakom sukladnosti ili jednakovrijedno ______________________________
B33: Cijev je kalibrirana i označena prema EN 12201-2 ili jednakovrijedno ________________________________________
B34: Izvedba cjevovoda prema PAS 1075 Tip 3, cijev s dimenzijama prema DIN 8074 s vanjskim zaštitnim slojem ili jednakovrijedno ______________________________
A35: III.01.09 | B35: Vodomjerno okno
B36: Dobava materijala i izvedba kompletnog betonskog vodomjernog okna unutarnjih dimenzija 180x360x180 cm. Okno izvedeno od betona sa dodacima za vodonepropusnost VDP 2, beton C30/37, razred izloženost XA 2, debljine stijenki i dna 25 cm. Na dnu okna izvodi se vodolovno grlo 40x40x40cm. Okno je pokriveno s tipskim ljevano željeznom poklopcem 60/60cm nosivosti 150 kN . Ispod poklopca u stijenke okna ugraditi penjalice na razmaku od 30 cm. Spoj cijevi sa betonskim stijenkama okna izvesti vodonepropusno - KGF komad. Cijevi se oslanjaju na betonski oslonac od betona C16/20. Obračun po kompletno izvedenom vodomjernom oknu uključujući i opremu koja se sastoji od dva nova vodomjera (MDK komad, zatvarača povratnog toka, hvatač nečistoća) uključujući i svu ostalu potrebnu opremu sukladno uputi komunalnog poduzeća. U stavku je uključeno: - strojni iskop zemlje III-V kategorije - podložni betonC12/15 - beton C30/37 , V2 - unutarnja hidroizolacija fleksibilnim jedno komponentnim zaštitnim premazom ojačanim vlaknima na bazi bitumen emulzije - vanjska hidroizolacija pd PVC sintetičke hidro izolacijske folije, debljine 1.5mm - vodonepropusna obrada prodora cijevi - lj.ž. poklopac nosivosti 150 kN - zatrpavanje rova kamenim materijalom 16-62 mm - utovar , odvoz i zbrinjavanje viška iskopanog materijala Obračun po komadu funkcionalano izvedenog vodomjernog okna prema uputi komunalnog poduzeća. | C36: kom | D36: 1 | E36: 2500 | F36: =D36*E36 -> 2500
A37: III.01.10 | B37: Izvedba spoja na javnu vodoopskrbu.
B38: U stavku su uključeni svi potrebni radovi za izvedbu funkcionalnog priključka prema uputama komunalnog poduzeća, sa ZOPT ventilima. Obračun za komplet funkcionalno izvedeni priključak na javni vodovod. | C38: kom | D38: 1 | E38: 2500
A39: III.01.11 | B39: Nadzemni LJŽ hidrant
B40: Nabava, dobava i montaža lijevano-željeznog nadzemnog hidranta s automatskim ispustom prema HRN EN 1074-6 i HRN EN 14384. Za priključak vatrogasnih cijevi ugrađene su dvije gornje B-spojke (65 mm) i jednom donjom A-spojkom (100 mm). Uračunat pregled prije ugradnje, dotjerivanje zaštitom protiv korozije nakon ugradnje, izrada i montaža na hidrant pločice s brojčanom oznakom hidranta u skladu s normom Sektora vodoopskrbe, te sav brtveni i spojni materijal. Uključeni svi potrebni prijenosi. - prirubnice PN 10 za spoj po HRN EN 1092-2 i HRN EN 1333 - gumena brtva s prokronskim prstenom za pitku vodu, za radni tlak 10 do 40 bara, prema HRN EN 681 i HRN EN 1514. Obavezno stezanje s moment ključem prema preporuci proizvođača. - prokromski vijak odgovarajućih dimenzija po HRN EN ISO 4016 sa maticom po HRN EN ISO 4034 s podloškom. Obračun za komplet ugrađeni hidrant. | C40: kom | D40: 1 | E40: 1890 | F40: =D40*E40 -> 1890
B41: željezni nadzemni hidranta s automatskim ispustom prema HRN EN 1074-6 ili jednakovrijedno ____________________________ i HRN EN 14384 ili jednakovrijedno _______________________________
B42: - prirubnice PN 10 za spoj po HRN EN 1092-2 ili jednakovrijedno_______________________________ i HRN EN 1333 ili jednakovrijedno_____________________________________ - gumena brtva s prokronskim prstenom za pitku vodu, za radni tlak 10 do 40 bara, prema HRN EN 681 ili jednakovrijedno ___________________________________i HRN EN 1514 ili jednakovrijedno _________________________________________Obavezno stezanje s moment ključem prema preporuci proizvođača. - prokromski vijak odgovarajućih dimenzija po HRN EN ISO 4016 ili jednakovrijedno __________________________________________ sa maticom po HRN EN ISO 4034 ili jednakovrijedno ___________________________________ s podloškom.
A43: III.01.12 | B43: Podgrada hidranata opekom
...

Sheet IV.A. ETP - VANSKA INSTALACIJA
A1: Redni broj: | B1: OPIS STAVKE: | C1: Jedinica mjere: | D1: Količina: | E1: Jedinična cijena: | F1: Ukupno:
A4: IV.A | B4: VANJSKI RADOVI ELEKTRIČNIH INSTALACIJA
A6: 1. | B6: VANJSKI RADOVI
B8: Napomene:
A9: - | B9: Građevinski dio radova specificiranih u sklopu troškovnika električnih instalacija obavlja za to registrirana i ovlaštena pravna osoba, prema programu kontrole i osiguranja kvalitete iz građevinskog projekta te pod stručnim nadzorom građevinskog inženjera kome treba dostaviti tražene dokaze kvalitete.
B11: NN PRIKLJUČCI
A13: 1 | B13: Geodetski radovi za iskolčenje trase kabela i instalacijskih cijevi za priključni vod od glavnog razvodnog ormara (GRO) do svih vanjskih trošila koja se napajaju iz glavnog razvodnog ormara. | C13: m | D13: 400 | E13: 1 | F13: =D13*E13 -> 400
A15: 2 | B15: Geodetski snimak novo položenih instalacijskih cijevi. Geodetska snimka je podloga za dokumentaciju izvedenog stanja. | C15: m | D15: 400 | E15: 1 | F15: =D15*E15 -> 400
A17: 3 | B17: Izrada prodora u zidu ili podu građevine za polaganje instalacijskih cijevi za provlačenje kabela:
A18: - | B18: prodor za savitljivu rebrastu, dvostruku i zaštitnu cijev D-160 mm | C18: kom | D18: 5 | E18: 100 | F18: =D18*E18 -> 500
A19: - | B19: prodor za savitljivu rebrastu, dvostruku i zaštitnu cijev D-110 mm | C19: kom | D19: 2 | E19: 100 | F19: =D19*E19 -> 200
A20: - | B20: prodor za savitljivu rebrastu, dvostruku i zaštitnu cijev D-50 mm | C20: kom | D20: 3 | E20: 100 | F20: =D20*E20 -> 300
A22: 4 | B22: Vodotijesno brtvljenje prodora za polaganje instalacijskih cijevi odgovarajućom uvodnicom, nakon provlačenja kabela:
A23: - | B23: brtvljenje prodora za savitljivu rebrastu, dvostruku i zaštitnu cijev D-160 mm | C23: kom | D23: 5 | E23: 100 | F23: =D23*E23 -> 500
A24: - | B24: brtvljenje prodora za savitljivu rebrastu, dvostruku i zaštitnu cijev D-110 mm | C24: kom | D24: 2 | E24: 100 | F24: =D24*E24 -> 200
A25: - | B25: brtvljenje prodora za savitljivu rebrastu, dvostruku i zaštitnu cijev D-50 mm | C25: kom | D25: 3 | E25: 100 | F25: =D25*E25 -> 300
B27: ISKOP ISPOD TEMELJNE PLOČE GRAĐEVINE
A29: 5 | B29: Iskop rova za polaganje podzemnih instalacijskih cijevi za provlačenje NN kabela i trake uzemljenja:
A30: - | B30: Iskop rova širine 160 cm, dubine 90 cm ispod građevine za polaganje podzemnih instalacijskih cijevi za provlačenje NN kabela i trake uzemljenja. Ukupna dužina rova je 6 m. Nakon polaganja instalacijskih cijevi ponovno zatrpavanje rova uz nabijanje u slojevima uz uporabu motornog nabijača. | C30: m3 | D30: 8.64 | E30: 50 | F30: =D30*E30 -> 432
A31: - | B31: dobava, isporuka i nasipavanje betona u rov koji će u konačnici biti ispod temeljnje ploče građevine u dva sloja ukupno 30 cm (ispod i iznad položenih cijevi) po cijeloj dužini trase. | C31: m3 | D31: 2.88 | E31: 200 | F31: =D31*E31 -> 576
A32: - | B32: dobava, isporuka i nasipavanje šljunka u rov ispod temeljnje ploče građevine (45 cm) po cijeloj dužini trase. | C32: m3 | D32: 4.32 | E32: 50 | F32: =D32*E32 -> 216
A33: - | B33: dobava, isporuka i nasipavanje betona u rov ispod temeljnje ploče građevine ukupno 15 cm iznad nabijenog šljunka, a ispod buduće temeljnje ploče građevine po cijeloj dužini trase. | C33: m3 | D33: 1.44 | E33: 200 | F33: =D33*E33 -> 288
A34: - | B34: odvoz viška zemlje iz rova za polaganje instalacijskih cijevi za NN kabele i traku uzemljenja | C34: m3 | D34: 8.64 | E34: 10 | F34: =D34*E34 -> 86.4
B36: ISKOP ISPOD PROMETNICE / PARKINGA
A38: 6 | B38: Iskop rova za polaganje podzemnih instalacijskih cijevi za provlačenje NN kabela i trake uzemljenja:
A39: - | B39: Iskop rova širine 160 cm, dubine 90 cm ispod prometnice za polaganje podzemnih instalacijskih cijevi za provlačenje NN kabela i trake uzemljenja. Ukupna dužina rova je 5 m. Nakon polaganja instalacijskih cijevi ponovno zatrpavanje rova uz nabijanje u slojevima uz uporabu motornog nabijača. | C39: m3 | D39: 7.2 | E39: 40 | F39: =D39*E39 -> 288
A40: - | B40: dobava, isporuka i nasipavanje betona u rov koji će u konačnici biti ispod prometnih površina u dva sloja ukupno 30 cm (ispod i iznad položenih cijevi) po cijeloj dužini trase. | C40: m3 | D40: 2.4 | E40: 200 | F40: =D40*E40 -> 480
A41: - | B41: dobava, isporuka i nasipavanje šljunka u rov ispod prometnih površina (45 cm) po cijeloj dužini trase. | C41: m3 | D41: 3.6 | E41: 50 | F41: =D41*E41 -> 180
A42: - | B42: dobava, isporuka i nasipavanje betona u rov ispod kolnika ukupno 15 cm iznad nabijenog šljunka, a ispod budućeg asfalta ili betona po cijeloj dužini trase. | C42: m3 | D42: 0.9 | E42: 200 | F42: =D42*E42 -> 180
A43: - | B43: odvoz viška zemlje iz rova za polaganje instalacijskih cijevi za NN kabele i traku uzemljenja | C43: m3 | D43: 7.2 | E43: 10 | F43: =D43*E43 -> 72
A45: 7 | B45: Iskop rova za polaganje podzemnih instalacijskih cijevi za provlačenje NN kabela i trake uzemljenja:
A46: - | B46: Iskop rova širine 120 cm, dubine 90 cm ispod prometnice za polaganje podzemnih instalacijskih cijevi za provlačenje NN kabela i trake uzemljenja. Ukupna dužina rova je 59 m. Nakon polaganja instalacijskih cijevi ponovno zatrpavanje rova uz nabijanje u slojevima uz uporabu motornog nabijača. | C46: m3 | D46: 63.72 | E46: 20 | F46: =D46*E46 -> 1274.4
A47: - | B47: dobava, isporuka i nasipavanje betona u rov koji će u konačnici biti ispod prometnih površina u dva sloja ukupno 30 cm (ispod i iznad položenih cijevi) po cijeloj dužini trase. | C47: m3 | D47: 21.24 | E47: 200 | F47: =D47*E47 -> 4248
A48: - | B48: dobava, isporuka i nasipavanje šljunka u rov ispod prometnih površina (45 cm) po cijeloj dužini trase. | C48: m3 | D48: 31.86 | E48: 50 | F48: =D48*E48 -> 1593
A49: - | B49: dobava, isporuka i nasipavanje betona u rov ispod kolnika ukupno 15 cm iznad nabijenog šljunka, a ispod budućeg asfalta ili betona po cijeloj dužini trase. | C49: m3 | D49: 10.62 | E49: 200 | F49: =D49*E49 -> 2124
A50: - | B50: odvoz viška zemlje iz rova za polaganje instalacijskih cijevi za NN kabele i traku uzemljenja | C50: m3 | D50: 63.72 | E50: 10 | F50: =D50*E50 -> 637.2
A52: 8 | B52: Iskop rova za polaganje podzemnih instalacijskih cijevi za provlačenje NN kabela i trake uzemljenja:
A53: - | B53: Iskop rova širine 80 cm, dubine 90 cm ispod prometnice za polaganje podzemnih instalacijskih cijevi za provlačenje NN kabela i trake uzemljenja. Ukupna dužina rova je 8 m. Nakon polaganja instalacijskih cijevi ponovno zatrpavanje rova uz nabijanje u slojevima uz uporabu motornog nabijača. | C53: m3 | D53: 5.76 | E53: 40 | F53: =D53*E53 -> 230.4
A54: - | B54: dobava, isporuka i nasipavanje betona u rov koji će u konačnici biti ispod prometnih površina u dva sloja ukupno 30 cm (ispod i iznad položenih cijevi) po cijeloj dužini trase. | C54: m3 | D54: 1.92 | E54: 200 | F54: =D54*E54 -> 384
A55: - | B55: dobava, isporuka i nasipavanje šljunka u rov ispod prometnih površina (45 cm) po cijeloj dužini trase. | C55: m3 | D55: 2.88 | E55: 50 | F55: =D55*E55 -> 144
...

Sheet IV.B. ETP - UNUTARNJA INSTALACI
A1: Redni broj: | B1: OPIS STAVKE: | C1: Jedinica mjere: | D1: Količina: | E1: Jedinična cijena: | F1: Ukupno:
A4: IV.B | B4: UNUTARNJI RADOVI ELEKTRIČNIH INSTALACIJA
A6: B) | B6: ELEKTRIČNA INSTALACIJA ZGRADE
A8: 6. | B8: RAZVODNI ORMARI
A10: 1. | B10: GLAVNI RAZVODNI ORMAR (poz. GRO)
B11: Dobava, ugradnja i spajanje glavnog razvodnog ormara s ugrađenom sklopnom opremom kako slijedi:
B12: ORMAR
A13: - | B13: NN razvodni ormar, 1-vrata, 2000x600x600 mm (vxšxd), | C13: kom | D13: 4 | E13: 410
A14: - | B14: podnožje prema širini ormara, 100x600 mm | C14: kom | D14: 16 | E14: 410
A15: - | B15: bočne stranice (par) za ormare, 2000x600 mm (vxd) | C15: pak | D15: 1 | E15: 410
A16: - | B16: set za povezivanje ormara iznutra (6 kom.) | C16: pak | D16: 4 | E16: 410
A17: - | B17: spremnik za dokumentaciju, samoljepljivi, A4 | C17: kom | D17: 3 | E17: 410
A18: - | B18: ostali spojni i montažni materijal | C18: kompl. | D18: 1 | E18: 410
B19: PRIKLJUČNO POLJE (HEP-ODS) | E19: 410
A20: - | B20: NV rastavna sklopka vel. 01|250A, 3P, M8, stez. 70mm2, na ploču | C20: kom | D20: 4 | E20: 427
A21: - | B21: NV osigurač vel. 01, 160A/400V AC | C21: kom | D21: 12 | E21: 410
A22: - | B22: rastavna sklopka za cilindrične osigurače 10x38mm, 3P/32A, gG, 500V AC | C22: kom | D22: 1 | E22: 410
A23: - | B23: cilindrični osigurač, 10x38, 6A, gG, 500V AC | C23: kom | D23: 3 | E23: 410
A24: - | B24: strujni mjerni transformator 800/5A, klasa 0,5 | C24: kom | D24: 3 | E24: 410
A25: - | B25: mjerni uređaj i analizator mreže Napomena: dobavlja i ugrađuje HEP-ODS | C25: kom | D25: 1 | E25: 410
B26: PRIKLJUČNO POLJE (KORISNIK)
A27: - | B27: kompaktni prekidač snage, 3P/630A/50kA s termo-magnetskom zaštitom kabela, | C27: kom | D27: 1 | E27: 410
A28: - | B28: pomoćni kontakt 1C/O za CNUS, spojen na kompaktni prekidač | C28: kom | D28: 1 | E28: 410
A29: - | B29: NV rastavna sklopka vel.00|160A, 3P, M8, stez. 70 mm2, na ploču | C29: kom | D29: 1 | E29: 410
A30: - | B30: NV osigurač vel. 00, 80A/400V AC | C30: kom | D30: 3 | E30: 410
A31: - | B31: odvodnik prenapona tip I+II TNS 400/50kA | C31: kom | D31: 1 | E31: 410
A32: - | B32: rastavna sklopka za cilindrične osigurače 10x38mm, 3P/32A, gG, 500V AC | C32: kom | D32: 1 | E32: 410
A33: - | B33: cilindrični osigurač, 10x38, 6A, gG, 500V AC | C33: kom | D33: 3 | E33: 410
A34: - | B34: strujni mjerni transformator 800/5A, klasa 0,5 | C34: kom | D34: 4 | E34: 410
A35: - | B35: mjerni uređaj i analizator mreže s prikazom na ekranu na vratima GRO ormara (display dimenzija cca 96x96 mm): • mjerenje u 4 kvadranta • napon - linijski i fazni • min. napon po fazi • maks. napon po fazi • sadržaj viših harmonika po fazi • struja vodiča (faze) i nul-vodiča, srednja vrijednost po fazi, maks. srednja vrijednost po fazi, ukupna struja, sadržaj viših harmonika po fazi • ukupna snaga - radna, jalova i prividna snaga, snaga po fazi - radna, jalova i prividna snaga, srednja vrijednost, maks. srednja vrijednost • faktor snage - ukupni, po fazi • frekvencija • pogonski sati • radna energija - pozitivna ukupna, pozitivna po fazi • jalova energija - pozit. ukupna, pozit. po fazi • radna energija - negativna ukupna • jalova energija - negativna ukupna | C35: kom | D35: 1 | E35: 410
A36: - | B36: minijaturni zaštitni prekidač, B karakteristika, 2A, 2-polni, 10kA | C36: kom | D36: 2 | E36: 410
A37: - | B37: transformator, 1-fazni | 230/024V | 60VA, IP00 | C37: kom | D37: 1 | E37: 410
A38: - | B38: udarno tipkalo (gljiva) za ručni isklop u nuždi, deblokada povlačenjem, sprežni element, sklopni element, N/O (radni), prednja montaža, zaštitna kragna za gljivasta tipkala | C38: kom | D38: 1 | E38: 410
... A49: - | B49: kompaktni prekidač snage, 3P/160A/50kA s termo-magnetskom zaštitom kabela | C49: kom | D49: 1 | E49: 410
B50: SIGURNOSNI SUSTAVI (ZAOBILAZNI VOD)
A51: - | B51: kompaktni prekidač snage 3P, nazivne struje tijela prekidača 125A/25kA s termo-magnetskom zaštitom jedinicom In=80A, podesiva Ir=(0.7-1.0) x In | C51: kom | D51: 1 | E51: 410
B52: POLJE POTROŠNJE
A53: - | B53: kompaktni prekidač snage, 4P/200A/25kA s termo-magnetskom zaštitom kabela, sa funkcijom mjerenja E ( I, U, P, S, Q, f, PF, cos (fi), E, THDu, THDi, min/max snaga potrošnje u zadanom kliznom periodu...) te prijenosom mjerenih veličina komunikacijskim protokolom | C53: kom | D53: 1 | E53: 410
A54: - | B54: kompaktni prekidač snage, 3P/400A/50kA s termo-magnetskom zaštitom kabela, sa funkcijom mjerenja E ( I, U, P, S, Q, f, PF, cos (fi), E, THDu, THDi, min/max snaga potrošnje u zadanom kliznom periodu...) te prijenosom mjerenih veličina komunikacijskim protokolom | C54: kom | D54: 1 | E54: 410
A55: - | B55: kompaktni prekidač snage, 3P/160A/50kA s termo-magnetskom zaštitom kabela, sa funkcijom mjerenja E ( I, U, P, S, Q, f, PF, cos (fi), E, THDu, THDi, min/max snaga potrošnje u zadanom kliznom periodu...) te prijenosom mjerenih veličina komunikacijskim protokolom | C55: kom | D55: 1 | E55: 410
...

Sheet IV.C. ETP - OSTALI RADOVI
A1: Redni broj: | B1: OPIS STAVKE: | C1: Jedinica mjere: | D1: Količina: | E1: Jedinična cijena: | F1: Ukupno:
A4: IV.C | B4: OSTALI RADOVI
A6: C) | B6: OSTALI RADOVI
A8: 19. | B8: ISPITIVANJE ELEKTRIČNE INSTALACIJE I IZRADA DOKUMENTACIJE
A10: 1. | B10: Zapisnik o pregledu i ispitivanju el. instalacije:
A11: - | B11: Otpor izolacije,
A12: - | B12: Otpor petlji kvara svih strujnih krugova,
A13: - | B13: Funkcionalnost zaštite od indirektnog dodira,
A14: - | B14: Povezanost metalnih masa i neprekinutost zaštitnih vodiča,
A15: - | B15: Ispitivanje intenziteta opće rasvjete
A16: - | B16: Ispitivanje intenziteta vanjske rasvjete
A17: - | B17: Funkcionalno ispitivanje i ispitivanje intenziteta nužne rasvjete,
A18: - | B18: Ispitivanje funkcionalnosti daljinskog isključenja el. energije u nuždi
... A20: - | B20: Zapisnik o
B21: - funkcionalnom ispitivanju instalacije slabe struje
B22: - mjerenju gušenja instalacije slabe struje,
B23: - mjerenju otpora izolacije instalacije slabe struje
A24: - | B24: Zapisnik i Uvjerenje o:
B25: - funkcionalnom ispitivanju instalacije sustava odimljavanja
A26: - | B26: Ispitni listovi za elektro ormare i CE naljepnice izdane od strane izrađivača ormara
C27: kompl | D27: 1 | E27: 2100 | F27: =D27*E27 -> 2100
A29: 2. | B29: Izrada nacrta izvedenog stanja s ucrtanim svim izmjenama nastalim tokom izvođenja. Predano investitoru u 3 primjerka (u kvaliteti za tehnički pregled) | C29: kompl | D29: 1 | E29: 2500 | F29: =D29*E29 -> 2500
A31: 3. | B31: Isporuka jednopolnih shema - izvedeno stanje u PVC foliji i umetnuto u vrata razvodnih ormara | C31: kompl | D31: 1 | E31: 1250 | F31: =D31*E31 -> 1250
B33: UKUPNO 19.: | F33: =SUM(F27:F31) -> 5850

Sheet IV.D. ETP - VATRODOJAVA
A1: Redni broj: | B1: OPIS STAVKE: | C1: Jedinica mjere: | D1: Količina: | E1: Jedinična cijena: | F1: Ukupno:
A4: IV.D. | B4: VATRODOJAVA
A6: D) | B6: SUSTAVA ZAŠTITE OD POŽARA
A8: 20. | B8: SUSTAV ZA AUTOMATSKU DOJAVU POŽARA
A10: 1 | B10: Dobava i isporuka adresabilne vatrodojavne centrale s dvije analogno adresabilne petlje, s mogućnosti spajanja do 128 elemenata po petlji i proširenja s dodatne dvije petlje, s intuitivnim grafičkim LCD zaslonom. Karakteristike: - minimalno 2 petlje, proširivo do minimalno 4, uz 512 zona i 300 izlaznih grupa - Ethernet port s TCP/IP protokolom za daljinsku dijagnostiku, održavanje i programiranje - grafički LCD zaslon sukladan normi HRN EN 54 ili jednakovrijednoj, s ikonicama i za prikaz do 256 zona - 3 USB porta s podrškom za memorijske stickove i RS232 sučeljem za pisač - obavještavanje e-mailom izravno s centrale (4 korisnička računa) - struktura izbornika za do 3 operatera (20 korisnika i šifri) - memorija događaja za minimalno 9999 zapisa - mogućnost autonomije minimalno do 72 sata u normalnom radu i 30 minuta u alarmu - izlazi: minimalno 4x 750 mA / 24 VDC s mogućnošću programiranja; 2x 350 mA / 24 VDC za požarni alarm / grešku; 2x relejni izlazi za požarni alarm / grešku; 1x aux 500 mA / 24 VDC - ulazi: minimalno 2 - napajanje: 220/230 VAC, 50/60 Hz, - stupanj zaštite kućišta: minimalno IP30 - sukladno standardima CPD, WEEE, RoHS, normama HRN EN 54-2, HRN EN 54-4, HRN EN 54-21 ili jednakovrijednima - kompatibilna sa softverom za integraciju sustava tehničke zaštite Advisor Management ATS8600 bez dodatnih konvertera signala | C10: kom | D10: 1 | E10: 2850 | F10: =D10*E10 -> 2850
A12: 2 | B12: Dobava i isporuka kartice petlje za vatrodojavnu centralu. Za prihvat dodatne dvije petlje. | C12: kom | D12: 1 | E12: 1100 | F12: =D12*E12 -> 1100
A14: 3 | B14: Dobava i isporuka filtera za uzemljenje vatrodojavne centrale | C14: kom | D14: 1 | E14: 155 | F14: =D14*E14 -> 155
A16: 4 | B16: Dobava i isporuka vatrootpornog ormara za smještaj centrale za dojavu požara, dimenzija 800x800x250 mm, ispitan i certificiran prema normi HRN DIN 4102-5 (obostrana požarna otpornost). Sastoji se od jednokrilnih protupožarnih zaokretnih čeličnih vrata otpornosti na požar razreda T60 i čelične pregradne stijene otpornosti na požar razreda F90-A. | C16: kom | D16: 1 | E16: 1699 | F16: =D16*E16 -> 1699
A18: 5 | B18: Dobava i isporuka telefonskog komunikatora za spoj na dežurnu službu. Komunikator za generiranje rezervne linije i pozivne funkcije preko PSTN-a i GSM/GPRS-a. 5 programabilnih terminala. 15 minuta za glasovnu poruku. U kompletu metalno kućište, step-down modul za napajanje 12 V, rezervna akumulatorska baterija 12 VDC 1,7 Ah. | C18: kom | D18: 1 | E18: 705 | F18: =D18*E18 -> 705
A20: 6 | B20: Dobava i isporuka akumulatorskih baterija 12 VDC, 26 Ah za autonomiju vatrodojavne centrale 72 h. | C20: kom | D20: 2 | E20: 85 | F20: =D20*E20 -> 170
A22: 7 | B22: Dobava i isporuka kućišta za smještaj akumulatorskih baterija | C22: kom | D22: 1 | E22: 55 | F22: =D22*E22 -> 55
A24: 8 | B24: Dobava i isporuka adresabilnog optičkog detektora požara s ugrađenim algoritmom za dijagnostički test samog sebe. LED dioda za signalizaciju stanja. Mogućnost programiranja osjetljivosti putem vatrodojavne centrale. Tehničke karakteristike: - radni napon minimalno 17 VDC, maksimalno 28 VDC - potrošnja struje maksimalno 0,35 mA (normalan rad), maksimalno 4 mA (alarm) - stupanj zaštite kućišta minimalno IP43 - radna temperatura minimalno u rasponu od -10°C do +60°C - mogućnost adresiranja od 1 do 128 - mogućnost zamjene optičke komore - uređaj sukladan standardima i normama CE, CPR i HRN EN 54-7 ili jednakovrijednima | C24: kom | D24: 124 | E24: 52 | F24: =D24*E24 -> 6448
B25: uređaj sukladan standardima i normama CE, CPR i HRN EN 54-7 ili jednakovrijednima ____________________________
A26: 9 | B26: Dobava i isporuka adresabilnog višekriterijskog detektora požara s kombiniranim optičkim i termičkim senzorom. Senzore je moguće konfigurirati u pet različitih logičkih načina rada. Mogućnost programiranja osjetljivosti putem vatrodojavne centrale. Tehničke karakteristike: - radni napon minimalno 17 VDC, maksimalno 28 VDC - potrošnja struje maksimalno 0,35 mA (normalan rad), maksimalno 4 mA (alarm) - stupanj zaštite kućišta minimalno IP23 - radna temperatura minimalno u rasponu od -10°C do +60°C - mogućnost adresiranja od 1 do 128 - mogućnost zamjene optičke komore - uređaj sukladan standardima i normama CE, CPR i HRN EN 54-7 ili jednakovrijednima - minimalno 5 načina rada: samo optički; samo termički - fiksna temperatura; samo termički - gradijent porasta temperature; dualno (neovisno optički i termički); multisenzor s dva stupnja osjetljivosti na dim | C26: kom | D26: 1 | E26: 65 | F26: =D26*E26 -> 65
B27: uređaj sukladan standardima i normama CE, CPR i HRN EN 54-7 ili jednakovrijednima _____________________________
A28: 10 | B28: Dobava i isporuka adresabilnog termičkog detektora požara s termičkim senzorom. DT2063N je termički javljač koji reagira na promjenu temperature u prostoru. Zadovoljava europske EN-54 standarde. Tehničke karakteristike: - radni napon minimalno 17 VDC, maksimalno 28 VDC - potrošnja struje maksimalno 0,27 mA (normalan rad), maksimalno 4,7 mA (alarm) - stupanj zaštite kućišta minimalno IP20 - radna temperatura minimalno u rasponu od -10°C do +60°C - mogućnost adresiranja od 1 do 128 - uređaj sukladan standardima i normama CE, CPR i HRN EN 54-5 ili jednakovrijednima - način rada: samo termički - fiksna temperatura; samo termički - gradijent porasta temperature | C28: kom | D28: 9 | E28: 58 | F28: =D28*E28 -> 522
B29: uređaj sukladan standardima i normama CE, CPR i HRN EN 54-5 ili jednakovrijednima ___________________________________
A30: 11 | B30: Dobava i isporuka podnožja detektora požara sa 4 kontakta. Mora biti kompatibilan sa specificiranim automatskim javljačima požara. | C30: kom | D30: =D24+D26+D28-D33 -> 123 | E30: 6 | F30: =D30*E30 -> 738
A33: 12 | B33: Dobava i isporuka podnožja detektora požara s integriranim izolatorom petlje. Tehničke karakteristike: - stupanj zaštite kućišta minimalno IP30 - radna temperatura u minimalnom rasponu od -10°C do +50°C - mora biti sukladan normi HRN EN 54-17 ili jednakovrijednoj - mora biti kompatibilan sa specificiranim automatskim javljačima požara | C33: kom | D33: 11 | E33: 6 | F33: =D33*E33 -> 66
B34: sukladan normi HRN EN 54-17 ili jednakovrijednoj ____________________
A35: 13 | B35: Dobava i isporuka crvenog, adresabilnog ručnog javljača požara. Sa LED indikatorom za signalizaciju stanja. Tehničke karakteristike: - napajanje minimalno u rasponu od 17 do 38 VDC - potrošnja struje: maksimalno do 0,18 mA (normalan rad), maksimalno do 2,8 mA (alarm) - stupanj zaštite kućišta: minimalno IP41 - radna temperatura: minimalno u rasponu od -25°C do +72°C - sukladan sa standardima CE i CPD, normama HRN EN 54-11 ili jednakovrijednima | C35: kom | D35: 10 | E35: 79 | F35: =D35*E35 -> 790
B36: sukladan sa standardima CE i CPD, normama HRN EN 54-11 ili jednakovrijednima __________________________
A37: 14 | B37: Dobava i isporuka podnožija za adresabilni ručni javljač požara | C37: kom | D37: =D35 -> 10 | E37: 15 | F37: =D37*E37 -> 150
A39: 15 | B39: Dobava i isporuka crvenog, adresabilnog ručnog javljača požara u IP67 zaštiti. Sa LED indikatorom za signalizaciju stanja. Tehničke karakteristike: - napajanje minimalno u rasponu od 17 do 38 VDC - potrošnja struje: maksimalno do 0,18 mA (normalan rad), maksimalno do 2,8 mA (alarm) - stupanj zaštite kućišta: minimalno IP67 - radna temperatura: minimalno u rasponu od -25°C do +72°C - sukladan sa standardima CE i CPD, normama HRN EN 54-11 ili jednakovrijednima | C39: kom | D39: 10 | E39: 215 | F39: =D39*E39 -> 2150
B40: sukladan sa standardima CE i CPD, normama HRN EN 54-11 ili jednakovrijednima _____________________
A41: 16 | B41: Dobava i isporuka podnožija za adresabilni ručni javljač požara u IP67 zaštiti | C41: kom | D41: =D39 -> 10 | E41: 15 | F41: =D41*E41 -> 150
A43: 17 | B43: Dobava i isporuka paralelnog indikatora prorade automatskih javljača požara u spuštenom stropu. | C43: kom | D43: 53 | E43: 17 | F43: =D43*E43 -> 901
A45: 18 | B45: Dobava i isporuka "L" nosača za montažu automatskih javljače u voznom oknu lifta | C45: kom | D45: 1 | E45: 35 | F45: =D45*E45 -> 35
A47: 19 | B47: Dobava i isporuka adresabilnog ulazno-izlaznog modula sa četiri selektabilno nadzirana ulaza i četiri magnestki zapirana izlazna kontakta. Tehničke karakteristike: - minimalno 4 izlaza (nenadzirani) 2 A / 30 VDC - minimalno 4 ulaza - radni napon: minimalno u rasponu 17-39 VDC - potrošnja struje: maksimalno do 0,30 mA (normalan rad), do 0,350 mA (alarm) - radna temperatura: minimalno u rasponu od -5°C do +40°C - stupanj zaštite kućišta minimalno IP40 - sukladan sa normom HRN EN 54-17 ili jednakovrijednom | C47: kom | D47: 11 | E47: 179 | F47: =D47*E47 -> 1969
B48: sukladan sa normom HRN EN 54-17 ili jednakovrijednom ____________________
A49: 20 | B49: Dobava i isporuka adresabilnog modula za prihvat konvencionalnih elemenata. Tehničke karakteristike: - prihvat do 30 detektora - radni napon: minimalno u rasponu 21-28 VDC - potrošnja struje: maksimalno do 15 mA (normalan rad), do 40 mA (alarm) - radna temperatura: minimalno u rasponu od -10°C do +55°C - stupanj zaštite kućišta minimalno IP40 - sukladan sa normom HRN EN 54-18 ili jednakovrijednom | C49: kom | D49: 1 | E49: 55 | F49: =D49*E49 -> 55
B50: sukladan sa normom HRN EN 54-18 ili jednakovrijednom________________________
A51: 21 | B51: Dobava i isporuka konvencionalnog optičkog detektora požara. Optički javljač koji reagira na nastanak dima u prostoru. Zadovoljava europske EN-54 standarde. Tehničke karakteristike: - radni napon minimalno 8,5 VDC, maksimalno 33DC - potrošnja struje maksimalno 0,01 mA (normalan rad), maksimalno 60 mA (alarm) - stupanj zaštite kućišta minimalno IP43 - radna temperatura minimalno u rasponu od -10°C do +60°C - uređaj sukladan standardima i normama CE i HRN EN 45 ili jednakovrijednima | C51: kom | D51: 3 | E51: 55 | F51: =D51*E51 -> 165
B52: uređaj sukladan standardima i normama CE i HRN EN 45 ili jednakovrijednima ____________________
A53: 22 | B53: Dobava i isporuka podnožja detektora požara sa 6 kontakta. Mora biti kompatibilan sa specificiranim konvencionalnim automatskim javljačima požara. | C53: kom | D53: =D51 -> 3 | E53: 17 | F53: =D53*E53 -> 51
A55: 23 | B55: Dobava i isporuka unutarnje adresabilne crvene vatrodojavne sirene s bljeskalicom napajane iz linije. Tehničke karakteristike: - crvena boja kućišta i crvena bljeskalica - radni napon u minimalnom rasponu od 17 do 32 VDC - potrošnja struje u alarmu: maksimalno 31 mA - glasnoća zvuka: minimalno u rasponu od 97 dB - mogućnost odabira minimalno 32 različita tona - radna temperatura: minimalno u rasponu od -10°C do +55°C - stupanj zaštite kućišta minimalno IP65 - sukladna normi HRN EN 54-3 ili jednakovrijednoj | C55: kom | D55: 8 | E55: 130 | F55: =D55*E55 -> 1040
B56: - sukladn normi HRN EN 54-3 ili jednakovrijednoj _____________________
A57: 24 | B57: Dobava i isporuka vanjske adresabilne crvene vatrodojavne sirene s bljeskalicom napajane iz linije. Tehničke karakteristike: - crvena boja kućišta i crvena bljeskalica - radni napon u minimalnom rasponu od 17 do 32 VDC - potrošnja struje u alarmu: maksimalno 31 mA - glasnoća zvuka: minimalno u rasponu od 97 dB - mogućnost odabira minimalno 32 različita tona - radna temperatura: minimalno u rasponu od -10°C do +55°C - stupanj zaštite kućišta minimalno IP65 - sukladna normi HRN EN 54-3 ili jednakovrijednoj | C57: kom | D57: 8 | E57: 158 | F57: =D57*E57 -> 1264
B58: - sukladno normi HRN EN 54-3 ili jednakovrijednoj _____________________
A59: 25 | B59: Dobava i isporuka prespojne kutije za prihvat termoosjetljivig kabela. Tehničke karakteristike: - dimenzije 94 x 94x 57 mm - stupanj zaštite kućišta minimalno IP65/66 | C59: kom | D59: 1 | E59: 179 | F59: =D59*E59 -> 179
...

Sheet IV.E. ETP - SUNCANA ELEKTRANA
A1: Redni broj: | B1: OPIS STAVKE: | C1: Jedinica mjere: | D1: Količina: | E1: Jedinična cijena: | F1: Ukupno:
A4: IV.E. | B4: SUNČANA ELEKTRANA
A6: E) | B6: SUNČANA ELEKTRANA
B8: Napomena:
A9: - | B9: Na krovu građevine je planirana ugradnja sunčane elektrane vršne snage 100 kW.
A10: - | B10: Cijena za svaku stavku mora uključivati dobavu, ugradnju, spajanje, polaganje/instalaciju i spajanje do potpune funkcionalnosti kako stavke tako i sustava u cjelini.
A12: 21. | B12: OPREMA SUNČANE ELEKTRANE
B14: KROVNA KONSTRUKCIJA
A15: 1. | B15: Dobava, ugradnja i spajanje aluminijske krovne konstrukcije / montažnog sustava za 278 FN modula na ravnom neprohodnom krovu, nagiba od maksimalno 7 stupnja, konstrukcija se montira na krov:
A16: - | B16: bazna konstrukcija - Al podprofil | C16: m | D16: 360 | E16: 7 | F16: =D16*E16 -> 2520
A17: - | B17: bazna konstrukcija - Al nadprofil | C17: m | D17: 530 | E17: 7 | F17: =D17*E17 -> 3710
A18: - | B18: montažni elementi za spoj bazne konstrukcije na ravni krov | C18: komplet | D18: 1 | E18: 1500 | F18: =D18*E18 -> 1500
A19: - | B19: motažni elementi za spoj podprofila i nadprofila | C19: komplet | D19: 1 | E19: 1500 | F19: =D19*E19 -> 1500
A20: - | B20: montažni elementi za spoj FN modula na baznu konstrukciju | C20: komplet | D20: 1 | E20: 1500 | F20: =D20*E20 -> 1500
A21: - | B21: podprofilne i nadprofilne produžnice, pričvrsnice, inox vijci (obični i samobušeći), matice, podloške, brtve i sl. | C21: komplet | D21: 1 | E21: 500 | F21: =D21*E21 -> 500
B24: FN PANELI, KONEKTORI I PRIBOR
A25: 2. | B25: Dobava, ugradnja/montaža FN panela na prethodno pripremljenu nosivu podkonstrukciju i spajanje:
B26: - snaga 450 Wp, - otpornost na opterećenje vjetra/snijega min. 4000/5400 Pa, - dimenzije: max 1762x1134x30 mm, - težina: max. 21.0 kg, - broj ćelija 144, - toplinski ojačano staklo s visokom propusnosti / 1.6 mm, - razvodna kutija IP68,
B27: - odlična požarna sigurnost i otpornost na vanjske uvjete, - priključak MC4 kompatibilan, - priključni kabel 4 mm2, - tip ćelija Monokristalne 166x83 mm, - jamstvo na materijal i tehnologiju 25 godina, - linearno jamstvo na izlaznu snagu min 84.95% snage 30 godina, - minimalne performanse panela pri standardnim uvjetima ispitivanja (STC 1000W/m2, 25°C, AM 1,5): - snaga u točki maksimalne snage: 450 W (+5%/-0%), - napon u točki max. snage, Umpp: 44,6 V, - struja u točki max. snage, Impp: 10,09 A, - napon otvorenog kruga, Uoc: 52,9 V, - struja kratkog spoja, Isc: 10,74 A,
B28: - max. napon sustava DC1500V, - max. struja sustava 20 A, - temperaturni koeficijenti panela: - temp. koeficijent struje kratkog spoja minimalno + 0,04 % / °C, - temp. koeficijent napona otvorenog kruga maksimalno – 0,24 % / °C, - temp. koeficijent maksimalne snage maksimalno 0,30 % / °C, - temperatura za trajni pogon panela: 43 ± 2 °C, - dozvoljeni raspon temperatura za trajni pogon panela: -40 °C do +85 °C | C28: kom | D28: 278 | E28: 128 | F28: =D28*E28 -> 35584
F29: =D29*E29 -> 0
A30: - | B30: Spojnica MC4 muška, za kabel 4-6 mm2, maks. promjer 5,5-9 mm | C30: kom | D30: 278 | E30: 4 | F30: =D30*E30 -> 1112
A31: - | B31: Spojnica MC4 ženska, za kabel 4-6 mm2, maks. promjer 5,5-9 mm | C31: kom | D31: 278 | E31: 4 | F31: =D31*E31 -> 1112
A32: - | B32: Kabel SOLAR XLR (PV1-F), 4 mm² plave boje | C32: m | D32: 1000 | E32: 2 | F32: =D32*E32 -> 2000
A33: - | B33: Kabel SOLAR XLR (PV1-F), 4 mm² crvene boje | C33: m | D33: 1000 | E33: 2 | F33: =D33*E33 -> 2000
A34: - | B34: Kabelske vezice UV stabilne | C34: kom | D34: 600 | E34: 0.3 | F34: =D34*E34 -> 180
A35: - | B35: Kabelski kanal min. 55x200 mm, vruće pocinčan | C35: m | D35: 115 | E35: 30 | F35: =D35*E35 -> 3450
A36: - | B36: Neperforirani poklopac, za kabelski kanal, 200mm | C36: m | D36: 115 | E36: 10 | F36: =D36*E36 -> 1150
A37: - | B37: Izrada prodora i vodotjesno brtvljenje otvora na krovu nakon polaganja svih kabela za napajanje FN opreme na krovu zgrade. Otvor cca 150/100 mm | C37: komplet | D37: 1 | E37: 150 | F37: =D37*E37 -> 150
B40: FN PRETVARAČ - INVERTER
A41: 3. | B41: Dobava, ugradnja/montaža i spajanje izmjenjivača (FN pretvarač - inverter), 100 kW, 3f, IP65:
B42: - dimenzije max (vxšxd) 700/1035/365 mm, - težina max. 93 kg, - IP 66 min., - dozvoljena temperatura za trajni pogon: - 25 °C do 60 °C
B43: - ulazne karakteristike izmjenjivača (DC strana): - broj MPP trackera 10, - broj string-ova po MPP trackeru: 2 ili 1, - opseg ulaznog DC napona (U_DC_min - U_DC_max): 200 - 1000 V - startna vrijednost DC napona: 200 V - nazivni ulazni napon: 600 V - maksimalna struja po MPPT-u: 30,0 A - maksimalna struja kratkog spoja po string-u: 40A
B44: -izlazne karakteristike izmjenjivača (AC strana): - nazivna snaga: 100 kW, - maksimalna izlazna snaga: 110 kVA, - mrežni priključak: 3~ NPE 400V, - frekvencija mreže: 50/60 Hz, - ukupna harmonička distorzija maksimalno ≤3%, - faktor snage: približno 1 (podesivo 0.8-0.8 ind./kap.), - maksimalna efikasnost (FN-mreža) min. 98,8%, - europska efikasnost (ηEU) min. 98,6%. | C44: kom | D44: 1 | E44: 6000 | F44: =D44*E44 -> 6000
B46: UKUPNO 21.: | F46: =SUM(F16:F45) -> 63968
A49: 22. | B49: KABELI I INSTALACIJSKI PRIBOR I MATERIJAL
B51: Napomena:
A52: - | B52: Sunčana elektrana spaja se na glavni razvodni ormar GRO u prizemlju predmetne zgrade.
