Workbook

Sheet 1. naslov
A5: Osnovna škola Klinča Sela
A7: Rekonstrukcija školskog sportskog igrališta PŠ repišće
A14: Troškovnik građevinskih i obrtničkih radova uređenja igrališta i okoliša

Sheet 2. rekapitulacija
B3: Rekapitulacija - troškovnik rekonstrukcija igrališta u PŠ Repišće
A6: II. REKAPITULACIJA TROŠKOVA - RAZRADA
A9: I: | B9: PRIPREMNI RADOVI | G9: bez PDV-a
B11: UKUPNO PRIPREMNI RADOVI | G11: ='3. troškovnik'!G138 -> 2200
A13: II: | B13: RUŠENJE I DEMONTAŽA | G13: bez PDV-a
B15: UKUPNO RUŠENJE I DEMONTAŽA | G15: ='3. troškovnik'!G142 -> 12252
A17: III. | B17: ZEMLJANI RADOVI | G17: bez PDV-a
B19: UKUPNO ZEMLJANI RADOVI | G19: ='3. troškovnik'!G146 -> 14231.5
A21: IV: | B21: BETONSKI I ARMIRANOBETONSKI RADOVI | G21: bez PDV-a
G23: ='3. troškovnik'!G150 -> 45430
A25: V. | B25: KONSTRUKCIJA IGRALIŠTA | G25: bez PDV-a
B27: UKUPNO KONSTRUKCIJA IGRALIŠTA | G27: ='3. troškovnik'!G154 -> 38794
A29: VI. | B29: ZAŠTITNA OGRADA IGRALIŠTA | G29: bez PDV-a
B31: ZAŠTITNA OGRADA IGRALIŠTA | G31: ='3. troškovnik'!G158 -> 20320
A33: VII. | B33: DOBAVA I UGRADNJA OPREME
B35: DOBAVA I UGRADNJA OPREME | G35: ='3. troškovnik'!G162 -> 14120
A37: VIII. | B37: ODVODNJA | G37: bez PDV-a
B39: ODVODNJA | G39: ='3. troškovnik'!G166 -> 1612
A41: IX. | B41: ELEKTROINSTALACIJE I VANJSKA RASVJETA | G41: bez PDV-a
B43: ELEKTROINSTALACIJE I VANJSKA RASVJETA | G43: ='3. troškovnik'!G170 -> 15525
A45: X. | B45: HORTIKULTURNO UREĐENJE
B47: HORTIKULTURNO UREĐENJE | G47: ='3. troškovnik'!G174 -> 2400
A49: II. REKAPITULACIJA TROŠKOVA - SVEUKUPNO
B52: SVEUKUPNO BEZ PDV-a | G52: ='3. troškovnik'!G179 -> 166884.5
B53: PDV 25% | F53: 0.25 | G53: =G52*F53 -> 41721.125
B54: SVEUKUPNO S PDV-om | G54: =G52+G53 -> 208605.62

Sheet 3. troškovnik
A1: 0
A3: 1 | B3: REKONSTRUKCIJA ŠKOLSKOG SPORTSKOG IGRALIŠTA PŠ REPIŠĆE
B6: GRAĐEVINSKO OBRTNIČKI RADOVI UREĐENJA IGRALIŠTA I OKOLIŠA | C6: jed.mj. | D6: kol. | E6: jed. cijena
A8: 1.A | B8: PRIPREMNI RADOVI
A10: 1.A.01./a | B10: Elaborat iskolčenja i geodetska mjerenja | C10: kom | D10: 1 | E10: 1200 | G10: =D10*E10 -> 1200
A11: 1.B.01./a | B11: Projekt elektroinstalacije | C11: kom | D11: 1 | E11: 1000 | G11: =D11*E11 -> 1000
B12: UKUPNO PRIPREMNI RADOVI | G12: =SUM(E10:E11) -> 2200
A14: 2.B | B14: RUŠENJE I DEMONTAŽA
A16: 1.B.01 | B16: Iskapčanje postojeće elektroinstalacije za rad na rasvjetnim stupovima igrališta | C16: kom | D16: 1 | E16: 200 | G16: =D16*E16 -> 200
A17: 1.B.02 | B17: Strojno rušenje armirano betonskih potpornih zidova zajedno sa stopama i zidova ograde | C17: m3 | D17: 28 | E17: 120 | G17: =D17*E17 -> 3360
A18: 1.B.03 | B18: Strojno uklanjanje asfaltne površine igrališta do zrnate podloge. Debljina asfalta je cca 12 cm. Uklonjeni asfalt se usitnjava, utovaruje u kamion i odvozi na zbrinjavanje, prema Pravilniku o vrstama otpada. | C18: m2 | D18: 880 | E18: 6 | G18: =D18*E18 -> 5280
A19: 1.B.03 | B19: Pregled nasipa kamenog i šljunčanog materijala ispod asfaltne površine igrališta. Strojno uklanjanje nestabilnog dijela nasipa debljine cca 20 cm. Odlaganje na gradilišnu deponiju | C19: m2 | D19: 176 | E19: 2 | G19: =D19*E19 -> 352
A20: 1.B.03 | B20: Utovar i odvoz građevinske šute i naknada za zbrinjavanje građevinskog otpada | C20: m3 | D20: 204 | E20: 15 | G20: =D20*E20 -> 3060
B21: UKUPNO RUŠENJE I DEMONTAŽA | G21: =SUM(G16:G20) -> 12252
A23: 3.C | B23: ZEMLJANI RADOVI
A25: 3.C.01 | B25: Kontrola temeljnog tla i dodatni nadzor ovlaštenih geomehaničara prilikom iskopa. Predviđa se 5 obilazaka | C25: kom | D25: 5 | E25: 150 | G25: =D25*E25 -> 750
A26: 3.C.02 | B26: Strojni iskop humusa sa šljunčanim materijalom, debljine 30 cm. | C26: m3 | D26: 30 | E26: 10 | G26: =D26*E26 -> 300
A27: 3.C.03 | B27: Strojni široki iskop za potporne zidove u materijalu C kategorije prema GN 200 iskop u kategoriji 3 /II do 4/III | C27: m3 | D27: 160 | E27: 10 | G27: =D27*E27 -> 1600
A28: 3.C.04 | B28: Razni iskopi za temelje i kanale u materijalu C kategorije prema GN 200 iskop u kategoriji 3/II do 4/III s pravilnom obradom profila iskopa. Dubina iskopa do 1 m. | C28: m3 | D28: 48 | E28: 10 | G28: =D28*E28 -> 480
A29: 3.C.05 | B29: Izrada pokosa na dijelu uz cestu i prema školi. Rad uključuje formiranje pravilnog pokosa 3/1 od postojeće zemlje | C29: m3 | D29: 60 | E29: 10 | G29: =D29*E29 -> 600
A30: 3.C.06 | B30: Dobava i razastiranja sloja tampon šljunka, debljine 10 cm ispod temeljnih traka, stopa i stepenica | C30: m3 | D30: 18 | E30: 40 | G30: =D30*E30 -> 720
A31: 3.C.07 | B31: Nasipavanje uz potporne i rubne arm. bet. zidove sa zemljom dobivenom iz iskopa do visine prema projektu | C31: m3 | D31: 30 | E31: 10 | G31: =D31*E31 -> 300
A32: 3.C.08 | B32: Uređenje temeljnog nasipa na igralištu nakon iskopa planiranjem te dobavom i ugradnjom geotekstila | C32: m2 | D32: 881 | E32: 1.5 | G32: =D32*E32 -> 1321.5
A33: 3.C.09 | B33: Izrada nasipa od mehanički sabijenog zrnastog kamenog materijala, debljina sloja do 20 cm. | C33: m3 | D33: 180 | E33: 28 | G33: =D33*E33 -> 5040
A34: 3.C.10 | B34: Izrada plitke drenaže od perforiranih dvoslojnih drenažnih PVC cijevi profila DN 160 mm, iskop rova, dobava cijevi | C34: m1 | D34: 44 | E34: 30 | G34: =D34*E34 -> 1320
A35: 3.C.11 | B35: Utovar odvoz i zbrinjavanje viška zemlje na trajnu deponiju udaljenosti do 25 km | C35: m3 | D35: 180 | E35: 10 | G35: =D35*E35 -> 1800
B36: UKUPNO ZEMLJANI RADOVI | G36: =SUM(G25:G35) -> 14231.5
B38: BETONSKI I ARMIRANOBETONSKI RADOVI
A39: 4D.01 | B39: Dobava mrežaste armature Q 166 i betona, ugradba i zaštita. | C39: kg | D39: 520 | E39: 1.5 | G39: =D39*E39 -> 780
A40: 4.D.02 | B40: Izvedba betonske podloge za nadstrešnice, u zemlji. Mali presjek, beton tlačne čvrstoće C 25/30 (MB-30). Debljina podloge 20 cm. | C40: m3 | D40: 5.2 | E40: 200 | G40: =D40*E40 -> 1040
A41: 4D.03 | B41: Izrada podložnog betona ispod trakastih temelja, stopa i vanjskih AB površina, prije polaganja | C41: m3 | D41: 15 | E41: 100 | G41: =D41*E41 -> 1500
A42: 4D.04 | B42: Izrada arm. bet. trakastih temelja i razdjelnih zidova u zemlji. Dobava betona, ugradba i zaštita. - beton | C42: m3 | D42: 42 | E42: 130 | G42: =D42*E42 -> 5460
B43: oplata | C43: m2 | D43: 220 | E43: 25 | G43: =D43*E43 -> 5500
A44: 4D.05 | B44: Izrada arm. bet. Potpornih zidova u zemlji, i djelomično u oplati - beton | C44: m3 | D44: 40 | E44: 130 | G44: =D44*E44 -> 5200
B45: oplata | C45: m2 | D45: 210 | E45: 25 | G45: =D45*E45 -> 5250
A46: 4D.06 | B46: Izrada arm. bet. vanjskih ravnih stepenica, dobava betona, ugradba i zaštita. - beton | C46: m3 | D46: 7.2 | E46: 150 | G46: =D46*E46 -> 1080
B47: oplata | C47: m2 | D47: 32 | E47: 40 | G47: =D47*E47 -> 1280
A48: 4D.07 | B48: Izrada zamjenskog betonskog materijala u slučaju promjene temeljnog tla. Dobava betona i ugradba. | C48: m3 | D48: 10 | E48: 100 | G48: =D48*E48 -> 1000
B49: Armatura | C49: kg | D49: 1100 | E49: 1.5 | G49: =D49*E49 -> 1650
A50: 4D.08 | B50: Izrada armirano betonskih zidova, dna i ploče šahta za drenažnu pumpu. Dobava betona, ugradba i zaštita. | C50: m3 | D50: 4 | E50: 120 | G50: =D50*E50 -> 480
...
