Workbook

Sheet NASLOVNICA
A2: PLANINARSKI DOM ŽITNICA, OKOLNI OBJEKTI I OBJEKTI NA VRHU JAPETIĆA
A4: TROŠKOVNIK GRĐEVINSKO-OBRTNIČKIH I INSTALATERSKIH RADOVA

Sheet REKAPITULACIJA
B2: PLANINARSKI DOM ŽITNICA, OKOLNI OBJEKTI I OBJEKTI NA VRHU JAPETIĆA
B4: REKAPITULACIJA
A6: 1. | B6: ARHITEKTURA
A8: 1.A. | B8: PLANINARSKI DOM ŽITNICA
A9: A. | B9: GRAĐEVINSKI RADOVI
A10: A.1. | B10: PRIPREMNI RADOVI | C10: =SUM('1. ARHITEKTURA'!F35) -> 5850
A11: A.2. | B11: UKLANJANJE | C11: =SUM('1. ARHITEKTURA'!F50) -> 26000
A12: A.3. | B12: ZEMLJANI RADOVI | C12: =SUM('1. ARHITEKTURA'!F94) -> 41487
A13: A.4. | B13: BETONSKI I ARMIRANO-BETONSKI RADOVI | C13: =SUM('1. ARHITEKTURA'!F276) -> 325057.4
A14: A.5. | B14: ZIDARSKI RADOVI | C14: =SUM('1. ARHITEKTURA'!F346) -> 44484
A15: A.6. | B15: TESARSKI RADOVI | C15: =SUM('1. ARHITEKTURA'!F411) -> 148775
A16: B. | B16: OBRTNIČKI RADOVI
A17: B.1. | B17: IZOLATERSKI RADOVI | C17: =SUM('1. ARHITEKTURA'!F456) -> 61510.7
A18: B.2. | B18: LIMARSKI RADOVI | C18: =SUM('1. ARHITEKTURA'!F514) -> 40305.5
A19: B.3. | B19: FASADERSKI RADOVI | C19: =SUM('1. ARHITEKTURA'!F532) -> 23735
A20: B.4. | B20: ALUMINIJSKA I BRAVARSKA STOLARIJA | C20: =SUM('1. ARHITEKTURA'!F724) -> 128162.12
A21: B.5. | B21: STOLARSKI RADOVI | C21: =SUM('1. ARHITEKTURA'!F755) -> 34750
A22: B.6. | B22: PROTUPOŽARNA STOLARIJA | C22: =SUM('1. ARHITEKTURA'!F766) -> 4450
A23: B.7. | B23: UNUTARNJA STOLARIJA | C23: =SUM('1. ARHITEKTURA'!F838) -> 65719
A24: B.8. | B24: PROTUPOŽARNA UNUTARNJA STOLARIJA | C24: =SUM('1. ARHITEKTURA'!F864) -> 9563
A25: B.9. | B25: BRAVARSKI RADOVI | C25: =SUM('1. ARHITEKTURA'!F924) -> 50159
A26: B.10. | B26: PROTUPOŽARNA INSTALACIJSKA VRATA | C26: =SUM('1. ARHITEKTURA'!F932) -> 2380
A27: B.11. | B27: PODOPOLAGAČKI RADOVI | C27: =SUM('1. ARHITEKTURA'!F953) -> 35959.5
A28: B.12. | B28: KERAMIČARSKI RADOVI | C28: =SUM('1. ARHITEKTURA'!F987) -> 50415
A29: B.13. | B29: KAMENARSKI RADOVI | C29: =SUM('1. ARHITEKTURA'!F1006) -> 14500
A30: B.14. | B30: GIPSARSKI RADOVI | C30: =SUM('1. ARHITEKTURA'!F1065) -> 15385
A31: B.15. | B31: POŽARNE GIPSANE OBLOGE | C31: =SUM('1. ARHITEKTURA'!F1113) -> 30289
A32: B.16. | B32: SOBOSLIKARSKI I LIČILAČKI RADOVI | C32: =SUM('1. ARHITEKTURA'!F1138) -> 21827.5
A33: B.17. | B33: RAZNE UGRADNJE | C33: =SUM('1. ARHITEKTURA'!F1162) -> 4500
A34: B.18. | B34: PROTUPOŽARNA BRTVLJENJA | C34: =SUM('1. ARHITEKTURA'!F1208) -> 32610
A35: B.19. | B35: KUHINJSKA OPREMA | C35: =SUM('1. ARHITEKTURA'!F1369) -> 113787
A36: 1.A. | B36: PLANINARSKI DOM ŽITNICA UKUPNO | C36: =SUM(C10:C35) -> 1331660.7
A38: 1.B. | B38: OSTALI OBJEKTI / VIDIKOVAC, STIJENA ZA BOULDER, VODOSPREMA
A39: A.B. | B39: GRAĐEVINSKI RADOVI
A40: A.B.2. | B40: ZEMLJANI RADOVI | C40: =SUM('1. ARHITEKTURA'!F1453) -> 21035.2
A41: A.B.3. | B41: BETONSKI I ARMIRANO BETONSKI RADOVI | C41: =SUM('1. ARHITEKTURA'!F1548) -> 87242
A42: A.B.4. | B42: ZIDARSKI RADOVI | C42: =SUM('1. ARHITEKTURA'!F1579) -> 5324
A43: A.B.5. | B43: TESARSKI RADOVI | C43: =SUM('1. ARHITEKTURA'!F1632) -> 61260
A44: B.B. | B44: OBRTNIČKI RADOVI
A45: B.B.1. | B45: IZOLATERSKI RADOVI | C45: =SUM('1. ARHITEKTURA'!F1664) -> 19101.4
...

Sheet OPĆI UVJETI
B1: PLANINARSKI DOM ŽITNICA, OKOLNI OBJEKTI I OBJEKTI NA VRHU JAPETIĆA
B3: OPĆI UVJETI
B5: Ovaj projekt se člankom 14. stavak 2. podstavak 6. Zakona o autorskom pravu i srodnim pravima (NN 111/21) smatra autorskim djelom.
B6: Prilikom razrade onih dijelova projekta koji nisu definirani izvedbenom dokumentacijom pridržavati se svega iz glavnog i izvedbenog projekta. U slučaju neophodnih promjena, prilikom razrade glavnog/izvedbenog projekta, tražiti suglasnost u pisanom obliku koje izrađivaču glavnog i izvedbenog projekta daje Autor projekta, sukladno 115. st. 4 . Zakonu o autorskom pravu i srodnim pravima.
B7: Izrađivač razrade izvedbenog projekta (izvedbeni nacrti, detalji, radionički nacrti) je dužan poštovati moralna autorska prava autora projekta i ponašati se u skladu s propisima koji uređuju autorska prava.
B9: Izvođač je dužan izraditi kompozitne nacrte instalacija (tlocrt stropova), te predočiti ih glavnom projektantu na ovjeru.
B10: Detalji, planovi i nacrti koji nisu definirani izvedbenim projektom, a potrebni su za funkcioniranje gradilišta, izvođač izrađuje i predočava ih glavnom projektantu na ovjeru.
B12: Nacrti, tehnički opis i ovaj troškovnik čine cijelinu projekta.
B13: Izvođač je dužan proučiti sve gore navedene dijelove projekta, te u slučaju nejasnoća tražiti objašnjenje od projektanta, odnosno iznijeti svoje primjedbe.
B14: Nepoznavanje crtanog dijela projekta i tehničkog opisa neće se prihvatiti kao razlog za povišenje jediničnih cijena ili greške u izvedbi.
B15: Izvođač je dužan pridržavati se svih važećih zakona i propisa.
B16: Izvođač je prilikom uvođenja u posao dužan, u okviru ugovorene cijene, preuzeti parcelu, te obavjestiti nadležne službe o otvaranju gradilišta.
... B35: Svi proizvodi koji su u Troškovniku opisani uz navođenje trgovačke marke/oznake popraćeni su formulacijom "ili jednakovrijedan". Dokaz jednakovrijednosti u vidu tehničke specifikacije, tehničkih listova, certifikata koji potvrđuju kvalitetu i sl. dužan je ponuditelj dostaviti uz ponudu, u svrhu ocjene sukladnosti tražene po projektu.

Sheet 1. ARHITEKTURA
A1: 1. | B1: ARHITEKTURA
A3: RB | B3: STAVKA | C3: JEDINICA MJERE | D3: KOLIČINA | E3: JEDINIČNA CIJENA | F3: UKUPNA CIJENA
A5: 1.A. | B5: PLANINARSKI DOM NA ŽITNICI
B7: GRAĐEVINSKO-OBRTNIČKI RADOVI
A9: A | B9: GRAĐEVINSKI RADOVI
B11: OPĆE NAPOMENE:
B13: Svi radovi navedeni u ovom troškovniku moraju biti izvedeni stručno i solidno, prema projektu,važećim zakonima , tehničkim propisima i uputama nadzorne službe. Osim toga , izvođač je obavezan pridržavati se uputa projektanta/nadzora u svim pitanjima koja se odnose na izbor i obradu materijala i način izvedbe pojedinih detalja, ukoliko to nije već opisano troškovnikom. U slučaju da opis pojedine stavke nije dovoljno jasan, mjerodavan je Projekt uklanjanja, ili uputa i tumačenje projektanta/nadzora. O tome se izvođač treba informirati već prilikom sastavljanja jedinične cijene. Izvođač je dužan prilikom sastavljana ponude proučiti sve potrebne projekte radi potpunog uvida u objekt. U jediničnim cijenama moraju biti obuhvaćeni svi troškovi potrebni za dovršenje predviđenog rada, tj. materijal s prevozima i prenosima, troškovi mehanizacije, radna snaga sa svim dodacima, svi režijski troškovi izvođača, obveze, porezi, dobit i ostalo, tako da je ponuđena cijena konačna. U ponuđenim jediničnim cijenama moraju također biti obuhvaćeni svi pripremni radovi potrebni za izgradnju zgrade, kao što je izvedba svih pomoćnih objekta i instalacijskih priključaka gradilišta, ograde gradilišta itd. Svi upotrebljeni i ugrađeni materijali moraju odgovarati Hrvatskim normama, a atesti ne smiju biti stariji od godine dana. Atesti za betone se moraju odnositi na uzorke betona uzete na mjestu i u vrijeme ugradnje pojedine tehnološke faze betoniranja.
B14: Izvođač je dužan prije izvedbe, a nakon uklanjanja objekta izraditi elaborat geomehaničkih radova, kako bi se utvrdila nosivost tla, koja je sada pretpostavljena. Empirijski je ona kategorizirana kao A (stijenovito), no moguća su djelomična odstupanja. Eventualne izmjene moraju se dokumentirati i u Glavnom projektu izmijeniti, ukoliko se zadire u temeljna svojstva građevine.
A17: A.1. | B17: PRIPREMNI RADOVI
A19: A.1.1 | B19: Postavljanje ograde gradilišta po rubu parcele
B20: Ograda visine cca 2,0 m. Na ogradu postaviti potrebne oznake (zabrana pristupa neovlaštenim osobama, obavezno korištenje HTZ opreme i dr. prema Zakonu o gradnji) | C20: m | D20: 350 | E20: 5 | F20: =ROUND(D20*E20,2) -> 1750
A22: A.1.2. | B22: Dvokrilna vrata na ulazu u gradilište
B23: Vrata veličine 4,0 x 2,0 m. | C23: komad | D23: 1 | E23: 500 | F23: =ROUND(D23*E23,2) -> 500
A25: A.1.3. | B25: Gradilišna ploča
B26: Izrada i postavljanje gradilišne ploče veličine 1,0x1,4 m. | C26: komad | D26: 1 | E26: 500 | F26: =ROUND(D26*E26,2) -> 500
A28: A.1.4. | B28: Geodetski radovi koji obuhvaćaju geodetska mjerenja, izradu elaborata iskolčenja objekta (OBAVEZA IZVOĐAČA) s određivanjem svih poprečnih i uzdužnih profila, sva geodetska mjerenja kojima se podaci s projekta prenose na teren (vertikalno i horizontalno), osiguranje pojedinih točaka koje služe za rekonstrukciju osovine i visine objekta. Prema stanju na licu mjesta predstavnici izvođača, naručioca, nadzorni inženjer i geodeta odrediti će profile. Opseg tih radova mora zadovoljavati potrebe gradnje, kontrole radova i obračuna. Svi podaci trebaju biti evidentirani u građevinskom dnevniku. | C28: paušal | D28: 1 | E28: 2000 | F28: =ROUND(D28*E28,2) -> 2000
A30: A.1.5. | B30: Postavljanje signalizacije za potrebe gradilišta
B31: Dobava i izvedba signalizacije za potrebe gradilišta, prema Zakonu o sigurnosti prometa na cestama (NN 67/08, 48/10, 74/11, 80/13, 158/13, 92/14, 64/15, 108/17, 70/19, 42/20, 85/22, 114/22, 133/23) i Pravilniku o prometnim znakovima, signalizaciji i opremi na cestama (NN 92/19), regulacija na ulici te uklanjanje nakon završetka svih radova. Predviđeno vrijeme trajanja privremene regulacije prometa je za vrijeme trajanja svih radova. Cijenu treba ponuditi prema elaboratu privremene regulacije prometa, a po računu ovlaštenog poduzeća. | C31: paušal | D31: 1 | E31: 500 | F31: =ROUND(D31*E31,2) -> 500
A33: A.1.6. | B33: Izrada nanosne skele. | C33: m | D33: 200 | E33: 3 | F33: =ROUND(D33*E33,2) -> 600
A35: A.1. | B35: PRIPREMNI RADOVI UKUPNO: | F35: =SUM(F20:F33) -> 5850
A38: A.2. | B38: UKLANJANJE
A40: A.2.1. | B40: Uklanjanje planinarskog doma
B41: Pažljivo uklanjanje cijelog planinarskog doma, u skladu s projektom uklanjanja. Prethodno je potrebno kuću očistiti od svog inventara, koji se može dalje koristiti. Uklanjanje se vrši tako da se što više mateirjala ponovno koristi u izgradnji novog doma, poput drvene građe ili kamena. Stoga je potrebno pažljivo ukloniti sav materijal, a ono što će se ponovno koristiti deponirati na gradilištu. Pažljivo treba ukloniti: * limeni crijep / deponiranje na gradilištu * krovna potkonstrukcija / deponiranje na gradilištu * krovna konstrukcija / deponiranje na gradilištu * dimnjak po cijeloj visini / utovar i odvoz na gradilišnu deponiju * drvena građa međukatnih konstrukcija / sortirati i dobre dijelove deponirati na gradilištu * drvena konstrukcija kata / sortirati i dobre dijelove deponirati na gradilištu * ziđe stare (izvorne) zgrade u prizemlju od kamenih blokova / sortirati, očistiti od morta i vezivnog materijala i sortirati na gradilištu * kameni temelji izvorne zgrade / sortirati, očistiti od morta i vezivnog materijala i sortirati na gradilištu Posebnu pažnju treba posvetiti kaljevoj peći (rastaviti i deponirati na gradilištu), te policama s vješalicama u blagovaonici, koje isto treba pažljivo demontirati staviti na sigurno mjesto. Ostatak doma treba pažljivo ukloniti, utovariti i odvesti na gradilišnu deponiju udaljenu do 30 km. Uračunati utovar u kamion, odvoz i odlaganje materijala na gradilišnom deponiju udaljenom do 30 km. U cijenu treba uključiti i pristojbu za odlaganje otpada na gradilišnom deponiju. Prije davanja ponude postojeću građevinu je potrebno pregledati. | C41: komplet | D41: 1 | E41: 20000 | F41: =ROUND(D41*E41,2) -> 20000
A43: A.2.2. | B43: Uklanjanje objekta uz planinarski dom
B44: Uklanjanje objekta uz planinarski dom - kiosk, veličine GBP= cca 20,00, m2, pravokutnog tlocrta, s jednostrešnim krovom, koji se sastoji od drvene konstrukcije, s vratima i prozorom, zajedno s temeljem objekta. Uklanjanje se vrši tako da se što više mateirjala ponovno koristi u izgradnji novog doma, poput drvene građe ili kamena. Stoga je potrebno pažljivo ukloniti sav materijal, a ono što će se ponovno koristiti deponirati na gradilištu. Pažljivo treba ukloniti: * limeni crijep / deponiranje na gradilištu * drvenu građu / sortirati i deponirati na gradilištu Ostatak treba pažljivo ukloniti, utovariti i odvesti na gradilišnu deponiju udaljenu do 30 km. Uračunati utovar u kamion, odvoz i odlaganje materijala na gradilišnom deponiju udaljenom do 30 km. U cijenu treba uključiti i pristojbu za odlaganje otpada na gradilišnom deponiju. Prije davanja ponude postojeću građevinu je potrebno pregledati. | C44: komplet | D44: 1 | E44: 3000 | F44: =ROUND(D44*E44,2) -> 3000
A46: A.2.3. | B46: Uklanjanje stepenica u terenu
B47: Pažljivo uklanjanje stepenica u terenu, te čišćenje kamena i njegovo deponiranje na gradilištu, za kasniju ponovnu upotrebu.
B48: Površina zahvata = 10,00 m2. | C48: komad | D48: 1 | E48: 3000 | F48: =ROUND(D48*E48,2) -> 3000
A50: A.2. | B50: UKLANJANJE UKUPNO: | F50: =SUM(F41:F48) -> 26000
A53: A.3. | B53: ZEMLJANI RADOVI
B55: OPĆI UVJETI
B57: OPĆI UVJETI ZEMLJANIH RADOVA Tlocrtno iskolčenje zgrade i određivanje kote ±0,00) provesti prema planu Situacija koristeći i geodetsku snimku . Iskolčenje će prije početka radova pregledati i eventualno korigirati projektant. Prije početka zemljanih radova, teren treba očistiti od šiblja i korova ili manjih stabala. Stabla vaditi sa korijenjem. Ti radovi kao i radovi oko razmjeravanja terena i obilježavanja zgrade uračunati su u jedinične cijene. Planiranje dna širokog iskopa i iskopa za temelje izvesti sa točnošću od ±3 cm, što je uključeno u jediničnu cijenu. Iskop kontroliraju i prihvaćaju nadzorni inžinjer i geodet koji je iskolčio zgradu. Ukoliko izvođač prilikom iskopa zemlje naiđe na bilo kakve predmete, objekte ili instalacije, dužan je na tom mjestu obustaviti radove i o tome obavijestiti investitora i nadzornog inženjera. Iskopani materijal treba odlagati na dovoljnom odstojanju od ruba iskopa, da ne dođe do zarušavanja, prema uputi geomehaničara. Ukoliko je izvođač otkopao ispod projektom predviđene temeljne ravnine obavezan je bez naknade popuniti tako nastale šupljine betonom MB10 do projektirane kote.Zabranjeno popunjavanje šljunkom. Količine iskopa, transporta i nasipa zemlje obračunavaju se prema sraslom stanju tla. Ukoliko troškovničkom stavkom nije drugačije navedeno odvoz zemlje uključuje transport na gradilišnu deponiju udaljenu do 30 km. Napomena: Kod odvoza materijala od iskopa ne uzima se posebno u obzir koeficijent rastresitosti.
A60: A.3.1. | B60: Čišćenje građevinske parcele od nepotrebnog sadržaja (raslinja, smeća i dr.) s utovarom, odvozom i odlaganjem smeća na gradilišnu deponiju na udaljenosti do 30 km. U cijenu treba biti ukljućena i naknada za odlaganje smeća na gradilišnoj deponiji. | C60: m² | D60: 200 | E60: 5 | F60: =ROUND(D60*E60,2) -> 1000
A62: A.3.2. | B62: Strojni iskop površinskog humusnog sloja zatravnjenog tla i tla oko doma debljine 30 cm sa utovarom u kamion, odvozom i odlaganjem humusa na gradilišnom deponiju udaljenom do 30 km. Obračun po m3 stvarno iskopanih količina u sraslom stanju. | C62: m³ | D62: 60 | E62: 20 | F62: =ROUND(D62*E62,2) -> 1200
A64: A.3.3. | B64: Široki strojni iskop tla A kategorije za dovođenje terena na projektirane visine sa pravilnim profiliranjem stranica iskopa. Iskopani materijal se utovara u kamion, odvozi i odlaže na gradilišnu deponiju udaljenu do 30 km. Obračun po m3 stvarno iskopanih količina u sraslom stanju. | C64: m³ | D64: 1150 | E64: 18 | F64: =ROUND(D64*E64,2) -> 20700
A66: A.3.4. | B66: Produbljenje iskopa u tlu A kategorije za okna dizala i sprinkler-bazena. Strojni iskop sa pravilnim profiliranjem stranica iskopa. Iskopani materijal se odlaže na gradilištu i koristi za kasnija zatrpavanja i nasipavanja. Obračun po m3 stvarno iskopanih količina u sraslom stanju. | C66: m³ | D66: 16.15 | E66: 50 | F66: =ROUND(D66*E66,2) -> 807.5
A68: A.3.5. | B68: Strojni iskop tla A kategorije za temeljne trake ispod potpornih i upornih zidova sa pravilnim profiliranjem stranica iskopa. Iskopani materijal se odlaže na gradilištu i koristi za kasnija zatrpavanja i nasipavanja. Obračun po m3 stvarno iskopanih količina u sraslom stanju. | C68: m³ | D68: 36 | E68: 30 | F68: =ROUND(D68*E68,2) -> 1080
A70: A.3.6. | B70: Ručno planiranje dna širokog iskopa i iskopa za temeljne trake na +- 3 cm točnosti. | C70: m² | D70: 350 | E70: 2 | F70: =ROUND(D70*E70,2) -> 700
A72: A.3.7. | B72: Dobava, razastiranje i zbijanje tamponskog sloja šljunka (cakumpak) u sloju debljine 20 cm ispod temeljne ploče. Sloj treba biti zbijen do stupnja ispitane zbijenosti izražen kao modul stišljivosti Mv = 30 MPa i isplaniran na 2 cm točnosti. Obračun po m3 idealnog obujma. | C72: m³ | D72: 65 | E72: 45 | F72: =ROUND(D72*E72,2) -> 2925
A74: A.3.8. | B74: Dobava, razastiranje i zbijanje tamponskog sloja šljunka (cakumpak) u sloju debljine 10 cm ispod temeljnih traka potpornih i upornih zidova. Sloj treba biti zbijen do stupnja ispitane zbijenosti izražen kao modul stišljivosti Mv = 30 MPa i isplaniran na 2 cm točnosti. Obračun po m3 idealnog obujma. | C74: m³ | D74: 5.7 | E74: 45 | F74: =ROUND(D74*E74,2) -> 256.5
...

Sheet 2. ELEKTRO
A1: 2. | B1: ELEKTRO
A3: RB | B3: STAVKA | C3: JEDINICA MJERE | D3: KOLIČINA | E3: JEDINIČNA CIJENA | F3: UKUPNA CIJENA
A5: 2.A. | B5: KROVNA FOTONAPONSKA ELEKTRANA
B7: OPĆI UVJETI
B9: U jediničnim cijenama za sve stavke troškovnika, ponuda mora sadržavati ukupne troškove materijala i rada do potpunog dovršenja cjelokupnog posla, uključujući:
B10: * nabavu i transport na gradilište, utovare, istovare, skladištenje i čuvanje,
B11: * sav rad, glavni i pomoćni, uporabu lakih pokretnih skela, sva potrebna podupiranja, sav unutrašnji transport i potrebnu zaštitu izvedenih radova,
B12: * spajanje i montažu, uključujući sav potreban spojni, montažni, pričvrsni i ostali materijal potreban za potpuno funkcioniranje,
B13: * po potrebi uzemljenje,
B14: * izradu utora po zidovima i prodora kroz zidove i podove (stropove) kompletno sa zbinjavanjem istih,
B15: * sva prateća čišćenja tijekom izvođenja radova,
B16: * troškove zbrinjavanja otpada,
B17: * izradu prateće radioničke dokumentacije za sve razvodne ormare, izradu natpisnih pločica, oznaka kabela i rednih stezaljki,
B18: * nabavu i transport na radilište, utovare, istovare, skladištenje i čuvanje,
B19: * građevinsku pripomoć u vidu izrada niša, ugradbom i obzidavanjem razvodnih polja te sve ostale građevinske radove koji se odnose na elektroinstalaterske radove,
... B30: Za eventualne štete uzrokovane neodgovornim ili nestručnim radom, odgovara Izvoditelj radova te ih je obavezan nadoknaditi Investitoru.
A33: 2.A.1. | B33: FOTONAPONSKA ELEKTRANA
B35: NAPOMENA:
B36: Za potkonstrukciju solarnog sustava i fotonaponske module vijdeti ARHITEKTURA - stavka B.18.9.
A38: 2.A.1.1. | B38: Dobava, montaža i spajanje invertera izlazne snage AC 10.000 W, maksimalna ulazna snaga DC 15.000 Wp STC, maksimalni ulazni napon 1.100 Vdc, nazivni napon mreže 3 ~ N-PE 400 Vac, maksimalna izlazna struja 16,9 Aac, frekvencija 50 Hz, 60 Hz / - 5Hz … +5 Hz, faktor distiorzije THD < 3%, stupanj mehaničke zaštite IP65. | C38: komad | D38: 1 | E38: 3000 | F38: =ROUND(D38*E38,2) -> 3000
A40: 2.A.1.2. | B40: Dobava, montaža i spajanje konektora za solarne module, set muški + ženski, 4mm2 / 6mm2 | C40: komad | D40: 8 | E40: 5.88 | F40: =ROUND(D40*E40,2) -> 47.04
A42: 2.A.1.3. | B42: Razdjelnici
B43: Dobava montaža i spajanje razvodnog ormara elektrane "RO-AC (AC BOX)" koji se sastoji od slijedeće ugrađene opreme:
B44: Podžbukni razdjelnik, 2x12 modula, IP30 | C44: komad | D44: 1 | E44: 146 | F44: =ROUND(D44*E44,2) -> 146
B45: Džep za dokumentaciju A5 | C45: komad | D45: 1 | E45: 20 | F45: =ROUND(D45*E45,2) -> 20
B46: FID sklopka 25A, 4 polna, 300 mA, 6kA | C46: komad | D46: 1 | E46: 20 | F46: =ROUND(D46*E46,2) -> 20
B47: Naponski okidač za FID sklopku 230 VAC | C47: komad | D47: 1 | E47: 20 | F47: =ROUND(D47*E47,2) -> 20
B48: Tropolna rastavna osiguračka sklopka veličine 10x38 mm, nazivni napon 500VAC | C48: komad | D48: 2 | E48: 20 | F48: =ROUND(D48*E48,2) -> 40
B49: Izolirani rastalni ulošci veličine 10x38 mm gG sa indikatorom - udaračem, nazivna struja 25 A, nazivni naponi 500VAC | C49: komad | D49: 3 | E49: 20 | F49: =ROUND(D49*E49,2) -> 60
B50: Izolirani rastalni ulošci veličine 10x38 mm gG sa indikatorom - udaračem, nazivna struja 20 A, nazivni naponi 500VAC | C50: komad | D50: 3 | E50: 20 | F50: =ROUND(D50*E50,2) -> 60
B51: Odvodnik prenapona klasa B+C, 4P, 25kA | C51: komad | D51: 1 | E51: 39 | F51: =ROUND(D51*E51,2) -> 39
B52: Automatski osigurač B6, 1 polni, 6 kA | C52: komad | D52: 1 | E52: 20 | F52: =ROUND(D52*E52,2) -> 20
B53: Kontrolno brojilo 3F 1T 80A, za montažu na šinu | C53: komad | D53: 1 | E53: 20 | F53: =ROUND(D53*E53,2) -> 20
B54: Ispitni list razvodnog ormara elektrane "RO-AC" | C54: komad | D54: 1 | E54: 20 | F54: =ROUND(D54*E54,2) -> 20
B55: Izjava o sukladnosti i oznaka o sukladnosti u ormaru za razvodni ormar elektrane "RO-AC" | C55: komad | D55: 1 | E55: 20 | F55: =ROUND(D55*E55,2) -> 20
B56: Ostali sitni nespecificirani materijal (L, N i PE sabirnice, nosači, kanalice, stopice, vijci i sl.). Cjena komplet izvedenog ormara sa montažom i spajanjem na objektu, te isporukom sheme spajanja stvarno izvedenog stanja | C56: komad | D56: 1 | E56: 20 | F56: =ROUND(D56*E56,2) -> 20
A58: 2.A.1.4. | B58: Dobava montaža i spajanje razvodnog ormara elektrane "RO-DC (DC BOX)" koji se sastoji od slijedeće ugrađene opreme:
B59: Nadžbukni razdjelnik, 1x12 modula, IP30 | C59: komad | D59: 1 | E59: 100 | F59: =ROUND(D59*E59,2) -> 100
B60: Džep za dokumentaciju A5 | C60: komad | D60: 1 | E60: 10 | F60: =ROUND(D60*E60,2) -> 10
B61: Dvopolna rastavna osiguračka sklopka veličine 10x38 mm, nazivni napon 1000VDC | C61: komad | D61: 2 | E61: 50 | F61: =ROUND(D61*E61,2) -> 100
...

Sheet 3. STROJARSKI
A1: 3. | B1: STROJARSKE INSTALACIJE
A3: RB | B3: STAVKA | C3: JEDINICA MJERE | D3: KOLIČINA | E3: JEDINIČNA CIJENA | F3: UKUPNA CIJENA
A5: 3.1. | B5: DIZALICA TOPLINE
B7: NAPOMENA:
B8: Sitni potrošni materijal koji nije posebno specificiran, a potreban je za montažu navedenog materijala i opreme žica za varenje, plin, pile za željezo i sl. uključen je u cijenu ponude.
B9: Građevinska pripomoć na uspostavi prodora potrebnih za polaganje cjevovoda iz trošovnika, zaštita cjevovoda u podu i križanja sa ostalim instalacijama obuhvaća sve potrebne radove na izradi prodora u zidovima, podovima i stropovima u kojima se otvori ne moraju izvoditi strojno te se isto obračunavaju u ponudi.
B10: Oprema se montira do pune pogonske gotovosti.
A13: 3.1.1. | B13: Dobava i montaža dizalice topline sa zrakom hlađenim kondenzatorom (aksijalnim ventilatorima) i hidrauličkim modulom kao kompaktna jedinica sa scroll rashladnim kompresorom, sve u izvedbi za vanjsku ugradnju Kompresor je DC inverter sa promjenjivim učinom što omogučava da jedinica radi bez hidrauličkog spremika (uz zadovoljen uvjet minimalne količine radnog medija). U sklopu uređaja nalazi se elektrokomandni ormar sa mikroprocesorskim regulatorom za upravljanje radom uređaja uz mogućnosti klizanja prema vanjskoj temperaturi, nadzor radnih parametara, dijagnozu greške, mogućnost izbora postavne vrijednosti i prikaz parametara. Hidraulički modul se satoji od cirkulacijske crpke (promjenjivog protoka), ekspanzijske posude i sigurnosnog ventila. Za zaštitu hidrauličkog modula od smrzavanja isporučuje se sa ugrađenim elektrogrijačem
B14: Uređaj se ispručuje s kaskadnim ragulatorom za vođenje tri vjedinice i pripremu PTV-a Uz uređaj se isporučuju protočna sklopka (flow switch), ožićeni daljinski upravljač i antivibracijska postolja kriterij za nuđenje: učin grijanja pri -15°C i 40/45°C ne manji od traženog, energetski razred A +++ u grijanju i buka( zvučna snaga) ne veća od tražene Qh=14,5 kW pri 7/12°C, Tok=35°C Qg= 16kW pri 40/45°C, Tok=-15° Qg= 16kW pri 30/35°C, Tok=7° SCOP: 4,46 Lw= 66dB(A) | C14: komplet | D14: 3 | E14: 12000 | F14: =ROUND(D14*E14,2) -> 36000
A16: 3.1.2. | B16: Dobava i montaža zaporne kuglaste slaviea sa ispustom u kompletu sa holenderima i brtvama
B17: NO40 | C17: komad | D17: 6 | E17: 50 | F17: =ROUND(D17*E17,2) -> 300
A19: 3.1.3. | B19: Dobava i montaža hvatača nečistoća u kompletu sa holenderima i brtvama
B20: NO40 | C20: komad | D20: 3 | E20: 300 | F20: =ROUND(D20*E20,2) -> 900
A22: 3.1.4. | B22: Dobava i montaža Fleksibilnog spoja dizalice topline na cijevnu instalaciju grijanja i hlađenja, uključivo holendere i brtve
B23: NO40 | C23: komad | D23: 6 | E23: 100 | F23: =ROUND(D23*E23,2) -> 600
A25: 3.1.5. | B25: Dobava i montaža bakrene cijevi za razvod medija, u kompletu sa koljenima, prelaznim komadima i račvama, dimenzija:
B26: Ø42 mm | C26: m | D26: 45 | E26: 60 | F26: =ROUND(D26*E26,2) -> 2700
B27: Ø54 mm | C27: m | D27: 20 | E27: 70 | F27: =ROUND(D27*E27,2) -> 1400
A29: 3.1.6. | B29: Dobava i montaža izolacija cjevovoda od pjenastog polimera (PEEF) sa parnom branom, za sustave klimatizacije, u kompletu sa ljepilom i trakom Toplinska vodljivost izolacije λ (0°C) ≤ 0,35 W/mK, koeficijent otpora difuziji vodene pare μ ≥ 10.000 Razred reakcije na požar prema HRN EN13501.1: B-s3d0 ili jednakovrijedno. kriterij za nuđenje: toplinska vodljivost izolacije ne manja od tražene i odgovarajući razred reakcije na požar
B30: 9x42 mm | C30: m | D30: 45 | E30: 8 | F30: =ROUND(D30*E30,2) -> 360
B31: 9x54 mm | C31: m | D31: 25 | E31: 10 | F31: =ROUND(D31*E31,2) -> 250
A33: 3.1.7. | B33: Punjenje sustava dizalice topline smjesom propilen glikola točke smrzavanja -25°C | C33: l | D33: 150 | E33: 8 | F33: =ROUND(D33*E33,2) -> 1200
A35: 3.1.8. | B35: Dobava i montaža automatskog odzračnog lončića u kompletu sa nepovratnim ventilom radi mogućnost izmjene lončića pod tlakom | C35: komad | D35: 6 | E35: 50 | F35: =ROUND(D35*E35,2) -> 300
A37: 3.1.9. | B37: Čelični profili, navojne šipke i obujmice za ovješenje cjevovoda i opreme, u kompletu sa antikorozivnom zaštitom | C37: kg | D37: 80 | E37: 7 | F37: =ROUND(D37*E37,2) -> 560
A39: 3.1.10. | B39: Izrada građevinskog postolja za dizalicu topline Postolje se izrađuje od pocinčanih čeličnih profila, stavka obuhvaća izradu radioničkih nacrta, statički proračun, dopremu, antikorozivnu zaštitu, ličenje i ugradnju materijala Okvirna težina: 150kg | C39: komplet | D39: 3 | E39: 500 | F39: =ROUND(D39*E39,2) -> 1500
A41: 3.1.11. | B41: Korištenje auto dizalice za postavljanje opreme u podrum objekta Visina dizanja sa okolnog terena H= 2m | C41: komplet | D41: 1 | E41: 300 | F41: =ROUND(D41*E41,2) -> 300
A43: 3.1.12. | B43: Tlačna proba izvedenog dijela instalacije | C43: komplet | D43: 1 | E43: 100 | F43: =ROUND(D43*E43,2) -> 100
A45: 3.1.13. | B45: Ispiranje instalacija grijanja vodom do postizanja zadovoljavajuće čistoće | C45: komplet | D45: 1 | E45: 100 | F45: =ROUND(D45*E45,2) -> 100
A47: 3.1.14. | B47: Elektro povezivanje dizalice topline | C47: komplet | D47: 3 | E47: 100 | F47: =ROUND(D47*E47,2) -> 300
A49: 3.1.15. | B49: Puštanje u pogon opreme, programiranje parametara, ovjera garancije od strane ovlaštenog servisera, obuka korisnika, dostava uputa na hrvatskom jeziku | C49: komplet | D49: 1 | E49: 2000 | F49: =ROUND(D49*E49,2) -> 2000
A51: 3.1. | B51: DIZALICA TOPLINE UKUPNO: | F51: =SUM(F14:F49) -> 48870
A53: 3.2. | B53: STROJARNICA
B55: NAPOMENA:
B56: Sitni potrošni materijal koji nije posebno specificiran, a potreban je za montažu navedenog materijala i opreme žica za varenje, plin, pile za željezo i sl. uključen je u cijenu ponude.
B57: Građevinska pripomoć na uspostavi prodora u zidovima i podovima za prolaz cjevovoda uključena je u cijenu ponude.
B58: Oprema se montira do pune pogonske gotovosti.
A61: 3.2.1. | B61: Dobava i montaža samostojćeg izoliraog spremnika za pripremu PTV pomoću dizalica topline. Spiralni izmjenivač ugrađen u spremnik je povećane površine za rad sa dizalicama topline. Spremnik je izrađen od čeličnog lima zaštičenog dvokomponentni premazom za pitku vodu, anodnom zaštitom od korozije u kompletu sa termometrima i priključcima za: hladnu vodu, PTV, recirkulaciju i dizalicu topline kriterij za nuđenje: volumen, učin i snaga el grijača ne manji od V= 750 litara, Qg=40 kW, 10/45°C, polaz dizalice 50°C dimenzija: Ø855xH2050 dodatni el. grijač Nel= 3 kW, 230V | C61: komad | D61: 1 | E61: 2000 | F61: =ROUND(D61*E61,2) -> 2000
A63: 3.2.2. | B63: Dobava i montaža akumulacijskog spremnika od čeličnog lima, samostojeći, odložen izolacijom za sustave klimatizacije i grijanja u kompletu sa priključcima, ispusnom slavinom i odzrakom Koristi se i kao hidraulička skretnica kriterij za nuđenje: volumen ne manji od V= 100 lit | C63: komad | D63: 1 | E63: 500 | F63: =ROUND(D63*E63,2) -> 500
A65: 3.2.3. | B65: Dobava i montaža elektronski regulirane cirkulacijske crpke za podno grijanje, u kompletu sa holenderima i brtvama ili sa prirubnicama, brtvama, vijcima i maticama kriterij za nuđenje: protok i visina dobave ne manji od tražene V= 3,53m3/h H= 7 mVS N= 150 W /230 V | C65: komad | D65: 1 | E65: 800 | F65: =ROUND(D65*E65,2) -> 800
A67: 3.2.4. | B67: Dobava i montaža elektronski regulirane cirkulacijske crpke za ventilokovektorsko grijanje, u kompletu sa holenderima i brtvama ili sa prirubnicama, brtvama, vijcima i maticama kriterij za nuđenje: protok i visina dobave ne manji od tražene V= 5,8 m3/h H= 7 mVS N= 180 W /230 V | C67: komad | D67: 1 | E67: 1000 | F67: =ROUND(D67*E67,2) -> 1000
...

Sheet 4. VODOVOD I KANALIZACIJA
A1: 4. | B1: VODOVOD I KANALIZACIJA
A3: RB | B3: STAVKA | C3: JEDINICA MJERE | D3: KOLIČINA | E3: JEDINIČNA CIJENA | F3: UKUPNA CIJENA
A5: 4.A. | B5: VANJSKI VODOVOD I KANALIZACIJA
A7: 4.A.1. | B7: ZEMLJANI RADOVI - VODOVOD
A9: 4.A.1.1. | B9: Geodetsko iskolčenje trase vanjskog vodovoda prije izvođenja radova-dužina 112m | C9: m | D9: 112 | E9: 10 | F9: =ROUND(D9*E9,2) -> 1120
A11: 4.A.1.2. | B11: Iskop kanala u zemljištu tipa A za polaganje vodovodnih cijevi. Dubinu iskopa izvesti do 1,2m. Širina rova 0,6m. Predviđen je ručni iskop 30% i strojni iskop 70%.
B12: - iskop | C12: m³ | D12: 80.7 | E12: 20 | F12: =ROUND(D12*E12,2) -> 1614
A14: 4.A.1.3. | B14: Proširenje dna rova u zemljištu tipa A radi izvedbe vodomjernog okna. Iskopani materijal odbaciti na udaljenost preko 1.0 m od bočne ivice rova, kako bi se spriječilo urušavanje iskopanog materijala u rov. | C14: m³ | D14: 115 | E14: 20 | F14: =ROUND(D14*E14,2) -> 2300
A16: 4.A.1.4. | B16: Planiranje dna rova s odstupanjem ± 2.0 cm. | C16: m² | D16: 67.5 | E16: 5 | F16: =ROUND(D16*E16,2) -> 337.5
A18: 4.A.1.5. | B18: Dobava pijeska, ubacivanje u rov, te izrada pješčane posteljice na dnu rova, u sloju debljine 10 cm. | C18: m³ | D18: 6.75 | E18: 50 | F18: =ROUND(D18*E18,2) -> 337.5
A20: 4.A.1.6. | B20: Dobava pijeska, ubacivanje u rov, te razastiranje s laganim nabijanjem oko i do visine od 15 cm iznad tjemena cijevi. | C20: m³ | D20: 10.1 | E20: 50 | F20: =ROUND(D20*E20,2) -> 505
A22: 4.A.1.7. | B22: Dobava i polaganje u rov iznad vodovodnih cijevi PVC trake sa natpisom "POZOR - VODOVOD" i vodljivom žicom za detekciju trase | C22: m | D22: 112 | E22: 1 | F22: =ROUND(D22*E22,2) -> 112
A24: 4.A.1.8. | B24: Zatrpavanje rova materijalom od iskopa, po slojevima do 30 cm, uz istovremeno obilno močenje i nabijanje materijala ručnim nabijačima. U materijalu ne smije biti kamenja promjera većeg od 12 cm. | C24: m³ | D24: 64 | E24: 20 | F24: =ROUND(D24*E24,2) -> 1280
A26: 4.A.1.9. | B26: Odvoz materijala preostalog od iskopa, nakon zatrpavanja rova na gradsku deponiju (do 30 km), uključivo utovar, istovar i razastiranje. Količina u rastresitom stanju za zemljište III kategorije | C26: m³ | D26: 165 | E26: 20 | F26: =ROUND(D26*E26,2) -> 3300
A28: 4.A.1.10. | B28: Planiranje terena nakon izvršenog zatrpavanja rova. Pretpostavljena širina planiranja je 1,0 m. Obračun po m2 obrađene površine. | C28: m² | D28: 112 | E28: 10 | F28: =ROUND(D28*E28,2) -> 1120
A30: 4.A.1. | B30: ZEMLJANI RADOVI - VODOVOD UKUPNO: | F30: =SUM(F28,F26,F24,F22,F20,F18,F16,F14,F12,F9) -> 12026
A32: 4.A.2. | B32: ZEMLJANI RADOVI - KANALIZACIJA
A34: 4.A.2.1. | B34: Geodetsko iskolčenje trase vanjske kanalizacije prije izvođenja radova-dužina 41m | C34: komplet | D34: 1 | E34: 500 | F34: =ROUND(D34*E34,2) -> 500
A36: 4.A.2.2. | B36: Iskop kanala u zemljištu III. kategorije za polaganje kanalizacijskih cijevi. Dubinu iskopa izvesti prema projektu, a pad kanala u projektiranom nagibu.Širina rova 0,8m. Predviđen je ručni iskop 30% i strojni iskop 70%. NAPOMENA: Točnu kategoriju zemlje utvrditi na licu mjesta. | C36: m³ | D36: 65.6 | E36: 20 | F36: =ROUND(D36*E36,2) -> 1312
B37: - iskop | C37: m³ | D37: 45.2 | E37: 20 | F37: =ROUND(D37*E37,2) -> 904
B38: Proširenje dna rova u zemljištu III. kategorije radi izvedbe revizionog okna, bio pročistača,upojnih bunara. Iskopani materijal odbaciti na udaljenost preko 1.0 m od bočne ivice rova, kako bi se spriječilo urušavanje iskopanog materijala u rov.
A40: 4.A.2.3. | B40: Planiranje dna rova s odstupanjem ± 2.0 cm. | C40: m² | D40: 32.8 | E40: 5 | F40: =ROUND(D40*E40,2) -> 164
A42: 4.A.2.4. | B42: Dobava pijeska i izrada posteljice za kanalizacijske cijevi. Posteljica ispod kanalizacijskih cijevi je debljine 10 cm. Nabija se strojnim i ručnim nabijačima i po potrebi vlaži. Posteljica mora biti ravna, prilagođena obliku cijevi i uzdužnom padu tako da cijevi po cijeloj dužini naliježu na istu. Podmetanje kamena ispod cijevi ili podupiranje najstrože se zabranjuje. Obračun po m3 izvedene posteljice. | C42: m³ | D42: 3.28 | E42: 50 | F42: =ROUND(D42*E42,2) -> 164
A44: 4.A.2.5. | B44: Dobava materijala i izrada obloge za kanalizacijske cijevi. Oko prethodno montiranih kanalizacijskih cijevi izvodi se obloga od sitnog materijala - pijesak ili finiji zamjenski materijal iz pozajmišta (0-40 mm), a do visine 30 cm iznad vrha tjemena cijevi. Obračun po m3 izvedene obloge. | C44: m³ | D44: 15 | E44: 50 | F44: =ROUND(D44*E44,2) -> 750
A46: 4.A.2.6. | B46: Dobava i polaganje u rov iznad kanalizacijski cijevi PVC trake sa natpisom "POZOR - kanalizacija" i vodljivom žicom za detekciju trase | C46: m | D46: 41 | E46: 1 | F46: =ROUND(D46*E46,2) -> 41
A48: 4.A.2.7. | B48: Zatrpavanje rova materijalom od iskopa, po slojevima od 30 cm, uz istovremeno obilno močenje i nabijanje materijala ručnim nabijačima. | C48: m³ | D48: 48 | E48: 20 | F48: =ROUND(D48*E48,2) -> 960
A50: 4.A.2.8. | B50: Odvoz viška materijala na deponiju Sav višak materijala iz iskopa rovova za kanalizacijske kolektore i priključke, građevinskih jama za kontrolna okna i vodolovna grla, a koji je ostao nakon zatrpavanja istih mora se odvesti na deponiju udaljenosti do 30 km. U cijenu je uključen utovar, prijevoz, istovar, te razastiranje materijala. Obračun po m3 materijala, u rastresitom stanju. | C50: m³ | D50: 78.5 | E50: 20 | F50: =ROUND(D50*E50,2) -> 1570
A52: 4.A.2.9. | B52: Planiranje terena nakon izvršenog zatrpavanja rova. Pretpostavljena širina planiranja je 1,0 m. Obračun po m2 obrađene površine. | C52: m² | D52: 41 | E52: 10 | F52: =ROUND(D52*E52,2) -> 410
A54: 4.A.2. | B54: ZEMLJANI RADOVI - KANALIZACIJA UKUPNO: | F54: =SUM(F34:F52) -> 6775
A56: 4.A.3. | B56: BETONSKI RADOVI - VODOVOD
A58: 4.A.3.1. | B58: Izrada betonskih sidrenih blokova na horizontalnim lomovima trase cjevovoda betonom C 15/20. U cijenu uključeno proširenje i produbljenje rova na mijestu bloka te izvedba u odgovarajućoj oplati. | C58: komad | D58: 3 | E58: 100 | F58: =ROUND(D58*E58,2) -> 300
A60: 4.A.3.2. | B60: Vodosprema hidrantske mreže - 108 m3 korisnog volumena - vidi projekt arhitekture (stavka A.B.3.6.) Stavka uključuje kompletnu armaturu za nadopunu vodospreme, uključujući kutni ventil sa plovkom DN40mm, usisnu košaru DN100 te pripadajuči cjevovod. Sve komplet za potpunu funkcionalnost protupožarne vodospreme.
B61: NAPOMENA: Prije izvođenja radova dimenzije kontrukcije i armiranje usuglasiti sa projektom konstrukcije. Točne pozicije proboja utvrditi sa proizvođaćem opreme. | C61: komplet | D61: 1 | E61: 2000 | F61: =ROUND(D61*E61,2) -> 2000
A63: 4.A.3.3. | B63: Sanacija filtera postojećeg spremnika pitke vode, koji uključuje izmjenu šljunka. Podrazumijeva sav rad i materijal, sve prijevoze i prijenose.“ | C63: komplet | D63: 1 | E63: 1000 | F63: =ROUND(D63*E63,2) -> 1000
A65: 4.A.3.4. | B65: Izrada betonskih osiguranja kapa i uporišta vanjskih hidranata betonom C 20. U cijenu uključeno proširenje i produbljenje rova na mjestu uporišta i osiguranja te izvedba u odgovarajučoj oplati. | C65: komad | D65: 1 | E65: 500 | F65: =ROUND(D65*E65,2) -> 500
A67: 4.A.3.5. | B67: Izrada suhozida oko hidranta uključivo ispuna pijeskom. Suhozid izvesti od opeke dimenzija 12x25x6,5cm. | C67: komad | D67: 1 | E67: 300 | F67: =ROUND(D67*E67,2) -> 300
A69: 4.A.3.6. | B69: Dobava i ugradnja betona C15/20 za izradu betonskog postolja hidrantskog ormarića. U cijenu uračunata potrebna oplata, sav materijal i rad. | C69: komad | D69: 1 | E69: 300 | F69: =ROUND(D69*E69,2) -> 300
A71: 4.A.3. | B71: BETONSKI RADOVI - VODOVOD UKUPNO: | F71: =SUM(F58:F69) -> 4400
A73: 4.A.4. | B73: BETONSKI RADOVI - KANALIZACIJA
A75: 4.A.4.1. | B75: Izvedba revizionog okna na kanalizaciji armiranim vodonepropusnim nabijenim betonom C30/37 u dvostranoj oplati, debljine stijenki 20 cm. Stjenke okna ožbukati cementnom žbukom 1:2 zaglađenom do crnog sjaja. Iznad okna na dubini oko 10 cm od kote uređenog terena izvesti armirano-betonsku ploču C25/30, debljine 15 cm s otvorom za silazak u okno. Iznad otvora u ploči montirati poklopac s okvirom veličine poklopca 600x600 mm za opterećenje B125kN na prometnim površinama i A15 na zelenim površinama (uzeti u obzir u ovoj stavci). U cijeni je izvedba, dobava i ugradnja stupaljki u stjenke revizionog okna izrađene iz lijevanog željeza. Prije ugradbe, stupaljke od korozije zaštititi dvostrukim premazom uljane boje.
...

Sheet 5. SPRINKLER
A1: 5. | B1: SPRINKLER
A3: RB | B3: STAVKA | C3: JEDINICA MJERE | D3: KOLIČINA | E3: JEDINIČNA CIJENA | F3: UKUPNA CIJENA
A5: 5.1. | B5: SPRINKLER STANICA - STROJARSKI DIO
B7: NAPOMENA:
B8: Za svu opremu uključena je tlačna proba, ispiranje cjevovoda i odzračivanje, te čišćenje gradilišta od ostataka montaže.
B9: U cijenu je uključeno i stavljanje instalacije u pripravno radno stanje - punjenje preljevnog spremnika vodom , podešavanje parametara sustava (tlakovi, protoci, signalizacija i sl.) te punjenje cjevovoda komprimiranim zrakom pod tlakom.
B10: U cijenu je uključen sav sitni potrošni materijal.
B11: U cijenu je uključeno prvo ispitivanje sprinkler instalacije od ovlaštene pravne osobe, te dobava zapisnika jednom tiskanom izdanju i PDF formatu na prijenosnom mediju i uvjerenja o funkcionalnosti sprinkler sustava , puštanje u rad kompletnog sustava
A14: 5.1.1. | B14: Dobava i ugradnja Sprinkler alarmne ventilske stanice “mokra” NO100 u kompletu sa sprinkler alarmnim ventilom NO100, tampon bocom, zasunom s indikacijom otvorenosti NO100 (2 kom) ispred i iznad sprinkler ventila, ventilom alarmnog zvona sa indikacijom otvorenosti, svom pripadajućom armaturom, manometrima i alarmnom tlačnom sklopkom, sve s dokazom kvalitete- izjavom o sukladnosti i s VdS certifikatom) | C14: komplet | D14: 1 | E14: 2152.07 | F14: =ROUND(D14*E14,2) -> 2152.07
A16: 5.1.2. | B16: Dobava i ugradnja Sprinkler alarmne ventilske stanice “suha” NO80 u kompletu sa sprinkler alarmnim ventilom NO80, ubrzivačem, zasunom s indikacijom otvorenosti NO80 (2 kom) ispred i iznad sprinkler ventila, ventilom alarmnog zvona sa indikacijom otvorenosti, svom pripadajućom armaturom, manometrima, signalna tlačna sklopka za nadzor tlaka zraka i alarmnom tlačnom sklopkom, sve s dokazom kvalitete- izjavom o sukladnosti i s VdS certifikatom) | C16: komplet | D16: 1 | E16: 3959.18 | F16: =ROUND(D16*E16,2) -> 3959.18
A18: 5.1.3. | B18: Dobava i ugradnja alarmnog zvona - hidrauličkog, u kompletu s hvatačem nečistoća s dokazom kvalitete- izjavom o sukladnosti i s VdS certifikatom) - ulaz 3/4", izlaz 1" | C18: komplet | D18: 2 | E18: 295.94 | F18: =ROUND(D18*E18,2) -> 591.88
A20: 5.1.4. | B20: Dobava i ugradnja elektromotorne sprinkler pumpe na postolju N=7,5kW, 3x400V, vertikalna izvedba , u kompletu s prirubnicama i protuprirubnicama NO100, brtvama i vijčanim spojevima; kompezacijom na usisu; asimetričnom i simetričnom redukcijom, (Pumpa s dokazom kvalitete- hrvatskom izjavom o sukladnosti i izjavom o sukladnosti prema VdS) Q=0,0 l/min; H=4,2 bar Q=420 l/min; H=4,2 bar Q=570 l/min; H=4,0 bar Q=660 l/min; H=3,9 bar Q=840 l/min; H= 3,5 bar Q=1.080 l/min; H= 2,5 bar | C20: komplet | D20: 1 | E20: 3955.43 | F20: =ROUND(D20*E20,2) -> 3955.43
A22: 5.1.5. | B22: Dobava i ugradnja elektromotorne jockey pumpe na postolju, u kompletu s elektromotorom, N=1,5kW, 3x400V, ivertikalna izvedba, u kompletu s prirubnicama, protuprirubnicama, brtvama i vijčanim spojevima; sa svom potrebnom svjetlosnom i zvučnom signalizacijom , sukladno VdS propisima, (s dokazom kvalitete- izjavom o sukladnosti) | C22: komplet | D22: 1 | E22: 1202.14 | F22: =ROUND(D22*E22,2) -> 1202.14
A24: 5.1.6. | B24: Dobava i ugradnja zasuna s indikacijom otvorenosti (sa krajnjom sklopkom - tamper switch) NP16, u kompletu s prirubnicama, protuprirubnicama, brtvama i vijčanim spojevima; s dokazom kvalitete- izjavom o sukladnosti i s VdS certifikatom) slijedeće dimenzije: NO150 | C24: komplet | D24: 1 | E24: 589.37 | F24: =ROUND(D24*E24,2) -> 589.37
A26: 5.1.7. | B26: Dobava i ugradnja zasuna s indikacijom otvorenosti (sa krajnjom sklopkom - tamper switch) NP16, u kompletu s prirubnicama, protuprirubnicama, brtvama i vijčanim spojevima; s dokazom kvalitete- izjavom o sukladnosti i s VdS certifikatom) slijedeće dimenzije: NO100 | C26: komplet | D26: 2 | E26: 194.75 | F26: =ROUND(D26*E26,2) -> 389.5
A28: 5.1.8. | B28: Dobava i ugradnja zasuna s indikacijom otvorenosti (sa krajnjom sklopkom - tamper switch) NP16, u kompletu s prirubnicama, protuprirubnicama, brtvama i vijčanim spojevima; s dokazom kvalitete- izjavom o sukladnosti i s VdS certifikatom) slijedeće dimenzije: NO50 | C28: komplet | D28: 2 | E28: 121.98 | F28: =ROUND(D28*E28,2) -> 243.96
A30: 5.1.9. | B30: Dobava i ugradnja mjerne blende u kompletu s mjernim instrumentom, s dokazom kvalitete- izjavom o sukladnosti i s VdS certifikatom) slijedeće dimenzije: slijedećih dimenzija: NO80 | C30: komplet | D30: 1 | E30: 646.67 | F30: =ROUND(D30*E30,2) -> 646.67
A32: 5.1.10. | B32: Dobava i ugradnja kuglastog ventila, navojni NP16, slijedećih dimenzija: NO25 -1" | C32: komplet | D32: 4 | E32: 33.09 | F32: =ROUND(D32*E32,2) -> 132.36
A34: 5.1.11. | B34: Dobava i ugradnja nepovratnog ventila, NP10, u kompletu sa utornim spojnicama (s VdS certifikatom), slijedeće dimenzije: NO100 | C34: komplet | D34: 2 | E34: 161.7 | F34: =ROUND(D34*E34,2) -> 323.4
A36: 5.1.12. | B36: Dobava i ugradnja nepovratnog ventila, navojni NP16, slijedećih dimenzija: NO25 -1" | C36: komplet | D36: 1 | E36: 31.99 | F36: =ROUND(D36*E36,2) -> 31.99
... A108: 5.1.49. | B108: Dobava i ugradnja materijala za brtvljenje navojnih spojeva. | C108: komplet | D108: 1 | E108: 178.02 | F108: =ROUND(D108*E108,2) -> 178.02
A110: 5.1. | B110: SPRINKLER STANICA - STROJARSKI DIO UKUPNO: | F110: =SUM(F8:F108) -> 31092.74
A112: 5.2. | B112: SPRINKLER STANICA - ELEKTRO DIO
B114: NAPOMENA:
B115: U cijenu ponude je uključena dobava i montaža specifizirane opreme te ožičenje i spajanje vodiča - kabela na sprinker opremu.
A118: 5.2.1. | B118: Dobava i ugradnja napojno-upravljačkog ormara sprinkler pumpe I jockey pumpe , N=9,0 kW , sa svom potrebnom svjetlosnom i zvučnom signalizacijom, sukladno VdS propisima (s dokazom kvalitete- hrvatskom izjavom o sukladnosti i izjavom o sukladnosti prema VdS) | C118: komplet | D118: 1 | E118: 2010 | F118: =ROUND(D118*E118,2) -> 2010
A120: 5.2.2. | B120: Dobava i ugradnja sprinkler centrale 8 zona u kompletu s aku baterijama za potrebnu autonomiju. | C120: komplet | D120: 1 | E120: 458 | F120: =ROUND(D120*E120,2) -> 458
A122: 5.2.3. | B122: Dobava i ugradnja višedijelne kružne brtve za brtvljenje kabela za prodor kabela kroz beton, za brtvljenje pod tlakom, uz bušenje rupe. | C122: komplet | D122: 1 | E122: 90 | F122: =ROUND(D122*E122,2) -> 90
A124: 5.2.4. | B124: Dobava i ugradnja kabela JBY-STY-2X2X0,8MM2 za spajanje indikatora protoka, krajnjih sklopki , tlačnih sklopki, te ostale elektro opreme u sprinkler stanici, te spajanje sprinkler ormara sa sprinkler nadzornom centralom | C124: m | D124: 30 | E124: 2.1 | F124: =ROUND(D124*E124,2) -> 63
A126: 5.2.5. | B126: Dobava i ugradnja kabela PP-Y 3x1,5mm za napajanje nivo sonde u bazenu vode s prespojnom kutijom | C126: komplet | D126: 10 | E126: 3.47 | F126: =ROUND(D126*E126,2) -> 34.7
A128: 5.2.6. | B128: Dobava i ugradnja nivo sonde za nadzor nivoa vode u bazenu s prespojnom kutijom | C128: komplet | D128: 1 | E128: 285 | F128: =ROUND(D128*E128,2) -> 285
A130: 5.2.7. | B130: Dobava i ugradnja temperaturnog osjetnika - termostat s mogućnošću podešavanja | C130: komplet | D130: 1 | E130: 55 | F130: =ROUND(D130*E130,2) -> 55
A132: 5.2.8. | B132: Dobava i ugradnja nadzirane kutije za ključ sprinkler stanice | C132: komplet | D132: 1 | E132: 96 | F132: =ROUND(D132*E132,2) -> 96
A134: 5.2.9. | B134: Dobava i ugradnja detektora vode (senzor poplave) | C134: komplet | D134: 1 | E134: 118 | F134: =ROUND(D134*E134,2) -> 118
A136: 5.2.10. | B136: Dobava i ugradnja "Kauflex" cijevi ili jednakovrijedne fi16 za montažu kabela , u kompletu s nosačima I uvodnicama | C136: m | D136: 30 | E136: 3.65 | F136: =ROUND(D136*E136,2) -> 109.5
A138: 5.2.11. | B138: Dobava i ugradnja "Kauflex" cijevi ili jednakovrijedne fi12 za montažu kabela , u kompletu s nosačima I uvodnicama | C138: m | D138: 20 | E138: 3.24 | F138: =ROUND(D138*E138,2) -> 64.8
A140: 5.2.12. | B140: Dobava i ugradnja metalne perforirane kabelske police s poklopcem i montažnim i spojnim priborom PK-50/30, za razvod kablova | C140: m | D140: 15 | E140: 41.18 | F140: =ROUND(D140*E140,2) -> 617.7
... A148: 5.2.16. | B148: Sva ispitivanja ispravnosti električnih instalacija I elektro opreme sukladno zakonskoj regulativi (mjerenje otpora izolacije, mjerenje prijelaznog otpora I sl.) te obuka korisnika I izrada dokumentacije izvedenog stanja u jednom tiskanom primjerku te u PDF formatu na prijenosnom mediju. | C148: komplet | D148: 1 | E148: 1180 | F148: =ROUND(D148*E148,2) -> 1180
A150: 5.2. | B150: SPRINKLER STANICA - ELEKTRO DIO UKUPNO: | F150: =SUM(F118:F148) -> 7710.95
A152: 5.3. | B152: ŠTIĆENI PROSTOR
...

Sheet 6. DIZALA
A1: 6. | B1: DIZALA
A3: RB | B3: STAVKA | C3: JEDINICA MJERE | D3: KOLIČINA | E3: JEDINIČNA CIJENA | F3: UKUPNA CIJENA
B7: Sve radove izvesti prema opisu troškovnika i opisu pojedinih grupa radova. Ako neke stavke imaju nejasan i nedovoljan opis, onda svaki započeti opis pojedine stavke znači cjelokupnu izradu te stavke, to jest nabavu, dopremu materijala, sve prenose i prijevoze, izradu, zaštitu, njegovanje pojedinih elemenata po izradi i nakon ugradnje i sl. Jediničnom cijenom potrebno je obuhvatiti:
B8: a) izvođač radova dužan je prije početka radova provjeriti kote postojeċeg stanja terena u odnosu na relativnu kotu (0,00) kod svih ulaza
B9: b) ukoliko se ukažu eventualne nejednakosti između projekta i stanja na gradilišta izvođač radova dužan je pravovremeno o tome pisano izvjestiti investitora, projektanta i nadzornog inženjera i zatražiti potrebna objašnjenja.
B10: c) izvođač je dužan prije izrade / narudžbe opreme izvršiti kontrolu ugradnih mjera na licu mjesta
B11: d) svu potrebnu provjeru točnosti količina u troškovniku vršiti bez posebne naplate to jest o trošku izvođača radova.
B12: Ovi radovi izvode se prema posebnom projektu za dizala. Tehnički opis iz projektne dokumentacije koji se odnosi na ovu vrstu radova, smatra se sastavnim dijelom ovih općih napomena, odnosno sastavnim dijelom ovog troškovnika. Dizala trebaju biti ugrađena u potpunosti u skladu:
B14: • Sigurnosna pravila za konstrukciju i ugradnju dizala -- Dizala za prijevoz osoba i tereta -- 20. dio: Osobna dizala i teretno osobna dizala (EN 81-20:2014 ili jednakovrijedno)
B15: • Sigurnosna pravila za konstrukciju i ugradnju dizala -- Pregledi i ispitivanja -- 50. dio: Pravila projektiranja, proračuni, pregledi i ispitivanja dijelova dizala (EN 81-50:2014 ili jednakovrijedno)
B16: • Sigurnosna pravila za konstrukciju i ugradnju dizala – 3. dio: Električna i hidraulična maloteretna dizala EN 81-3:2000+A1:2008/AC:2009 ili jednakovrijedno
B17: • Pravilnik o sigurnosti dizala (NN 20/16)
B18: • Pravilnik o sigurnosti strojeva (NN 28/2011)
B20: Dozvoljene su i druge harmonizirane norme iz obitelji EN 81 ili jednakovrijedno ukoliko rješenje dizala zahtijeva pozivanje na iste. Nije dozvoljen početak ugradnje dizala prije predočenja važećih certifikata.
... B41: • Otvor(i) za odimljavanje u atmosferu - pri vrhu voznog okna, prema uvjetima zadanima u tekstu i crtežu projekta ugradnje dizala. • Dozvoljena temperatura u voznom oknu: min. +5 °C, max +40 °C • Napajanje (napojni vod za dizalo) te svi beznaponski kontakti (iz vatrodojave, agregatskog sustava itd.) ukoliko isti postoje i ako dizalo mora imati automatiku rada sukladno primljenim signalima. Svi ostali vodovi (za slanje signala prema CNUSu i sl.) Presjek napojnih vodova odrediti sukladno dizalima u izvedbenoj fazi projekta. Svi vodovi dovedeni su do upravljačkog ormara dizala • Analogna telefonska linija za dvosmjerni komunikacijski uređaj u kabini dizala, dovedena do upravljačkog ormara dizala • Kuke ili profili za montažu, sukladno dizalima u izvedbenoj fazi projekta. • Statika, konstrukcija, materijal i izvedba voznog okna, završno oblaganje voznog okna, ostakljivanje, radovi oko voznog okna i na voznom oknu. • Ispunjavanje zazora između vrata voznog okna i građevinskog otvora za vrata voznog okna vatrootpornim materijalom sukladno vatrootpornosti stijena voznog okna na granici požarnog odjeljka. • Završna obrada građevinskog otvora za vrata voznog okna nakon ugradnje dizala. • Osvjetljenje ispred upravljačkog ormara dizala 200 luxa, mjereno na podu. Osvjetljenje na prilazima voznom oknu min. 50 luxa, mjereno na podu. • Spajanje postrojenja dizala na instalaciju za izjednačavanje potencijala u objektu. • Prebojavanje svih stijena voznog okna (uključivo pod i strop voznog okna) protuprašnom bojom (protuprašnim premazom) gdje je primjenjivo • Ostale napomene navedene u crtežima dizala.
A44: 6.1. | B44: DIZALO D1
B46: Osnovni podaci o dizalu Vrsta osobno dizalo Nazivna nosivost dizala 675 kg Broj osoba 9 osoba Nazivna brzina vožnje 1 m/s Broj stanica/ulaza 4/4 oznake stanica: -1, 0, 1, 2 (stanica 0 = glavna stanica) Broj ulaza u kabinu 2, prolazno pod 180° Instalacija: za suhi zatvoreni prostor temperature od +5°C do +40°C; vlaga ne smije kondenzirati Visina dizanja 9,92 m Vrsta upravljanja simpleks, sabirno u oba smjera Glavno napajanje / napajanje rasvjete i utičnice 400 V 50 Hz / 230V 50 Hz
B47: Pogon električni / trakcijski – bezreduktorski frekvencijski regulirani pogon Smještaj pogona dizalo nema posebnu strojarnicu (MRL); pogonsko postrojenje smješteno je unutar voznog okna dizala Vođenje kabina: klizno vođenje s min 4 papuče po 2 vodilice (po 2 papuče po vodilici) protuuteg: klizno vođenje s min 4 papuče po 2 vodilice (po 2 papuče po vodilici) Vozno okno Izvedba: armiranobetonsko Dimenzije: širina BS: 1625 mm dubina TS: 1800 mm dubina jame HSG: 1100 mm nadvišenje HSK: min 3010 mm Vrata voznog okna: Tip automatska, horizontalno posmična, teleskopska, 2 krila / T2 Dimenzije širina BT: 900 mm visina HT: 2100 mm Izvedba dovratnici: obojani čelični lim krila: obojani čelični lim vatrootpornost: EW30 u stanici 0, EW60 u stanici -1, sve prema HRN EN81-58 Kabina / dimenzije, interijer i oprema Dimenzije širina BK: 1200 mm dubina TK: 1400 mm svijetla visina HKC: 2100 mm Stranice brušeni nehrđajući čelik Pod Lokalna ugradnja, obaveza investitora Strop brušeni nehrđajući čelik
B48: Rasvjeta • LED rasvjeta u stropu • nužna rasvjeta Upravljačka lamela • pokazivač položaja kabine i smjera vožnje; • tipke za kabinski (unutarnji) poziv za sve stanice s Brailleovim oznakama • tipkalo za otvaranje vrata, tipkalo za zatvaranje vrata • tipkalo za alarm (zvono) Ostala oprema • ogledalo • rukohvat • alarm (zvono) • dvosmjerni komunikacijski uređaj iz kabine prema van • tablica s podacima o nosivosti, broju osoba i tvorničkim brojem dizala Zahvatna naprava kabine: s progresivnim (postupnim) djelovanjem, za brzinu od 1 m/s Vrata kabine Tip i dimenzije (identično kao i vrata voznog okna / vidi vrata voznog okna) Izvedba blende/fronte: brušeni nehrđajući čelik krila: brušeni nehrđajući čelik Zaštita putnika svjetlosna zavjesa Količina kabinskih vrata 2
B49: Ostalo Protuuteg dizala: čelični okvir ispunjen blokovima (od betona, čelika i sl.) Vodilice dizala: po dvije vodilice za kabinu i za protuuteg vodilice se izvode kao stojeće, pridržavane po visini koznolama pričvršćenima na zid voznog okna Odbojnici za kabinu i za protuuteg, dimenzionirani i odabrani prema brzini dizala, masi nazivno opterećene kabine i masi protuutega Ovjes kabine i protuutega (u odnosu na pogonski motor) faktor ovjesa KZU=2 (ovjes 2:1) Automatska evakuacija u najbližu stanicu (kod nestanka napajanja električnom energijom)
B50: Privremeni sigurnosni uređaj Uređaj za osiguravanje minimalno potrebnog sigurnosnog prostora na krovu kabine tijekom servisne, odnosno inspekcijske vožnje (nadvišenje dizala smanjeno u odnosu na standardno zahtijevano prema EN81-20 ili jednakovrijedno). Uređaj mora zadovoljavati odredbe EN81-21 ili jednakovrijedno. Uređaj za otvaranje kočnice pogonskog motora dizala Uređaj služi za otvaranje pogonske kočnice u slučaju zastoja dizala i potrebe za evakuacijom putnika iz kabine dizala. Korištenje kočnice opisano je u uputama koje se nalaze u upravljačkom ormaru dizala. Korištenje uređaja dozvoljeno je samo uz strogo pridržavanje uputa, a spašavanje iz kabine smije provoditi samo za to ovlaštena odnosno osposobljena osoba. Uređaj može biti mehanički (na principu poluge) ili električni (napajan baterijski). Upravljanje i elementi upravljanja Signalizacija po stanicama digitalni pokazivač položaja kabine (sve stanice) digitalni pokazivač smjera daljnje vožnje (sve stanice) potvrda zadanog vanjskog poziva (sve stanice) zvučni signal dolaska kabine u stanicu (sve stanice) Vanjski pozivi po stanicama pozivna tipka "vožnja gore" (najniža stanica) pozivna tipka "vožnja dolje" (najviša stanica) pozivna tipka "vožnja dolje", pozivna tipka "vožnja gore"(ostale stanice) Signalizacija u kabini digitalni pokazivač položaja kabine digitalni pokazivač smjera daljnje vožnje zvučni i optički signal prepoterećenja kabine zvučni signal «Alarm» potvrda zadanog kabinskog poziva
B51: Grupa upravljanja (upravljački uređaj) i funkcije upravljanja svi električni i elektronički sklopovi i uređaji potrebni za automatsko upravljanje dizalom, rasvjeta voznog okna i pripadajuće utičnice u postrojenju dizala UKLJUČENE FUNKCIJE: • upravljanje: simpleks, sabirno u oba smjera (kabinski pozivi putem upravljačke lamele za svaku stanicu, vanjski poziv u svakoj stanici) • kontrola otvaranja i zatvaranja vrata u stanici (putem tipkala na upravljačkoj lameli) • požarni program – detaljan opis pogledati pod "Mjere zaštite od požara" • dvosmjerni komunikacijski uređaj iz kabine prema van • povratno upravljanje • servisno upravljanje • alarmni uređaj • signalizacija u kabini i u stanicama • kontrola točnosti pristajanja, poravnavanja i nekontroliranog gibanja • kontrola svjetlosne zavjese (kabinska vrata) • kontrola preopterećenja kabine sa zvučnim i svjetlosnim signalom o preopterećenju u kabini • automatska evakuacija u slučaju nestanka napajanja električnom energijom • privremeni sigurnosni uređaj za slučaj smanjenog nadvišenja Položaj upravljačkog ormara dizala druga najviša stanica, u okviru vrata voznog okna
B52: Izrada i dobava opreme postrojenja dizala prema tehničkom opisu postrojenja dizala. | C52: komplet | D52: 1 | E52: 25000 | F52: =ROUND(D52*E52,2) -> 25000
B53: Montaža postrojenja dizala, priprema za tehnički pregled, tehnički pregled dizala. Izvedbeni projekt dizala u jednom tiskanom primjerku i u PDF formatu, na prijenosnom mediju, puštanje dizala u pogon i primopredaja | C53: komplet | D53: 1 | E53: 2000 | F53: =ROUND(D53*E53,2) -> 2000
B54: Odvoz i zbrinjavanje otpada (ambalaža materijala dizala, nastali otpad prilikom montaže dizala). | C54: komplet | D54: 1 | E54: 2000 | F54: =ROUND(D54*E54,2) -> 2000
A56: 6.1. | B56: DIZALO D1 UKUPNO | F56: =SUM(F52:F55) -> 29000
A58: 6.2. | B58: MALOTERETNO DIZALO MTD1
B60: vrsta dizala: maloteretno dizalo (samo za prijevoz tereta, nije za prijevoz osoba) nazivna nosivost: 100 kg nazivna brzina vožnje: 0,4 m/s visina dizanja: 3,15 m glavno napajanje 3×400V, 50 Hz (3P+PE+N) napajanje rasvjete i utičnice 1×230V, 50 Hz (P+PE+N) broj ulaza u kabinu: 2, pod 180° broj stanica / ulaza: 2/2 vrsta upravljanja: potpuno vanjsko instalacija: za suhi, grijani prostor
B61: signalizacija: signalizacija prijema naredbe na tipkalu za komandu, koje služi bilo za pozivanje kabine ili za slanje kabine u sljedeću stanicu, indikator zauzetosti (dizalo u stanici s otvorenim vratima), indikator kretanja dizala (strelica), indikator stanice (dizalo dostupno i stoji u stanici sa zatvorenim vratima) vozno okno: samonosiva čelična konstrukcija (širina SW=900mm, dubina SD=650 mm, nadvišenje HRmin=2860 mm, poslužna visina SH=800 mm) sa zaštitama na nasuprotnim stranama stanica radi zaštite od ispadanja materijala kod utovaranja (prolazna kabina dizala) okružena armiranim betonom, opekom, gipskartonskim pločama ili sličnim materijalom uz zatvorene sve zazore i otvore preostale nakon ugradnje dizala (nije dio ovog projekta) vrata voznog okna: ručna, vertikalno posmična, 2 krila, metalna izvedba, materijal: čelični lim brušeni nehrđajući čelik, dimenzije DW×DH=600 x 800 mm, vatrootporna EW30 u stanici 0 i EW60 u stanici -1
B62: kabina maloteretnog dizala: metalna izvedba sa stranicama od nehrđajućeg brušenog čeličnog lima i 1 policom; Svijetle dimenzije kabine: širina CW=600 mm, dubina CD=500 mm, visina CH=800 mm;
B63: protuuteg maloteretnog dizala: metalni okvir s metalnim i betonskim elementima vodilice kabine i protuutega: specijalni profili iz čeličnog lima smještaj pogonskog stroja: u vrhu voznog okna, iznad zadnje stanice smještaj upravljačke jedinice: u istom prostoru gdje je i pogonski stroj
B64: vrata prostora pogonskog stroja ručna okretna, s otvaranjem prema van, vatrootporna EW30 pogonski stroj: elektromotor s reduktorom, pogonskom i otklonskom užnicom za ovjesnu užad ovjes 1:1 snaga motora do 0,55 kW, In <= 1,6 A, Ia<= 9,6 A pogonsko uže: čelično pleteno uže, 2 komada
B65: grupa upravljanja: izvedena za potpuno vanjsko upravljanje za dvije postaje; automatika upravljanja elektromotornim pogonom dizala; signalizacija zauzetosti
B66: Izrada i dobava opreme postrojenja maloteretnog dizala prema tehničkom opisu postrojenja dizala. | C66: komplet | D66: 1 | E66: 12000 | F66: =ROUND(D66*E66,2) -> 12000
B67: Montaža postrojenja dizala, priprema za tehnički pregled, tehnički pregled dizala. Izvedbeni projekt dizala u jednom tiskanom primjerku i u PDF formatu, na prijenosnom mediju, puštanje dizala u pogon i primopredaja | C67: komplet | D67: 1 | E67: 2000 | F67: =ROUND(D67*E67,2) -> 2000
B68: Odvoz i zbrinjavanje otpada (ambalaža materijala dizala, nastali otpad prilikom montaže dizala). | C68: komplet | D68: 1 | E68: 2000 | F68: =ROUND(D68*E68,2) -> 2000
A70: 6.2. | B70: MALOTERETNO DIZALO MTD1 | F70: =SUM(F66:F69) -> 16000
A73: 6. | B73: DIZALA UKUPNO: | F73: =SUM(F70,F56) -> 45000

Sheet 7. PRISTUPNI PUT
A1: 7. | B1: PRISTUPNI PUT
A3: RB | B3: STAVKA | C3: JEDINICA MJERE | D3: KOLIČINA | E3: JEDINIČNA CIJENA | F3: UKUPNA CIJENA
A5: 7.1. | B5: PRIPREMNI RADOVI
A7: 7.1.1. | B7: Geodetski radovi
