Workbook

Sheet Naslovna i opći uvjeti
B2: INVESTITOR: MINISTARSTVO UNUTARNJIH POSLOVA RH
B3: LOKACIJA: JASTREBARSKO, ULICA IVANE BRLIĆ MAŽURANIĆ BB
B4: GRAĐEVINA: SKLADIŠTA BR. 1, 2, 5, 6 I OTVORENI PLATOI BR. 4 I 5
B5: RADOVI: UREĐENJE SKLADIŠTA I OTVORNIH PLATOA
B6: PROJEKTANT: CAPITAL ING d.o.o. ZAGREB
B33: TROŠKOVNIK GRAĐEVINSKO-OBRTNIČKIH I INSTALATERSKIH RADOVA
B62: listopad 2025. godine
A64: stavka | B64: opis stavke | C64: jedin. mjere | D64: količina | E64: jedinična cijena (kn) | F64: ukupno (kn) | G64: jedinična cijena (euro) | H64: ukupno (euro)
B66: OPĆI UVJETI I NAPOMENE
B67: GRAĐEVINSKO-OBRTNIČKI RADOVI
B68: OPĆI UVJETI
B69: Cijena za sve stavke (bez obzira što je eventualno samom stavkom drugačije opisano) mora uključivati: dobavu materijala, transport, montažu (ugradnju) sa svim materijalom i pomoćnim materijalom, radom i horizontalnim i vertikalnim transportom na gradilištu potrebne za dovršenje radova do potpune funkcionalne ili estetske gotovosti.
B70: Cijena izvođenja betonskih i čeličnih konstrukcija mora obuhvatiti i razrede izloženosti konstrukcija koji se mogu pojaviti unutar teritorija Republike Hrvatske. Sva demontirana oprema i svi dijelovi konstrukcije i otpad nastao uklanjanjem građevina ili dijelova građevina se zbrinjava sukladno važećim propisima Republike Hrvatske. Sav materijal, opremu i uređaje kod dopreme na gradilište, a prije ugradnje, izvođač je dužan upisati u dnevnik građenja, te nadzornom organu dostaviti ateste i uvjerenja o kvaliteti, kao i garancijske listove i tehničku dokumentaciju sa podacima o uređajima i opremi. Bez istog materijali, oprema i uređaji ne smiju biti ugrađeni.
B71: Sav demontirani i porušeni materijal zbrinuti kako je propisano prostornim planom, zakonima i pravilnicima o otpadu, a troškove obuhvatiti jediničnom cijenom jer se nikakvi troškovi odvoza, sortiranja i zbrinjavanja neće posebno priznavati. Ovi troškovi naznačit će se opisom - uključivo odvoz i gospodarenje otpadom.
B72: Gospodarenje otpadom obaveza je izvođača i potrebno ga je riješiti u skladu s Prostornim planom uređenja, Planom gospodarenja otpadom, Zakonom o otpadu i Pravilnikom o gospodarenju građevnim otpadom te ostalim važećim propisima.
B73: Radovi se izvode u svemu prema projektu i detaljima projektanta, a sve radnje vezano za stabilnost konstrukcije potrebno je usaglasiti s nadzornim inženjerom nakon provjere postojećeg stanja.
B74: Kako bi građevina bila pristupačna osobama s invaliditetom i smanjene pokretljivosti te omogućavala sigurnu evakuaciju unutar predviđenog vremena, pojedini otvori vrata moraju imati, ovisno o poziciji i namjeni prostora, propisanu minimalnu svijetlu dimenziju otvora koja iznosi 90/100/110×208 cm.
B75: Prije prilagodbe postojećih otvora i izvedbe novih otvora, Izvođač mora uskladiti potrebne dimenzije građevinskih otvora sa dimenzijama dovratnika Proizvođača bravarije/stolarije.
B76: Napomena se odnosi na SVE stavke troškovnika. Troškovnik zajedno s grafičkim dijelom projekta su jedna cjelina i nije ih moguća različito interpretirati. Sve stavke izvesti do potpune funkcionalne gotovosti bez obzira na opis! Sve mjere kontrolirati u naravi!
B77: INSTALACIJE VODOVODA I ODVODNJE
... B99: Izvođač je dužan prijenos, ugradnju i svu građevinsku pripomoć izvesti o svom trošku, te sve te radove nuditi u jediničnim cijenama ovog troškovnika.

Sheet Skladište 1
A1: stavka | B1: opis stavke | C1: jedin. mjere | D1: količina | E1: jedinična cijena (euro) | F1: ukupno (euro)
A3: A. | B3: GRAĐEVINSKO-OBRNIČKI RADOVI
A5: 1. | B5: PRIPREMNI RADOVI
A6: 1.1. | B6: Čišćenje terena od raslinja oko građevine, siječenje i skupljanje. U stavku uključeno uklanjanje smeća, prepreka, drveća, i sl., košenja trave i korova, te utovar i odvoz otpadnog materijala na gradsku deponiju, uključeno u cijeni stavke. | C6: kpl | D6: 1 | E6: 5000 | F6: =D6*$E6 -> 5000
A7: 1.2. | B7: Geodetske usluge Ovim radovima potrebno je obuhvatiti angažman ovlaštenog geodete za sva potrebna iskolčenja, označavanje visina, održavanje mjernih točaka tokom gradilišta i sve popratne geodetske usluge potrebne za izvođenje radova. | C7: kpl | D7: 1 | E7: 500 | F7: =D7*$E7 -> 500
B8: 1. Pripremni radovi ukupno: | F8: =SUM(F6:F7) -> 5500
A10: 2. | B10: RUŠENJA I DEMONTAŽE
A11: 2.1. | B11: Demontaža i iznošenje postojećeg namještaja i opreme. Dio opreme je potrebno deponirati na gradilištu na mjesto koje predvidi nadzorni inženjer zbog vraćanja u objekt nakon izvedbe svih radova. U jediničnu cijenu uključen sav potreban rad, svi transporti, sortiranje i zbrinjavanje građevinskog otpada prema važećem Pravilniku. Napomena: prije početka radova korisnik je dužan ukloniti sav skladišteni materijal i opremu u skladištu. Ova stavka se odnosi samo na eventualno zaostalu opremu/materijal koju prema zahtjevu investitora izvođač mora ukloniti te privremeno zbrinuti na drugoj lokaciji i/ili trajno zbrinuti na pripadnu deponiju. Obračun po m3 opreme koja se odvozi. | C11: m3 | D11: 50 | E11: 50 | F11: =D11*$E11 -> 2500
A12: 2.2. | B12: Pažljiva ručna demontaža i uklanjanje rasvjetnih tijela - nadgradna, ovješena, zidna i stropna. U jediničnu cijenu uključen sav potreban rad, laka pokretna skela, svi transporti, sortiranje i zbrinjavanje građevinskog otpada prema važećem Pravilniku. Obračun po komadu. | C12: kom | D12: 14 | E12: 30 | F12: =D12*$E12 -> 420
A13: 2.3. | B13: Pažljiva ručna demontaža i uklanjanje te zbrinjavanje postojećih instalacija jake i slabe struje unutar zone obuhvata (skladišta).
A14: a) | B14: demontaža instalacije (kabela, cijevi, razvodnih kutija) | C14: m' | D14: 200 | E14: 1 | F14: =D14*$E14 -> 200
A15: b) | B15: demontaža utičnica i prekidača | C15: kom | D15: 20 | E15: 10 | F15: =D15*$E15 -> 200
A16: c) | B16: demontaža razvodnih ormara | C16: kom | D16: 2 | E16: 50 | F16: =D16*$E16 -> 100
A17: 2.4. | B17: Demontaža i zbrinjavanje vanjskih metalnih prozora sa djelomičnim staklom. Prozor dimenzija 180×157 cm. U stavci uključena demontaža, odvoz, zbrinjavanje. Pri nuđenju cijeni uključena i cijena zbrinjavanja. U jediničnu cijenu uključen sav potreban rad, laka pokretna skela, svi transporti, sortiranje i zbrinjavanje građevinskog otpada prema važećem Pravilniku. Obračun po komadu demontirane stavke. | C17: kom | D17: 12 | E17: 50 | F17: =D17*$E17 -> 600
A18: 2.5. | B18: Demontaža i zbrinjavanje vanjskih metalnih dvokrilnih vrata. 'Pažljiva demontaža, utovar i odvoz na na mjesto koje odredi investitor postojećih otvora - vanjskih garažnih vrata na istočnom i zapadnom pročelju. Vrata su dimenzija 300×300 cm. Vrata su metalna, dvokrilna, ugrađena između AB stupova. U jediničnu cijenu uračunati skelu, sav rad, materijal i pribor potreban za izvršenje stavke u cijelosti. Obračun prema komadu. Obračun po komadu demontirane stavke. | C18: kom | D18: 20 | E18: 100 | F18: =D18*$E18 -> 2000
A19: 2.6. | B19: Demontaža i zbrinjavanje unutarnjih vrata i prozora. U stavci uključena demontaža, odvoz, zbrinjavanje. Pri nuđenju cijeni uključena i cijena zbrinjavanja. U jediničnu cijenu uključen sav potreban rad, laka pokretna skela, svi transporti, sortiranje i zbrinjavanje građevinskog otpada prema važećem Pravilniku. Obračun po komadu demontirane stavke. | C19: kom | D19: 1 | E19: 100 | F19: =D19*$E19 -> 100
A20: 2.7. | B20: Demontaža i skidanje postojećih gromobranskih traka na krovu i pročeljima objekta, uključivo s pripadajućim elementima i držačima. Radove izvesti pažljivo, kako ne bi došlo do oštećenja ostalih elemenata ovojnice građevine. U jediničnu cijenu uključen sav potreban rad, laka pokretna skela, svi transporti, sortiranje i zbrinjavanje građevinskog otpada prema važećem Pravilniku. Obračun po m' demontirane stavke. | C20: m' | D20: 100 | E20: 2 | F20: =D20*$E20 -> 200
A21: 2.8. | B21: Demontaža i uklanjanje svih postojećih limenih opšava na krovu i prozorima (limarski elementi oborinske odvodnje - žljebovi, oborinske vertikale itd., rubni opšavi krova, prozorski opšavi i sl.), uključivo s svim pripadajućim pričvrsnim elementima. Radove izvesti pažljivo, kako ne bi došlo do oštećenja ostalih elemenata ovojnice građevine. U jediničnu cijenu uključen sav potreban rad, laka pokretna skela, svi transporti, sortiranje i zbrinjavanje građevinskog otpada prema važećem Pravilniku. Obračun po m' demontiranih elemenata bez obzira na razvijenu širinu. | C21: m' | D21: 150 | E21: 5 | F21: =D21*$E21 -> 750
A22: 2.9. | B22: Demontaža i zbrinjavanje valovitih salonitnih ploča krova. U jediničnu cijenu uključen sav potreban rad, laka pokretna skela, svi transporti, sortiranje i zbrinjavanje građevinskog otpada prema važećem Pravilniku. Pri nuđenju stavke je u cijenu potrebno ukalkulirati zbrinjavanje opasnog otpada koji sadrži azbest. Obračun po m2 demontiranih, odvezenih i zbrinutih ploča. | C22: m2 | D22: 650 | E22: 22 | F22: =D22*$E22 -> 14300
A23: 2.10. | B23: Demontaža i uklanjanje postojećih metalnih elemenata (armature, šipke, žica). U jediničnu cijenu uključen sav potreban rad, sva podupiranja, lako pokretna skela, svi transporti, sortiranje i zbrinjavanje građevinskog otpada prema važećem Pravilniku. Obračun po kg. | C23: kg | D23: 100 | E23: 3 | F23: =D23*$E23 -> 300
A24: 2.11. | B24: Rušenje i uklanjanje postojećih unutarnjih zidanih zidova. U stavku obračunato rušenje te odvoz na gradski deponij. Uz sva potrebna podupiranja te zaštitu ljudi i ostale konstrukcije, na pozicijama uklanjanja postojećih zidova određenim projektnom dokumentacijom. Uključivo sa svim potrebnim podupiranjima obodnih konstrukcija. Zidovi su visine cca 290 cm, debljine 10-15 cm. Radove izvesti pažljivo, kako ne bi došlo do oštećenja ostalih elemenata građevine. Zidovi su zidani porobetonskim blokovima. U jediničnu cijenu uključen sav potreban rad, laka pokretna skela, svi transporti, sortiranje i zbrinjavanje građevinskog otpada prema važećem Pravilniku. Obračun po m3 zida. | C24: m3 | D24: 14 | E24: 400 | F24: =D24*$E24 -> 5600
A25: 2.12. | B25: Pažljivo ručno razgrađivanje i uklanjanje postojećih zidanih zabatnih zidova. Uključivo sa svim slojevima pročelja. U stavku obračunato rušenje te odvoz na gradski deponij. Uz sva potrebna podupiranja te zaštitu ljudi i ostale konstrukcije, na pozicijama uklanjanja postojećih zidova određenim projektnom dokumentacijom. Uključivo sa svim potrebnim podupiranjima obodnih konstrukcija. Zidovi su max. visine cca 165 m, na visini od 310 cm. Debljine 25 cm. Radove izvesti pažljivo, kako ne bi došlo do oštećenja ostalih elemenata građevine. Zidovi su zidani blok opekom. Slojevi konstrukcije: - vanjska fasadna žbuka d=2 cm - zidani zid d=25 cm - unutarnja fasadna žbuka d=2 cm U jediničnu cijenu uključen sav potreban rad, laka pokretna skela, svi transporti, sortiranje i zbrinjavanje građevinskog otpada prema važećem Pravilniku. Obračun po m3 zida. | C25: m3 | D25: 29 | E25: 400 | F25: =D25*$E25 -> 11600
... A27: 2.14. | B27: Čišćenje od masnoća, otprašivanje i brušenje postojeće podne armirano-betonske ploče sa zapunjavanje rupa i neravnina (priprema za izvedbu hidroizolacije), uključivo sav potreban materijal i rad. | C27: m2 | D27: 550 | E27: 5 | F27: =D27*$E27 -> 2750
B28: 3. Rušenja i demontaže ukupno: | F28: =SUM(F11:F27) -> 43870
A30: 3. | B30: ZEMLJANI RADOVI
A31: 3.1. | B31: Kombinirani ručni i strojni iskop površinskog sloja tla - humusa i tla C kategorije u širokom iskopu uz obodne zidove, u širini pojasa potrebnog za izvedbu vanjskih staza i postolja klima jedinice. Iskop tla u prosječnoj debljini sloja cca 30 cm. Jediničnom cijenom obuhvaćena potrebna zaštita sokla postojećih zgrada, tijekom izvođenja radova, očuvanih do razine uređenog terena - zaštita temelja tijekom radova na iskopu. U jediničnu cijenu uključen sav potreban rad, svi utovari, transporti i zbrinjavanje viška iskopanog materijala na odgovarajućem deponiju, uključivo sa svim taksama i naknadama prema važećem Pravilniku. Obračun se vrši po m3 iskopanog materijala u sraslom stanju.
A32: a) | B32: strojni iskop | C32: m3 | D32: 18 | E32: 20 | F32: =D32*$E32 -> 360
A33: b) | B33: ručni iskop | C33: m3 | D33: 17 | E33: 80 | F33: =D33*$E33 -> 1360
A34: 3.2. | B34: Kombinirani ručni i strojni široki iskop tla C kategorije u debljini sloja potrebnog za izvedbu novog vanjskog stubišta. Iskop se izvodi u visini iskopa cca 100 cm od kote postojećeg tla odnosno do dna temeljnih zidova stubišta. Uključivo s formiranjem pokosa (u vanjskom prostoru) i izvedbom potrebnih podupiranja kosine nasipa prema opkopu. Ovisno o sraslosti tla će se nagib pokosa prilagoditi. Način rada odabrati sukladno raspoloživoj tehnologiji izvođača radova (ponuditelja). U jediničnu cijenu uključen sav potreban rad, svi utovari, transporti i zbrinjavanje viška iskopanog materijala na odgovarajućem deponiju, uključivo sa svim taksama i naknadama prema važećem Pravilniku. Deponiju osigurava izvođač. Obračun se vrši po m3 iskopanog materijala u sraslom stanju.
A35: a) | B35: strojni iskop | C35: m3 | D35: 8 | E35: 20 | F35: =D35*$E35 -> 160
A36: b) | B36: ručni iskop | C36: m3 | D36: 2 | E36: 80 | F36: =D36*$E36 -> 160
A37: 3.3. | B37: Ručno i strojno planiranje dna iskopa s točnošću +/- 2 cm. Obračun po m2 isplanirane površine.
A38: a) | B38: strojno planiranje | C38: m2 | D38: 50 | E38: 5 | F38: =D38*$E38 -> 250
A39: b) | B39: ručno planiranje | C39: m2 | D39: 50 | E39: 5 | F39: =D39*$E39 -> 250
A40: 3.4. | B40: Dobava, nasipavanje, nabijanje i planiranje tamposkog sloja kamenog agregata granulacija 0-30 mm u sloju debljine 30 cm ispod betonske ploče staze i stubišta - u svrhu izravnanja podloge. Nasipavanje na pripremljenu i isplaniranu površinu iskopa. Zbijenost posteljice treba iznositi minimalno 50 MN/m2, a istu kontrolirati na svakih 100 m2 izvedenog tamponskog sloja. Prije izvedbe nasipa obavezan pregled temeljnog tla od ovlaštenog nadzora. Obračun po m3 ugrađenog materijala. | C40: m3 | D40: 30 | E40: 60 | F40: =D40*$E40 -> 1800
A41: 3.5. | B41: Obrada i planiranje pokosa tla iskopom i nasipavanjem. Obrada okolnog tla uz vanjske stube, prilagođavajući ga prirodnom postojećem nagibu. Način rada odabrati sukladno raspoloživoj tehnologiji izvođača radova (ponuditelja). Obračun po m2. | C41: m2 | D41: 20 | E41: 20 | F41: =D41*$E41 -> 400
A42: 3.6. | B42: Čišćenje terena oko objekta nakon završetka svih radova na objektu, kao i poslije svake faze rada na objektu. Stavka obuhvaća utovar otpadnog materijala u prijevozno sredstvo i odvoz na javni deponij uključivo troškovi deponiranja. Obračun kao komplet. | C42: kpl | D42: 1 | E42: 300 | F42: =D42*$E42 -> 300
B43: 3. Zemljani radovi ukupno: | F43: =SUM(F32:F42) -> 5040
A45: 4. | B45: ARMIRANO-BETONSKI I ARMIRAČKI RADOVI
A46: 4.1. | B46: Dobava betona i izvedba armiranobetonske podne ploče objekta. Izvedba betonom C30/37. Ploča (2500 kg/m3) se izvodi u debljini 12 cm. Ploča se izvodi na postojeću betonsku ploču, pravilno izoliranu. Izvoditi prema projektu arhitekture, planovima oplate i ostaloj izvedbenoj dokumentaciji te prema uputstvima projektanta konstrukcije i nadzornog inženjera. U jediničnu cijenu uključena je i sva potrebna daščana oplata ako nije posebno navedeno u stavci, te rabic pletivo za radne prekide ovisno o tehnologiji izvođenja. Obavezno dilatiranje prema pravilima struke. Obračun po m3 betona, m2 oplate i kg armature.
...

Sheet Skladište 2
A1: stavka | B1: opis stavke | C1: jedin. mjere | D1: količina | E1: jedinična cijena (euro) | F1: ukupno (euro)
A3: A. | B3: GRAĐEVINSKO-OBRNIČKI RADOVI
A5: 1. | B5: PRIPREMNI RADOVI
A6: 1.1. | B6: Čišćenje terena od raslinja oko građevine, siječenje i skupljanje. U stavku uključeno uklanjanje smeća, prepreka, drveća, i sl., košenja trave i korova, te utovar i odvoz otpadnog materijala na gradsku deponiju, uključeno u cijeni stavke. | C6: kpl | D6: 1 | E6: 5000 | F6: =D6*$E6 -> 5000
A7: 1.2. | B7: Geodetske usluge Ovim radovima potrebno je obuhvatiti angažman ovlaštenog geodete za sva potrebna iskolčenja, označavanje visina, održavanje mjernih točaka tokom gradilišta i sve popratne geodetske usluge potrebne za izvođenje radova. | C7: kpl | D7: 1 | E7: 500 | F7: =D7*$E7 -> 500
B8: 1. Pripremni radovi ukupno: | F8: =SUM(F6:F7) -> 5500
A10: 2. | B10: RUŠENJA I DEMONTAŽE
A11: 2.1. | B11: Demontaža i iznošenje postojećeg namještaja i opreme. Dio opreme je potrebno deponirati na gradilištu na mjesto koje predvidi nadzorni inženjer zbog vraćanja u objekt nakon izvedbe svih radova. U jediničnu cijenu uključen sav potreban rad, svi transporti, sortiranje i zbrinjavanje građevinskog otpada prema važećem Pravilniku. Napomena: prije početka radova korisnik je dužan ukloniti sav skladišteni materijal i opremu u skladištu. Ova stavka se odnosi samo na eventualno zaostalu opremu/materijal koju prema zahtjevu investitora izvođač mora ukloniti te privremeno zbrinuti na drugoj lokaciji i/ili trajno zbrinuti na pripadnu deponiju. Obračun po m3 opreme koja se odvozi. | C11: m3 | D11: 50 | E11: 50 | F11: =D11*$E11 -> 2500
A12: 2.2. | B12: Pažljiva ručna demontaža i uklanjanje rasvjetnih tijela - nadgradna, ovješena, zidna i stropna. U jediničnu cijenu uključen sav potreban rad, laka pokretna skela, svi transporti, sortiranje i zbrinjavanje građevinskog otpada prema važećem Pravilniku. Obračun po komadu. | C12: kom | D12: 14 | E12: 30 | F12: =D12*$E12 -> 420
A13: 2.3. | B13: Pažljiva ručna demontaža i uklanjanje te zbrinjavanje postojećih instalacija jake i slabe struje unutar zone obuhvata (skladišta).
A14: a) | B14: demontaža instalacije (kabela, cijevi, razvodnih kutija) | C14: m' | D14: 200 | E14: 1 | F14: =D14*$E14 -> 200
A15: b) | B15: demontaža utičnica i prekidača | C15: kom | D15: 20 | E15: 10 | F15: =D15*$E15 -> 200
A16: c) | B16: demontaža razvodnih ormara | C16: kom | D16: 2 | E16: 50 | F16: =D16*$E16 -> 100
A17: 2.4. | B17: Demontaža i zbrinjavanje vanjskih metalnih prozora sa djelomičnim staklom. Prozor dimenzija 180×157 cm. U stavci uključena demontaža, odvoz, zbrinjavanje. Pri nuđenju cijeni uključena i cijena zbrinjavanja. U jediničnu cijenu uključen sav potreban rad, laka pokretna skela, svi transporti, sortiranje i zbrinjavanje građevinskog otpada prema važećem Pravilniku. Obračun po komadu demontirane stavke. | C17: kom | D17: 12 | E17: 50 | F17: =D17*$E17 -> 600
A18: 2.5. | B18: Demontaža i zbrinjavanje vanjskih metalnih dvokrilnih vrata. 'Pažljiva demontaža, utovar i odvoz na na mjesto koje odredi investitor postojećih otvora - vanjskih garažnih vrata na istočnom i zapadnom pročelju. Vrata su dimenzija 300×300 cm. Vrata su metalna, dvokrilna, ugrađena između AB stupova. U jediničnu cijenu uračunati skelu, sav rad, materijal i pribor potreban za izvršenje stavke u cijelosti. Obračun prema komadu. Obračun po komadu demontirane stavke. | C18: kom | D18: 20 | E18: 100 | F18: =D18*$E18 -> 2000
A19: 2.6. | B19: Demontaža i zbrinjavanje unutarnjih vrata i prozora. U stavci uključena demontaža, odvoz, zbrinjavanje. Pri nuđenju cijeni uključena i cijena zbrinjavanja. U jediničnu cijenu uključen sav potreban rad, laka pokretna skela, svi transporti, sortiranje i zbrinjavanje građevinskog otpada prema važećem Pravilniku. Obračun po komadu demontirane stavke. | C19: kom | D19: 1 | E19: 100 | F19: =D19*$E19 -> 100
A20: 2.7. | B20: Demontaža i skidanje postojećih gromobranskih traka na krovu i pročeljima objekta, uključivo s pripadajućim elementima i držačima. Radove izvesti pažljivo, kako ne bi došlo do oštećenja ostalih elemenata ovojnice građevine. U jediničnu cijenu uključen sav potreban rad, laka pokretna skela, svi transporti, sortiranje i zbrinjavanje građevinskog otpada prema važećem Pravilniku. Obračun po m' demontirane stavke. | C20: m' | D20: 100 | E20: 2 | F20: =D20*$E20 -> 200
A21: 2.8. | B21: Demontaža i uklanjanje svih postojećih limenih opšava na krovu i prozorima (limarski elementi oborinske odvodnje - žljebovi, oborinske vertikale itd., rubni opšavi krova, prozorski opšavi i sl.), uključivo s svim pripadajućim pričvrsnim elementima. Radove izvesti pažljivo, kako ne bi došlo do oštećenja ostalih elemenata ovojnice građevine. U jediničnu cijenu uključen sav potreban rad, laka pokretna skela, svi transporti, sortiranje i zbrinjavanje građevinskog otpada prema važećem Pravilniku. Obračun po m' demontiranih elemenata bez obzira na razvijenu širinu. | C21: m' | D21: 150 | E21: 5 | F21: =D21*$E21 -> 750
A22: 2.9. | B22: Demontaža i zbrinjavanje valovitih salonitnih ploča krova. U jediničnu cijenu uključen sav potreban rad, laka pokretna skela, svi transporti, sortiranje i zbrinjavanje građevinskog otpada prema važećem Pravilniku. Pri nuđenju stavke je u cijenu potrebno ukalkulirati zbrinjavanje opasnog otpada koji sadrži azbest. Obračun po m2 demontiranih, odvezenih i zbrinutih ploča. | C22: m2 | D22: 650 | E22: 22 | F22: =D22*$E22 -> 14300
A23: 2.10. | B23: Demontaža i uklanjanje postojećih metalnih elemenata (armature, šipke, žica). U jediničnu cijenu uključen sav potreban rad, sva podupiranja, lako pokretna skela, svi transporti, sortiranje i zbrinjavanje građevinskog otpada prema važećem Pravilniku. Obračun po kg. | C23: kg | D23: 100 | E23: 3 | F23: =D23*$E23 -> 300
A24: 2.11. | B24: Pažljivo ručno razgrađivanje i uklanjanje postojećih zidanih zabatnih zidova. Uključivo sa svim slojevima pročelja. U stavku obračunato rušenje te odvoz na gradski deponij. Uz sva potrebna podupiranja te zaštitu ljudi i ostale konstrukcije, na pozicijama uklanjanja postojećih zidova određenim projektnom dokumentacijom. Uključivo sa svim potrebnim podupiranjima obodnih konstrukcija. Zidovi su max. visine cca 165 m, na visini od 310 cm. Debljine 25 cm. Radove izvesti pažljivo, kako ne bi došlo do oštećenja ostalih elemenata građevine. Zidovi su zidani blok opekom. Slojevi konstrukcije: - vanjska fasadna žbuka d=2 cm - zidani zid d=25 cm - unutarnja fasadna žbuka d=2 cm U jediničnu cijenu uključen sav potreban rad, laka pokretna skela, svi transporti, sortiranje i zbrinjavanje građevinskog otpada prema važećem Pravilniku. Obračun po m3 zida. | C24: m3 | D24: 29 | E24: 400 | F24: =D24*$E24 -> 11600
A25: 2.12. | B25: Uklanjanje i odvoz postojeće žbuke. Stavka se primjenjuje za površine zidova/stupova koji se zadržavaju te podrazumijeva otucanje žbuke, odvoz i zbrinjavanje šute, zaštite prilikom izvođenja radova i potrebnu skelu. Obračun po m2 uklonjene žbuke. | C25: m2 | D25: 150 | E25: 15 | F25: =D25*$E25 -> 2250
A26: 2.13. | B26: Čišćenje od masnoća, otprašivanje i brušenje postojeće podne armirano-betonske ploče sa zapunjavanje rupa i neravnina (priprema za izvedbu hidroizolacije), uključivo sav potreban materijal i rad. | C26: m2 | D26: 550 | E26: 5 | F26: =D26*$E26 -> 2750
B27: 3. Rušenja i demontaže ukupno: | F27: =SUM(F11:F26) -> 38270
A29: 3. | B29: ZEMLJANI RADOVI
A30: 3.1. | B30: Kombinirani ručni i strojni iskop površinskog sloja tla - humusa i tla C kategorije u širokom iskopu uz obodne zidove, u širini pojasa potrebnog za izvedbu vanjskih staza i postolja klima jedinice. Iskop tla u prosječnoj debljini sloja cca 30 cm. Jediničnom cijenom obuhvaćena potrebna zaštita sokla postojećih zgrada, tijekom izvođenja radova, očuvanih do razine uređenog terena - zaštita temelja tijekom radova na iskopu. U jediničnu cijenu uključen sav potreban rad, svi utovari, transporti i zbrinjavanje viška iskopanog materijala na odgovarajućem deponiju, uključivo sa svim taksama i naknadama prema važećem Pravilniku. Obračun se vrši po m3 iskopanog materijala u sraslom stanju.
A31: a) | B31: strojni iskop | C31: m3 | D31: 18 | E31: 20 | F31: =D31*$E31 -> 360
A32: b) | B32: ručni iskop | C32: m3 | D32: 17 | E32: 80 | F32: =D32*$E32 -> 1360
A33: 3.2. | B33: Kombinirani ručni i strojni široki iskop tla C kategorije u debljini sloja potrebnog za izvedbu novog vanjskog stubišta. Iskop se izvodi u visini iskopa cca 100 cm od kote postojećeg tla odnosno do dna temeljnih zidova stubišta. Uključivo s formiranjem pokosa (u vanjskom prostoru) i izvedbom potrebnih podupiranja kosine nasipa prema opkopu. Ovisno o sraslosti tla će se nagib pokosa prilagoditi. Način rada odabrati sukladno raspoloživoj tehnologiji izvođača radova (ponuditelja). U jediničnu cijenu uključen sav potreban rad, svi utovari, transporti i zbrinjavanje viška iskopanog materijala na odgovarajućem deponiju, uključivo sa svim taksama i naknadama prema važećem Pravilniku. Deponiju osigurava izvođač. Obračun se vrši po m3 iskopanog materijala u sraslom stanju.
A34: a) | B34: strojni iskop | C34: m3 | D34: 8 | E34: 20 | F34: =D34*$E34 -> 160
A35: b) | B35: ručni iskop | C35: m3 | D35: 2 | E35: 80 | F35: =D35*$E35 -> 160
A36: 3.3. | B36: Ručno i strojno planiranje dna iskopa s točnošću +/- 2 cm. Obračun po m2 isplanirane površine.
A37: a) | B37: strojno planiranje | C37: m2 | D37: 50 | E37: 5 | F37: =D37*$E37 -> 250
A38: b) | B38: ručno planiranje | C38: m2 | D38: 50 | E38: 5 | F38: =D38*$E38 -> 250
A39: 3.4. | B39: Dobava, nasipavanje, nabijanje i planiranje tamposkog sloja kamenog agregata granulacija 0-30 mm u sloju debljine 30 cm ispod betonske ploče staze i stubišta - u svrhu izravnanja podloge. Nasipavanje na pripremljenu i isplaniranu površinu iskopa. Zbijenost posteljice treba iznositi minimalno 50 MN/m2, a istu kontrolirati na svakih 100 m2 izvedenog tamponskog sloja. Prije izvedbe nasipa obavezan pregled temeljnog tla od ovlaštenog nadzora. Obračun po m3 ugrađenog materijala. | C39: m3 | D39: 30 | E39: 60 | F39: =D39*$E39 -> 1800
A40: 3.5. | B40: Obrada i planiranje pokosa tla iskopom i nasipavanjem. Obrada okolnog tla uz vanjske stube, prilagođavajući ga prirodnom postojećem nagibu. Način rada odabrati sukladno raspoloživoj tehnologiji izvođača radova (ponuditelja). Obračun po m2. | C40: m2 | D40: 20 | E40: 20 | F40: =D40*$E40 -> 400
A41: 3.6. | B41: Čišćenje terena oko objekta nakon završetka svih radova na objektu, kao i poslije svake faze rada na objektu. Stavka obuhvaća utovar otpadnog materijala u prijevozno sredstvo i odvoz na javni deponij uključivo troškovi deponiranja. Obračun kao komplet. | C41: kpl | D41: 1 | E41: 300 | F41: =D41*$E41 -> 300
B42: 3. Zemljani radovi ukupno: | F42: =SUM(F31:F41) -> 5040
A44: 4. | B44: ARMIRANO-BETONSKI I ARMIRAČKI RADOVI
A45: 4.1. | B45: Dobava betona i izvedba armiranobetonske podne ploče objekta. Izvedba betonom C30/37. Ploča (2500 kg/m3) se izvodi u debljini 12 cm. Ploča se izvodi na postojeću betonsku ploču, pravilno izoliranu. Izvoditi prema projektu arhitekture, planovima oplate i ostaloj izvedbenoj dokumentaciji te prema uputstvima projektanta konstrukcije i nadzornog inženjera. U jediničnu cijenu uključena je i sva potrebna daščana oplata ako nije posebno navedeno u stavci, te rabic pletivo za radne prekide ovisno o tehnologiji izvođenja. Obavezno dilatiranje prema pravilima struke. Obračun po m3 betona, m2 oplate i kg armature.
...

Sheet Skladište 5
A1: stavka | B1: opis stavke | C1: jedin. mjere | D1: količina | E1: jedinična cijena (euro) | F1: ukupno (euro)
A3: A. | B3: GRAĐEVINSKO-OBRNIČKI RADOVI
A5: 1. | B5: PRIPREMNI RADOVI
A6: 1.1. | B6: Čišćenje terena od raslinja oko građevine, siječenje i skupljanje. U stavku uključeno uklanjanje smeća, prepreka, drveća, i sl., košenja trave i korova, te utovar i odvoz otpadnog materijala na gradsku deponiju, uključeno u cijeni stavke. | C6: kpl | D6: 1 | E6: 5000 | F6: =D6*$E6 -> 5000
A7: 1.2. | B7: Geodetske usluge Ovim radovima potrebno je obuhvatiti angažman ovlaštenog geodete za sva potrebna iskolčenja, označavanje visina, održavanje mjernih točaka tokom gradilišta i sve popratne geodetske usluge potrebne za izvođenje radova. | C7: kpl | D7: 1 | E7: 500 | F7: =D7*$E7 -> 500
B8: 1. Pripremni radovi ukupno: | F8: =SUM(F6:F7) -> 5500
A10: 2. | B10: RUŠENJA I DEMONTAŽE
A11: 2.1. | B11: Demontaža i iznošenje postojećeg namještaja i opreme. Dio opreme je potrebno deponirati na gradilištu na mjesto koje predvidi nadzorni inženjer zbog vraćanja u objekt nakon izvedbe svih radova. U jediničnu cijenu uključen sav potreban rad, svi transporti, sortiranje i zbrinjavanje građevinskog otpada prema važećem Pravilniku. Napomena: prije početka radova korisnik je dužan ukloniti sav skladišteni materijal i opremu u skladištu. Ova stavka se odnosi samo na eventualno zaostalu opremu/materijal koju prema zahtjevu investitora izvođač mora ukloniti te privremeno zbrinuti na drugoj lokaciji i/ili trajno zbrinuti na pripadnu deponiju. Obračun po m3 opreme koja se odvozi. | C11: m3 | D11: 50 | E11: 50 | F11: =D11*$E11 -> 2500
A12: 2.2. | B12: Pažljiva ručna demontaža i uklanjanje rasvjetnih tijela - nadgradna, ovješena, zidna i stropna. U jediničnu cijenu uključen sav potreban rad, laka pokretna skela, svi transporti, sortiranje i zbrinjavanje građevinskog otpada prema važećem Pravilniku. Obračun po komadu. | C12: kom | D12: 14 | E12: 30 | F12: =D12*$E12 -> 420
A13: 2.3. | B13: Pažljiva ručna demontaža i uklanjanje te zbrinjavanje postojećih instalacija jake i slabe struje unutar zone obuhvata (skladišta).
A14: a) | B14: demontaža instalacije (kabela, cijevi, razvodnih kutija) | C14: m' | D14: 200 | E14: 1 | F14: =D14*$E14 -> 200
A15: b) | B15: demontaža utičnica i prekidača | C15: kom | D15: 20 | E15: 10 | F15: =D15*$E15 -> 200
A16: c) | B16: demontaža razvodnih ormara | C16: kom | D16: 2 | E16: 50 | F16: =D16*$E16 -> 100
A17: 2.4. | B17: Demontaža i zbrinjavanje vanjskih metalnih prozora sa djelomičnim staklom. Prozor dimenzija 180×157 cm. U stavci uključena demontaža, odvoz, zbrinjavanje. Pri nuđenju cijeni uključena i cijena zbrinjavanja. U jediničnu cijenu uključen sav potreban rad, laka pokretna skela, svi transporti, sortiranje i zbrinjavanje građevinskog otpada prema važećem Pravilniku. Obračun po komadu demontirane stavke. | C17: kom | D17: 12 | E17: 50 | F17: =D17*$E17 -> 600
A18: 2.5. | B18: Demontaža i zbrinjavanje vanjskih metalnih dvokrilnih vrata. 'Pažljiva demontaža, utovar i odvoz na na mjesto koje odredi investitor postojećih otvora - vanjskih garažnih vrata na istočnom i zapadnom pročelju. Vrata su dimenzija 300×300 cm. Vrata su metalna, dvokrilna, ugrađena između AB stupova. U jediničnu cijenu uračunati skelu, sav rad, materijal i pribor potreban za izvršenje stavke u cijelosti. Obračun prema komadu. Obračun po komadu demontirane stavke. | C18: kom | D18: 20 | E18: 100 | F18: =D18*$E18 -> 2000
A19: 2.6. | B19: Demontaža i zbrinjavanje unutarnjih vrata i prozora. U stavci uključena demontaža, odvoz, zbrinjavanje. Pri nuđenju cijeni uključena i cijena zbrinjavanja. U jediničnu cijenu uključen sav potreban rad, laka pokretna skela, svi transporti, sortiranje i zbrinjavanje građevinskog otpada prema važećem Pravilniku. Obračun po komadu demontirane stavke. | C19: kom | D19: 1 | E19: 100 | F19: =D19*$E19 -> 100
A20: 2.7. | B20: Demontaža i skidanje postojećih gromobranskih traka na krovu i pročeljima objekta, uključivo s pripadajućim elementima i držačima. Radove izvesti pažljivo, kako ne bi došlo do oštećenja ostalih elemenata ovojnice građevine. U jediničnu cijenu uključen sav potreban rad, laka pokretna skela, svi transporti, sortiranje i zbrinjavanje građevinskog otpada prema važećem Pravilniku. Obračun po m' demontirane stavke. | C20: m' | D20: 100 | E20: 2 | F20: =D20*$E20 -> 200
A21: 2.8. | B21: Demontaža i uklanjanje svih postojećih limenih opšava na krovu i prozorima (limarski elementi oborinske odvodnje - žljebovi, oborinske vertikale itd., rubni opšavi krova, prozorski opšavi i sl.), uključivo s svim pripadajućim pričvrsnim elementima. Radove izvesti pažljivo, kako ne bi došlo do oštećenja ostalih elemenata ovojnice građevine. U jediničnu cijenu uključen sav potreban rad, laka pokretna skela, svi transporti, sortiranje i zbrinjavanje građevinskog otpada prema važećem Pravilniku. Obračun po m' demontiranih elemenata bez obzira na razvijenu širinu. | C21: m' | D21: 150 | E21: 5 | F21: =D21*$E21 -> 750
A22: 2.9. | B22: Demontaža i zbrinjavanje valovitih salonitnih ploča krova. U jediničnu cijenu uključen sav potreban rad, laka pokretna skela, svi transporti, sortiranje i zbrinjavanje građevinskog otpada prema važećem Pravilniku. Pri nuđenju stavke je u cijenu potrebno ukalkulirati zbrinjavanje opasnog otpada koji sadrži azbest. Obračun po m2 demontiranih, odvezenih i zbrinutih ploča. | C22: m2 | D22: 650 | E22: 22 | F22: =D22*$E22 -> 14300
A23: 2.10. | B23: Demontaža i uklanjanje postojećih metalnih elemenata (armature, šipke, žica). U jediničnu cijenu uključen sav potreban rad, sva podupiranja, lako pokretna skela, svi transporti, sortiranje i zbrinjavanje građevinskog otpada prema važećem Pravilniku. Obračun po kg. | C23: kg | D23: 100 | E23: 3 | F23: =D23*$E23 -> 300
A24: 2.11. | B24: Pažljivo ručno razgrađivanje i uklanjanje postojećih zidanih zabatnih zidova. Uključivo sa svim slojevima pročelja. U stavku obračunato rušenje te odvoz na gradski deponij. Uz sva potrebna podupiranja te zaštitu ljudi i ostale konstrukcije, na pozicijama uklanjanja postojećih zidova određenim projektnom dokumentacijom. Uključivo sa svim potrebnim podupiranjima obodnih konstrukcija. Zidovi su max. visine cca 165 m, na visini od 310 cm. Debljine 25 cm. Radove izvesti pažljivo, kako ne bi došlo do oštećenja ostalih elemenata građevine. Zidovi su zidani blok opekom. Slojevi konstrukcije: - vanjska fasadna žbuka d=2 cm - zidani zid d=25 cm - unutarnja fasadna žbuka d=2 cm U jediničnu cijenu uključen sav potreban rad, laka pokretna skela, svi transporti, sortiranje i zbrinjavanje građevinskog otpada prema važećem Pravilniku. Obračun po m3 zida. | C24: m3 | D24: 29 | E24: 400 | F24: =D24*$E24 -> 11600
A25: 2.12. | B25: Uklanjanje i odvoz postojeće žbuke. Stavka se primjenjuje za površine zidova/stupova koji se zadržavaju te podrazumijeva otucanje žbuke, odvoz i zbrinjavanje šute, zaštite prilikom izvođenja radova i potrebnu skelu. Obračun po m2 uklonjene žbuke. | C25: m2 | D25: 150 | E25: 15 | F25: =D25*$E25 -> 2250
A26: 2.13. | B26: Čišćenje od masnoća, otprašivanje i brušenje postojeće podne armirano-betonske ploče sa zapunjavanje rupa i neravnina (priprema za izvedbu hidroizolacije), uključivo sav potreban materijal i rad. | C26: m2 | D26: 550 | E26: 5 | F26: =D26*$E26 -> 2750
B27: 3. Rušenja i demontaže ukupno: | F27: =SUM(F11:F26) -> 38270
A29: 3. | B29: ZEMLJANI RADOVI
A30: 3.1. | B30: Kombinirani ručni i strojni iskop površinskog sloja tla - humusa i tla C kategorije u širokom iskopu uz obodne zidove, u širini pojasa potrebnog za izvedbu vanjskih staza i postolja klima jedinice. Iskop tla u prosječnoj debljini sloja cca 30 cm. Jediničnom cijenom obuhvaćena potrebna zaštita sokla postojećih zgrada, tijekom izvođenja radova, očuvanih do razine uređenog terena - zaštita temelja tijekom radova na iskopu. U jediničnu cijenu uključen sav potreban rad, svi utovari, transporti i zbrinjavanje viška iskopanog materijala na odgovarajućem deponiju, uključivo sa svim taksama i naknadama prema važećem Pravilniku. Obračun se vrši po m3 iskopanog materijala u sraslom stanju.
A31: a) | B31: strojni iskop | C31: m3 | D31: 24 | E31: 20 | F31: =D31*$E31 -> 480
A32: b) | B32: ručni iskop | C32: m3 | D32: 24 | E32: 80 | F32: =D32*$E32 -> 1920
A33: 3.2. | B33: Kombinirani ručni i strojni široki iskop tla C kategorije u debljini sloja potrebnog za izvedbu novog vanjskog stubišta. Iskop se izvodi u visini iskopa cca 100 cm od kote postojećeg tla odnosno do dna temeljnih zidova stubišta. Uključivo s formiranjem pokosa (u vanjskom prostoru) i izvedbom potrebnih podupiranja kosine nasipa prema opkopu. Ovisno o sraslosti tla će se nagib pokosa prilagoditi. Način rada odabrati sukladno raspoloživoj tehnologiji izvođača radova (ponuditelja). U jediničnu cijenu uključen sav potreban rad, svi utovari, transporti i zbrinjavanje viška iskopanog materijala na odgovarajućem deponiju, uključivo sa svim taksama i naknadama prema važećem Pravilniku. Deponiju osigurava izvođač. Obračun se vrši po m3 iskopanog materijala u sraslom stanju.
A34: a) | B34: strojni iskop | C34: m3 | D34: 11 | E34: 20 | F34: =D34*$E34 -> 220
A35: b) | B35: ručni iskop | C35: m3 | D35: 3 | E35: 80 | F35: =D35*$E35 -> 240
A36: 3.3. | B36: Ručno i strojno planiranje dna iskopa s točnošću +/- 2 cm. Obračun po m2 isplanirane površine.
A37: a) | B37: strojno planiranje | C37: m2 | D37: 65 | E37: 5 | F37: =D37*$E37 -> 325
A38: b) | B38: ručno planiranje | C38: m2 | D38: 65 | E38: 5 | F38: =D38*$E38 -> 325
A39: 3.4. | B39: Dobava, nasipavanje, nabijanje i planiranje tamposkog sloja kamenog agregata granulacija 0-30 mm u sloju debljine 30 cm ispod betonske ploče staze i stubišta - u svrhu izravnanja podloge. Nasipavanje na pripremljenu i isplaniranu površinu iskopa. Zbijenost posteljice treba iznositi minimalno 50 MN/m2, a istu kontrolirati na svakih 100 m2 izvedenog tamponskog sloja. Prije izvedbe nasipa obavezan pregled temeljnog tla od ovlaštenog nadzora. Obračun po m3 ugrađenog materijala. | C39: m3 | D39: 30 | E39: 60 | F39: =D39*$E39 -> 1800
A40: 3.5. | B40: Obrada i planiranje pokosa tla iskopom i nasipavanjem. Obrada okolnog tla uz vanjske stube, prilagođavajući ga prirodnom postojećem nagibu. Način rada odabrati sukladno raspoloživoj tehnologiji izvođača radova (ponuditelja). Obračun po m2. | C40: m2 | D40: 20 | E40: 20 | F40: =D40*$E40 -> 400
A41: 3.6. | B41: Čišćenje terena oko objekta nakon završetka svih radova na objektu, kao i poslije svake faze rada na objektu. Stavka obuhvaća utovar otpadnog materijala u prijevozno sredstvo i odvoz na javni deponij uključivo troškovi deponiranja. Obračun kao komplet. | C41: kpl | D41: 1 | E41: 300 | F41: =D41*$E41 -> 300
B42: 3. Zemljani radovi ukupno: | F42: =SUM(F31:F41) -> 6010
A44: 4. | B44: ARMIRANO-BETONSKI I ARMIRAČKI RADOVI
A45: 4.1. | B45: Dobava betona i izvedba armiranobetonske podne ploče objekta. Izvedba betonom C30/37. Ploča (2500 kg/m3) se izvodi u debljini 12 cm. Ploča se izvodi na postojeću betonsku ploču, pravilno izoliranu. Izvoditi prema projektu arhitekture, planovima oplate i ostaloj izvedbenoj dokumentaciji te prema uputstvima projektanta konstrukcije i nadzornog inženjera. U jediničnu cijenu uključena je i sva potrebna daščana oplata ako nije posebno navedeno u stavci, te rabic pletivo za radne prekide ovisno o tehnologiji izvođenja. Obavezno dilatiranje prema pravilima struke. Obračun po m3 betona, m2 oplate i kg armature.
...

Sheet Skladište 6
A1: stavka | B1: opis stavke | C1: jedin. mjere | D1: količina | E1: jedinična cijena (euro) | F1: ukupno (euro)
A3: A. | B3: GRAĐEVINSKO-OBRNIČKI RADOVI
A5: 1. | B5: PRIPREMNI RADOVI
A6: 1.1. | B6: Čišćenje terena od raslinja oko građevine, siječenje i skupljanje. U stavku uključeno uklanjanje smeća, prepreka, drveća, i sl., košenja trave i korova, te utovar i odvoz otpadnog materijala na gradsku deponiju, uključeno u cijeni stavke. | C6: kpl | D6: 1 | E6: 5000 | F6: =D6*$E6 -> 5000
A7: 1.2. | B7: Geodetske usluge Ovim radovima potrebno je obuhvatiti angažman ovlaštenog geodete za sva potrebna iskolčenja, označavanje visina, održavanje mjernih točaka tokom gradilišta i sve popratne geodetske usluge potrebne za izvođenje radova. | C7: kpl | D7: 1 | E7: 500 | F7: =D7*$E7 -> 500
B8: 1. Pripremni radovi ukupno: | F8: =SUM(F6:F7) -> 5500
A10: 2. | B10: RUŠENJA I DEMONTAŽE
A11: 2.1. | B11: Demontaža i iznošenje postojećeg namještaja i opreme. Dio opreme je potrebno deponirati na gradilištu na mjesto koje predvidi nadzorni inženjer zbog vraćanja u objekt nakon izvedbe svih radova. U jediničnu cijenu uključen sav potreban rad, svi transporti, sortiranje i zbrinjavanje građevinskog otpada prema važećem Pravilniku. Napomena: prije početka radova korisnik je dužan ukloniti sav skladišteni materijal i opremu u skladištu. Ova stavka se odnosi samo na eventualno zaostalu opremu/materijal koju prema zahtjevu investitora izvođač mora ukloniti te privremeno zbrinuti na drugoj lokaciji i/ili trajno zbrinuti na pripadnu deponiju. Obračun po m3 opreme koja se odvozi. | C11: m3 | D11: 50 | E11: 50 | F11: =D11*$E11 -> 2500
A12: 2.2. | B12: Pažljiva ručna demontaža i uklanjanje rasvjetnih tijela - nadgradna, ovješena, zidna i stropna. U jediničnu cijenu uključen sav potreban rad, laka pokretna skela, svi transporti, sortiranje i zbrinjavanje građevinskog otpada prema važećem Pravilniku. Obračun po komadu. | C12: kom | D12: 14 | E12: 30 | F12: =D12*$E12 -> 420
A13: 2.3. | B13: Pažljiva ručna demontaža i uklanjanje te zbrinjavanje postojećih instalacija jake i slabe struje unutar zone obuhvata (skladišta).
A14: a) | B14: demontaža instalacije (kabela, cijevi, razvodnih kutija) | C14: m' | D14: 200 | E14: 1 | F14: =D14*$E14 -> 200
A15: b) | B15: demontaža utičnica i prekidača | C15: kom | D15: 20 | E15: 10 | F15: =D15*$E15 -> 200
A16: c) | B16: demontaža razvodnih ormara | C16: kom | D16: 2 | E16: 50 | F16: =D16*$E16 -> 100
A17: 2.4. | B17: Demontaža i zbrinjavanje vanjskih metalnih prozora sa djelomičnim staklom. Prozor dimenzija 180×157 cm. U stavci uključena demontaža, odvoz, zbrinjavanje. Pri nuđenju cijeni uključena i cijena zbrinjavanja. U jediničnu cijenu uključen sav potreban rad, laka pokretna skela, svi transporti, sortiranje i zbrinjavanje građevinskog otpada prema važećem Pravilniku. Obračun po komadu demontirane stavke. | C17: kom | D17: 12 | E17: 50 | F17: =D17*$E17 -> 600
A18: 2.5. | B18: Demontaža i zbrinjavanje vanjskih metalnih dvokrilnih vrata. 'Pažljiva demontaža, utovar i odvoz na na mjesto koje odredi investitor postojećih otvora - vanjskih garažnih vrata na istočnom i zapadnom pročelju. Vrata su dimenzija 300×300 cm. Vrata su metalna, dvokrilna, ugrađena između AB stupova. U jediničnu cijenu uračunati skelu, sav rad, materijal i pribor potreban za izvršenje stavke u cijelosti. Obračun prema komadu. Obračun po komadu demontirane stavke. | C18: kom | D18: 20 | E18: 100 | F18: =D18*$E18 -> 2000
A19: 2.6. | B19: Demontaža i zbrinjavanje unutarnjih vrata i prozora. U stavci uključena demontaža, odvoz, zbrinjavanje. Pri nuđenju cijeni uključena i cijena zbrinjavanja. U jediničnu cijenu uključen sav potreban rad, laka pokretna skela, svi transporti, sortiranje i zbrinjavanje građevinskog otpada prema važećem Pravilniku. Obračun po komadu demontirane stavke. | C19: kom | D19: 1 | E19: 100 | F19: =D19*$E19 -> 100
A20: 2.7. | B20: Demontaža i skidanje postojećih gromobranskih traka na krovu i pročeljima objekta, uključivo s pripadajućim elementima i držačima. Radove izvesti pažljivo, kako ne bi došlo do oštećenja ostalih elemenata ovojnice građevine. U jediničnu cijenu uključen sav potreban rad, laka pokretna skela, svi transporti, sortiranje i zbrinjavanje građevinskog otpada prema važećem Pravilniku. Obračun po m' demontirane stavke. | C20: m' | D20: 100 | E20: 2 | F20: =D20*$E20 -> 200
A21: 2.8. | B21: Demontaža i uklanjanje svih postojećih limenih opšava na krovu i prozorima (limarski elementi oborinske odvodnje - žljebovi, oborinske vertikale itd., rubni opšavi krova, prozorski opšavi i sl.), uključivo s svim pripadajućim pričvrsnim elementima. Radove izvesti pažljivo, kako ne bi došlo do oštećenja ostalih elemenata ovojnice građevine. U jediničnu cijenu uključen sav potreban rad, laka pokretna skela, svi transporti, sortiranje i zbrinjavanje građevinskog otpada prema važećem Pravilniku. Obračun po m' demontiranih elemenata bez obzira na razvijenu širinu. | C21: m' | D21: 150 | E21: 5 | F21: =D21*$E21 -> 750
A22: 2.9. | B22: Demontaža i zbrinjavanje valovitih salonitnih ploča krova. U jediničnu cijenu uključen sav potreban rad, laka pokretna skela, svi transporti, sortiranje i zbrinjavanje građevinskog otpada prema važećem Pravilniku. Pri nuđenju stavke je u cijenu potrebno ukalkulirati zbrinjavanje opasnog otpada koji sadrži azbest. Obračun po m2 demontiranih, odvezenih i zbrinutih ploča. | C22: m2 | D22: 650 | E22: 22 | F22: =D22*$E22 -> 14300
A23: 2.10. | B23: Demontaža i uklanjanje postojećih metalnih elemenata (armature, šipke, žica). U jediničnu cijenu uključen sav potreban rad, sva podupiranja, lako pokretna skela, svi transporti, sortiranje i zbrinjavanje građevinskog otpada prema važećem Pravilniku. Obračun po kg. | C23: kg | D23: 100 | E23: 3 | F23: =D23*$E23 -> 300
A24: 2.11. | B24: Rušenje i uklanjanje postojećih unutarnjih zidanih zidova. U stavku obračunato rušenje te odvoz na gradski deponij. Uz sva potrebna podupiranja te zaštitu ljudi i ostale konstrukcije, na pozicijama uklanjanja postojećih zidova određenim projektnom dokumentacijom. Uključivo sa svim potrebnim podupiranjima obodnih konstrukcija. Zidovi su visine cca 290 cm, debljine 10-15 cm. Radove izvesti pažljivo, kako ne bi došlo do oštećenja ostalih elemenata građevine. Zidovi su zidani porobetonskim blokovima. U jediničnu cijenu uključen sav potreban rad, laka pokretna skela, svi transporti, sortiranje i zbrinjavanje građevinskog otpada prema važećem Pravilniku. Obračun po m3 zida. | C24: m3 | D24: 14 | E24: 400 | F24: =D24*$E24 -> 5600
A25: 2.12. | B25: Pažljivo ručno razgrađivanje i uklanjanje postojećih zidanih zabatnih zidova. Uključivo sa svim slojevima pročelja. U stavku obračunato rušenje te odvoz na gradski deponij. Uz sva potrebna podupiranja te zaštitu ljudi i ostale konstrukcije, na pozicijama uklanjanja postojećih zidova određenim projektnom dokumentacijom. Uključivo sa svim potrebnim podupiranjima obodnih konstrukcija. Zidovi su max. visine cca 165 m, na visini od 310 cm. Debljine 25 cm. Radove izvesti pažljivo, kako ne bi došlo do oštećenja ostalih elemenata građevine. Zidovi su zidani blok opekom. Slojevi konstrukcije: - vanjska fasadna žbuka d=2 cm - zidani zid d=25 cm - unutarnja fasadna žbuka d=2 cm U jediničnu cijenu uključen sav potreban rad, laka pokretna skela, svi transporti, sortiranje i zbrinjavanje građevinskog otpada prema važećem Pravilniku. Obračun po m3 zida. | C25: m3 | D25: 29 | E25: 15 | F25: =D25*$E25 -> 435
... A27: 2.14. | B27: Čišćenje od masnoća, otprašivanje i brušenje postojeće podne armirano-betonske ploče sa zapunjavanje rupa i neravnina (priprema za izvedbu hidroizolacije), uključivo sav potreban materijal i rad. | C27: m2 | D27: 550 | E27: 10 | F27: =D27*$E27 -> 5500
B28: 3. Rušenja i demontaže ukupno: | F28: =SUM(F11:F27) -> 33955
A30: 3. | B30: ZEMLJANI RADOVI
A31: 3.1. | B31: Kombinirani ručni i strojni iskop površinskog sloja tla - humusa i tla C kategorije u širokom iskopu uz obodne zidove, u širini pojasa potrebnog za izvedbu vanjskih staza i postolja klima jedinice. Iskop tla u prosječnoj debljini sloja cca 30 cm. Jediničnom cijenom obuhvaćena potrebna zaštita sokla postojećih zgrada, tijekom izvođenja radova, očuvanih do razine uređenog terena - zaštita temelja tijekom radova na iskopu. U jediničnu cijenu uključen sav potreban rad, svi utovari, transporti i zbrinjavanje viška iskopanog materijala na odgovarajućem deponiju, uključivo sa svim taksama i naknadama prema važećem Pravilniku. Obračun se vrši po m3 iskopanog materijala u sraslom stanju.
A32: a) | B32: strojni iskop | C32: m3 | D32: 24 | E32: 20 | F32: =D32*$E32 -> 480
A33: b) | B33: ručni iskop | C33: m3 | D33: 24 | E33: 80 | F33: =D33*$E33 -> 1920
A34: 3.2. | B34: Kombinirani ručni i strojni široki iskop tla C kategorije u debljini sloja potrebnog za izvedbu novog vanjskog stubišta. Iskop se izvodi u visini iskopa cca 100 cm od kote postojećeg tla odnosno do dna temeljnih zidova stubišta. Uključivo s formiranjem pokosa (u vanjskom prostoru) i izvedbom potrebnih podupiranja kosine nasipa prema opkopu. Ovisno o sraslosti tla će se nagib pokosa prilagoditi. Način rada odabrati sukladno raspoloživoj tehnologiji izvođača radova (ponuditelja). U jediničnu cijenu uključen sav potreban rad, svi utovari, transporti i zbrinjavanje viška iskopanog materijala na odgovarajućem deponiju, uključivo sa svim taksama i naknadama prema važećem Pravilniku. Deponiju osigurava izvođač. Obračun se vrši po m3 iskopanog materijala u sraslom stanju.
A35: a) | B35: strojni iskop | C35: m3 | D35: 11 | E35: 20 | F35: =D35*$E35 -> 220
A36: b) | B36: ručni iskop | C36: m3 | D36: 3 | E36: 80 | F36: =D36*$E36 -> 240
A37: 3.3. | B37: Ručno i strojno planiranje dna iskopa s točnošću +/- 2 cm. Obračun po m2 isplanirane površine.
A38: a) | B38: strojno planiranje | C38: m2 | D38: 65 | E38: 5 | F38: =D38*$E38 -> 325
A39: b) | B39: ručno planiranje | C39: m2 | D39: 65 | E39: 5 | F39: =D39*$E39 -> 325
A40: 3.4. | B40: Dobava, nasipavanje, nabijanje i planiranje tamposkog sloja kamenog agregata granulacija 0-30 mm u sloju debljine 30 cm ispod betonske ploče staze i stubišta - u svrhu izravnanja podloge. Nasipavanje na pripremljenu i isplaniranu površinu iskopa. Zbijenost posteljice treba iznositi minimalno 50 MN/m2, a istu kontrolirati na svakih 100 m2 izvedenog tamponskog sloja. Prije izvedbe nasipa obavezan pregled temeljnog tla od ovlaštenog nadzora. Obračun po m3 ugrađenog materijala. | C40: m3 | D40: 30 | E40: 60 | F40: =D40*$E40 -> 1800
A41: 3.5. | B41: Obrada i planiranje pokosa tla iskopom i nasipavanjem. Obrada okolnog tla uz vanjske stube, prilagođavajući ga prirodnom postojećem nagibu. Način rada odabrati sukladno raspoloživoj tehnologiji izvođača radova (ponuditelja). Obračun po m2. | C41: m2 | D41: 20 | E41: 20 | F41: =D41*$E41 -> 400
A42: 3.6. | B42: Čišćenje terena oko objekta nakon završetka svih radova na objektu, kao i poslije svake faze rada na objektu. Stavka obuhvaća utovar otpadnog materijala u prijevozno sredstvo i odvoz na javni deponij uključivo troškovi deponiranja. Obračun kao komplet. | C42: kpl | D42: 1 | E42: 300 | F42: =D42*$E42 -> 300
B43: 3. Zemljani radovi ukupno: | F43: =SUM(F32:F42) -> 6010
A45: 4. | B45: ARMIRANO-BETONSKI I ARMIRAČKI RADOVI
A46: 4.1. | B46: Dobava betona i izvedba armiranobetonske podne ploče objekta. Izvedba betonom C30/37. Ploča (2500 kg/m3) se izvodi u debljini 12 cm. Ploča se izvodi na postojeću betonsku ploču, pravilno izoliranu. Izvoditi prema projektu arhitekture, planovima oplate i ostaloj izvedbenoj dokumentaciji te prema uputstvima projektanta konstrukcije i nadzornog inženjera. U jediničnu cijenu uključena je i sva potrebna daščana oplata ako nije posebno navedeno u stavci, te rabic pletivo za radne prekide ovisno o tehnologiji izvođenja. Obavezno dilatiranje prema pravilima struke. Obračun po m3 betona, m2 oplate i kg armature.
...

Sheet Otvoreni platoi 4 i 5
A1: stavka | B1: opis stavke | C1: jedin. mjere | D1: količina | E1: jedinična cijena (euro) | F1: ukupno (euro)
A3: 1. | B3: GRAĐEVINSKI RADOVI
A4: 1.1. | B4: Čišćenje terena od raslinja oko građevine, siječenje i skupljanje. U stavku uključeno uklanjanje smeća, prepreka, drveća, i sl., košenja trave i korova, te utovar i odvoz otpadnog materijala na gradsku deponiju, uključeno u cijeni stavke. Površina zahvata je približno 5.500 m2. | C4: kpl | D4: 1 | E4: 1000 | F4: =D4*$E4 -> 1000
A5: 1.2. | B5: Geodetske usluge Ovim radovima potrebno je obuhvatiti angažman ovlaštenog geodete za sva potrebna iskolčenja, označavanje visina, održavanje mjernih točaka tokom gradilišta i sve popratne geodetske usluge potrebne za izvođenje radova. Površina zahvata iznosi cca 5.500 m2. | C5: kpl | D5: 1 | E5: 1000 | F5: =D5*$E5 -> 1000
A6: 1.3. | B6: Kombinirani ručni i strojni iskop površinskog sloja tla - humusa u širokom iskopu. Iskop tla u prosječnoj debljini sloja cca 30 cm. U jediničnu cijenu uključen sav potreban rad, svi utovari, transporti i zbrinjavanje viška iskopanog materijala na odgovarajućem deponiju, uključivo sa svim taksama i naknadama prema važećem pravilniku. Obračun se vrši po m3 iskopanog materijala u sraslom stanju. | C6: m3 | D6: 1450 | E6: 60 | F6: =D6*$E6 -> 87000
A7: 1.4. | B7: Kombinirani ručni i strojni iskop tla C kategorije u širokom iskopu. Iskop tla u prosječnoj debljini sloja cca 50 cm. U jediničnu cijenu uključen sav potreban rad, svi utovari, transporti i zbrinjavanje viška iskopanog materijala na odgovarajućem deponiju, uključivo sa svim taksama i naknadama prema važećem pravilniku. Obračun se vrši po m3 iskopanog materijala u sraslom stanju. | C7: m3 | D7: 2400 | E7: 60 | F7: =D7*$E7 -> 144000
A8: 1.5. | B8: Strojno štemanje, razbijanje, utovar i odvoz postojeće armirano-betonske podloge. U jediničnu cijenu uključen sav potreban rad, svi utovari, transporti i zbrinjavanje viška iskopanog materijala na odgovarajućem deponiju, uključivo sa svim taksama i naknadama prema važećem pravilniku. Obračun se vrši po m3 iskopanog materijala u sadašnjem stanju (potrebno ukalkulirati rastresitost). | C8: m3 | D8: 150 | E8: 250 | F8: =D8*$E8 -> 37500
A9: 1.6. | B9: Ručno i strojno planiranje dna iskopa s točnošću +/- 2 cm. Obračun po m2 isplanirane površine. | C9: m2 | D9: 5500 | E9: 1 | F9: =D9*$E9 -> 5500
A10: 1.7. | B10: Dobava, nasipavanje, nabijanje i planiranje tamponskog sloja kamenog agregata granulacija 0-30 mm u sloju debljine 80 cm sa izvedbom projektiranih padova. Nasipavanje na pripremljenu i isplaniranu posteljicu. Zbijenost posteljice treba iznositi minimalno 80 MN/m2, a istu kontrolirati na svakih 200 m2 izvedenog tamponskog sloja. Prije izvedbe nasipa obavezan pregled temeljnog tla od ovlaštenog nadzora. Obračun po m3 ugrađenog materijala. | C10: m3 | D10: 4500 | E10: 0.5 | F10: =D10*$E10 -> 2250
A11: 1.8. | B11: Obrada i planiranje pokosa tla iskopom i nasipavanjem. Izvodi se na rubnim površinama platoa na denivelacijama terena. Obrada okolnog tla uz platoe prilagođavajući ga prirodnom postojećem nagibu. Način rada odabrati sukladno raspoloživoj tehnologiji izvođača radova (ponuditelja). Obračun po m2 izvedenih pokosa. | C11: m2 | D11: 500 | E11: 10 | F11: =D11*$E11 -> 5000
A12: 1.9. | B12: Ispitivanje modula stišljivosti putem ovlaštene tvrtke i izdavanje izvješća o ostvarenim rezultatima. Predviđa se na svakih 200 m2 izvedenog tamponskog sloja. | C12: kom | D12: 25 | E12: 125 | F12: =D12*$E12 -> 3125
A13: 1.10. | B13: Čišćenje terena nakon završetka svih radova na platoima. Stavka obuhvaća utovar otpadnog materijala u prijevozno sredstvo i odvoz na javni deponij. Obračun kao komplet. | C13: kpl | D13: 1 | E13: 2000 | F13: =D13*$E13 -> 2000
A14: 1.11. | B14: Dobava i ugradnja cestovnih betonskih rubnjaka 18x24x100 cm uključivo svi popratni radovi i sav pomoćni materijal, rad i pribor.
A15: a) | B15: strojni i ručni iskop za ugradnju rubnjaka | C15: m3 | D15: 150 | E15: 20 | F15: =D15*$E15 -> 3000
A16: b) | B16: dobava i ugradnja rubnjaka u betonsku podlogu | C16: m' | D16: 300 | E16: 25 | F16: =D16*$E16 -> 7500
A17: c) | B17: zatrpavanje i izravnanje terena nakon ugradnje | C17: m3 | D17: 100 | E17: 10 | F17: =D17*$E17 -> 1000
A18: d) | B18: utovar i odvoz viška materijala | C18: m3 | D18: 50 | E18: 20 | F18: =D18*$E18 -> 1000
A19: 1.12. | B19: Strojna izrada asfaltnog nosivog sloja (AC 32 base, bit 50/70, AG6, M1), debljine 8 cm, proizvedenog i ugrađenog po vrućem postupku, vrste bitumena i agregata prema potvrđenom radnom sastavu. U cijenu je uključena nabava i prijevoz prethodno strojno proizvedene mješavine od agregata i bitumena kao veziva, nazivne veličine najvećeg zrna, vrste kamenog materijala i granulometrijskog sastava prema odredbama u projektu i u skladu prema: HRN EN 13043:2003 ili jednakovrijedno (agregati); HRN EN 12591:2009 ili jednakovrijedno (cestograđevni bitumen) i HRN EN 13108-1:2007 ili jednakovrijedno (asfaltbeton), te utovar, prijevoz, i strojna ugradnja (razastiranje i zbijanje). Izvedba, kontrola kakvoće i obračun prema HRN EN 13108-1 ili jednakovrijedno. Obračun se vrši po m2 gornje površine projektiranog sloja. U svemu prema O.T.U. 5-04. | C19: m2 | D19: 5200 | E19: 18 | F19: =D19*$E19 -> 93600
A20: 1.13. | B20: Strojna izrada asfaltnog habajućeg sloja (AC 11 surf bit 50/70 AG3 M3), debljine 4 cm, proizvedenog i ugrađenog po vrućem postupku, vrste bitumena i agregata prema potvrđenom radnom sastavu. U cijenu je uključena nabava i prijevoz prethodno strojno proizvedene mješavine od agregata i bitumena kao veziva, nazivne veličine najvećeg zrna, vrste kamenog materijala i granulometrijskog sastava prema odredbama u projektu i u skladu prema: HRN EN 13043:2003 ili jednakovrijedno (agregati); HRN EN 12591:2009 ili jednakovrijedno (cestograđevni bitumen) i HRN EN 13108-1:2007 ili jednakovrijedno (asfaltbeton), te utovar, prijevoz, i strojna ugradba (razastiranje i zbijanje). Izvedba, kontrola kakvoće i obračun prema HRN EN 13108-1 ili jednakovrijedno za teško prometno opterećenje. U cijenu izvedbe habajućeg sloja uključeno je čišćenje podloge. Obračun se vrši po m2 gornje površine habajućeg sloja. U svemu prema O.T.U. 6 – 03. | C20: m2 | D20: 5200 | E20: 15 | F20: =D20*$E20 -> 78000
A21: 1.14. | B21: Dobava materijala i izvedba horizontalne signalizacije:
A22: a) | B22: pune žute trake širine 15 cm | C22: m' | D22: 600 | E22: 10 | F22: =D22*$E22 -> 6000
A23: b) | B23: strelice za smjer kretanja | C23: m2 | D23: 30 | E23: 50 | F23: =D23*$E23 -> 1500
A24: 1.15. | B24: Dobava i postava prometnih znakova na pocinčanom stupu, uključivo i AB temelj (znak ''STOP'' - B02). | C24: kom | D24: 4 | E24: 200 | F24: =D24*$E24 -> 800
A25: 1.16. | B25: Uklapanje platoa na postojeću prometnicu. Izvodi se prema potrebi uz prethodni dogovor s nadzornim inženjerom.
A26: a) | B26: uklanjanje i odvoz AB rubnjaka 18/24/100 cm | C26: m' | D26: 50 | E26: 20 | F26: =D26*$E26 -> 1000
A27: b) | B27: strojno rezanje asfalta | C27: m' | D27: 50 | E27: 10 | F27: =D27*$E27 -> 500
A28: c) | B28: uklanjanje dijela asfalta frezanjem | C28: m2 | D28: 50 | E28: 50 | F28: =D28*$E28 -> 2500
B29: 1. Građevinski radovi ukupno: | F29: =SUM(F4:F28) -> 484775
A32: 2. | B32: INSTALACIJE ODVODNJE
A33: 2.1. | B33: Geodetsko iskolčenje trase vanjske kanalizacije prije izvođenja radova - dužina 503 m | C33: m' | D33: 503 | E33: 1 | F33: =D33*$E33 -> 503
A34: 2.2. | B34: Iskop kanala u zemljištu C kategorije za polaganje kanalizacijskih cijevi. Dubinu iskopa izvesti prema projektu, a pad kanala u projektiranom nagibu. Širina rova 0,8m. Predviđen je ručni iskop 30% i strojni iskop 70%. NAPOMENA: Točnu kategoriju zemlje utvrditi na licu mjesta. | C34: m3 | D34: 604 | E34: 15 | F34: =D34*$E34 -> 9060
A35: 2.3. | B35: Proširenje dna rova u zemljištu C kategorije radi izvedbe revizijskih okana i separatore lakih tekućina. Iskopani materijal odbaciti na udaljenost preko 1.0 m od bočne ivice rova, kako bi se spriječilo urušavanje iskopanog materijala u rov. | C35: m3 | D35: 48 | E35: 20 | F35: =D35*$E35 -> 960
A36: 2.4. | B36: Planiranje dna rova s odstupanjem ± 2.0 cm. | C36: m2 | D36: 403 | E36: 2 | F36: =D36*$E36 -> 806
A37: 2.5. | B37: Dobava pijeska i izrada posteljice za kanalizacijske cijevi. Prani riječni pijesak granulacije 0 - 4 mm. Posteljica ispod kanalizacijskih cijevi je debljine 10 cm. Nabija se strojnim i ručnim nabijačima i po potrebi vlaži. Materijal je potrebno zbiti do modula stišljivosti Ms=25 MN/m2. Posteljica mora biti ravna, prilagođena obliku cijevi i uzdužnom padu tako da cijevi po cijeloj dužini naliježu na istu. Podmetanje kamena ispod cijevi ili podupiranje najstrože se zabranjuje. Obračun po m3 izvedene posteljice. | C37: m3 | D37: 41 | E37: 50 | F37: =D37*$E37 -> 2050
A38: 2.6. | B38: Dobava materijala i izrada obloge za kanalizacijske cijevi. Oko prethodno montiranih kanalizacijskih cijevi izvodi se obloga od sitnog materijala - pijesak ili finiji zamjenski materijal iz pozajmišta (0-40 mm), a do visine 30 cm iznad vrha tjemena cijevi. Obračun po m3 izvedene obloge. | C38: m3 | D38: 202 | E38: 20 | F38: =D38*$E38 -> 4040
A39: 2.7. | B39: Dobava i polaganje u rov iznad kanalizacijski cijevi PVC trake sa natpisom "POZOR - kanalizacija" i vodljivom žicom za detekciju trase. | C39: m' | D39: 503 | E39: 1 | F39: =D39*$E39 -> 503
A40: 2.8. | B40: Zatrpavanje rova materijalom od iskopa, po slojevima od 30 cm, uz istovremeno obilno močenje i nabijanje materijala ručnim nabijačima. | C40: m3 | D40: 363 | E40: 15 | F40: =D40*$E40 -> 5445
