Workbook
Name _: #REF!
Name _: #REF!
Name __: #REF!
Name __: #REF!
Name _____: #REF!
Name _____: #REF!
Name _________: #REF!
Name _________: #REF!
Name ___________: #REF!
Name ___________: #REF!
Name _________________: #REF!
Name _________________: #REF!
Name _______________________: #REF!
Name _______________________: #REF!
Name ___IEJBVO: #REF!
Name ___IEJBVO: #REF!
Name __GL: #REF!
Name __GL: #REF!
Name _HKJB: #REF!
Name _HKJB: #REF!
Name _KKJ: #REF!
Name _KKJ: #REF!
Name ABHGBN: #REF!
Name ABHGBN: #REF!
Name BETONSKI_I_ARM.BETONSKI_RADOVI: #REF!
Name BETONSKI_I_ARM.BETONSKI_RADOVI: #REF!
Name BRAVARIJA_SKLONIŠTA: #REF!
Name BRAVARIJA_SKLONIŠTA: #REF!
Name CRNA_BRAVARIJA: #REF!
Name CRNA_BRAVARIJA: #REF!
Name ČELIČNA_KONSTRUKCIJA: #REF!
Name ČELIČNA_KONSTRUKCIJA: #REF!
Name ČPEOJGPOE: #REF!
Name ČPEOJGPOE: #REF!
Name dabnbn: #REF!
Name dabnbn: #REF!
Name DHB: #REF!
Name DHB: #REF!
Name DIMNJACI: #REF!
Name DIMNJACI: #REF!
Name DIZALA: #REF!
Name DIZALA: #REF!
Name E: #REF!
Name E: #REF!
Name Excel_BuiltIn_Print_Area_15_1: #REF!
Name Excel_BuiltIn_Print_Area_15_1: #REF!
Name Excel_BuiltIn_Print_Area_15_1: #REF!
Name Excel_BuiltIn_Print_Area_15_1: #REF!
Name Excel_BuiltIn_Print_Area_8_1: #REF!
Name Excel_BuiltIn_Print_Area_8_1: #REF!
Name Excel_BuiltIn_Print_Area_8_1: #REF!
Name Excel_BuiltIn_Print_Area_8_1: #REF!
Name FASADERSKI_RADOVI: #REF!
Name FASADERSKI_RADOVI: #REF!
Name FGHGF: #REF!
Name FGHGF: #REF!
Name gfn: #REF!
Name gfn: #REF!
Name INOX_BRAVARIJA: #REF!
Name INOX_BRAVARIJA: #REF!

Sheet XXXXXX

Sheet NASLOVNICA
A3: UGOSTITELJSKO-TURISTIČKA GRAĐEVINA PLANINARSKI DOM JELENIĆ KUĆA PROJEKTANTSKI TROŠKOVNIK SVIH RADOVA
B6: INVESTITOR: | C6: HRVATSKE ŠUME D.O.O.
B7: sjedište investitora: | C7: Branimirova 1, 10000 Zagreb
B9: GRAĐEVINA: | C9: UGOSTITELJSKO-TURISTIČKA GRAĐEVINA PLANINARSKI DOM JELENIĆ KUĆA
B10: lokacija zahvata:
C11: k.č.br. 1952 k.o. Grabar
C12: Jelenići 5, Golubići
B13: zajednička oznaka: | C13: 12.06/22-TR
B15: Projektant arhitekture: | C15: Kata Bukovac Peršun dipl.ing.arh.
B16: Projektant vodovoda, odvodnje, vatrozaštite i manipulativnih površina: | C16: Mario Vitez dipl.ing.građ.
B17: Projektant strojarskih instalacija: | C17: Krešimir Pećar dipl.ing.stroj.
B18: Projektant elektrotehničkih instalacija: | C18: Darko Rudvald mag.ing.el.
B19: Projektanti krajobraza: | C19: Bruno Andrašić dipl.ing.arh
C20: Višnja Šteko mag.ong.prosp.arch.
B22: Glavni projektant: | C22: Bruno Andrašić dipl.ing.arh
B24: datum: | C24: prosinac 2022.

Sheet OPĆI UVJETI
B1: OPĆI UVJETI:
A4: 1. | B4: Izvođač je dužan pridržavati se svih važećih zakona i propisa i to naročito Zakona o gradnji, Zakona o zaštiti na radu.
A5: 2. | B5: Izvođač je dužan, u okviru ugovorene cijene, ugraditi propisani adekvatan i prema važećim normama atestiran materijal. Izvođač je također dužan kod izrade konstrukcija, prema projektom određenom planu ispitivanja materijala, kontrolirati ugrađeni konstruktivni materijal u okviru ugovorene cijene. Troškovi ispitivanja materijala uzimanja uzoraka, laboratorijska obrada s izdavanjem atesta ispitnih protokola, te ispitivanje svih ugrađenih slojeva nasipa i kolničkih konstrukcija, ispitivanje cjevovoda na tlak, dezinfekcija cjevovoda, bakteriološka proba, puštanje sistema u rad i sl. moraju biti uključeni u jediničnu cijenu radova.
A6: 3. | B6: Za instalacijske sustave izvođač je dužan, u okviru ugovorene cijene, osim atesta o kvaliteti ugrađenih materijala, dati ateste za instalacijske sustave te izvještaje o kontrolnim ispitivanjima.
A7: 4. | B7: Izvođač je u okviru ugovorene cijene dužan izvršiti koordinaciju radova svih kooperanata na način da omogući kontinuirano odvijanje posla i zaštitu već izvedenih radova. Sva oštećenja nastala tokom gradnje otkloniti će izvođač o svom trošku.
A8: 5. | B8: Izvođač je dužan, u okviru ugovorene cijene, osigurati gradilište od djelovanja više sile i krađe.
A9: 6. | B9: Sav rad i materijal vezan za organizaciju građevinske proizvodnje: ograde, vrata gradilišta, putovi na gradilištu, uredi, blagovaonice, svlačionice, sanitarije gradilišta, spremišta materijala i alata, telefonski, električni, vodovodni i sl. priključci gradilišta kao i cijena korištenja priključaka uključeni su u ugovorenu cijenu.
A10: 7. | B10: Izvođač će zajedno sa nadzornim inženjerom izraditi vremenski plan (gantogram) aktivnosti na gradilištu i njime odrediti dinamiku financiranja, dobave materijala i opreme i sl.
A11: 8. | B11: Sva oštecenja prometnih ili ostalih javnih i ostalih površina parcele izvođač će po završetku radova o svom trošku dovesti u prvobitno stanje.
A12: 9. | B12: Prema uvjetima ovog troškovnika izvoditelj radova daje jedinične cijene svih radova, a one obuhvaćaju:
B13: a) organizaciju gradilišta i sve potrebne pripremne i završne radove, koji osiguravaju u cjelini kvalitetnu izvedbu, uključujući i troškove vezane uz zauzeće javne površine
B14: b) sve potrebne troškove za izvršenje samih radova i to za: rad, materijal, alat, skele, režiju, troškove montaže, troškove zaštite na radu, kao i sve druge izdatke po važećim propisima.
B15: c) redovito čišćenje i odvoženje viška materijala, zemlje, šute i otpada na deponij
B16: d) zaštita postojećih podzemnih instalacija na nužnim mjestima nakon što se utvrdi točan položaj instalacija. Točan položaj instalacija potrebno je odrediti prije započinjanja radova na izvođenju predmetnog zahvata. Nadzorni inženjer i predstavnik vlasnika instalacija će potom odrediti mjere zaštite ili potrebu izmještanja instalacija sukladno posebnim uvjetima.
B17: Predviđeni su svi potrebni radovi za zaštitu instalacija.
A18: 10. | B18: Svi radovi moraju biti potpuno gotovi kako je predviđeno po Ponudbenoj dokumentaciji, izvedeni pravilno po tehničkim propisima i standardima, s kvalitetnim materijalom i kvalitetnom stručnom radnom snagom.
B19: Za sve materijale, poluproizvode i gotove dijelove, koji će se upotrijebiti na svim radovima, izvoditelj je dužan podnijeti nadzornom inženjeru uzorke na odobrenje, odnosno izvršiti sistematsko ispitivanje i da o tome ispitivanju podnese nadzornom inženjeru ili naručitelju mjerodavne dokaze. Ovo ispitivanje pada na teret izvoditelja radova.
A20: 11. | B20: Materijali koji ne odgovaraju tehničkim uvjetima, propisima i standardima, ne smiju se ugraditi, a izvoditelj ih je dužan otkloniti s gradilišta bez troškova naknade.
A21: 12. | B21: Ukoliko tehnička dokumentacija nije potpuna ili izvoditelju razumljiva, izvoditelj radova je obavezan pravovremeno tražiti dopunu istoga kao i sva potrebna tumačenja.
A22: 13. | B22: Izvoditelj je dužan sve mjere u nacrtima kontrolirati na licu mjesta.
A23: 14. | B23: Izvoditelj je dužan na gradilištu zatrpati i nabiti sve jame koje je u tijeku radova morao otvoriti u zemljištu oko objekta, zemljište raščisti i poravnati, građevinu i česticu predati očišćenu od otpadaka građevinskog materijala, sa čistim podovima, bravarijom, stolarijom i prozorskim staklom, u tijeku radova i sve do predaje objekta održavati red i čistoću na gradilištu.
B24: Svi ovi radovi trebaju biti uračunati u cijene odgovarajućih pozicija i posebno se neće plaćati, osim onih koji su troškovnikom predviđeni.
A25: 15. | B25: Izvoditelj je dužan čuvati i sačuvati sve izvršene radove do primopredaje objekta i u tu svrhu mora izvršiti potrebna osiguranja po uputama nadzornog inženjera, što je uračunato u jedinične cijene i neće se posebno plaćati.
A26: 16. | B26: Izvoditelj je dužan osigurati higijensko-tehničke zaštitne mjere na gradilištu po postojećim propisima, što je uračunato u cijene i neće se posebno plaćati.
A27: 17. | B27: Obračun svih izvršenih radova obavlja se prema postojećim normama u graditeljstvu za tu vrstu radova.
A28: 18. | B28: Svi radovi koji će se zatvoriti u konstrukciju, prekriti slojevima ili na drugi način postati nevidljivi mogu se zatvoriti tek nakon pregleda i pozitivne ocjene nadzornog inženjera. Ovo se odnosi na sve instalacije i materijale koji će biti skriveni prekrivanjem drugog sloja preko njih.
A29: 19. | B29: Za vrijeme izvođenja radova izvođač je dužan osigurati nesmetan promet na postojećim prometnicama i prilaznim putevima i regulirati ga odgovarajućim prometnim znacima. Troškovi privremene signalizacije i regulacije prometa biti će uračunati u jediničnu cijenu i neće se posebno naplaćivati.
A30: 20. | B30: Sve stavke uključuju sav rad i materijal (osnovni i pomoćni materijal te spojni i pričvrsni materijal, materijal za završne obrade) sve do potpune gotovosti i funkcionalnosti. U jediničnu cijenu stavki su uključeni svi horizontalni i vertikalni transporti po gradilištu te sva potrebna mehanizacija, radna skela i materijal za podupiranje tijekom ugradnje stavki.
A31: 21. | B31: U cijenu uključiti čišćenje gradilišta u toku radova i završno fino čišćenje gradilišta i pranje nakon dovršetka gradnje prije predaje na korištenje investitoru, s odvozom šute i smeća na gradski deponij uz plaćanje naknada.
A32: 22. | B32: U cijenu uključiti i kontejner za održavanje radnih sastanaka sa investitorom, nadzornim inž.i projektantima koji mora biti opremljen konferencijskim stolom sa sjedalicama, infrastrukturnim priključcima, sanitarnim čvorom.
A33: 23. | B33: Sva ponuđena oprema i sustavi (na koju se odnosi primjena) trebaju zadovoljiti važeće kriterije i obavezna mjerila objavljena u Odluci komisije (EU) u cilju dodjele znaka za okoliš EU za turistički smještaj - EcoLabel ili jednakovrijedno.
B34: https://environment.ec.europa.eu/topics/circular-economy/eu-ecolabel-home/product-groups-and-criteria/holiday-accommodation_en
B35: a sukladno uvjetima navedenim na stranici nadležnog Ministarstva:
B36: https://mingor.gov.hr/o-ministarstvu-1065/djelokrug/uprava-za-klimatske-aktivnosti-1879/eko-oznake/znak-zastite-okolisa-europske-unije-eu-ecolabel/1420
B37: te je u tom smislu potrebno prilagoditi ponudu za pojedine stavke iz ovog troškovnika.
A39: 24. | B39: Za sve ugrađene građevne dijelove i materijale potrebno je dostaviti dokaze za okolišne ciljeve:
B40: - da građevni dijelovi i materijali korišteni u zgradi koji mogu doći u kontakt sa korisnicima emitiraju manje od 0,06 mg formaldehida po m3 materijala ili komponente i manje od 0,001 mg po m3 materijala kategorija 1A i 1B (kancerogeni hlapljivi organski spojevi)
B41: - da građevni dijelovi i materijali koji se koriste ne sadrže azbest niti tvari koje izazivaju veliku zabrinutost
B42: - svi instalirani uređaji za vodu (tuševi s mješalicom, slavine, WC školjke, vodokotlići i slično) moraju biti svrstani u prva dva razreda potrošnje vode EU vodne oznake EU Water Label ili jednakovrijedno, čime se osigurava ostvarenje minimalnog uvjeta zaštite voda i mora.
B43: http://www.europeanwaterlabel.eu
...

Sheet A_I_RUŠENJE I DEMONTAŽE
A1: A.I. | B1: RUŠENJA I DEMONTAŽE
A3: Redni broj | B3: Opis rada | C3: Jedinična mjera | D3: Količina | E3: Cijena u eurima | G3: JV
E5: Jedinična | F5: Ukupna
A7: 1 | B7: DJELOMIČNO UKLANJANJE GRAĐEVINSKIH DIJELOVA ZATEČENE ZGRADE
B8: UVODNA NAPOMENA:
B9: PRIJE NUĐENJA RADOVA NA UKLANJANJU GRAĐEVINE POTREBNO SE DETALJNO UPOZNATI SA STANJEM NA TERENU.
B11: OPIS GRAĐEVINE:
B12: RADOVI RUŠENJA I DEMONTAŽE ODNOSE SE NA DIO ZGRADE, SVE OSIM PREDNJEG ULIČNOG PROČELJA, KOJE SE ZADRŽAVA (UZ RESTAURACIJU I OBNOVU). ZGRADA JE KATNOSTI PRIZEMLJE+1.KAT+POTKROVLJE. ZGRADA JE STARIJA ZIDANICA SA MEĐUKATNIM KONSTRUKCIJAMA OD DRVENIH GREDNIKA. NAD ZGRADOM JE IZVEDENO KLASIČNO DRVENO DVOSTREŠNO KROVIŠTE POKRIVENO CRIJEPOM.
B14: RADOVI DEMONTAŽE I UKLANJANJA OBUHVAĆAJU SLIJEDEĆE:
A15: A | B15: DEMONTAŽA I UKLANJANJE ELEKTRIČNIH INSTALACIJA, RASVJETNIH TIJELA, I SVIH OSTALIH EL. IZVODA, PREKIDAČA I SL. UKLANJANJE SVIH RAZVODA SLABE I JAKE STRUJE STRUJE U POSTOJEĆOJ GRAĐEVINI. U CIJENI SVI EVENTUALNI POPRATNI GRAĐEVINSKI RADOVI NUŽNI ZA UKLANJANJE.
C16: KOMPLET | D16: 1 | E16: 1000 | F16: =D16*E16 -> 1000
A17: B | B17: OTPAJANJE DEMONTAŽA I UKLANJANJE SANITARNIH UREĐAJA I OPREME, UKLANJANJE INSTALACIJSKIH RAZVODA VODOVODA I KANALIZACIJE I ARMATURA UZ SVE EVENTUALNE POPRATNE GRAĐEVINSKE I OBRTNIČKE RADOVE.
C18: KOMPLET | D18: 1 | E18: 1000 | F18: =SUM(D18*E18) -> 1000
A20: C | B20: STROJNO/RUČNO RUŠENJE I UKLANJANJE SVIH PODNIH KONSTRUKCIJA PODOVA NA TLU, UKLJUČIVO S ZAVRŠNIM SLOJEM PODNE OBLOGE.
C21: M2 | D21: 110 | E21: 20 | F21: =SUM(D21*E21) -> 2200
A22: D | B22: DEMONTAŽA I UKLANJANJE SVIH BRAVARSKIH I STOLARSKIH ELEMENATA, PROZORA, DRVENIH GRILJA, VRATA, OSTAKLJENIH STIJENA I PREGRADA, OGRADA I SLIČNO, UKLJUČIVO PROZORSKE KLUPČICE I OSTALE LIMARSKE OPŠAVE, TE SLIJEPE OKVIRE STOLARSKIH ELEMENATA. NA OTVORIMA NA ULIČNOM PROČELJU (KOJE SE ZADRŽAVA U POSTOJEĆEM STANJU I RESTAURIRA) POTREBNO JE PAŽLJIVO DEMONTIRATI ULAZNA VRATA (KOJA SE RESTAURIRAJU I PONOVNO UGRAĐUJU), TE POSTOJEĆE PROZORE (KAO PREDLOŽAK ZA IZRADU NOVIH).
B23: ULAZNA VRATA | C23: KOMADA | D23: 1 | E23: 100 | F23: =SUM(D23*E23) -> 100
B24: PROZORI ULIČNOG PROČELJA | C24: KOMADA | D24: 10 | E24: 100 | F24: =SUM(D24*E24) -> 1000
B25: OSTALI OTVORI | C25: KOMADA | D25: 26 | E25: 100 | F25: =SUM(D25*E25) -> 2600
A27: E | B27: DEMONTAŽA I UKLANJANJE KROVNOG POKROVA OD GLINENOG CRIJEPA. UKLJUČIVO SVE LIMARSKE ELEMENTE OPŠAVA I KROVNE ODVODNJE. PLATFORMA ZA RAD I PRIHVAT U CIJENI. OBRAČUN PO M2 KROVA.
C28: M2 | D28: 200 | E28: 20 | F28: =SUM(D28*E28) -> 4000
A30: F | B30: DEMONTAŽA, RUŠENJE I UKLANJANJE KLASIČNE DRVENE KONSTRUKCIJE KROVIŠTA - OBRAČUN PO TLOCRTNOJ PROJEKCIJI KROVIŠTA.
C31: M2 | D31: 220 | E31: 20 | F31: =SUM(D31*E31) -> 4400
A33: G | B33: RAZGRADNJA, RUŠENJE I UKLANJANJE ZIDANIH DIMNJAKA, PO ETAPAMA (ETAŽAMA). SKELA ZA RAD I PRIHVAT U CIJENI.
C34: M1 | D34: 22 | E34: 100 | F34: =SUM(D34*E34) -> 2200
A36: H | B36: RUČNO I STROJNO RUŠENJE I UKLANJANJE ZIDANIH NOSIVIH I PREGRADNIH ZIDOVA PRIZEMLJA, 1. KATA I POTKROVLJA, UKLJUČIVO DRVENE ELEMENTE NADVOJA I SL. SKELA ZA RAD I PRIHVAT U CIJENI. OBRAČUN PO TLOCRTNOJ POVRŠINI ETAŽA.
C37: M2 | D37: 460 | E37: 40 | F37: =SUM(D37*E37) -> 18400
A38: I | B38: RAZBIJANJE, RUŠENJE I UKLANJANJE MEĐUKATNIH KONSTRUKCIJA NA DRVENIM GREDNICIMA UKLJUČIVO SA ZAVRŠNIM PODNIM OBLOGAMA (DASKA). SKELA ZA RAD I PRIHVAT U CIJENI. OBRAČUN PO TLOCRTNOJ POVRŠINI STROPA.
C39: M2 | D39: 260 | E39: 40 | F39: =SUM(D39*E39) -> 10400
A40: J | B40: ČIŠĆENJE, IZRAVNAVANJE I SANACIJA TERENA ISPOD I OKO GRAĐEVINE.
C41: KOMPLET | D41: 1 | E41: 2000 | F41: =SUM(D41*E41) -> 2000
A43: K | B43: UTOVAR, ODVOZ I ISTOVAR I ODLAGANJE SVOG MATERIJALA NASTALOG OD DEMONTAŽE I RUŠENJA IZ PRETHODNIH STAVAKA, TE ZBRINJAVANJE GRAĐEVINSKOG OTPADA SUKLADNO PROPISIMA.
C44: KOMPLET | D44: 1 | E44: 10000 | F44: =SUM(D44*E44) -> 10000
B46: REŠENJA I DEMONTAŽE UKUPNO | E46: EUR | F46: =SUM(F16:F44) -> 59300

Sheet A_II_ ZEMLJANI
A1: A.II. | B1: PRIPREMNI I ZEMLJANI RADOVI
A3: Redni broj | B3: Opis rada | C3: Jedinična mjera | D3: Količina | E3: Cijena u eurima | G3: JV
E5: Jedinična | F5: Ukupna
A7: 1 | B7: IZLAZAK OVLAŠTENOG GEOMEHANIČARA I PREGLED TEMELJNIH ISKOPA S UPISOM U GRAĐEVINSKI DNEVNIK.
C8: komplet | D8: 1 | E8: ='[1]A_II_ ZEMLJANI'!E8 -> 500 | F8: =D8*E8 -> 500
A10: 2 | B10: POVRŠINSKO STROJNO UKLANJANJE HUMUSNOG SLOJA ZEMLJE S DIJELA PARCELE. UKLANJA SE SLOJ U DEBLJINI OD 10 CM DO 20 CM. UKLONJENI MATERIJAL SE DEPONIRA NA GRADILIŠTU DO PONOVNOG RAZASTIRANJA I NIVELIRANJA TERENA NA PROJEKTIRANU KOTU.
C11: M2 | D11: 500 | E11: ='[1]A_II_ ZEMLJANI'!E11 -> 20 | F11: =E11*D11 -> 10000
A13: 3 | B13: STROJNI ŠIROKI ISKOP ZEMLJE B KATEGORIJE NA KOTI TERENA. MIN DUBINA ISKOPA 1 M ODNOSNO DO KOTE DNA TEMELJA POSTOJEĆE ZGRADE. STAVKA UKLJUČUJE ISKOP PRIJE UKLANJANJA DIJELA ZGRADE (UNUTAR POSTOJEĆIH PROSTORIJA UZ ULIČNO PROČELJA) DO KOTE DNA AB TEMELJNE KONSTRUKCIJE (MINIMALNO 1 M ODNOSNO DO KOTE DNA TEMELJA POSTOJEĆE ZGRADE) NADZEMNE ČELIČNE KONSTRUKCIJE ZA STABILIZACIJU I PRIDRŽANJE POSTOJEĆEG ULIČNOG PROČELJA KOJE SE ZADRŽAVA. UKLONJENI MATERIJAL SE DEPONIRA NA GRADILIŠTU DO PONOVNOG RAZASTIRANJA I NIVELIRANJA TERENA NA PROJEKTIRANU KOTU.
C14: M3 | D14: 275 | E14: ='[1]A_II_ ZEMLJANI'!E14 -> 40 | F14: =E14*D14 -> 11000
A16: 4 | B16: NASIPAVANJE, RAZASTIRANJE I NABIJANJE ZEMLJE U ROVOVE OD ŠIROKOG ISKOPA OKO GRAĐEVINE NA PROJEKTIRANU KOTU. NASIPAVANJE SE VRŠI U SLOJEVIMA OD MAX 30 CM. NABIJANJE ZEMLJE JE STROJNO UZ VLAŽENJE. KORISTITI ZEMLJU PREOSTALU OD ISKOPA.
C17: M3 | D17: 50 | E17: ='[1]A_II_ ZEMLJANI'!E17 -> 40 | F17: =E17*D17 -> 2000
A19: 5 | B19: PRIPREMA ZEMLJANE PODLOGE PARCELE ZA HUMUSNI SLOJ. ČIŠĆENJE KOMPLETNOG BUDUĆEG OZELENJENOG TERENA NA ČESTICI OD ŠUTE I OSTATAKA OD MATERIJALA OD GRADNJE, PLANIRANJE NA PROJEKTIRANU KOTU I GRUBO I FINO RAHLJENJE TLA NA PARCELI I ČIŠĆENJE TERENA OD OSTATAKA TVRDOG MATERIJALA.
C20: M2 | D20: 450 | E20: ='[1]A_II_ ZEMLJANI'!E20 -> 20 | F20: =E20*D20 -> 9000
A22: 6 | B22: RAZASTIRANJE HUMUSNOG SLOJA DO PROJEKTIRANE KOTE TLA S TOLERANCIJOM OD 2 CM NA OZELENJENI DIO PARCELE. KORISTITI HUMUSNI SLOJ DEPONIRAN NA GRADILIŠTU.
C23: M3 | D23: 50 | E23: ='[1]A_II_ ZEMLJANI'!E23 -> 20 | F23: =E23*D23 -> 1000
A25: 7 | B25: GEODETSKO SNIMANJE, NACRTI I OBRAČUN SVIH ZEMLJANIH RADOVA OD STRANE OVLAŠTENOG INŽENJERA GEODEZIJE S UPISOM U GRAĐEVINSKI DNEVNIK
C26: KOMPLET | D26: 1 | E26: ='[1]A_II_ ZEMLJANI'!E26 -> 1500 | F26: =E26*D26 -> 1500
A28: 8 | B28: UTOVAR, ODVOZ I ISTOVAR SVE SUVIŠNE ZEMLJE S GRADILIŠTA NA GRADSKU PLANIRKU UZ PLAĆANJE KOMUNALNE NAKNADE.
B29: OBRAČUN U SRASLOM STANJU | C29: M3 | D29: 225 | E29: ='[1]A_II_ ZEMLJANI'!E29 -> 20 | F29: =E29*D29 -> 4500
B31: PRIPREMNI I ZEMLJANI UKUPNO | F31: =SUM(F8:F29) -> 39500

Sheet A_III_ BETONSKI I AB
A1: A.III. | B1: BETONSKI I ARMIRANOBETONSKI
A3: Redni broj | B3: Opis rada | C3: Jedinična mjera | D3: Količina | E3: Cijena u eurima | G3: JV
E5: Jedinična | F5: Ukupna
B7: RADOVI PRIJE UKLANJANJA DIJELA GRAĐEVINE
A9: 1 | B9: DOBAVA MATERIJALA I BETONIRANJE PODLOŽNOG BETONA ISPOD TEMELJNE KONSTRUKCIJE ČELIČNE KONSTRUKCIJE ZA PRIDRŽANJE POSTOJEĆEG ULIČNOG PROČELJA KOJE SE ZADRŽAVA U POSTOJEĆEM STANJU. BETONIRANJE SE VRŠI BETONOM KVALITETE NE MANJE OD C 12/15, KLASE B.II U DEBLJINI MIN 5 CM. U CIJENU STAVKE URAČUNAT JE SAV POTREBAN MATERIJAL, NJEGOVA DOBAVA I UGRADNJA, TE OPLATA.
A10: A | B10: BETONA C 12/15 | C10: M3 | D10: 4 | E10: ='[1]A_III_ BETONSKI I AB'!E10 -> 200 | F10: =SUM(D10*E10) -> 800
A11: B | B11: DAŠČANE NEBLANJANE OPLATE | C11: M2 | D11: 4 | E11: ='[1]A_III_ BETONSKI I AB'!E11 -> 50 | F11: =SUM(D11*E11) -> 200
A13: 2 | B13: DOBAVA MATERIJALA I BETONIRANJE AB TEMELJNE KONSTRUKCIJE ČELIČNE KONSTRUKCIJE ZA PRIDRŽANJE POSTOJEĆEG ULIČNOG PROČELJA KOJE SE ZADRŽAVA U POSTOJEĆEM STANJU, BETONOM C25/30, XC2, U DAŠČANOJ OPLATI PREMA PROJEKTU, STATIČKOM PRORAČUNU I ARMATURNIM NACRTIMA. TEMELJI ULIČNOG PROČELJA IZVODE SE KAMPADNO: ISPOD ZIDA SE UKLANJAJU POSTOJEĆI TEMELJI I IZVODE SE NOVE ARMIRANOBETONSKE TRAKE. TRAKE SE IZVODE KAMPADNIM PODBETONIRAVANJEM U SEGMENTIMA NE VEĆIM OD 85 CM. TEMELJNA PLOČA ZA ČELIČNU KONSTRUKCIJU DEBLJINE JE 75 CM, PROTEŽE SE UNUTAR ZGRADE I POVEZANA JE S TEMELJNIM TRAKAMA OBJEKTA I PODNOM PLOČOM PRIZEMLJA DEBLJINE 15 CM. DUBINA DNA TEMELJA MIN 1M, ODNOSNO USKLADITI SA DUBINOM DNA POSTOJEĆIH TEMELJA ULIČNOG PROČELJA. U STAVKU URAČUNAT SAV POTREBAN RAD I MATERIJAL.
A14: A | B14: BETONA C25/30 | C14: M3 | D14: 50 | E14: ='[1]A_III_ BETONSKI I AB'!E14 -> 200 | F14: =SUM(D14*E14) -> 10000
A15: B | B15: OPLATE | C15: M2 | D15: 55 | E15: ='[1]A_III_ BETONSKI I AB'!E15 -> 50 | F15: =SUM(D15*E15) -> 2750
B17: RADOVI NAKON UKLANJANJA DIJELA GRAĐEVINE
A19: 3 | B19: DOBAVA MATERIJALA I BETONIRANJE PODLOŽNOG BETONA ISPOD TRAKASTIH TEMELJA GRAĐEVINE. BETONIRANJE SE VRŠI BETONOM KVALITETE NE MANJE OD C 12/15, KLASE B.II U DEBLJINI MIN 5 CM. U CIJENU STAVKE URAČUNAT JE SAV POTREBAN MATERIJAL, NJEGOVA DOBAVA I UGRADNJA, TE OPLATA.
A20: A | B20: BETONA C 12/15 | C20: M3 | D20: 3 | E20: ='[1]A_III_ BETONSKI I AB'!E20 -> 200 | F20: =SUM(D20*E20) -> 600
A21: B | B21: DAŠČANE NEBLANJANE OPLATE | C21: M2 | D21: 7 | E21: ='[1]A_III_ BETONSKI I AB'!E21 -> 50 | F21: =SUM(D21*E21) -> 350
A23: 4 | B23: DOBAVA MATERIJALA I BETONIRANJE PODLOŽNOG BETONA ISPOD TEMELJNE PLOČE VANJSKOG PODESTA ZA TERMOTEHNIKU SA SJEVERNE STRANE GRAĐEVINE. BETONIRANJE SE VRŠI BETONOM KVALITETE NE MANJE OD C 12/15, KLASE B.II U DEBLJINI MIN 5 CM. U CIJENU STAVKE URAČUNAT JE SAV POTREBAN MATERIJAL, NJEGOVA DOBAVA I UGRADNJA, TE OPLATA.
A24: A | B24: BETONA C 12/15 | C24: M3 | D24: 1.2 | E24: ='[1]A_III_ BETONSKI I AB'!E24 -> 200 | F24: =SUM(D24*E24) -> 240
A25: B | B25: DAŠČANE NEBLANJANE OPLATE | C25: M2 | D25: 1.5 | E25: ='[1]A_III_ BETONSKI I AB'!E25 -> 50 | F25: =SUM(D25*E25) -> 75
A27: 5 | B27: DOBAVA MATERIJALA I BETONIRANJE ARMIRANO-BETONSKIH TRAKASTIH TEMELJA ZGRADE, BETONOM C25/35, XC2 U DAŠČANOJ OPLATI PREMA PROJEKTU, STATIČKOM PRORAČUNU I ARMATURNIM NACRTIMA. U STAVKU URAČUNAT SAV POTREBAN RAD I MATERIJAL.
A28: A | B28: BETONA C25/30 | C28: M3 | D28: 30 | E28: ='[1]A_III_ BETONSKI I AB'!E28 -> 200 | F28: =SUM(D28*E28) -> 6000
A29: B | B29: OPLATE | C29: M2 | D29: 85 | E29: ='[1]A_III_ BETONSKI I AB'!E29 -> 40 | F29: =SUM(D29*E29) -> 3400
A31: 6 | B31: DOBAVA MATERIJALA I BETONIRANJE ARMIRANO-BETONSKE TEMELJNE PLOČE VANJSKOG PODESTA ZA TERMOTEHNIKU SA SJEVERNE STRANE GRAĐEVINE, DEBLJINE 30 CM, BETONOM C325/30, XC2 U DAŠČANOJ OPLATI PREMA PROJEKTU, STATIČKOM PRORAČUNU I ARMATURNIM NACRTIMA. U STAVKU URAČUNAT SAV POTREBAN RAD I MATERIJAL.
A32: A | B32: BETONA C25/30 | C32: M3 | D32: 7 | E32: ='[1]A_III_ BETONSKI I AB'!E32 -> 200 | F32: =SUM(D32*E32) -> 1400
A33: B | B33: OPLATE | C33: M2 | D33: 8.5 | E33: ='[1]A_III_ BETONSKI I AB'!E33 -> 50 | F33: =SUM(D33*E33) -> 425
A35: 7 | B35: DOBAVA MATERIJALA I BETONIRANJE ARMIRANO-BETONSKIH POTPORNIH ZIDOVA VANJSKOG PODESTA ZA TERMOTEHNIKU SA SJEVERNE STRANE GRAĐEVINE, DEBLJINE 25 CM, BETONOM C25/30, XC2 U DAŠČANOJ OPLATI PREMA PROJEKTU, STATIČKOM PRORAČUNU I ARMATURNIM NACRTIMA. U STAVKU URAČUNAT SAV POTREBAN RAD I MATERIJAL.
A36: A | B36: BETONA C25/30 | C36: M3 | D36: 8 | E36: ='[1]A_III_ BETONSKI I AB'!E36 -> 200 | F36: =SUM(D36*E36) -> 1600
A37: B | B37: OPLATE | C37: M2 | D37: 65 | E37: ='[1]A_III_ BETONSKI I AB'!E37 -> 50 | F37: =SUM(D37*E37) -> 3250
A39: 8 | B39: DOBAVA MATERIJALA I BETONIRANJE ARMIRANO-BETONSKE PODNE PLOČE PRIZEMLJA DEBLJINE 15 CM, BETONOM C25/30, XC2 PREMA PROJEKTU, STATIČKOM PRORAČUNU I ARMATURNIM NACRTIMA. U STAVKU URAČUNAT SAV POTREBAN RAD I MATERIJAL.
A40: A | B40: BETONA C25/30 | C40: M3 | D40: 25 | E40: ='[1]A_III_ BETONSKI I AB'!E40 -> 200 | F40: =SUM(D40*E40) -> 5000
A41: B | B41: RUBNE OPLATE | C41: M2 | D41: 10 | E41: ='[1]A_III_ BETONSKI I AB'!E41 -> 50 | F41: =SUM(D41*E41) -> 500
A43: 9 | B43: DOBAVA MATERIJALA I BETONIRANJE ARMIRANO-BETONSKOG STUBIŠTA PRIZEMLJA, BETONOM C25/30, XC1 U DAŠČANOJ OPLATI PREMA PROJEKTU, STATIČKOM PRORAČUNU I ARMATURNIM NACRTIMA. U STAVKU URAČUNAT SAV POTREBAN RAD I MATERIJAL.
A44: A | B44: BETONA C25/30 | C44: M3 | D44: 2.2 | E44: ='[1]A_III_ BETONSKI I AB'!E44 -> 500 | F44: =SUM(D44*E44) -> 1100
A45: B | B45: OPLATE | C45: M2 | D45: 15 | E45: ='[1]A_III_ BETONSKI I AB'!E45 -> 100 | F45: =SUM(D45*E45) -> 1500
A47: 10 | B47: DOBAVA MATERIJALA I BETONIRANJE ARMIRANO-BETONSKIH ZIDOVA I STUPOVA PRIZEMLJA, BETONOM C25/30, XC1 U DAŠČANOJ OPLATI PREMA PROJEKTU, STATIČKOM PRORAČUNU I ARMATURNIM NACRTIMA. U STAVKU URAČUNAT SAV POTREBAN RAD I MATERIJAL.
A48: A | B48: BETONA C25/30 | C48: M3 | D48: 18.5 | E48: ='[1]A_III_ BETONSKI I AB'!E48 -> 250 | F48: =SUM(D48*E48) -> 4625
A49: B | B49: OPLATE | C49: M2 | D49: 200 | E49: ='[1]A_III_ BETONSKI I AB'!E49 -> 60 | F49: =SUM(D49*E49) -> 12000
A51: 11 | B51: DOBAVA MATERIJALA I BETONIRANJE ARMIRANO-BETONSKIH GREDA I HORIZONTALNIH SERKLAŽA PRIZEMLJA, BETONOM C25/30, XC1 U DAŠČANOJ OPLATI PREMA PROJEKTU, STATIČKOM PRORAČUNU I ARMATURNIM NACRTIMA. U STAVKU URAČUNAT SAV POTREBAN RAD I MATERIJAL.
A52: A | B52: BETONA C25/30 | C52: M3 | D52: 1.1 | E52: ='[1]A_III_ BETONSKI I AB'!E52 -> 500 | F52: =SUM(D52*E52) -> 550
A53: B | B53: OPLATE | C53: M2 | D53: 10 | E53: ='[1]A_III_ BETONSKI I AB'!E53 -> 100 | F53: =SUM(D53*E53) -> 1000
A55: 12 | B55: DOBAVA MATERIJALA I JEDNOSTRANO TORKRETIRANJE POSTOJEĆEG ULIČNOG ZIDA PRIZEMLJA ARMIRANIM BETONOM DEBLJINE 5 CM, Postojeći zid se s unutarnje strane torkretira sa slojem armiranog betona od 5 cm (C25/30). Sloj torkreta se povezuje s postojećim zidanim zidom kemijski (injekcijskim mortom), armaturnim šipkama ubušenim na rasteru 30x30 cm i armira s mrežama. PREMA PROJEKTU, STATIČKOM PRORAČUNU I ARMATURNIM NACRTIMA. U STAVKU URAČUNAT SAV POTREBAN RAD I MATERIJAL. VISINA DO 3 M.
A56: A | B56: BETONA C25/30 | C56: M2 | D56: 45 | E56: ='[1]A_III_ BETONSKI I AB'!E56 -> 200 | F56: =SUM(D56*E56) -> 9000
...

Sheet A_IV_ ZIDARSKI RADOVI
A1: A.IV. | B1: ZIDARSKI RADOVI
A3: Redni broj | B3: Opis rada | C3: Jedinična mjera | D3: Količina | E3: Cijena u eurima | G3: JV
E5: Jedinična | F5: Ukupna
A7: 1 | B7: DOBAVA MATERIJALA I ZIDANJE NOSIVIH ZIDOVA VANJSKOG PLAŠTA ZGRADE OD BLOK OPEKE S POJAČANOM TOPLINSKOM ZAŠTITOM. ZID U DEBLJINI 25 CM. ZIDANJE SE VRŠI LJEPILOM, NA NAČIN USKLAĐEN S SPECIFIKACIJOM PROIZVOĐAČA.
A8: A | B8: PRIZEMLJE | C8: M3 | D8: 10 | E8: ='[1]A_IV_ ZIDARSKI RADOVI'!E8 -> 350 | F8: =SUM(D8*E8) -> 3500
A9: B | B9: 1. KAT | C9: M3 | D9: 15.5 | E9: ='[1]A_IV_ ZIDARSKI RADOVI'!E9 -> 350 | F9: =SUM(D9*E9) -> 5425
A10: C | B10: POTKROVLJE | C10: M3 | D10: 6 | E10: ='[1]A_IV_ ZIDARSKI RADOVI'!E10 -> 350 | F10: =SUM(D10*E10) -> 2100
A12: 2 | B12: DOBAVA MATERIJALA I ZIDANJE UNUTARNJIH NOSIVIH ZIDOVA ZGRADE OD BLOK OPEKE. ZID U DEBLJINI 20 I 25 CM. ZIDANJE SE VRŠI LJEPILOM, NA NAČIN USKLAĐEN S SPECIFIKACIJOM PROIZVOĐAČA.
B13: D=20 CM | C13: M3 | D13: 1.2 | E13: ='[1]A_IV_ ZIDARSKI RADOVI'!E13 -> 350 | F13: =SUM(D13*E13) -> 420
B14: D=25 CM | C14: M3 | D14: 2 | E14: ='[1]A_IV_ ZIDARSKI RADOVI'!E14 -> 350 | F14: =SUM(D14*E14) -> 700
B16: ZIDARSKI UKUPNO | F16: =SUM(F8:F14) -> 12145

Sheet A_V_ IZOLATERSKI RADOVI
A1: A.V. | B1: IZOLATERSKI RADOVI
A3: Redni broj | B3: Opis rada | C3: Jedinična mjera | D3: Količina | E3: Cijena u eurima | G3: JV
E5: Jedinična | F5: Ukupna
A7: 1 | B7: DOBAVA MATERIJALA I IZRADA HORIZONTALNE HIDROIZOLACIJE PODNE PLOČE PRIZEMLJA POLAGANJEM BITUMENSKIH TRAKA KVALITETE GV-4 × 2 sloja + HLADNI BITUMENSKI PREMAZ. DOBAVA I UGRADNJA PREMA TEHNOLOGIJI I UPUTI PROIZVOĐAČA S IZVEDBOM SVIH DETALJA SUKLADNO ZADANOJ TEHNOLOGIJI DOBAVLJAČA I PRAVILIMA STRUKE.
B8: IZOLIRANA POVRŠINA | C8: M2 | D8: 150 | E8: ='[1]A_V_ IZOLATERSKI RADOVI'!E8 -> 30 | F8: =SUM(D8*E8) -> 4500
A10: 2 | B10: DOBAVA MATERIJALA I IZRADA VERTIKALNE HIDROIZOLACIJE POLAGANJEM BITUMENSKE TRAKE KVALITETE GV 4 + HLADNI BITUMENSKI PREMAZ + POTREBNA ZIDARSKA OBRADA ZAGLAĐIVANJEM PLOHE AB ZIDA + ČEPASTA MEMBRANA OD POLIETILENA VISOKE GUSTOĆE (HDPE), OTPORNA NA UDARCE + ZAŠTITNI SLOJ GEOTEKSTILA 300G/M2, ZIDOVI U TLU I PO PODNOŽNOM OBODU GRAĐEVINE - KONTAKT S TLOM. UKLJUČIVO SAV RAD I MATERIJAL DO POTUPNE GOTOVOSTI.
A11: A | B11: BITUMENSKA TRAKE KVALITETE GV 4 + HLADNI BITUMENSKI PREMAZ | C11: M2 | D11: 60 | E11: ='[1]A_V_ IZOLATERSKI RADOVI'!E11 -> 40 | F11: =D11*E11 -> 2400
A12: B | B12: ČEPASTA MEMBRANA OD POLIETILENA VISOKE GUSTOĆE (HDPE), OTPORNA NA UDARCE + ZAŠTITNI SLOJ GEOTEKSTILA 300G/M2 | C12: M2 | D12: 36 | E12: ='[1]A_V_ IZOLATERSKI RADOVI'!E12 -> 10 | F12: =D12*E12 -> 360
A14: 3 | B14: DOBAVA MATERIJALA, KROJENJE XPS-a I IZRADA TERMOIZOLACIJSKOG SLOJA ZIDOVA U TLU POLAGANJEM XPS-a I NJEGOVIM LJEPLJENJEM ADEKVATNIM LJEPILOM ZA PODLOGU:
B15: XPS 300 kPa tlačne čvrstoće
B16: XPS SLOJ DEBLJINE 20 CM | C16: M2 | D16: 25 | E16: ='[1]A_V_ IZOLATERSKI RADOVI'!E16 -> 50 | F16: =D16*E16 -> 1250
B17: XPS SLOJ DEBLJINE 15 CM | C17: M2 | D17: 10 | E17: ='[1]A_V_ IZOLATERSKI RADOVI'!E17 -> 40 | F17: =D17*E17 -> 400
A19: 4 | B19: DOBAVA MATERIJALA I IZRADA TERMOIZOLACIJSKOG I RAZDJELNIH SLOJEVA PODNE KONSTRUKCIJE (PODA NA TLU) POLAGANJEM XPS-a I RAZDJELNIH SLOJEVA OD GEOTEKSTILA I GRAĐEVINSKE PVC FOLIJE. RAZDJELNE SLOJEVE PREKLAPATI 20 CM.
B20: XPS 300 kPa tlačne čvrstoće kod 10% naprezanja
A21: A | B21: XPS SLOJ DEBLJINE 10+5 CM IZMJENIČNO SLOŽENIH PLOČA | C21: M2 | D21: 130 | E21: ='[1]A_V_ IZOLATERSKI RADOVI'!E21 -> 40 | F21: =SUM(D21*E21) -> 5200
A22: B | B22: GEOTEKSTIL 300 G/M2 | C22: M2 | D22: 150 | E22: ='[1]A_V_ IZOLATERSKI RADOVI'!E22 -> 5 | F22: =SUM(D22*E22) -> 750
A23: C | B23: PVC GRAĐEVINSKA FOLIJA | C23: M2 | D23: 150 | E23: ='[1]A_V_ IZOLATERSKI RADOVI'!E23 -> 2 | F23: =SUM(D23*E23) -> 300
A24: D | B24: EPS-T - d= 2 CM | C24: M2 | D24: 130 | E24: ='[1]A_V_ IZOLATERSKI RADOVI'!E24 -> 15 | F24: =D24*E24 -> 1950
B26: IZOLATERSKI RADOVI UKUPNO | E26: EUR | F26: =SUM(F8:F24) -> 17110

Sheet A_VI_METALNE KONSTRUKCIJE
A1: A.VI. | B1: METALNE KONSTRUKCIJE
A3: Redni broj | B3: Opis rada | C3: Jedinična mjera | D3: Količina | E3: Cijena u eurima | G3: JV
E5: Jedinična | F5: Ukupna
A7: 1 | B7: Nabava, izrada, transport, istovar, odlaganje i montaža PRIVREMENE ČELIČNE KONSTRUKCIJE ZA PRIDRŽAVANJE POSTOJEĆEG ULIČNOG ZIDA (TIJEKOM UKLANJANJA OSTATKA ZGRADE), od čelika S235JR (ili jednakovrijedno sa slijedećim karakteristikama: Vlačna čvrstoća: 360-510MPa, Granica razvlačenja: 235 MPa, Istezanje: 26%, Brinellova tvrdoća: 104-154HB, Modul elastičnosti: 210 GPa)
C8: kg | D8: 7500 | E8: ='[1]A_VI_METALNE KONSTRUKCIJE'!E8 -> 3.8 | F8: =SUM(D8*E8) -> 28500
A10: 2 | B10: Izrada radioničkih nacrta čelične konstrukcije za pridržanje zida uličnog pročelja. Nacrte je potrebno pregledati i ovjeriti od strane projektanta glavnog projekta.
C11: kg | D11: 7500 | E11: ='[1]A_VI_METALNE KONSTRUKCIJE'!E11 -> 0.5 | F11: =SUM(D11*E11) -> 3750
A13: 3 | B13: Nabava, izrada, transport, istovar, odlaganje i montaža ČELIČNE KONSTRUKCIJE OGRADE UNUTARNJEG STUBIŠTA (stavka 1), od čelika S235JR(ili jednakovrijedno sa slijedećim karakteristikama: Vlačna čvrstoća: 360-510MPa, Granica razvlačenja: 235 MPa, Istezanje: 26%, Brinellova tvrdoća: 104-154HB, Modul elastičnosti: 210 GPa). Izrada prema radioničkoj dokumentaciji, prethodno čišćenje mlazom abraziva do propisanog sjaja, te zaštićena antikorozivnim sustavom: bojanjem (kategorija korozivnosti C1). Čelična konstrukcija sastavljena je od standardnih profila i čeličnih limova. U cijeni kompletan materijal i vijci za montažu.
B14: Svi radionički spojevi konstrukcije izvode se zavarivanjem, a montažni spojevi na gradilištu vijcima k.v. 8.8.; sve prema radioničkoj dokumentaciji.
A15: A | B15: stupovi od kvadratnih profila 50×50 mm visine 220 cm | C15: kg | D15: 70 | E15: ='[1]A_VI_METALNE KONSTRUKCIJE'!E15 -> 10 | F15: =SUM(D15*E15) -> 700
A16: B | B16: horizontalne ispune - ploča (flah) 40x5 mm | C16: kg | D16: 170 | E16: ='[1]A_VI_METALNE KONSTRUKCIJE'!E16 -> 10 | F16: =SUM(D16*E16) -> 1700
A18: 4 | B18: Izrada radioničkih nacrta za stavku 1. Nacrte je potrebno pregledati i ovjeriti od strane projektanta glavnog projekta.
C19: kom | D19: 1 | E19: ='[1]A_VI_METALNE KONSTRUKCIJE'!E19 -> 200 | F19: =SUM(D19*E19) -> 200
A21: 5 | B21: Nabava, izrada, transport, istovar, odlaganje i montaža POCINČANE ČELIČNE KONSTRUKCIJE VANJSKOG OGRAĐENOG PROSTORA ZA UREĐAJE TERMOTEHNIKE (stavka 2), od čelika S235JR(ili jednakovrijedno sa slijedećim karakteristikama: Vlačna čvrstoća: 360-510MPa, Granica razvlačenja: 235 MPa, Istezanje: 26%, Brinellova tvrdoća: 104-154HB, Modul elastičnosti: 210 GPa). Izrada prema radioničkoj dokumentaciji. Čelična konstrukcija sastavljena je od standardnih profila - kvadratnih cijevi 60×60 mm i 60×40 mm, čeličnih limova i pocinčane čelične žičane mreže 25×25 mm. U većem polju dvokrilna vrata dimenzija 130×220 cm koja se sastoje od okvira od pravokutnih profila 40×60 mm i ispune od pocinčane čelične zavarene žičane mreže oka 25×25 mm, uključivo sav potreban okov (petlje odgovarajuće nosivosti, štitnici, kvaka, brava) U cijeni kompletan materijal i vijci za montažu.
B22: Svi radionički spojevi konstrukcije izvode se zavarivanjem, a montažni spojevi na gradilištu vijcima k.v. 8.8.; sve prema radioničkoj dokumentaciji.
A23: A | B23: stupovi od kvadratnih cijevi 60×60×3 mm visine 220 cm | C23: kg | D23: 60 | E23: ='[1]A_VI_METALNE KONSTRUKCIJE'!E23 -> 10 | F23: =SUM(D23*E23) -> 600
A24: B | B24: okviri od pravokutnih cijevi 60×40×3 mm visine 220 cm | C24: kg | D24: 180 | E24: ='[1]A_VI_METALNE KONSTRUKCIJE'!E24 -> 10 | F24: =SUM(D24*E24) -> 1800
A25: C | B25: pocinčana čelična mehanička sidra - M16/50 | C25: kom | D25: 20 | E25: ='[1]A_VI_METALNE KONSTRUKCIJE'!E25 -> 15 | F25: =SUM(D25*E25) -> 300
A26: D | B26: ispuna od pocinčane čelične zavarene žičane mreže oka 25×25 mm | C26: m2 | D26: 15 | E26: ='[1]A_VI_METALNE KONSTRUKCIJE'!E26 -> 100 | F26: =SUM(D26*E26) -> 1500
A27: E | B27: okov | C27: komplet | D27: 1 | E27: ='[1]A_VI_METALNE KONSTRUKCIJE'!E27 -> 200 | F27: =SUM(D27*E27) -> 200
A29: 6 | B29: Izrada radioničkih nacrta za stavku 2. Nacrte je potrebno pregledati i ovjeriti od strane projektanta glavnog projekta.
C30: kom | D30: 1 | E30: ='[1]A_VI_METALNE KONSTRUKCIJE'!E30 -> 300 | F30: =SUM(D30*E30) -> 300
B32: METALNE KONSTRUKCIJE UKUPNO | E32: EUR | F32: =SUM(F2:F30) -> 39550

Sheet A_VII_TESARSKI RADOVI
A1: A.VII. | B1: TESARSKI RADOVI
A3: Redni broj | B3: Opis rada | C3: Jedinična mjera | D3: Količina | E3: Cijena u eurima | G3: JV
E5: Jedinična | F5: Ukupna
A7: 1 | B7: DOBAVA MATERIJALA I IZRADA DRVENOG DIJELA KONSTRUKCIJE KOSOG KROVA PREMA PRETHODNO IZRAĐENOJ RADIONIČKOJ DOKUMENTACIJI KOJA JE SASTAVNI DIO STAVKE. RADIONIČKU DOKUMENTACIJU POTREBNO JE OVJERITI OD STRANE PROJEKTANTA. KONSTRUKCIJA SE SASTOJI OD ROGOVA 12/14 CM, PRIČVRŠĆENIH METALNIM SPOJNIM SREDSTVIMA NA DRVENU POTKONSTRUKCIJU (NAZIDNICE 16/14 ILI 18/20 CM), UKRUTNIH GREDA 14/18 I 8/16 CM, STUPA 12/14 CM, GREDA UVALA 18/16 CM, OBLOGE KROVNE PLOHE OD VLAGOOTPORNIH OSB PLOČA, S UTOROM I PEROM ZA VANJSKU PRIMJENU, DEBLJNE 18 MM I KONTRALETVE 8×5 CM. LETVE ZA POSTAVU POKROVNIH ELEMENATA OD GLINENOG CRIJEPA OBRAĐENE U POKRIVAČKIM RADOVIMA. DRVENA GRAĐA OD CRNOGORICE II KLASE C24. U STAVCI JE URAČUNAT SAV POTREBAN MATERIJAL, DOBAVA KROJENJE I UGRADNJA, TE POMOĆNA I SPOJNA SREDSTVA. KONSTRUKCIJA SE OSLANJA NA PRIMARNU AB KONSTRUKCIJU. PRIJE UGRADNJE DRVENU KONSTRUKCIJU PREMAZATI INSEKTICIDNIM I FUNGICIDNIM SREDSTVOM. NA OSLONCIMA DRVETA NA ČELIČNE DIJELOVE IZVESTI RAZDJELNI SLOJ OD KROVNE LJEPENKE. KONSTRUKCIJA SE SASTOJI OD:
A8: A | B8: ROGOVA, MIJENA I STUPOVA 12/14 | C8: M3 | D8: 5.2 | E8: 1000 | F8: =SUM(D8*E8) -> 5200
A9: B | B9: NAZIDNICA 16/14 | C9: M3 | D9: 0.4 | E9: 1000 | F9: =SUM(D9*E9) -> 400
A10: C | B10: NAZIDNICA 18/20 | C10: M3 | D10: 0.8 | E10: 1000 | F10: =SUM(D10*E10) -> 800
A11: D | B11: GREDA 14/18 | C11: M3 | D11: 0.2 | E11: 1000 | F11: =SUM(D11*E11) -> 200
A12: E | B12: GREDA 8/16 | C12: M3 | D12: 1.2 | E12: 1000 | F12: =SUM(D12*E12) -> 1200
A13: F | B13: GREDA UVALA 18/16 | C13: M3 | D13: 0.4 | E13: 1000 | F13: =SUM(D13*E13) -> 400
A14: G | B14: OSB PLOČA 1.8 CM | C14: M2 | D14: 225 | E14: 30 | F14: =SUM(D14*E14) -> 6750
A15: H | B15: KROVNE LJEPENKE | C15: M2 | D15: 225 | E15: 10 | F15: =SUM(D15*E15) -> 2250
A16: I | B16: KONTRALETVA 8/5 | C16: M3 | D16: 1.2 | E16: 1500 | F16: =SUM(D16*E16) -> 1800
A17: J | B17: ČELIČNE PAPUČE | C17: KG | D17: 200 | E17: 10 | F17: =SUM(D17*E17) -> 2000
A18: K | B18: POCINČANA ČELIČNA MEHANIČKA SIDRA | C18: KG | D18: 80 | E18: 20 | F18: =SUM(D18*E18) -> 1600
A19: L | B19: IZRADA RADIONIČKIH NACRTA | C19: M2 | D19: 225 | E19: 5 | F19: =SUM(D19*E19) -> 1125
B21: TESARSKI RADOVI UKUPNO | F21: =SUM(F8:F19) -> 23725

Sheet B_I_LIMARSKI RADOVI
A1: B.I. | B1: LIMARSKI RADOVI
A3: Redni broj | B3: Opis rada | C3: Jedinična mjera | D3: Količina | E3: Cijena u eurima | G3: JV
E5: Jedinična | F5: Ukupna
B7: NAPOMENA:
B8: OPĆI UVJETI SU SASTAVNI DIO SVAKE POJEDINE STAVKE. Sve što je navedeno u njima, a nije u pojedinačnom opisu stavke smatra se uključenim u jediničnu cijenu.
B9: U jediničnim cijenama uračunati su svi radovi predmetne stavke, s dobavom potrebnog materijala, s istovarom i skladištenjem na gradilištu, sav horizontalni i vertikalni transport do radnog mjesta, kao i sva potrebna radna snaga i režijski troškovi, te svi potrebni radovi, predradnje i materijal prema uputama proizvođača. Predviđeni pokrov je aluminijski falcani lim iz legure AlMn1Mg0,5, mehanička svojstva H42, kvaliteta boje P.10 mat, za sve stavke. Boja za pojedine elemente prema izboru projektanta. U svim stavkama uključen je sav vezni materijal, kuke, ljepila i slično.
A11: 1 | B11: Dobava materijala, krojenje, savijanje, izrada, ugradnja i pričvršćivanje horizontalnih polukružnih ležećih oluka. Oluci se izvode od pocinčanog čeličnog lima d=1 mm. Svi spojevi ljepljeni PU elastičnim visoko viskoznim masama za konstruktivna lijepljenja. Na dijelu građevine oluci se montiraju i pričvršćuju preko prihvatnih elemenata od plosnog pocinčanog željeza 3/10 mm duljine 40 cm na svakih 50 cm, koji su uključeni u cijenu stavke. Završni oblik i ton u dogovoru sa nadležnim konzervatorima. U cijeni stavke je uključen sav rad i materijal, spojna i pomoćna sredstva, itd. sve do potpune gotovosti oluka. Obračun po m'.
C12: m' | D12: 35 | E12: ='[1]B_I_LIMARSKI RADOVI'!E12 -> 60 | F12: =D12*E12 -> 2100
A14: 2 | B14: Dobava i ugradnja okrugle vertikalne odvodne cijevi Ø 100mm za ležeći žljeb iz pocinčanog čeličnog lima. Boja i kvaliteta materijala kao osnovna pozicija uključivo sve potrebne obujmice, držače, trnove, revizijske otvore i koljena. Sve u kompletu prema uputama proizvođača. Obračun po m'.
C15: m' | D15: 28 | E15: ='[1]B_I_LIMARSKI RADOVI'!E15 -> 60 | F15: =D15*E15 -> 1680
A17: 3 | B17: Dobava i ugradnja kape dimnjaka i nosači iz aluminija dim. 800x800mm. Broj nosača ovisi o veličine dimnjačke kape. Uključivo 1 nehrđajući zavojni vijak M8 x 50mm sa plastičnom tiplom, 2 nehrđajuća vijka M8x30mm uz pripadajuće nehrđajuće matice. U boji i obradi kao osnovna pozicija. U stavku uključiti kompletan rad i materijal. Sve izvesti prema uputama i detaljima proizvođača.
C18: kom | D18: 1 | E18: ='[1]B_I_LIMARSKI RADOVI'!E18 -> 150 | F18: =D18*E18 -> 150
A20: 4 | B20: Dobava i ugradnja opšava otvora dimnjaka i ostalih krovnih prodora oko krovnih otvora (uključiti kitne lajsne) pocinčanim čeličnim limom r.š. 50 cm boje i kvalitete kao i osnovna pozicija. Lim uzdignut minimalno 15 cm. Uklljučiti sav spojni i brtveni materijal.
C21: m' | D21: 3 | E21: ='[1]B_I_LIMARSKI RADOVI'!E21 -> 150 | F21: =D21*E21 -> 450
A23: 5 | B23: Dobava materijala, krojenje, savijanje, izrada, ugradnja i pričvršćivanje spojeva krovnih ploha (krovnih uvala), spojeva krovnih ploha sa zidom i ostalih detalja na krovu građevine, od pocinčanog čeličnog lima d= 1mm. Svi spojevi ljepljeni PU elastičnim visoko viskoznim masama za konstruktivna lijepljenja. Boja i kvaliteta materijala kao osnovna pozicija uključivo sva potrebna spojna i pomoćna sredstva, sav rad i materijal. Sve u kompletu prema uputama proizvođača.
B24: razvijena širina 100 cm | C24: m' | D24: 8 | E24: ='[1]B_I_LIMARSKI RADOVI'!E24 -> 80 | F24: =D24*E24 -> 640
B25: razvijena širina 66 cm | C25: m' | D25: 6.5 | E25: ='[1]B_I_LIMARSKI RADOVI'!E25 -> 60 | F25: =D25*E25 -> 390
A27: 6 | B27: Dobava i ugradnja potkonstrukcije za fotonaponske panele sastavljen od: - aluminijskih držača za postavu na potkonstrukciju s varijabilnim držačem podesivim u svim smjerovima, uklj. spojne vijke. Pričvršćenje obostrano vijcima radi lakše montaže nosivog profila. - nosivih profila od aluminija (profilirane šine) za velika statička opterećenja. - spojnih aluminijskih elemenata za brzo i sigurno spajanje nosivih profila, sa brušenim rupama za montažu stezaljke modula. - ostali spojni elementi (klip za električni kabel, srednje i završne spojnice za pričvršćenje modula, spojnice za nosivi profil, set specijalnog ljepila).
B28: Točnu količinu i raspored elemenata potkonstrukcije za solarne sisteme daje odabrani proizvođač krovnog sustava nakon odabira konkretnog modela panela. Konstrukciju izvoditi stručno i isključivo prema uputama proizvođača. Stavka uključuje postavu i montažu svih elemenata do potpune funkcionalnosti zaprojektiranu sunčanu elektranu, paneli postavljeni u nagibu krova.
C29: kom | D29: 8 | E29: ='[1]B_I_LIMARSKI RADOVI'!E29 -> 500 | F29: =D29*E29 -> 4000
B31: LIMARSKI UKUPNO | E31: EUR | F31: =SUM(F1:F29) -> 9410

Sheet B_II_POKRIVAČKI RADOVI
A1: B.II. | B1: POKRIVAČKI RADOVI
A3: Redni broj | B3: Opis rada | C3: Jedinična mjera | D3: Količina | E3: Cijena u EUR | G3: JV
E5: Jedinična | F5: Ukupna
A7: 1 | B7: DOBAVA MATERIJALA I IZRADA TERMOIZOLACIJSKIH, RAZDJELNIH I ZAVRŠNIH SLOJEVA ZA POKRIVANJE DVOSTREŠNOG KOSOG KROVA OZNAKE K.1 NAD GRAĐEVINOM. UKLJUČITI POSTAVU LETVE I ZAVRŠNE KROVNE OBLOGE - GLINENOG CRIJEPA PO ODABIRU U DOGOVORU SA NADLEŽNIM KONZERVATOROM. RADOVE IZVODITI SUKLADNO UPUTAMA PROIZVOĐAČA ODABRANOG POKROVA. STAVKA UKLJUČUJE SAV POTREBAN RAD MATERIJAL I SITAN PRIBOR I PRIČVRSNA SREDSTVA, SNJEGOBRANE, ELEMENTE ZA ODZRAKU, SLJEMENSKE ELEMENTE - SVE DO POTPUNE GOTOVOSTI KROVNOG SUSTAVA. KROVNA KONSTRUKCIJA SE SASTOJI OD SLIJEDEĆIH SLOJEVA:
A8: A | B8: POTKROVNA FOLIJA POLOŽENA NA NOSIVU DAŠČANU OBLOGU | C8: M2 | D8: 250 | E8: 10 | F8: =SUM(D8*E8) -> 2500
A9: B | B9: MINERALNA VUNA 14 + 12 CM | C9: M2 | D9: 225 | E9: 60 | F9: =SUM(D9*E9) -> 13500
A10: C | B10: BITUMENSKA TRAKA S ULOŠKOM KROVNOG KARTONA - SEKUNDARNI KROV | C10: M2 | D10: 225 | E10: 20 | F10: =SUM(D10*E10) -> 4500
A11: D | B11: LETVA 3×5 CM | C11: M3 | D11: 3 | E11: 1500 | F11: =SUM(D11*E11) -> 4500
A12: E | B12: GLINENI CRIJEP | C12: M2 | D12: 225 | E12: 60 | F12: =SUM(D12*E12) -> 13500
B14: POKRIVAČKI UKUPNO | E14: EUR | F14: =SUM(F7:F12) -> 38500

Sheet B_III_STOLARSKI RADOVI
A1: B.III. | B1: STOLARSKI RADOVI
A3: Redni broj | B3: Opis rada | C3: Jedinična mjera | D3: Količina | E3: Cijena u eurima | G3: JV
E5: Jedinična | F5: Ukupna
B7: NAPOMENE: SVE MJERE POTREBNO JE PROVJERITI U NARAVI!
B8: OPĆI UVJETI UZ STOLARSKE RADOVE
B10: Dobavljač otvora na fasadi ima slijedeće obveze: (fasada= prozori, vrata, prozorske/fasadne/podizno-klizne stijene)
B11: 1 Projektiranje, izrada i ugradba svih dijelova koji čine integralnu, sigurnu i vodonepropusnu fasadu prema nacrtima i ovom opisu.
B12: 2 Izvoditelj se obavezuje izraditi i ugraditi otvore do potpune gotovosti, u već provjerenim i certifiranim sustavima, te se od njega očekuju visoka kvaliteta izvedbe. Sva tehnička rješenja koja izvoditelj predlaže i primjenjuje moraju biti usklađena s HRN-ma ili jednakovrijedno i propisima te usvojenim EN ili jednakovrijedno (kada je zakonom utvrđena njihova obvezna primjena).
B13: 3 Koordinirati svoje aktivnosti sa sa ostalim sudionicima u projektu a prema terminskom planu.
B14: 4 Ugraditi stolariju u predviđenom roku i prema pravilima struke.
B15: Izvoditelj ugovara izradu otvora fasade do kompletne gotovosti. Rasteri i tipovi otvora fasade su definirani nacrtima, a količine ugovornog troškovnika se odnose na dimenzije rastera iz arhitektonskih nacrta. Ukupna cijena uključuje:
B16: - Dobavu, transport, skladištenje te montažu svih elemenata fasade do konačne ugradnje;
B17: - Sve predradnje prije montaže (izmjera, iscrtavanje potrebnih osi, visinske kote, te određivanje geometrije fasade);
B18: - Potrebne podkonstrukcije (svi sidreni i pričvrsni elementi)
B19: - Ostakljenje te isporuku rezervnih stakala
... B47: VANJSKA STOLARIJA
A49: 1 | B49: RESTAURACIJA POSTOJEĆIH GLAVNIH ULAZNIH VRATA I NJIHOVA PONOVNA UGRADNJA U DOGOVORU SA KONZERVATORSKIM NADZOROM. OPISANO U KONZERVATORSKO RESTAURATORSKIM RADOVIMA.
B50: ST.1
A52: 2 | B52: IZRADA, DOBAVA I UGRADNJA DVOKRILNOG ZAOKRETNOG PROZORA ULIČNOG PROČELJA (PRIZEMLJE), PROIZVODNE MJERE 88/148 CM. DOPROZORNIK I OKVIR KRILA OD HRASTOVINE I KLASE. OSTAKLJENJE IZO STAKLOM 6/16/4 S LOW-E PREMAZOM I ISPUNJENO PLEMENITIM PLINOM. ZAVRŠNA OBRADA DRVETA, LAZURNI PREMAZ + PRIPREMNE RADNJE U TONU PO IZBORU PROJEKTANTA OKOV: 2 PETLJE ODGOVARAJUĆE NOSIVOSTI. POLUOLIVA, ŠTITNICI, PROZOR SE IZRAĐUJE PREMA SAČUVANOM UZORKU POSTOJEĆEG ULIČNOG PROZORA. SVE MJERE POTREBNO JE PROVJERITI U NARAVI! RADIONIČKE NACRTE PRIJE IZVEDBE TREBA PREGLEDATI I OVJERITI PROJEKTANT I NADLEŽNI KONZERVATOR!
B53: ST.2 | C53: KOM | D53: 2 | E53: ='[1]B_III_STOLARSKI RADOVI'!E53 -> 600 | F53: =SUM(D53*E53) -> 1200
B54: ST.2 - UKLJUČIVO POTREBAN POSEBANI OKOV ZA AUTOMATSKO OTVARANJE (ZA ODIMLJAVANJE U SLUČAJU POŽARA, PREKO SUSTAVA VATRODOJAVE). | C54: KOM | D54: 2 | E54: ='[1]B_III_STOLARSKI RADOVI'!E54 -> 1800 | F54: =SUM(D54*E54) -> 3600
A56: 3 | B56: IZRADA, DOBAVA I UGRADNJA DVOKRILNOG ZAOKRETNOG PROZORA ULIČNOG PROČELJA (1. KAT), PROIZVODNE MJERE 140/143 CM. DOPROZORNIK I OKVIR KRILA OD HRASTOVINE I KLASE. OSTAKLJENJE IZO STAKLOM 6/16/4 S LOW-E PREMAZOM I ISPUNJENO PLEMENITIM PLINOM. ZAVRŠNA OBRADA DRVETA, LAZURNI PREMAZ + PRIPREMNE RADNJE U TONU PO IZBORU PROJEKTANTA OKOV: 2 PETLJE ODGOVARAJUĆE NOSIVOSTI. POLUOLIVA, ŠTITNICI, PROZOR SE IZRAĐUJE PREMA SAČUVANOM UZORKU POSTOJEĆEG ULIČNOG PROZORA. SVE MJERE POTREBNO JE PROVJERITI U NARAVI! RADIONIČKE NACRTE PRIJE IZVEDBE TREBA PREGLEDATI I OVJERITI PROJEKTANT I NADLEŽNI KONZERVATOR!
B57: ST.3 | C57: KOM | D57: 1 | E57: ='[1]B_III_STOLARSKI RADOVI'!E57 -> 400 | F57: =SUM(D57*E57) -> 400
A59: 4 | B59: IZRADA, DOBAVA I UGRADNJA DVOKRILNOG ZAOKRETNOG PROZORA ULIČNOG PROČELJA (1. KAT), PROIZVODNE MJERE 88/143 CM. DOPROZORNIK I OKVIR KRILA OD HRASTOVINE I KLASE. OSTAKLJENJE IZO STAKLOM 6/16/4 S LOW-E PREMAZOM I ISPUNJENO PLEMENITIM PLINOM. ZAVRŠNA OBRADA DRVETA, LAZURNI PREMAZ + PRIPREMNE RADNJE U TONU PO IZBORU PROJEKTANTA OKOV: 2 PETLJE ODGOVARAJUĆE NOSIVOSTI. POLUOLIVA, ŠTITNICI, PROZOR SE IZRAĐUJE PREMA SAČUVANOM UZORKU POSTOJEĆEG ULIČNOG PROZORA. SVE MJERE POTREBNO JE PROVJERITI U NARAVI! RADIONIČKE NACRTE PRIJE IZVEDBE TREBA PREGLEDATI I OVJERITI PROJEKTANT I NADLEŽNI KONZERVATOR!
B60: ST.4 | C60: KOM | D60: 4 | E60: ='[1]B_III_STOLARSKI RADOVI'!E60 -> 600 | F60: =SUM(D60*E60) -> 2400
A62: 5 | B62: IZRADA, DOBAVA I UGRADNJA DVOKRILNOG ZAOKRETNOG PROZORA ULIČNOG PROČELJA (1. KAT), PROIZVODNE MJERE 140/136 CM. DOPROZORNIK I OKVIR KRILA OD HRASTOVINE I KLASE. OSTAKLJENJE IZO STAKLOM 6/16/4 S LOW-E PREMAZOM I ISPUNJENO PLEMENITIM PLINOM. ZAVRŠNA OBRADA DRVETA, LAZURNI PREMAZ + PRIPREMNE RADNJE U TONU PO IZBORU PROJEKTANTA OKOV: 2 PETLJE ODGOVARAJUĆE NOSIVOSTI. POLUOLIVA, ŠTITNICI, PROZOR SE IZRAĐUJE PREMA SAČUVANOM UZORKU POSTOJEĆEG ULIČNOG PROZORA. SVE MJERE POTREBNO JE PROVJERITI U NARAVI! RADIONIČKE NACRTE PRIJE IZVEDBE TREBA PREGLEDATI I OVJERITI PROJEKTANT I NADLEŽNI KONZERVATOR!
B63: ST.5 | C63: KOM | D63: 1 | E63: ='[1]B_III_STOLARSKI RADOVI'!E63 -> 1100 | F63: =SUM(D63*E63) -> 1100
A65: 6 | B65: IZRADA, DOBAVA I UGRADNJA JEDNOKRILNOG ZAOKRETNO-OTKLOPNOG PROZORA PROIZVODNE MJERE 60/90 CM (SJEVERNO PROČELJE ZGRADE). DOPROZORNIK I OKVIR KRILA OD HRASTOVINE I KLASE - GREDICE 8/8 CM. OSTAKLJENJE IZO STAKLOM 6/16/4 S LOW-E PREMAZOM I ISPUNJENO PLEMENITIM PLINOM. ZAVRŠNA OBRADA DRVETA, LAZURNI PREMAZ + PRIPREMNE RADNJE U TONU PO IZBORU PROJEKTANTA U DOGOVORU SA NADLEŽNIM KONZERVATOROM. OKOV: PETLJE ODGOVARAJUĆE NOSIVOSTI. PLUOLIVA, ŠTITNICI. SVE MJERE POTREBNO JE PROVJERITI U NARAVI! RADIONIČKE NACRTE PRIJE IZVEDBE TREBA PREGLEDATI I OVJERITI PROJEKTANT I NADLEŽNI KONZERVATOR!
B66: STOL.ST. 1 - DESNI | C66: KOM | D66: 3 | E66: ='[1]B_III_STOLARSKI RADOVI'!E66 -> 550 | F66: =SUM(D66*E66) -> 1650
B67: STOL.ST. 1 - LIJEVI | C67: KOM | D67: 3 | E67: ='[1]B_III_STOLARSKI RADOVI'!E67 -> 550 | F67: =SUM(D67*E67) -> 1650
A69: 7 | B69: IZRADA, DOBAVA I UGRADNJA VANJSKIH JEDNOKRILNIH ZAOKRETNIH VRATA SA NADSVJETLOM PROIZVODNE MJERE 95/258 CM (JUŽNO PROČELJE ZGRADE, PRIZEMLJE). DOPROZORNIK I OKVIR KRILA OD HRASTOVINE I KLASE - GREDICE 8/8 CM. KRILO IZVEDENO ROŠTILJNOM DRVENOM HRASTOVOM KONSTRUKCIJOM DEBLJINE 8 CM UNUTAR KOJU SE UGRAĐUJE TERMOIZOLACIJSKI SLOJ OD POLIURETANSKE PIJENE. OBLOGA KRILA SE IZVODI OD OPLEMENJENIH DRVENIH PLOČA U BOJI PRIRODNOG HRASTA. OSTAKLJENJE NADSVJETLA IZO STAKLOM 6/16/4 S LOW-E PREMAZOM I ISPUNJENO PLEMENITIM PLINOM. ZAVRŠNA OBRADA DRVETA, LAZURNI PREMAZ + PRIPREMNE RADNJE U TONU PO IZBORU PROJEKTANTA U DOGOVORU SA NADLEŽNIM KONZERVATOROM. VRATA SE OTVARAJU PREMA VAN. OKOV: PETLJE ODGOVARAJUĆE NOSIVOSTI. PLUOLIVA, ŠTITNICI, BRAVA. SVE MJERE POTREBNO JE PROVJERITI U NARAVI! RADIONIČKE NACRTE PRIJE IZVEDBE TREBA PREGLEDATI I OVJERITI PROJEKTANT I NADLEŽNI KONZERVATOR!
B70: STOL.ST. 2 - DESNA | C70: KOM | D70: 1 | E70: ='[1]B_III_STOLARSKI RADOVI'!E70 -> 3300 | F70: =SUM(D70*E70) -> 3300
A72: 8 | B72: IZRADA, DOBAVA I UGRADNJA DVOKRILNOG ZAOKRETNOG PROZORA PROIZVODNE MJERE 95/148 CM (SJEVERNO PROČELJE ZGRADE). DOPROZORNIK I OKVIR KRILA OD HRASTOVINE I KLASE - GREDICE 8/8 CM. OSTAKLJENJE IZO STAKLOM 6/16/4 S LOW-E PREMAZOM I ISPUNJENO PLEMENITIM PLINOM. ZAVRŠNA OBRADA DRVETA, LAZURNI PREMAZ + PRIPREMNE RADNJE U TONU PO IZBORU PROJEKTANTA U DOGOVORU SA NADLEŽNIM KONZERVATOROM. OKOV: PETLJE ODGOVARAJUĆE NOSIVOSTI. PLUOLIVA, ŠTITNICI. SVE MJERE POTREBNO JE PROVJERITI U NARAVI! RADIONIČKE NACRTE PRIJE IZVEDBE TREBA PREGLEDATI I OVJERITI PROJEKTANT I NADLEŽNI KONZERVATOR!
B73: STOL.ST. 3 | C73: KOM | D73: 2 | E73: ='[1]B_III_STOLARSKI RADOVI'!E73 -> 650 | F73: =SUM(D73*E73) -> 1300
A75: 9 | B75: IZRADA, DOBAVA I UGRADNJA DVOKRILNOG ZAOKRETNOG PROZORA PROIZVODNE MJERE 120/155 CM (ISTOČNO PROČELJE ZGRADE). DOPROZORNIK I OKVIR KRILA OD HRASTOVINE I KLASE - GREDICE 8/8 CM. OSTAKLJENJE IZO STAKLOM 6/16/4 S LOW-E PREMAZOM I ISPUNJENO PLEMENITIM PLINOM. ZAVRŠNA OBRADA DRVETA, LAZURNI PREMAZ + PRIPREMNE RADNJE U TONU PO IZBORU PROJEKTANTA U DOGOVORU SA NADLEŽNIM KONZERVATOROM. OKOV: PETLJE ODGOVARAJUĆE NOSIVOSTI. PLUOLIVA, ŠTITNICI. SVE MJERE POTREBNO JE PROVJERITI U NARAVI! RADIONIČKE NACRTE PRIJE IZVEDBE TREBA PREGLEDATI I OVJERITI PROJEKTANT I NADLEŽNI KONZERVATOR!
B76: STOL.ST.4 | C76: KOM | D76: 2 | E76: ='[1]B_III_STOLARSKI RADOVI'!E76 -> 900 | F76: =SUM(D76*E76) -> 1800
A78: 10 | B78: IZRADA, DOBAVA I UGRADNJA VANJSKE ČETVERODIJELNE OSTAKLJENE FIKSNE STIJENE PROIZVODNE MJERE 340/245 CM (ISTOČNO PROČELJE ZGRADE). DOPROZORNIK I OKVIRI OD HRASTOVINE I KLASE - GREDICE 8/8 CM. OSTAKLJENJE IZO STAKLOM 6/16/4 S LOW-E PREMAZOM I ISPUNJENO PLEMENITIM PLINOM. ZAVRŠNA OBRADA DRVETA, LAZURNI PREMAZ + PRIPREMNE RADNJE U TONU PO IZBORU PROJEKTANTA U DOGOVORU SA NADLEŽNIM KONZERVATOROM. SVE MJERE POTREBNO JE PROVJERITI U NARAVI! RADIONIČKE NACRTE PRIJE IZVEDBE TREBA PREGLEDATI I OVJERITI PROJEKTANT I NADLEŽNI KONZERVATOR!
B79: STOL.ST. 5 | C79: KOM | D79: 1 | E79: ='[1]B_III_STOLARSKI RADOVI'!E79 -> 6000 | F79: =SUM(D79*E79) -> 6000
A81: 11 | B81: IZRADA, DOBAVA I UGRADNJA DVOKRILNOG ZAOKRETNOG PROZORA PROIZVODNE MJERE 95/143 CM (SJEVERNO PROČELJE ZGRADE). DOPROZORNIK I OKVIR KRILA OD HRASTOVINE I KLASE - GREDICE 8/8 CM. OSTAKLJENJE IZO STAKLOM 6/16/4 S LOW-E PREMAZOM I ISPUNJENO PLEMENITIM PLINOM. ZAVRŠNA OBRADA DRVETA, LAZURNI PREMAZ + PRIPREMNE RADNJE U TONU PO IZBORU PROJEKTANTA U DOGOVORU SA NADLEŽNIM KONZERVATOROM. OKOV: PETLJE ODGOVARAJUĆE NOSIVOSTI. PLUOLIVA, ŠTITNICI. SVE MJERE POTREBNO JE PROVJERITI U NARAVI! RADIONIČKE NACRTE PRIJE IZVEDBE TREBA PREGLEDATI I OVJERITI PROJEKTANT I NADLEŽNI KONZERVATOR!
B82: STOL.ST. 6 | C82: KOM | D82: 2 | E82: ='[1]B_III_STOLARSKI RADOVI'!E82 -> 600 | F82: =SUM(D82*E82) -> 1200
...

Sheet B_IV_BRAVARSKI RADOVI 
A1: B.IV. | B1: BRAVARSKI RADOVI
A3: Redni broj | B3: Opis rada | C3: Jedinična mjera | D3: Količina | E3: Cijena u eurima | G3: JV
E5: Jedinična | F5: Ukupna
B7: NAPOMENA: SVE MJERE POTREBNO JE PROVJERITI U NARAVI! RADIONIČKE NACRTE PRIJE IZVEDBE TREBA PREGLEDATI I OVJERITI PROJEKTANT!
A8: 1 | B8: UNUTARNJA PROTUPOŽARNA VRATA
B9: IZRADA, DOBAVA I UGRADNJA JEDNOKRILNIH ZAOKRETNIH PROTUPOŽARNIH VRATA VATROOTPORNOSTI EI2 30-C
B10: VRATA SU DIMENZIJA 80/220 CM, ZAVRŠNA OBRADA BOJA U TONU PO IZBORU investitora.
B11: Okov izvesti originalan od dobavljača sustava usklađen nosivošću i tipom s težinom otvora i načinom otvaranja + mehanizam za automatsko zatvaranje vrata.
B12: ukupno: BRAVARSKA STAVKA 18 | C12: KOM | D12: 1 | E12: 1900 | F12: =SUM(D12*E12) -> 1900
B14: BRAVARSKI UKUPNO | E14: EUR | F14: =SUM(F11:F12) -> 1900

Sheet B_V_ ZAVRŠNI ZIDARSKI RADOVI
A1: B.V. | B1: ZAVRŠNI ZIDARSKI RADOVI
A3: Redni broj | B3: Opis rada | C3: Jedinična mjera | D3: Količina | E3: Cijena u eurima | G3: JV
E5: Jedinična | F5: Ukupna
A7: 1 | B7: DOBAVA MATERIJALA I IZRADA SLOJA CEMENTNOG ESTRIHA NA POLOŽENE SLOJEVE OD EPS-T DEBLJINE 2 CM I PE FOLIJE KOJI SU U CIJENI. POLISTIREN I PE FOLIJU PODIĆI PO VERTIKALI UZ ZIDOVE.
B8: Estrih je armiran mrežom 4 mm, okna 10 x 10 cm, u sredini sloja ili sintetskim vlaknima prema uputama proizvođača! Mješavina kamenog agregata 0-8 mm (frakcija 0 – 4 mm ne više od 60 %) sa količinom cementa do 380 kg/m3 ili gotova industrijski pripremljena smjesa.
A9: A | B9: ESTRIH PROJEKTNE DEBLJINE 7,5 CM | C9: M2 | D9: 10 | E9: ='[1]B_V_ ZAVRŠNI ZIDARSKI RADOVI'!E9 -> 40 | F9: =SUM(D9*E9) -> 400
A10: B | B10: ESTRIH PROJEKTNE DEBLJINE 6,5 CM | C10: M2 | D10: 115 | E10: ='[1]B_V_ ZAVRŠNI ZIDARSKI RADOVI'!E10 -> 30 | F10: =SUM(D10*E10) -> 3450
A11: B | B11: ESTRIH PROJEKTNE DEBLJINE 5,5 CM | C11: M2 | D11: 215 | E11: ='[1]B_V_ ZAVRŠNI ZIDARSKI RADOVI'!E11 -> 30 | F11: =SUM(D11*E11) -> 6450
A13: 2 | B13: DOBAVA MATERIJALA, ZIDANJE I UGRADNJA TROSLOJNOG DIMOVODNOG KANALA PROMJERA DIMOVODNE CIJEVI 20 CM. U CIJENI STAVKE JE I ŠAMOTNA CIJEV S FAZONSKIM KOMADIMA, ODSTOJNICI, ARMATURA, POSUDA ZA KONDENZAT DILATACIONA TRAKA, KIT ZA UNUTARNJU CIJEV, MINERALNA VUNA I VANJSKI OMOTAČ TE ZAVRŠNA MANŠETA OD LIMA 1,5 MM I MONTAŽNA ARMIRANO BETONSKA KAPA, VRATŠCA ZA ČIŠĆENJE I PRIKLJUČNI ELEMENT. SVE DO POTPUNE GOTOVOSTI DIMNJAKA.
A14: A | B14: DIMNJAKA | C14: M1 | D14: 12 | E14: ='[1]B_V_ ZAVRŠNI ZIDARSKI RADOVI'!E14 -> 300 | F14: =SUM(D14*E14) -> 3600
A15: B | B15: PRIKLJUČCI TROŠILA | C15: KOM | D15: 1 | E15: ='[1]B_V_ ZAVRŠNI ZIDARSKI RADOVI'!E15 -> 200 | F15: =SUM(D15*E15) -> 200
A16: C | B16: VRATAŠCA ZA ČIŠĆENJE | C16: KOM | D16: 1 | E16: ='[1]B_V_ ZAVRŠNI ZIDARSKI RADOVI'!E16 -> 200 | F16: =SUM(D16*E16) -> 200
A17: D | B17: MONTAŽNA AB I LIMENA KAPA | C17: KOM | D17: 1 | E17: ='[1]B_V_ ZAVRŠNI ZIDARSKI RADOVI'!E17 -> 500 | F17: =SUM(D17*E17) -> 500
A18: E | B18: POSUDE ZA KONDENZAT | C18: KOM | D18: 1 | E18: ='[1]B_V_ ZAVRŠNI ZIDARSKI RADOVI'!E18 -> 200 | F18: =SUM(D18*E18) -> 200
A21: 3 | B21: DOBAVA MATERIJALA I IZRADA UNUTARNJE STROJNE CEMENTNE PRODUŽNE ŽBUKE ZIDOVA D=1,5 CM NA PODLOZI OD AB ILI BLOK OPEKE, UKLJUČIVO KONTAKTNI VEZNI SLOJ, KUTNI PROFILI, RABICIRANO PO UGLOVIMA (CCA 10 % POVRŠINE). SKELA UKLJUČENA U CIJENU. VISINA DO 3 M. KORISTITI GOTOVU INDUSTRIJSKI PRIREĐENU SMJESU.
C22: M2 | D22: 410 | E22: ='[1]B_V_ ZAVRŠNI ZIDARSKI RADOVI'!E22 -> 30 | F22: =SUM(D22*E22) -> 12300
A24: 4 | B24: DOBAVA MATERIJALA I IZRADA UNUTARNJE STROJNE PRODUŽNE ŽBUKE STROPA, D=1,5 CM NA PODLOZI OD AB. OBVEZAN KONTAKTNI VEZNI SLOJ - CEMNTNI ŠPRIC, KUTNI PROFILI, RABIC PO UGLOVIMA (10 % POVRŠINE) SKELA UKLJUČENI U CIJENU. VISINA DO 3 M. KORISTITI GOTOVU INDUSTRIJSKI PRIREĐENU SMJESU.
C25: M2 | D25: 160 | E25: ='[1]B_V_ ZAVRŠNI ZIDARSKI RADOVI'!E25 -> 30 | F25: =SUM(D25*E25) -> 4800
A27: 5 | B27: ZIDARSKA PRIPOMOĆ KOD INSTALATERSKIH I OBRTNIČKIH RADOVA, RAZNA ŠTEMANJA, KRPANJA, PROBIJANJA, SITNI RADOVI I POPRAVCI NAKON OŠTEĆENJA.
B28: obračun sukladno ovjernim građevnim dnevnicima - predvidivo | C28: R/S | D28: 250 | E28: ='[1]B_V_ ZAVRŠNI ZIDARSKI RADOVI'!E28 -> 15 | F28: =SUM(D28*E28) -> 3750
A30: 6 | B30: ČIŠĆENJE OBJEKTA I GRADILIŠTA U TOKU IZVOĐENJA RADOVA I ZAVRŠNO FINO ČIŠĆENJE GRADILIŠTA I PRANJE GRAĐEVINE NAKON DOVRŠETKA GRADNJE I PREDAJE NA KORIŠTENJE INVESTIORU, SA ODVOZOM ŠUTE I SMEĆA NA GRADSKI DEPONIJ UZ PLAĆANJE KOMUNALNE NAKNADE.
C31: komplet | D31: 1 | E31: ='[1]B_V_ ZAVRŠNI ZIDARSKI RADOVI'!E31 -> 2500 | F31: =SUM(D31*E31) -> 2500
B33: ZAVRŠNI ZIDARSKI UKUPNO | E33: EUR | F33: =SUM(F9:F31) -> 38350

Sheet B_VI_ GIPSARSKI RADOVI
A1: B.VI. | B1: GIPSARSKI RADOVI
A3: Redni broj | B3: Opis rada | C3: Jedinična mjera | D3: Količina | E3: Cijena u eurima | G3: JV
E5: Jedinična | F5: Ukupna
A7: 1 | B7: DOBAVA MATERIJALA I IZRADA GIPSKARTONSKOG PREGRADNOG ZIDA DEBLJINE D=15 CM. ZID OBOSTRANO DVOSTRUKO OBLOŽEN G.K. PLOČOM D=1,25 CM SA SLOJEM IZOLACIJE OD MINERALNE VUNE, D= 8 CM. U CIJENU URAČUNATI I IZRADU OTVORA ZA UGRADBU VRATA TE KOMPLET BANDAŽIRANJE SPOJEVA I GLETANJE S BRUŠENJEM I IMPREGNACIJOM DO PODLOGE SPREMNE ZA BOJANJE. MAX VISINA ZIDA 300 CM.
A8: A | B8: ZIDA | C8: M2 | D8: 125 | E8: ='[1]B_VI_ GIPSARSKI RADOVI'!E8 -> 75 | F8: =SUM(D8*E8) -> 9375
A9: B | B9: DOPLATA ZA VLAGOOTPORNE PLOČE U JEDOM SLOJU | C9: M2 | D9: 100 | E9: ='[1]B_VI_ GIPSARSKI RADOVI'!E9 -> 5 | F9: =SUM(D9*E9) -> 500
A10: C | B10: DOPLATA ZA IZRADU POJAČANIH RUBOVA OTVORA ZA MONTAŽU BRAVARIJE I STIJENA | C10: M1 | D10: 12 | E10: ='[1]B_VI_ GIPSARSKI RADOVI'!E10 -> 100 | F10: =SUM(D10*E10) -> 1200
A12: 2 | B12: DOBAVA MATERIJALA I IZRADA GIPSKARTONSKOG PREGRADNOG ZIDA DEBLJINE D=10 CM. ZID OBOSTRANO DVOSTRUKO OBLOŽEN G.K. PLOČOM D=1,25 CM SA SLOJEM IZOLACIJE OD MINERALNE VUNE, D= 4 CM. U CIJENU URAČUNATI I IZRADU OTVORA ZA UGRADBU VRATA TE KOMPLET BANDAŽIRANJE SPOJEVA I GLETANJE S BRUŠENJEM I IMPREGNACIJOM DO PODLOGE SPREMNE ZA BOJANJE. MAX VISINA ZIDA 320 CM.
A13: A | B13: ZIDA | C13: M2 | D13: 90 | E13: ='[1]B_VI_ GIPSARSKI RADOVI'!E13 -> 75 | F13: =SUM(D13*E13) -> 6750
A14: B | B14: DOPLATA ZA VLAGOOTPORNE PLOČE U JEDOM SLOJU | C14: M2 | D14: 75 | E14: ='[1]B_VI_ GIPSARSKI RADOVI'!E14 -> 5 | F14: =SUM(D14*E14) -> 375
A16: 3 | B16: DOBAVA MATERIJALA I IZRADA GIPSKARTONSKOG PREGRADNOG ZIDA DEBLJINE D=7,5 CM. ZID OBOSTRANO OBLOŽEN VLAGOOTPORNOM G.K. PLOČOM D=1,25 CM. U CIJENU URAČUNATI I IZRADU OTVORA ZA UGRADBU VRATA TE KOMPLET BANDAŽIRANJE SPOJEVA I GLETANJE S BRUŠENJEM I IMPREGNACIJOM DO PODLOGE SPREMNE ZA BOJANJE. MAX VISINA ZIDA 300 CM.
C17: M2 | D17: 25 | E17: ='[1]B_VI_ GIPSARSKI RADOVI'!E17 -> 65 | F17: =SUM(D17*E17) -> 1625
A19: 4 | B19: DOBAVA MATERIJALA I IZRADA GIPSKARTONSKOG PREGRADNOG VATROOTPORNOG ZIDA F60 DEBLJINE D=15 CM SA SVIM SLOJEVIMA DANIM OD DOBAVLJAČA SUSTAVA DO TRAŽENE RAZINE VATROOTPORNOSTI. U CIJENU URAČUNATI I IZRADU OTVORA ZA UGRADBU VRATA TE KOMPLET BANDAŽIRANJE SPOJEVA I GLETANJE S BRUŠENJEM DO PODLOGE SPREMNE ZA BOJANJE. MAX VISINA ZIDA 300 CM. U CIJENI JE I DOSTAVA ATESTA OD STRANE PROIZVOĐAČA SUSTAVA ZA TRAŽENU RAZINU VATROOTPORNOSTI.
A20: A | B20: ZIDA | C20: M2 | D20: 25 | E20: ='[1]B_VI_ GIPSARSKI RADOVI'!E20 -> 100 | F20: =SUM(D20*E20) -> 2500
A21: B | B21: DOPLATA ZA PARNU BRANU PREMA NEGRIJANOM PROSTORU | C21: M2 | D21: 12 | E21: ='[1]B_VI_ GIPSARSKI RADOVI'!E21 -> 10 | F21: =SUM(D21*E21) -> 120
A23: 5 | B23: DOBAVA MATERIJALA I IZRADA SPUŠTENIH STROPOVA OD PUNIH G.K. PLOČA D=1,25 CM NA POCINČANOJ PODKONSTRUKCIJI. U CIJENU URAČUNATI I IZRADU OTVORA ZA UGRADNJU RASVJETE, VENT. REŠETKI I OSTALIH INST. IZVODA, TE KOMPLET BANDAŽIRANJE SPOJEVA I GLETANJE S BRUŠENJEM I IMPREGNACIJOM DO PODLOGE SPREMNE ZA BOJANJE. VISINA VJEŠANJA DO 125 CM. REVIZIJSKA OKNA DODATNO PO OBRAČUNU.
A24: A | B24: STROPA | C24: M2 | D24: 170 | E24: ='[1]B_VI_ GIPSARSKI RADOVI'!E24 -> 60 | F24: =SUM(D24*E24) -> 10200
A25: C | B25: REVIZIJSKA OKNA S POKLOPCEM DIMENZIJA 60/60 CM | C25: KOM | D25: 2 | E25: ='[1]B_VI_ GIPSARSKI RADOVI'!E25 -> 100 | F25: =SUM(D25*E25) -> 200
A27: 6 | B27: DOBAVA MATERIJALA I IZRADA OBLOGE KOSIH KROVNIH PLOHA GIPS-KARTONSKIM PLOČAMA SA POSTAVLJANJEM RAZDJELNIH SLOJEVA. U CIJENU URAČUNATI I IZRADU SVIH DETALJA OBLOGE OKO OTVORA, KROVNIH PROZORA I SL. KOMPLET BANDAŽIRANJE SPOJEVA I GLETANJE S BRUŠENJEM I IMPREGNACIJOM DO PODLOGE SPREMNE ZA BOJANJE. SLOJEVI KONSTRUKCIJE SU SLJEDEĆI:
B28: - PAROPROPUSNA FOLIJA
B29: - PARNA BRANA - LJEPLJENA PO PREKLOPIMA, µ > 1.000.000
B30: - GIPSKARTONSKA VATROOTPORNA PLOČA D=1,25 CM - na pocinčanim čeličnim C profilima 100 mm postavljenim poprečno na sekundarne profile
B31: - GIPSKARTONSKA PLOČA D=1,25 CM
C32: m2 | D32: 340 | E32: ='[1]B_VI_ GIPSARSKI RADOVI'!E32 -> 60 | F32: =ROUND(D32*E32,2) -> 20400
