Workbook
Name _1Excel_BuiltIn_Print_Area_1: #REF!
Name _1Excel_BuiltIn_Print_Area_1: #REF!
Name _1Excel_BuiltIn_Print_Area_1: #REF!
Name _1Excel_BuiltIn_Print_Area_1: #REF!
Name _1Excel_BuiltIn_Print_Area_1: #REF!
Name _1Excel_BuiltIn_Print_Area_1: #REF!
Name _1Excel_BuiltIn_Print_Area_1: #REF!
Name _rbr: #REF!
Name _rbr: #REF!
Name _rbr: #REF!
Name _rbr: #REF!
Name _rbr: '6. PORTAFON'!$A$1
Name _rbr: '7. STRUKTURNO KABLIRANJE'!$A$1
Name _rbr: #REF!
Name _rbr: #REF!
Name a: #REF!
Name a_1: #REF!
Name a_10: #REF!
Name a_2: #REF!
Name a_3: #REF!
Name a_4: #REF!
Name a_5: #REF!
Name a_6: #REF!
Name a_7: #REF!
Name a_8: #REF!
Name a_9: #REF!
Name ad: '9. STOL. '!$A$1:$H$93
Name af: '11.FASAD.'!$A$1:$H$29
Name ag: '12. LIČIL.'!$A$1:$H$29
Name ah: '15.PODOPOL. '!$A$1:$H$23
Name aj: '2. BET. I AB'!$A$1:$H$65
Name ak: '3. ZID.'!$A$1:$H$66
Name ANEX_I: [1]List1!$S$8
Name ANEX_II: [1]List1!$S$9
Name AQDE: #REF!
Name AQDE: #REF!
Name AQDE: #REF!
Name AQDE: #REF!
Name AQDE: #REF!
Name AQDE: #REF!
Name AQDE: #REF!
Name AQDE: #REF!
Name AQDE: #REF!
Name Arm_beton: #REF!
Name Arm_beton: #REF!
Name Arm_beton: #REF!
Name Arm_beton: #REF!
Name Arm_beton: #REF!
Name Arm_beton: #REF!
Name Arm_beton: #REF!
Name Arm_beton: #REF!
Name Arm_beton: #REF!
Name Arm_beton: #REF!
Name Armiracki: #REF!
Name Armiracki: #REF!
Name Armiracki: #REF!
Name Armiracki: #REF!
Name Armiracki: #REF!
Name Armiracki: #REF!
Name Armiracki: #REF!

Sheet SVE
A3: 1. | C3: 01.01. | D3: PRIPREMNI RADOVI, DEMONTAŽE I RUŠENJA
A5: =IF(OR(B5="",B5= " ")," ",$A$3) -> 1. | B5: =IF(AND(D5>0,NOT(D5=" "),NOT(D4>0)),1+(COUNTIF($B$3:B4,">0"))," ") -> 1 | C5: 01.01.001. | D5: Skidanje pokrova krova s odlaganjem na odlagalište udaljenosti do 50 m.
A6: =IF(OR(B6="",B6= " ")," ",$A$3) | B6: =IF(AND(D6>0,NOT(D6=" "),NOT(D5>0)),1+(COUNTIF($B$3:B5,">0"))," ") | E6: m2
A7: =IF(OR(B7="",B7= " ")," ",$A$3) | B7: =IF(AND(D7>0,NOT(D7=" "),NOT(D6>0)),1+(COUNTIF($B$3:B6,">0"))," ")
A8: =IF(OR(B8="",B8= " ")," ",$A$3) -> 1. | B8: =IF(AND(D8>0,NOT(D8=" "),NOT(D7>0)),1+(COUNTIF($B$3:B7,">0"))," ") -> 2 | C8: 01.01.002. | D8: Demontaža drvene krovne konstrukcije s odlaganjem na udaljenost do 50 m.
A9: =IF(OR(B9="",B9= " ")," ",$A$3) | B9: =IF(AND(D9>0,NOT(D9=" "),NOT(D8>0)),1+(COUNTIF($B$3:B8,">0"))," ") | E9: m2
A10: =IF(OR(B10="",B10= " ")," ",$A$3) | B10: =IF(AND(D10>0,NOT(D10=" "),NOT(D9>0)),1+(COUNTIF($B$3:B9,">0"))," ")
A11: =IF(OR(B11="",B11= " ")," ",$A$3) -> 1. | B11: =IF(AND(D11>0,NOT(D11=" "),NOT(D10>0)),1+(COUNTIF($B$3:B10,">0"))," ") -> 3 | C11: 01.01.003. | D11: Demontaža, utovar i odvoz krovne limarije i limarije odvodnih oborinskih voda na odlagalište udaljeno do 50 m.
A12: =IF(OR(B12="",B12= " ")," ",$A$3) | B12: =IF(AND(D12>0,NOT(D12=" "),NOT(D11>0)),1+(COUNTIF($B$3:B11,">0"))," ") | E12: m1
A13: =IF(OR(B13="",B13= " ")," ",$A$3) | B13: =IF(AND(D13>0,NOT(D13=" "),NOT(D12>0)),1+(COUNTIF($B$3:B12,">0"))," ")
A14: =IF(OR(B14="",B14= " ")," ",$A$3) -> 1. | B14: =IF(AND(D14>0,NOT(D14=" "),NOT(D13>0)),1+(COUNTIF($B$3:B13,">0"))," ") -> 4 | C14: 01.01.004. | D14: Rušenje međukatnih i tavanskih konstrukcija uz sva potrebna osiguranja kako ne bi došlo do nepredviđenog urušavanja dijelova zgrade, s odvozom otpadnog materijala na udaljenost do 50 m.
A15: =IF(OR(B15="",B15= " ")," ",$A$3) | B15: =IF(AND(D15>0,NOT(D15=" "),NOT(D14>0)),1+(COUNTIF($B$3:B14,">0"))," ") | D15: a) drveni grednici | E15: m2
A16: =IF(OR(B16="",B16= " ")," ",$A$3) | B16: =IF(AND(D16>0,NOT(D16=" "),NOT(D15>0)),1+(COUNTIF($B$3:B15,">0"))," ") | D16: b) AB ploče | E16: m2
A17: =IF(OR(B17="",B17= " ")," ",$A$3) | B17: =IF(AND(D17>0,NOT(D17=" "),NOT(D16>0)),1+(COUNTIF($B$3:B16,">0"))," ")
A18: =IF(OR(B18="",B18= " ")," ",$A$3) -> 1. | B18: =IF(AND(D18>0,NOT(D18=" "),NOT(D17>0)),1+(COUNTIF($B$3:B17,">0"))," ") -> 5 | C18: 01.01.005. | D18: Vađenje postojeće drvene vanjske stolarije, sa svim potrebnim radovima i odvozom na odlagalište do 50 m udaljenosti.
A19: =IF(OR(B19="",B19= " ")," ",$A$3) | B19: =IF(AND(D19>0,NOT(D19=" "),NOT(D18>0)),1+(COUNTIF($B$3:B18,">0"))," ") | E19: kom
A20: =IF(OR(B20="",B20= " ")," ",$A$3) | B20: =IF(AND(D20>0,NOT(D20=" "),NOT(D19>0)),1+(COUNTIF($B$3:B19,">0"))," ")
A21: =IF(OR(B21="",B21= " ")," ",$A$3) -> 1. | B21: =IF(AND(D21>0,NOT(D21=" "),NOT(D20>0)),1+(COUNTIF($B$3:B20,">0"))," ") -> 6 | C21: 01.01.006. | D21: Ručno rušenje u cijelosti, nosivih, zabatnih i pregradnih zidova, s odvozom otpadnog materijala na udaljenost do 50 m.
A22: =IF(OR(B22="",B22= " ")," ",$A$3) | B22: =IF(AND(D22>0,NOT(D22=" "),NOT(D21>0)),1+(COUNTIF($B$3:B21,">0"))," ")
A23: =IF(OR(B23="",B23= " ")," ",$A$3) -> 1. | B23: =IF(AND(D23>0,NOT(D23=" "),NOT(D22>0)),1+(COUNTIF($B$3:B22,">0"))," ") -> 7 | D23: a) od pune cigle
A24: =IF(OR(B24="",B24= " ")," ",$A$3) | B24: =IF(AND(D24>0,NOT(D24=" "),NOT(D23>0)),1+(COUNTIF($B$3:B23,">0"))," ") | E24: m3
A25: =IF(OR(B25="",B25= " ")," ",$A$3) | B25: =IF(AND(D25>0,NOT(D25=" "),NOT(D24>0)),1+(COUNTIF($B$3:B24,">0"))," ")
A26: =IF(OR(B26="",B26= " ")," ",$A$3) -> 1. | B26: =IF(AND(D26>0,NOT(D26=" "),NOT(D25>0)),1+(COUNTIF($B$3:B25,">0"))," ") -> 8 | C26: 01.01.007. | D26: Strojni iskop i rušenje betonskih kon-strukcijskih elemenata malih i srednjh presjeka, kao što su temelji, nadtemeljni zidovi i podna ploča s odvozom otpadnog materijala na udaljenost do 50 m.
A27: =IF(OR(B27="",B27= " ")," ",$A$3) | B27: =IF(AND(D27>0,NOT(D27=" "),NOT(D26>0)),1+(COUNTIF($B$3:B26,">0"))," ") | E27: m3
A28: =IF(OR(B28="",B28= " ")," ",$A$3) | B28: =IF(AND(D28>0,NOT(D28=" "),NOT(D27>0)),1+(COUNTIF($B$3:B27,">0"))," ")
A29: =IF(OR(B29="",B29= " ")," ",$A$3) -> 1. | B29: =IF(AND(D29>0,NOT(D29=" "),NOT(D28>0)),1+(COUNTIF($B$3:B28,">0"))," ") -> 9 | C29: 01.01.008. | D29: Čišćenje terena od smeća, raslinja, šiblja i stabala do Ć 10 cm debljine pri dnu i manjih prepreka, drvenih i žičanih ograda i sl., košenje trave i korova, sve uz pomoć radnika II ktg. Siječenje gusto obraslog raslinja kod korijenja i vađenje korijenja bu
A30: =IF(OR(B30="",B30= " ")," ",$A$3) | B30: =IF(AND(D30>0,NOT(D30=" "),NOT(D29>0)),1+(COUNTIF($B$3:B29,">0"))," ") | E30: m2 | H30: .
A31: =IF(OR(B31="",B31= " ")," ",$A$3) | B31: =IF(AND(D31>0,NOT(D31=" "),NOT(D30>0)),1+(COUNTIF($B$3:B30,">0"))," ")
A32: =IF(OR(B32="",B32= " ")," ",$A$3) -> 1. | B32: =IF(AND(D32>0,NOT(D32=" "),NOT(D31>0)),1+(COUNTIF($B$3:B31,">0"))," ") -> 10 | C32: 01.01.009. | D32: Strojni iskop humusa u sloju debljine 20 cm, s guranjem buldožerom do 60 m. Odlaganje zemlje na predviđenu lokaciju.
A33: =IF(OR(B33="",B33= " ")," ",$A$3) | B33: =IF(AND(D33>0,NOT(D33=" "),NOT(D32>0)),1+(COUNTIF($B$3:B32,">0"))," ") | E33: m3
A34: =IF(OR(B34="",B34= " ")," ",$A$3) | B34: =IF(AND(D34>0,NOT(D34=" "),NOT(D33>0)),1+(COUNTIF($B$3:B33,">0"))," ")
A35: =IF(OR(B35="",B35= " ")," ",$A$3) -> 1. | B35: =IF(AND(D35>0,NOT(D35=" "),NOT(D34>0)),1+(COUNTIF($B$3:B34,">0"))," ") -> 11 | C35: 01.01.010. | D35: Strojni široki iskop u zemlji za temeljnu ploču. Iskop seže do dubine 7,70 m od od kote ±0,00 (+116,80 N.M.). U cijenu su uračunata sva potrebna podupiranja i razupiranja, osiguranje iskopa i susjednih objekata, izrada prilaznih rampi, eventualni rad u mo
A36: =IF(OR(B36="",B36= " ")," ",$A$3) | B36: =IF(AND(D36>0,NOT(D36=" "),NOT(D35>0)),1+(COUNTIF($B$3:B35,">0"))," ") | D36: Napomena:
A37: =IF(OR(B37="",B37= " ")," ",$A$3) | B37: =IF(AND(D37>0,NOT(D37=" "),NOT(D36>0)),1+(COUNTIF($B$3:B36,">0"))," ") | D37: Radovi iz ove stavke se ne nude, jer su obuhvaćeni posebnim projektom za široki iskop s osiguranjem građevne jame.
A38: =IF(OR(B38="",B38= " ")," ",$A$3) | B38: =IF(AND(D38>0,NOT(D38=" "),NOT(D37>0)),1+(COUNTIF($B$3:B37,">0"))," ") | E38: m3
A39: =IF(OR(B39="",B39= " ")," ",$A$3) | B39: =IF(AND(D39>0,NOT(D39=" "),NOT(D38>0)),1+(COUNTIF($B$3:B38,">0"))," ")
A40: =IF(OR(B40="",B40= " ")," ",$A$3) -> 1. | B40: =IF(AND(D40>0,NOT(D40=" "),NOT(D39>0)),1+(COUNTIF($B$3:B39,">0"))," ") -> 12 | C40: 01.01.011. | D40: Planiranje dna građevinske jame širokog iskopa za temeljnu ploču s točnošću ± 3 cm i prosječnim otkopom zemlje 0,05 m3 / m2 / m, te odvozom zemlje na udaljenost do 50 m. Obračun po m2 isplanirane površine.
A41: =IF(OR(B41="",B41= " ")," ",$A$3) | B41: =IF(AND(D41>0,NOT(D41=" "),NOT(D40>0)),1+(COUNTIF($B$3:B40,">0"))," ") | E41: m2
A42: =IF(OR(B42="",B42= " ")," ",$A$3) | B42: =IF(AND(D42>0,NOT(D42=" "),NOT(D41>0)),1+(COUNTIF($B$3:B41,">0"))," ")
A43: =IF(OR(B43="",B43= " ")," ",$A$3) -> 1. | B43: =IF(AND(D43>0,NOT(D43=" "),NOT(D42>0)),1+(COUNTIF($B$3:B42,">0"))," ") -> 13 | C43: 01.01.012. | D43: Nabijanje zemlje dna građevinske jame (širokog iskopa) do modula stišljivosti tla od M = 7000 kN / m3 .
...

Sheet NASLOVNICA I UKUPNA REKAP.
D7: Projektantski ured:
D8: Studio Obris d.o.o.
D9: Stonska 1, 10000 Zagreb
D10: OIB: 81273222992
D12: Investitor:
D13: Agencija za pravni promet i posredovanje nekretninama, Savska cesta 41/VI, Zagreb
D14: OIB: 69331375926
D16: Građevina:
D17: Višestambena zgrada
D19: Lokacija:
D20: na novoformiranoj k.č.br. 1148/4 k.o. Ivanić - Grad u Ivanić – Gradu
D21: (formirana od dijela k.č.br. 1148/1 k.o. Ivanić – Grad)
... D53: SVEUKUPNA REKAPITULACIJA GRAĐEVINSKO OBRTNIČKO INSTALATERSKIH RADOVA
A56: A | D56: GRAĐEVINSKO OBRTNIČKI RADOVI | H56: =SUM('GRAĐ_OBRT_NASL_REKAP_OPĆI U'!H96) -> 1918738
A58: B | D58: VODOOPSKRBA I ODVODNJA | H58: =ViK!G251 -> 196957
A60: C | D60: ELEKTROTEHNIČKE INSTALACIJE | H60: =REKAPITULACIJA!F26 -> 221548.05
A62: D | D62: STROJARSKE INSTALACIJE | H62: ='STROJARSKE INSTALACIJE'!F425 -> 329190
D64: SVEUKUPNI RADOVI | H64: =SUM(H56,H58,H60,H62) -> 2666433
D66: PDV 25% | H66: =PRODUCT(H64,0.25) -> 666608.26
D68: SVEUKUPNI RADOVI S PDV-om | H68: =SUM(H64,H66) -> 3333041.3

Sheet GRAĐ_OBRT_NASL_REKAP_OPĆI U
D7: Projektantski ured:
D8: Studio Obris d.o.o.
D9: Stonska 1, 10000 Zagreb
D10: OIB: 81273222992
D12: Investitor:
D13: Agencija za pravni promet i posredovanje nekretninama, Savska cesta 41/VI, Zagreb
D14: OIB: 69331375926
D16: Građevina:
D17: Višestambena zgrada
D19: Lokacija:
D20: na novoformiranoj k.č.br. 1148/4 k.o. Ivanić - Grad u Ivanić – Gradu
D21: (formirana od dijela k.č.br. 1148/1 k.o. Ivanić – Grad)
... D53: REKAPITULACIJA GRAĐEVINSKO-OBRTNIČKI RADOVI
A55: 01. | D55: PRIPREMNI I ZEMLJANI RADOVI | H55: ='1.ZEM.'!H76 -> 77911.5
A57: 02. | D57: BETONSKI I ARMIRANO - BETONSKI RADOVI | H57: ='2. BET. I AB'!H64 -> 693852.5
A59: 03. | D59: ZIDARSKI RADOVI | H59: ='3. ZID.'!H65 -> 136944
A61: 04. | D61: SKELE | H61: ='4.SKELE'!H15 -> 21840
A63: 05. | D63: IZOLATERSKI RADOVI | H63: ='5.IZOL.'!H102 -> 112460
A65: 06. | D65: LIMARSKI RADOVI | H65: ='6.LIM'!H98 -> 152291
A67: 07. | D67: TESARSKI RADOVI | H67: ='7.TES.'!H38 -> 81505
A69: 08. | D69: GIPSKARTONSKI RADOVI | H69: ='8.GIPS.'!H27 -> 21215
A71: 09. | D71: STOLARSKI RADOVI | H71: ='9. STOL. '!H92 -> 49630
A73: 10. | B73: 1. | D73: VANJSKA ALUMINIJSKA BRAVARIJA I PVC STOLARIJA | H73: ='10.1.BRAV.ALU VANJ.'!H125 -> 106880
A75: 10. | B75: 2. | D75: PROTUPOŽARNA BRAVARIJA | H75: ='10.2.BRAV.PP'!H64 -> 42800
A77: 10. | B77: 3 | D77: ČELIČNA BRAVARIJA | H77: ='10.3. ČN BRAVARIJA'!H59 -> 26551
A79: 11. | D79: FASADERSKI RADOVI | H79: ='11.FASAD.'!H29 -> 117775
A81: 12. | D81: SOBOSLIKARSKO LIČILAČKI RADOVI | H81: ='12. LIČIL.'!H29 -> 72285
A83: 13. | D83: PARKETARSKI RADOVI | H83: ='13. PARKETARSKI'!H16 -> 52060
A85: 14. | D85: KERAMIČARSKI RADOVI | H85: ='14.KER. '!H36 -> 73384
A87: 15. | D87: PODOPOLAGAČKI RADOVI | H87: ='15.PODOPOL. '!H22 -> 15100
A89: 16. | D89: OPREMA | H89: ='16. OPREMA'!H29 -> 3770
A91: 17. | D91: OKOLIŠ | H91: ='17. OKOLIŠ'!H54 -> 53484
A93: 18. | D93: OSTALO | H93: ='18. OSTALO'!H24 -> 7000
D96: UKUPNO GRAĐEVINSKO OBRTNIČKI RADOVI | H96: =SUM(H55:H93) -> 1918738
B99: OPĆI UVJETI IZGRADNJE
B101: Ovim troškovnikom obuhvaćeni su svi građevinski i obrtnički radovi za izgradnju višestambene građevine, na novoformiranoj k.č.br. 1148/4 k.o. Ivanić – Grad u Ivanić – Gradu (formirana od dijela k.č.br. 1148/1 k.o. Ivanić – Grad).
B102: Ovi opći uvjeti su sastavni dio troškovnika i u svemu ih se treba pridržavati, osim ako u stavci troškovnika to nije drugačije navedeno. Sav ugrađeni materijal treba odgovarati uvjetima iz opisa troškovnika i nacrta te odgovarajućim Hrvatskim normama ili tehničkim uvjetima za izvođenje istih radova, a ukoliko se to posebno traži opisom i drugim propisima. Izvoditelj treba kvalitetu ugrađenih materijala i stručnosti radnika dokazati odgovarajućim atestima i uvjerenjima izdanim od strane za to ovlaštene organizacije. S obzirom na kompleksnost građevinskog zahvata obnove preporuča se da izvođač izvrši pregled lokacije prije davanja ponude, kako bi kod formiranja cijene obuhvatio sve potrebne radove i troškove na pripremnim radovima.
B103: Izvođenje radova mora biti usklađeno s načelom „ne čini značajnu štetu“ („do no significant harm“ - DNSH), odnosno ne smije imati značajnije negativne utjecaje na klimu, okoliš, prirodni ekosustav, vodu i ostale okolišne ciljeve u smislu Uredbe (EU) 2020/852 i izmjene Uredbe (EU) 2019/2088. Povezano s otpadom/kružnom ekonomijom: Od gospodarskih subjekata koji provode rušenje i izgradnju se zahtjeva mjera osiguranja da najmanje 70% (težinski) neopasnog građevinskog otpada i otpada od rušenja (isključujući prirodni materijal naveden u kategoriji 17 05 04 u Europska lista otpada uspostavljena Odlukom 2000/532/EZ) nastala na gradilištu budu pripremljena za ponovnu uporabu, recikliranje i oporabu drugog materijala, uključujući postupke zatrpavanja otpadom koji zamjenjuje druge materijale, u skladu s hijerarhijom otpada i EU Protokola o gospodarenju otpadom od gradnje i rušenja. U građevinsku dokumentaciju se ulažu dokaznice o nastalim količinama pojedine vrste otpada, na način da je iz istih razvidan obračun težine nastalog otpada koji je uključen u mjeru ponovne uporabe i recikliranja te njegova udjela u ukupnoj količini nastala otpada na gradilištu. Građevinski otpad koji je uključen u predmetnu mjeru se odvozi u odgovarajuće postrojenje za reciklažu, odnosno preradu u reciklirani materijal, a provedba mjere se dokazuje evidencijom o postupanju s otpadom ili očevidnikom o nastanku i tijeku otpada. Dokaznu dokumentaciju je potrebno čuvati na gradilištu te u jednom primjerku dostaviti Naručitelju. Naručitelj ima pravo provesti provjere pridržava li se gospodarski subjekt odredbi o izvršenju ugovora u skladu s EU načelima, u bilo kojem trenutku tijekom trajanja ugovora.
B104: Izvedba radova treba biti prema nacrtima, općim uvjetima i opisu radova, detaljima te važećim standardima i tehničkim uvjetima za odgovarajuću vrstu radova i obračunata u skladu s važećim građevinskim normama. Ukoliko građevinske norme ne postoje za istu vrstu radova, treba se služiti tehničkim uvjetima za izvođenje odgovarajućih radova. Eventualna odstupanja treba prethodno dogovoriti s nadzornim inženjerom i projektantom za svaki pojedini slučaj. U slučaju nesuglasica između građevinskih normi i tehničkih uvjeta, važeći su uvjeti obračuna i rada iz građevinskih normi.
B105: Prije početka radova izvođač treba kontrolirati na gradilištu sve mjere potrebne za njegov rad te pregledati sve podloge prema kojima će izvoditi radove. Naročitu pažnju kod toga treba posvetiti usuglašavanju građevinskih i instalaterskih nacrta. Ako ustanovi neke razlike u mjerama, nedostatke ili pogreške u podlogama, dužan je pravovremeno obavijestiti nadzornog inženjera i projektanta te zatražiti rješenja. Sve eventualne nejasnoće treba izvođač riješiti sa projektantom prije davanja ponude, jer se naknadni zahtjevi neće uvažiti. Prije izvođenja radova treba provjeriti kvalitetu materijala koji se ugrađuje, od strane projektanta ili nadzornog inženjera i izvesti radove u skladu s detaljima izvedbe i opisom iz troškovnika.
...

Sheet 1.ZEM.
A2: 01. | D2: PRIPREMNI I ZEMLJANI RADOVI
D4: NAPOMENA:
D5: OPĆI UVJETI SU SASTAVNI DIO SVAKE POJEDINE STAVKE. Sve što je navedeno u njima, a nije u pojedinačnom opisu stavke smatra se uključenim u jediničnu cijenu.
D6: Iskopi i zatrpavanja za sve rovove za polaganje vodovoda i kanalizacije, te kanalizaciona okna i vodomjerno okno obračunati su u troškovniku vodoopskrbe i odvodnje.
A8: Red. | B8: br. | D8: Opis stavke | E8: J.m. | F8: Kol. | G8: Jed.cijena | H8: Uk.cijena
A10: 01. | B10: 01. | D10: Čišćenje terena na mjestu izgradnje. U cijenu je obuhvaćeno sječenje grmlja, stabala, te uklanjanje korjenja, te svog otpadnog materijala i sl. Stavka uključuje utovar i odvoz, a raspolaganje drvom dogovoriti s predstavnikom Investitora i Nadzornim inženjerom. Obračun po m² očišćene površine.
E11: m² | F11: 2325 | G11: 1 | H11: =SUM(F11*G11) -> 2325
A13: 01. | B13: 02. | D13: Izvedba pripremnih radova što prema općim i posebnim uvjetima obuhvaća slijedeće: kontrolu i određivanje točnih geodetskih visina, provjeru mjera i veličina obuhvata, kontrolu i markiranje trasa instalacija i priključaka, kao i druge pripremne radove koje je potrebno izvesti kako bi se mogao definirati opseg radova, potrebni zahvati, te izraditi plan i redoslijed aktivnosti. Radove je obvezan izvršiti izvođač prije nego pristupi izvođenju ostalih radova, prema zajednički utvrđenoj dinamici od strane investitora i izvođača.
D14: Iskolčenje građevine i svih elemenata uređenja parcele (elemenata krajobraznog uređenja, pješačkih i kolnih površina ). Pri izvođenju iskolčenja izraditi nanosnu skelu i postavljanje i održavanje dobro uočljivih iskolčenih oznaka na terenu od početka radova do predaje Skela mora biti čvrsto ugrađena u zemlju tako da ne postoji mogućnost njenog pomicanja tokom trajanja radova. Iskolčenje izvršiti geodetskim instrumentima.
D15: Po izvršenom iskolčenju sastaviti zapisnik o iskolčenju. Obračun se vrši po izlasku na teren.
E16: kompl. | F16: 1 | G16: 4000 | H16: =SUM(F16*G16) -> 4000
A18: 01. | B18: 03. | D18: Izlazak ovlaštenog geomehaničara na lokaciju u vrijeme izvedbe iskopa za temelje najmanje 3 puta, ili po dogovoru. Jedinična cijena jednog izlaska. Obračun po stvarnoj količini izlazaka.
E19: kom | F19: 1 | G19: 500 | H19: =SUM(F19*G19) -> 500
A21: 01. | B21: 04. | D21: Strojni iskop gornjeg sloja humusa debljine cca 30 cm. Stavka obuhvaća strojni iskop humusa sa guranjem do 50 m, te utovar i odvoz na privremenu deponiju na gradilištu za kasniju upotrebu. Obračun po m³ iskopa u sraslom stanju.
E22: m³ | F22: 290 | G22: 15 | H22: =SUM(F22*G22) -> 4350
A24: 01. | B24: 05. | D24: Strojni široki iskop u zemlji "C" kategorije sa odbacivanjem materijala u stranu. Iskop izvesti sa kosinama iskopa prilagođenim kategoriji terena (60°). Ako geomehaničar odredi uvidom na licu mjesta da treba izvesti zamjenu materijala ispod temelja iskop se vrši do nosivog terena. Stavka obuhvaća strojni iskop zemlje sa guranjem do 50 m, te utovar i odvoz na privremenu deponiju na gradilištu za kasniju upotrebu. Obračun po m³ iskopa zbijene zemlje.
D25: Iskop prema kotama u izvedbenom projektu: do kote -0.75
E26: m³ | F26: 161 | G26: 15 | H26: =SUM(F26*G26) -> 2415
A28: 01. | B28: 06. | D28: Strojni iskop zemlje za temeljne trake prema zadanom profilu u zemlji "C" kategorije. U cijeni je uključen iskop i osiguranje iskopa od urušavanja s razupiranjem ako je to potrebno, utovar i odvoz, odnosno odbacivanje zemlje na rub jame za naknadno zatrpavanje iskopa oko temelja. Obračun po m³ iskopa zbijene zemlje.
D29: Iskop prema kotama u izvedbenom projektu:
C30: a. | D30: do kote -1.65 | E30: m³ | F30: 370 | G30: 15 | H30: =SUM(F30*G30) -> 5550
C31: a. | D31: do kote -1.02 | E31: m³ | F31: 56.3 | G31: 15 | H31: =SUM(F31*G31) -> 844.5
C32: a. | D32: do kote -1.40 | E32: m³ | F32: 11.8 | G32: 15 | H32: =SUM(F32*G32) -> 177
A34: 01. | B34: 07. | D34: Strojni široki iskop zemlje u prosječnom sloju od 40 cm za izvedbu slojeva kolne površine na terenu interne pritsupne prometnice prema zadanom profilu, u zemlji "C" kategorije. Stavka obuhvaća strojni iskop zemlje sa guranjem do 50 m, te utovar i odvoz na privremenu deponiju na gradilištu za kasniju upotrebu. Obračun po m³ iskopa zbijene zemlje.
E35: m³ | F35: 183 | G35: 15 | H35: =SUM(F35*G35) -> 2745
A37: 01. | B37: 08. | D37: Strojni široki iskop zemlje u prosječnom sloju od 40 cm za izvedbu slojeva na terenu za vanjska parkirališta prema zadanom profilu, u zemlji "C" kategorije. Stavka obuhvaća strojni iskop zemlje sa guranjem do 50 m, te utovar i odvoz na privremenu deponiju na gradilištu za kasniju upotrebu. Obračun po m³ iskopa zbijene zemlje.
E38: m³ | F38: 111 | G38: 15 | H38: =SUM(F38*G38) -> 1665
A40: 01. | B40: 09. | D40: Strojni iskop iskop zemlje u prosječnom sloju 20 za izvedbu slojeva popločane pješačke površine prema zadanom profilu u zemlji "C" kategorije. Stavka obuhvaća strojni iskop zemlje sa guranjem do 50 m, te utovar i odvoz na privremenu deponiju na gradilištu za kasniju upotrebu. Obračun po m³ iskopa zbijene zemlje.
E41: m³ | F41: 35 | G41: 20 | H41: =SUM(F41*G41) -> 700
A43: 01. | B43: 10. | D43: Planiranje dna iskopa za radove u st. 1.05.- 1.09., s točnošću +/- 2 cm, uključivo odsijecanje i prebacivanje viška iskopa. Izvesti ručno. Obračun po m².
E44: m² | F44: 1267 | G44: 3 | H44: =SUM(F44*G44) -> 3801
A46: 01. | B46: 11. | D46: Dobava, razastiranje i planiranje sloja nabijenog šljunka ili tucanika debljine 20 cm u iskopu kao podloge ispod ab temeljne konstrukcije okoliša, građevine, te podnih ploča uz nabijanje do potrebne zbijenosti po uputi geomehaničara. Obračun po m³ planiranog nabijenog šljunka.
C47: a. | D47: debljine 20 cm (ispod građevine) | E47: m³ | F47: 181 | G47: 50 | H47: =SUM(F47*G47) -> 9050
C48: b. | D48: debljine 20 cm (pristupni pješački putevi) | E48: m³ | F48: 35 | G48: 50 | H48: =SUM(F48*G48) -> 1750
C49: c. | D49: debljine 35 cm (kolni pristup - zbijenost podloge (Ms>=80 MN/m2)) | E49: m³ | F49: 97 | G49: 50 | H49: =SUM(F49*G49) -> 4850
C50: c. | D50: debljine 30 cm (parkirališta) | E50: m³ | F50: 84 | G50: 50 | H50: =SUM(F50*G50) -> 4200
A52: 01. | B52: 12. | D52: Dobava i ugradnja geotekstila (netkani geotekstil 300 g/m2) ispod tamponskog sloja vanjskih površina opločenja. Isti treba položiti na pripremljeno temeljno tlo (isplanirano i sabijeno). Minimalni preklop je 30 cm. Stavkom obuhvaćen sav materijal, oprema i rad.
E53: m² | F53: 180 | G53: 3 | H53: =SUM(F53*G53) -> 540
A55: 01. | B55: 13. | D55: Dobava, razastiranje i planiranje sloja pijeska s dodatkom 10% hidrauličkog vapna debljine 5cm u iskopu kao podloge za postavljanje završnih obloga uređenja okolišnih staza oko građevine. Obračun po m³ planiranog sloja.
E56: m³ | F56: 173 | G56: 5 | H56: =SUM(F56*G56) -> 865
...

Sheet 2. BET. I AB
A2: 02. | D2: BETONSKI I ARMIRANO BETONSKI RADOVI
D4: Napomena:
D5: OPĆI UVJETI SU SASTAVNI DIO SVAKE POJEDINE STAVKE. Sve što je navedeno u njima, a nije u pojedinačnom opisu stavke smatra se uključenim u jediničnu cijenu.
D6: U cijeni pojedine stavke armirano-betonskih radova obuhvaćeno:
D7: Dobava betona, ugradba u konstrukciju sa svim pripremnim radovima, skele, oplata, zaštita betona od niskih i visokih temperatura, projekt betona, te ispitivanje uzoraka. Sva potrebna oplata (predviđena je glatka s bandažiranim spojevima), postava i skidanje sa svim potrebnim podupiranjima. Svi potrebni popravci betoniranih elemenata nakon skidanja oplate kao i zapunjavanje otvora nastalih od elemenata oplate (vezači razupore, distanceri i td.) te uređenje betona na spojevima oplate. Jedinična cijena u betonskim radovima se odnosi na kompletan rad i materijal (beton s oplatom i umetcima XPS-a). Obračun radova za betonske i arm. betonske konstrukcije izvodi se prema važećim propisima i prosječnim normama u građevinarstvu, ako to nije troškovnikom drugačije predviđeno.
D8: Armiranobetonski radovi za vodomjerno okno obračunati su u troškovniku vodoopskrbe i odvodnje.
A10: Red. | B10: br. | D10: Opis stavke | E10: J.m. | F10: Kol. | G10: Jed.cijena | H10: Uk.cijena
A12: 02. | B12: 01. | D12: Izvedba betonske podloge C12/15 temeljnih konstrukcija debljine d=10 cm ispod trakastih temelja građevine, trakastih temelja zidova okoliša i rubnih temelja podnih ploča. Izvodi se na prethodno zbijenoj podlozi. Oplata ruba uključena u cijenu. Kod betoniranja obavezno pratiti projekte instalacija. Ugradba strojna. Obračun po m³ ugrađenog betona.
E13: m³ | F13: 30 | G13: 150 | H13: =SUM(F13*G13) -> 4500
A15: 02. | B15: 02. | D15: Izvedba armiranobetonske podloge C12/15 debljine d=5 cm ispod podne ploče građevine i podnih ploča terasa. Oplata ruba uključena u cijenu. Kod betoniranja obavezno pratiti projekte instalacija. Ugradba strojna. Obračun po m³ ugrađenog betona.
E16: m³ | F16: 30 | G16: 150 | H16: =SUM(F16*G16) -> 4500
A18: 02. | B18: 03. | D18: Izvedba AB trakastih temelja (80x80 cm) i nadtemeljnih zidova (d=20 cm) betonom C25/30 u glatkoj rubnoj oplati. Temelji i nadtemeljni zidovi se betoniraju po redosljedu i uputi projektanta konstrukcije. Kod betoniranja obvezno pratiti projekte instalacija, te prodore cijevi brtviti. Ugradnja strojna. Jediničnom cijenom obračunati svu potrebnu oplatu kao i sva potrebna podupiranja. Temelje izvesti prema izvedbenoj dokumentaciji. Obračun po m³ ugrađenog betona.
C19: a. | D19: trakasti temelji 80x80 cm | E19: m³ | F19: 210 | G19: 250 | H19: =SUM(F19*G19) -> 52500
C20: b. | D20: nadtemeljni zidovi 20 cm | E20: m³ | F20: 25.7 | G20: 550 | H20: =SUM(F20*G20) -> 14135
A22: 02. | B22: 04. | D22: Izvedba AB rubnih trakastih temelja (40x80 cm) podnih ploča terasa betonom C25/30 u glatkoj rubnoj oplati. U cijenu stavke uključiti i izvedbu AB nadtemeljnog zida okoliša (ulazni podest) d=20 cm. Temelji se betoniraju po redosljedu i uputi projektanta konstrukcije. Kod betoniranja obvezno pratiti projekte instalacija, te prodore cijevi brtviti. Ugradnja strojna. Jediničnom cijenom obračunati svu potrebnu oplatu kao i sva potrebna podupiranja. Temelje izvesti prema izvedbenoj dokumentaciji. Obračun po m³ ugrađenog betona.
C23: a. | D23: trakasti temelji 40x80 cm | E23: m³ | F23: 6.85 | G23: 350 | H23: =SUM(F23*G23) -> 2397.5
C24: b. | D24: nadtemeljni zidovi 20 cm | E24: m³ | F24: 3.2 | G24: 550 | H24: =SUM(F24*G24) -> 1760
A26: 02. | B26: 05. | D26: Izvedba AB trakastih temelja vanjskih stuba i rampa na tlu betonom C25/30 u glatkoj rubnoj oplati. Temelji stuba su dim 40x100 i 50x97 cm, a rampe su dim 40x80 i 50x85 cm. Temelji se betoniraju po redosljedu i uputi projektanta konstrukcije. Kod betoniranja obvezno pratiti projekte instalacija, te prodore cijevi brtviti. Ugradnja strojna. Jediničnom cijenom obračunati svu potrebnu oplatu kao i sva potrebna podupiranja. Temelje izvesti prema izvedbenoj dokumentaciji. Obračun po m³ ugrađenog betona.
C27: a. | D27: trakasti temelji stuba dim 40x100 i 50x97 cm | E27: m³ | F27: 8.7 | G27: 350 | H27: =SUM(F27*G27) -> 3045
C28: b. | D28: trakasti temelji rampe dim 40x80 i 50x85 cm | E28: m³ | F28: 4 | G28: 350 | H28: =SUM(F28*G28) -> 1400
A30: 02. | B30: 06. | D30: Izvedba AB ploče prizemlja zgrade na tlu debljine d=16 cm i podnih ploča terasa debljine d=16 cm. Ploče su zaglađene s gornje strane kao priprema za postavljanje hidroizolacije i izvode se betonom C25/30 u glatkoj rubnoj oplati. Ploča se betonira po redosljedu i na način po uputi projektanta konstrukcije. Jediničnom cijenom obračunati svu potrebnu oplatu i sva potrebna podupiranja. Kod betoniranja obvezno pratiti projekte instalacija. Ugradba strojna. Obračun po m³ ugrađenog betona.
E31: m³ | F31: 94 | G31: 180 | H31: =SUM(F31*G31) -> 16920
A33: 02. | B33: 07. | D33: Izvedba AB ploče rampe na tlu debljine d=16 cm. Ploča se izvodi u nagibu od 5%, zaglađena je s gornje strane kao priprema za postavljanje hidroizolacije i izvodi se betonom C25/30 u glatkoj rubnoj oplati. Ploča se betonira po redosljedu i na način po uputi projektanta konstrukcije. Jediničnom cijenom obračunati svu potrebnu oplatu i sva potrebna podupiranja. Kod betoniranja obvezno pratiti projekte instalacija. Ugradba strojna. Obračun po m³ ugrađenog betona.
E34: m³ | F34: 2.15 | G34: 220 | H34: =SUM(F34*G34) -> 473
A36: 02. | B36: 08. | D36: Izvedba AB vanjskih stubišnih krakova i ulaznog podesta na tlu. AB ploča podesta je d=16 cm i zaglađena je s gornje strane kao priprema za postavljanje hidroizolacije. Stube i podest izvode se betonom C25/30 u glatkoj rubnoj oplati. Sve prema izvedbenom projektu i statičkom proračunu. Jediničnom cijenom obračunati svu potrebnu oplatu i sva potrebna podupiranja. Kod betoniranja obvezno pratiti projekte instalacija. Ugradba strojna. Obračun po m³ ugrađenog betona.
C37: a. | D37: stube | E37: m³ | F37: 1.3 | G37: 1000 | H37: =SUM(F37*G37) -> 1300
C38: b. | D38: ulazni podest | E38: m³ | F38: 14.7 | G38: 250 | H38: =SUM(F38*G38) -> 3675
A40: 02. | B40: 09. | D40: Izvedba vanjskih AB zidova prizemlja, 1. i 2 kata debljine 20 cm betonom C25/30 u dvostranoj glatkoj oplati. U cijenu uključena potrebna oplata za glatki beton, te kutije za otvore i prodore u zidovima. Brtvljenje dilatacionih reški izvesti elastomernim brtvama. Kod betoniranja obavezno pratiti projekte instalacija. Obračun po m³ ugrađenog betona.
C41: a. | D41: d=20 VZ1, VZ1', VZ2, VZ2', VZ3 | E41: m³ | F41: 248 | G41: 530 | H41: =SUM(F41*G41) -> 131440
A43: 02. | B43: 10. | D43: Izvedba unutarnjih AB zidova prizemlja, 1. i 2 kata debljine 20 cm betonom C25/30 u dvostranoj glatkoj oplati. U cijenu uključena potrebna oplata za glatki beton, te kutije za otvore i prodore u zidovima. Brtvljenje dilatacionih reški izvesti elastomernim brtvama. Kod betoniranja obavezno pratiti projekte instalacija. Obračun po m³ ugrađenog betona.
C44: a. | D44: d=20 RZ1, RZ2, RZ3, RZ4 | E44: m³ | F44: 260 | G44: 530 | H44: =SUM(F44*G44) -> 137800
A46: 02. | B46: 11. | D46: Betoniranje AB greda raznih presjeka betonom C25/30, u glatkoj oplati. Grede izvesti prema izvedbenoj dokumentaciji. U jediničnu cijenu uključena sva podupiranja i oplate. Obračun po m³ ugrađenog betona.
E47: m³ | F47: 13 | G47: 1000 | H47: =SUM(F47*G47) -> 13000
A49: 02. | B49: 12. | D49: Betoniranje AB ploča međukatnih konstrukcija - stropova prizemlja, 1. i 2. kata, debljine 20 cm, betonom C25/30, u glatkoj oplati. U jediničnoj cijeni uključena izvedba potrebne oplate i podupiranja, te radnih skela. Kod betoniranja obavezno pratiti projekte instalacija. Ugradba strojna. Ploču izvesti prema izvedbenoj dokumentaciji. Obračun po m³ ugrađenog betona.
C50: a. | D50: ploča strop prizemlja | E50: m³ | F50: 127 | G50: 350 | H50: =SUM(F50*G50) -> 44450
C51: b. | D51: ploča strop 1. kata | E51: m³ | F51: 127 | G51: 350 | H51: =SUM(F51*G51) -> 44450
C52: c. | D52: ploča strop 2. kata | E52: m³ | F52: 121 | G52: 350 | H52: =SUM(F52*G52) -> 42350
A54: 02. | B54: 13. | D54: Betoniranje AB krovne atike (zabati) zgrade debljine 20 cm i promjenjive visine (iznad AB ploče), betonom 25/30 cm. Atiku izvesti prema izvedbenoj dokumentaciji. U jediničnu cijenu uključena sva podupiranja i oplate. Kod betoniranja obavezno pratiti projekte instalacija. Ugradba strojna. Atiku izvesti prema izvedbenoj dokumentaciji. Obračun po m³ ugrađenog betona.
E55: m³ | F55: 32.5 | G55: 550 | H55: =SUM(F55*G55) -> 17875
A57: 02. | B57: 14. | D57: Betoniranje AB unutarnjih stubišnih krakova d=14 cm i podesta trokrakog stubišta d=14 cm (prizemlje - 1.kat - 2. kat). Jediničnom cijenom obračunati svu potrebnu oplatu i sva potrebna podupiranja. Ugradba strojna. Stube i ploče izvesti prema izvedbenoj dokumentaciji. Obračun po m³ ugrađenog betona.
...

Sheet 3. ZID.
A2: 03. | D2: ZIDARSKI RADOVI
D4: NAPOMENA:
D5: OPĆI UVJETI SU SASTAVNI DIO SVAKE POJEDINE STAVKE. Sve što je navedeno u njima, a nije u pojedinačnom opisu stavke smatra se uključenim u jediničnu cijenu.
D6: U jediničnim cijenama uračunati su svi radovi potrebni za izvršenje stavke, s dobavom potrebnog materijala i građevnih dijelova, s istovarom i uskladištenjem na gradilištu, sav horizontalni i vertikalni transport do radnog mjesta, kao i sva potrebna radna snaga i režijski troškovi. Sve potrebne skele za građevinske radove moraju biti uračunate u jediničnim cijenama pojedinih stavaka troškovnika, te se ne smiju posebno obračunavati. Ovo se ne odnosi na fasadnu skelu.
A8: Red. | B8: br. | D8: Opis stavke | E8: J.m. | F8: Kol. | G8: Jed.cijena | H8: Uk.cijena
A10: 03. | B10: 01. | D10: Zidarska obrada armiranobetonskih ploha izvedenih u glatkoj oplati za finalnu obradu (zidovi, stropovi, grede, stubište). Brušenje sitnih neravnina, naročito na sastavima oplate i rubovima. Zatvaranje i krpanje rupa od vezica i sl. Dobava materijala, transport do mjesta ugradbe, obrada ploha i obrada oko otvora obračunati su jediničnom cijenom.
C11: a. | D11: zidovi | E11: m² | F11: 2950 | G11: 3 | H11: =SUM(F11*G11) -> 8850
C12: b. | D12: stropovi, grede, stubišni krakovi i međupodest | E12: m² | F12: 1550 | G12: 3 | H12: =SUM(F12*G12) -> 4650
A14: 03. | B14: 02. | D14: Zidarska obrada armiranobetonskih ploha okoliša izvedenih u glatkoj oplati za finalnu obradu (parapetni zidovi ulaznog podesta). Brušenje sitnih neravnina, naročito na sastavima oplate i rubovima. Zatvaranje i krpanje rupa od vezica i sl. Dobava materijala, transport do mjesta ugradbe, obrada ploha i obrada oko otvora obračunati su jediničnom cijenom.
E15: m² | F15: 10 | G15: 20 | H15: =SUM(F15*G15) -> 200
A17: 03. | B17: 03. | D17: Izvedba plivajućeg cementnog estriha mikrobetona armiranog vlaknima (2200 kg/m³), fino zaglađenog u izvedbi i dilatiranog u polja, debljina prema specifikaciji u stavci. Postavlja se na PE foliju obračunatu u izolaterskim radovima. Podloga mora biti bočno odijeljen od zidova trakom elastificiranog polistirena d=2 cm u debljini podloge, obračunatog u izolaterskim radovima. Površina podloge mora biti ravna i završno fino zaglađena i obrađena te pripremljena za polaganje završnog poda, u lokalnom padu ka podnim slivnicima. Jediničnom cijenom obračunati potrebnu armaturu, kao i izvedbu radnih reški i njihovu obradu. Obračun po m².
C18: a. | D18: 5,5 cm - podovi na tlu (parket) - P1 | E18: m² | F18: 164 | G18: 18 | H18: =SUM(F18*G18) -> 2952
C19: b. | D19: 6 cm - podovi na tlu (keramika) - P1 | E19: m² | F19: 20 | G19: 30 | H19: =SUM(F19*G19) -> 600
C20: c. | D20: 5 cm - podovi na tlu - P1' i P2 | E20: m² | F20: 295 | G20: 18 | H20: =SUM(F20*G20) -> 5310
C21: d. | D21: 5,5 cm - međukatne konstrukcije (parket) - MK1, MK2, MK4, MK4'' | E21: m² | F21: 703 | G21: 18 | H21: =SUM(F21*G21) -> 12654
C22: e. | D22: 6 cm - međukatne konstrukcije (keramika) - MK1, MK2, | E22: m² | F22: 67 | G22: 22 | H22: =SUM(F22*G22) -> 1474
C23: f. | D23: 7 cm - međukatne konstrukcije - MK3 | E23: m² | F23: 121 | G23: 25 | H23: =SUM(F23*G23) -> 3025
C24: g. | D24: 5 cm - međukatne konstrukcije - MK1', MK2', MK4' | E24: m² | F24: 88 | G24: 18 | H24: =SUM(F24*G24) -> 1584
A26: 03. | B26: 04. | D26: Izvedba mikrobetona armiranog vlaknima (2500 kg/m³) i armaturnom mrežom fino zaglađenog u izvedbi debljina prema specifikaciji u stavci - otvoreni prostori. Površina podloge mora biti ravna i završno fino zaglađena i obrađena te pripremljena za polaganje završnog poda, u lokalnom padu ka podnim slivnicima. Jediničnom cijenom obračunati potrebnu armaturu, kao i izvedbu radnih reški i njihovu obradu. Obračun po m².
C27: a. | D27: u padu 6-8 cm - P3, MK5 | E27: m² | F27: 154 | G27: 30 | H27: =SUM(F27*G27) -> 4620
C28: b. | D28: ulazni podest d=6 cm - P4 | E28: m² | F28: 100 | G28: 30 | H28: =SUM(F28*G28) -> 3000
A30: 03. | B30: 05. | D30: Dobava, nabava i ugradnja podnog inox dilatacijskog "L" profila (praga) na mjestima spoja podnih obloga od različitih materijala. Profil minimalne širine 5 mm, visine prema visini završne podne obloge, učvršćen za podlogu navarenim sidrima. Profil ne smije viriti iz podne obloge. U cijeni kompletan materijal, sva pričvrsna i spojna sredstva, rad i alat do potpune gotovosti. Obračun po m'.
E31: m' | F31: 90 | G31: 20 | H31: =SUM(F31*G31) -> 1800
A33: 03. | B33: 06. | D33: Zidanje unutarnjih zidova blok opekom d=12 cm. Za zidanje zidova upotrebljava se produžni cementni mort M-5. U cijenu je uključen sav rad i materijal te potrebna skela. Obračun po m³.
D34: RZ5 | E34: m³ | F34: 60 | G34: 300 | H34: =SUM(F34*G34) -> 18000
A36: 03. | B36: 07. | D36: Zidanje instalacijskih šahtova u etaži potkrovlja punom opekom d=12 cm. Za zidanje zidova upotrebljava se produžni cementni mort M-5. U cijenu je uključen sav rad i materijal te potrebna skela. Obračun po m³.
E37: m³ | F37: 109 | G37: 35 | H37: =SUM(F37*G37) -> 3815
A39: 03. | B39: 08. | D39: Grubo i fino žbukanje vapneno cementnom žbukom debljine do 1,5 cm, 1800kg/m3 unutarnjih zidova od opeke. Sve spojeve različitih materijala obvezno rabicirati. Na sve uglove, vertikalne ili horizontalne, montirati zaštitne uglovne, odnosno sokl profile. U svemu prema uputama proizvođača odabranog proizvoda. U cijeni stavke sav potreban materijal, rad, priprema podloge, transporti i radna skela. Obračun po m².
E40: m² | F40: 1025 | G40: 18 | H40: =SUM(F40*G40) -> 18450
A42: 03. | B42: 09. | D42: Dobava montažnog dimovodno-dozračnog sustava koji se sastoji od dimovodnih cijevi od profilne izostatičke tehničke keramike (visina 66cm i 33cm), plašteva od laganog betona (visina 33cm, gustoća 1150 kg/m3), te ostalih elemenata prema uputi proizvođača. U negrijanom dijelu dimnjak je potrebno dodatno izolirati, a odvod kondenzata spojiti na kanalizacijski sustav preko sifona pri ugradnji.
D43: Namjena: ložište na plinsko gorivo
D44: Svojstva 1 prema HRN EN 13063-2: T200 P1 W2 O00 ili jednakovrijednoj; Svojstva 2 prema HRN EN 13063-3: T200 P1 W2 O00 ili jednakovrijednoj
D45: Dimenzije: dimovodni otvor Φ12cm, koncentrični dozračni otvor 19*19cm, vanjska mjera 28*28cm
C46: a. | D46: Komplet se sastoji od: posuda za kondenzat, otvor za reviziju i čišćenje x2, priključak ložišta x3, završna ploča s dozračnom rešetkom i konusom - ukupna visina 11,4 m | E46: kpl | F46: 4 | G46: 4400 | H46: =F46*G46 -> 17600
C47: b. | D47: Komplet se sastoji od: posuda za kondenzat, otvor za reviziju i čišćenje x2, priključak ložišta x2, završna ploča s dozračnom rešetkom i konusom - ukupna visina 8,5 m | E47: kpl | F47: 3 | G47: 3600 | H47: =F47*G47 -> 10800
C48: c. | D48: Ugradnja svih gore navedenih stavki dimnjaka | E48: m1 | F48: 72 | G48: 80 | H48: =SUM(F48*G48) -> 5760
A50: 03. | B50: 10. | D50: Nabava doprema i ugradnja materijala za protupožarno brtvljenje na prodoru instalacija (strojarske, elektro i instalacije vodovoda i idvodnje) kroz stropne, podne i zidne konstrukcije na granicama požarnih sektora. Protupožarno brtvljenje se izvodi atestiranim materijalom iste klase vatrootpornosti kao klasa građevinskog elementa, a sve u skaldu sa HRN EN 1366-3. Stavka obuhvaća sav potreban materijal i alat na ugradnji istih. Obračun se vrši po komadu kompletno izvedenog protupožarnog brtvljenja.
E51: kom | F51: 90 | G51: 30 | H51: =SUM(F51*G51) -> 2700
A53: 03. | B53: 11. | D53: Krpanje šliceva instalacijskih prodora
D54: Krpanje šliceva instalacijskih prodora cementnim mortom. Obračun po m1.
...

Sheet 4.SKELE
A2: 04. | D2: SKELE
D4: NAPOMENA:
D5: OPĆI UVJETI SU SASTAVNI DIO SVAKE POJEDINE STAVKE. Sve što je navedeno u njima, a nije u pojedinačnom opisu stavke smatra se uključenim u jediničnu cijenu.
D6: Pomoćne skele prema općim uvjetima ovog troškovnika.
A8: Red. | B8: br. | D8: Opis stavke | E8: J.m. | F8: Kol. | G8: Jed.cijena | H8: Uk.cijena
A10: 04. | B10: 01. | D10: Dovoz, montaža, najam i demontaža cijevne fasadne skele s podnicama, ogradom u visini svake etaže. Skela služi za izvedbu svih radova izvan objekta odnosno na fasadi objekta i krovištu objekta, ali i svim drugim radovima koji zahtijevaju fasadnu skelu. Svi radovi oko postave, razne preinake i odvoz fasadne skele uključeni su u jediničnu cijenu. Skelu treba postaviti tako da se nesmetano može pristupiti svim pročeljnim elementima. Širina skele je 100 cm, montira se na nužnoj udaljenosti od pročelja za nesmetano odvijanje radova. Skela mora biti propisno popođena mosnicama i ukrućena prema svim važećim propisima zaštite na radu i hrvatskim normama, a sigurna za sve prolaznike. Sidrenjem u objekt skela se mora osigurati od prevrtanja, a isto tako skelu je potrebno uzemljiti i osigurati od udara groma. Za skelu je potrebno napraviti statički proračun i nacrt te dati na potvrdu nadzornom inženjeru.
D11: Skela mora biti opremljena ogradama te čvrstom zaštitnom ceradom u punoj visini, penjalicama te laganim zaštitnim krovom od plastičnih ploča na svakoj gornjoj otvorenoj etaži radi kontinuirane izvedbe radova. Skela se montira na svim pročeljima. Visina skele od kote terena iznosi do 12,50 m zavisno o koti terena koja varira. Neposredno iznad poda treba izvesti punu daščanu ogradu visine 20 cm u svrhu zaštite od padanja materijala sa poda skele. Visina ograde sa vanjske strane skele iznosi 120 cm. Skelu treba izvesti uz propisnu signalizaciju kako to nalažu postojeći HTZ propisi.
D12: Materijal za skelu mora biti ispravan, prema svim važećim hrvaskim normama i pregledan od odgovorne osobe prije montaže. Skela je obračunata kao cjelokupna površina pročelja i može biti obračunata samo jednom u toku cjelokupne izgradnje. Prije izvedbe skele izvođač je dužan izraditi projekt skele što je u cijeni stavke. Obračun se vrši po m² vertikalne projekcije površine skele.
E13: m² | F13: 1680 | G13: 13 | H13: =SUM(F13*G13) -> 21840
A15: 04. | D15: SKELE UKUPNO: | H15: =SUM(H11:H14) -> 21840

Sheet 5.IZOL.
A2: 05. | D2: IZOLATERSKI RADOVI
D4: NAPOMENA:
D5: OPĆI UVJETI SU SASTAVNI DIO SVAKE POJEDINE STAVKE. Sve što je navedeno u njima, a nije u pojedinačnom opisu stavke smatra se uključenim u jediničnu cijenu.
D6: U jediničnim cijenama uračunati su svi radovi dotične stavke, s dobavom potrebnog materijala, s istovarom i uskladištenjem na gradilištu, sav horizontalni i vertikalni transport do radnog mjesta, kao i sva potrebna radna snaga i režijski troškovi, te sve potrebne radove, predradnje i materijal prema uputama proizvođača. (hladni premazi, impregniranja, čišćenja).
D7: U cijenu stavke uključena sva potrebna krojenja oko prodora, istaka i sl.
A9: Red. | B9: br. | D9: Opis stavke | E9: J.m. | F9: Kol. | G9: Jed.cijena | H9: Uk.cijena
D11: HIDROIZOLACIJE | F11: =IF(ISNUMBER(#REF!),IF(OR(E11="m1",E11="m2",E11="m3",E11="kg"),INT(#REF!*(1+#REF!/100)+0.999),INT(#REF!+0.999)),"")
A12: 05. | B12: 01. | D12: Hidroizolacija podnih ploča na tlu. Dobava i postava hidroizolacijske polimer-bitumenske plastomerne membrane težine 4.0 kg/m2, obostrano zaštićene sa PE folijom, ojačana staklenim voalom, prema EN 13707 ili jednakovrijedan ____________. Karakteristike: vlačna čvrstoća, uzdužna/poprečna: min. 300/200 N/mm (±20%) (12311-1 ili jednovrijedna __________), rastezanje, uzdužno/poprečno: min. 2/2 % (EN 12311-1 ili jednakovrijedan ____________). | F12: =IF(ISNUMBER(#REF!),IF(OR(E12="m1",E12="m2",E12="m3",E12="kg"),INT(#REF!*(1+#REF!/100)+0.999),INT(#REF!+0.999)),"")
D13: Membrana se ugrađuje u 2 sloja (bočni preklopi; 100mm, čeoni preklopi: 150mm) na podlogu pripremljenu sa temeljnim bitumenskim premazom u sustavu proizvođača membrane. Svi proizvodi trebaju biti kompatibilni. Radove izvesti prema uputama proizvođača materijala. Uključena obrada prodora. Obračun po m² površine.
D14: P1, P1', P2, P3, P4 | E14: m² | F14: 600 | G14: 28 | H14: =SUM(F14*G14) -> 16800
A16: 05. | B16: 02. | D16: Dobava i postava horizontalne i vertikalne hidroizolacije ukopanih dijelova građevine (dijelovi temelja i nadtemeljnih zidova) te sokla građevine. Izvodi se iz jednokomponentene elastomerne bitumenske tekuće membrane na vodenoj bazi, sve prema EN 1504-2 ili
D17: jednakovrijedna, EN 14891 ili jednakovrijedna, te EN 15814 ili jednakovrijedna____________. Karakteristike: gustoća min 1,50 kg/lit (EN 2811-1 ili jednakovrijedna________________); sadržaja VOC manje od 2g/l (EN 11890-2 ili jednakovrijedna________________); vlačna uzdužna čvrstoća armiranog sustava: min. 660 N (EN 12311-2 ili jednakovrijedna _________); poprečna vlačna čvrstoća armiranog sustava: min. 650 N (EN 12311-2 ili jednakovrijedna __________); izduljenje pri slomu armiranog sustava uzdužno: min. 48% (EN 12311-2 ili jednakovrijedna __________); izduljenje pri slomu armiranog sustava poprečno: min. 50% (EN 12311-2 ili jednakovrijedna_____________); vlačna čvrstoća prionjivosti : min. 2,5 MPa( En 1542 ili jednakovrijedna______________), na beton min: 1,5 N/mm2 (EN 14891 ili jednakovrijedna ___________); premošćenje pukotina: min. 3,5 mm pri 20 °C / min. 1,5 mm pri -5 °C (EN 14891 ili jednakovrijedna___________) i klasa CB2 (EN 15812 ili jednakovrijedna__________); paropropusnost :klasa II (EN 7783 ili jednakovrijedna___________); vodonepropusnost : min. 500 kPa (EN 14891 ili jednakovrijedna_________).
D18: Tekuća membrana se ugrađuje četkom, valjkom , gleterom ili strojno na podlogu (cementna, opeka, pločice, metal, drvo...) i sa svim dodatnim elementima istog sustava specificiranim od strane proizvođača materijala. Zaštita membrane na vertikali sa HDPE čepastom membranom ili XPSom (obračunato u drugoj stavci). Uključena obrada svih prodora uključujući cjevi, gromobran, pilote i sl.). Radove izvesti prema uputama proizvođača materijala. Svi proizvodi u sustavu trebaju biti kompatibilni. Obračun po m² površine.
D19: VZ1', VZ2', VZ3 | E19: m² | F19: 180 | G19: 30 | H19: =SUM(F19*G19) -> 5400
A21: 05. | B21: 03. | D21: Dobava i postava jednokomponentnog hidroizolacijskog morta na bazi cementa za brtvljenje betonskih ili cementnih površina. Prekid kapilarne vlage. Karakteristike: tlačne čvrstoće~ 35 N/mm2 prema EN 12190 ili jednovrijedna __________ , vlačne čvrstoće ~ 6 N/mm2 prema EN 12190 jednovrijedna _________, propusnost vodene pare SD < 5 m (klasa I) prema EN ISO 7783 jednovrijedna __________ , na betonskim površinama. Premaz se ugrađuje u 2 sloja na pripremljenu betonsku podlogu četkom i/ili gleterom s potrošnjom ca 4,0 kg/m2. Radove izvesti prema uputama proizvođača materijala. Obračun po m² obrađene površine.
E22: m² | F22: 280 | G22: 20 | H22: =SUM(F22*G22) -> 5600
A24: 05. | B24: 04. | D24: Izvedba sigurnosne hidroizolacije sanitarnih prostora na katovima, postavom dvokomp. elastičnog hidroizolacijskog morta na bazi cementa sa specijalnim alkalno otpornim polimerima, i sadržajem finih čestica agregata i odgovarajućih aditiva za hidroizolaciju. Mort se izvodi na za to pripremljenu podlogu (podloga mora biti suha, čista, bez udjela ulja i masti, bez nevezanog materijala i cementnog mlijeka) u dva sloja ukupne debljine 3 mm. U slučaju većih deformacija u prvi sloj je potrebno ugraditi polipropilensku mrežicu za armiranje. Sve spojeve zidova i ploča izvesti sa dodatnim ojačanjem (PP mrežica sa PVC ojačanjem za veće pomake). Potrošnja cca. 5 - 6 kg/mm/m². Svi detalji pričvršćivanja i spojeva, izvode se prema uputstvima proizvođača, uključivo sa dobavom potrebnog spojnog materijala u cijeni stavke. Obračun po m².
D25: MK1', MK2', MK4' | E25: m² | F25: 90 | G25: 25 | H25: =SUM(F25*G25) -> 2250
A27: 05. | B27: 05. | D27: Dobava i postava hidroizolacije iz sintetičke membrane na bazi mekog PVC-a na balkonima/lođama, tj. na prohodnim krovovima, armirana poliesterskom mrežicom, debljine d= 1,5 mm, obostrano zaštićene sa slojem geotekstila : donji 500 g/m2 , gornji : 300 g/m2. Membrane se polažu i mehanički fiksiraju za podlogu, nehrđajućim vijcima s podložnom pločicom u skladu s proračunom proizvođača hidroizolacijske membrane. Spojevi se obrađuju toplinskim ili kemijskim putem sa širinom vara od min. 3 cm, preklop 12 cm, u skladu s propisanom tehnologijom od strane proizvođača membrane. Radove treba izvoditi tvrtka sa važećom potvrdom sa školovanja kod proizvođača membrane. Obračun po m² ugrađenog materijala.
D28: Jediničnom cijenom obračunata je i postava dvostrukog PP/PES filc (geotekstil) na slojeve hidroizolacije. Uključivo vertikalno podizanje hidroizolacije na bočne zidove u visini od 10 cm. U cijeni su svi potrebni odgovarajući holkeri za vertikalno povijanje izolacije.
D29: Svi detalji pričvršćivanja i spojeva, izvode se prema uputstvima proizvođača, uključivo sa dobavom potrebnog spojnog materijala u cijeni stavke. Obračun po m² komplet slojeva.
D30: MK5, K2 | E30: m² | F30: 100 | G30: 70 | H30: =SUM(F30*G30) -> 7000
A32: 05. | B32: 06. | D32: Dobava i ugradba drenažne PEHD čepasta traka za oblaganje ekstrudiranog polistirena vanjskog zida u tlu. Čepovi okrenuti prema vanjskoj hidroizolaciji. Obavezno izvesti preklapanje od 10 cm s žbukom pročelja.
D33: Svi detalji pričvršćivanja i spojeva, izvode se prema uputstvima proizvođača, uključivo sa dobavom potrebnog spojnog materijala u cijeni stavke. Obračun po m².
D34: VZ3 | E34: m² | F34: 65 | G34: 5 | H34: =SUM(F34*G34) -> 325
D36: PE FOLIJE
A37: 05. | B37: 07. | D37: Dobava i postava PE folije, d=0,2 mm sa preklopom 10 cm u slojevima plivajućeg poda i oblogama zidova. PE folija se postavlja na slojeve toplinske izolacije u podovima na tlu i u međukatne konstrukcije (prema fizici). Postava horizontalno - slobodno položeno; postava vertikalno- točkasto fiksirano. Svi detalji pričvršćivanja i spojeva, izvode se prema uputstvima proizvođača, uključivo sa dobavom potrebnog spojnog materijala u cijeni stavke. Obračun po m².
D38: P1, P1', P2, P4 | E38: m² | F38: 555 | G38: 2 | H38: =SUM(F38*G38) -> 1110
D39: MK1, MK1', MK2, MK2', MK3, MK3', MK3'', MK4, MK4', MK4'' | E39: m² | F39: 1050 | G39: 2 | H39: =SUM(F39*G39) -> 2100
D40: RZ1, RZ2 | E40: m² | F40: 184 | G40: 2 | H40: =SUM(F40*G40) -> 368
A42: 05. | B42: 08. | D42: Dobava i ugradnja razdjelnog sloja krovne oplatne folije (podložna membrana većeg stupnja vodonepropusnosti) ispod krovnog falcanog lima iz polimernog bitumena ojačanog staklenim voalom sa površinskim slojem od perforirane sintetičke tkanine, debljine 1,5 mm. Specifična težina cca. 1400 g/m2, samoljepljivi uzdužni spojevi. Polaganje s preklopima 10 cm oplatu od dasaka (uključena u tesarskim radovima). Sve prema uputstvima proizvođača, uključivo sa dobavom potrebnog spojnog materijala u cijeni stavke. Obračun po m² ugrađenog materijala.
D43: K1 | E43: m² | F43: 645 | G43: 4 | H43: =SUM(F43*G43) -> 2580
A45: 05. | B45: 09. | D45: Dobava i montaža sigurnosnog žljeba koji se sastoji iz polimerne jednoslojne membrane -TPO/FPO folije kojom se oblaže potkonsktrukcija ispod upuštenog žljeba RŠ 100cm.
E46: m2 | F46: 10 | G46: 150 | H46: =SUM(F46*G46) -> 1500
A48: 05. | B48: 10. | D48: Dobava i izvedba folije za apsolutnu parnu branu s Sd˃700 - polimerbitumenska hidroizolacijska traka s uloškom Alu folije (1000 kg/m³), d=0,4 cm, trake za zavarivanje na hladnom bitumenskom prednamazu. Membrana se slobodno polaže na podlogu u preklopu spoja od 8 cm. Ljepljenje uračunato u stavku.
D49: Svi detalji izvode se prema uputstvima proizvođača, uključivo sa dobavom svog potrebnog materijala u cijeni stavke. Obračun po m².
D50: K1 | E50: m² | F50: 645 | G50: 16 | H50: =SUM(F50*G50) -> 10320
D52: TOPLINSKE IZOLACIJE
A53: 05. | B53: 11. | D53: Dobava i izvedba toplinske izolacije poda na tlu grijanog, negrijanog i slabogrijanog prostora. Na zaglađenu betonsku podlogu postavljaju se
D54: elastificirani ekspandirani polistiren (EePS) 2x1 cm;
...

Sheet 6.LIM
A2: 06. | D2: LIMARSKI RADOVI
D4: NAPOMENA:
D5: OPĆI UVJETI SU SASTAVNI DIO SVAKE POJEDINE STAVKE. Sve što je navedeno u njima, a nije u pojedinačnom opisu stavke smatra se uključenim u jediničnu cijenu.
D6: U cijenu svake pojedine stavke uključeno: svi radovi dotične stavke, s dobavom potrebnog materijala, s istovarom i uskladištenjem na gradilištu, sav horizontalni i vertikalni transport do radnog mjesta, kao i sva potrebna radna snaga i režijski troškovi, te sve potrebne radove, predradnje i materijal prema uputama proizvođača. U svim stavkama uključen je sav vezni materijal, kuke, silikonski kit, ljepila, podložna protukondezacijska folija itd.
A8: Red. | B8: br. | D8: Opis stavke | E8: J.m. | F8: Kol. | G8: Jed.cijena | H8: Uk.cijena
A10: 06. | B10: 01. | D10: Dobava i montaža krovnog pokrova na krovima s različitim nagibima od 15-28° iz aluminijskih traka u boji prema odabiru projektanta u izvedbi s dvostrukim stojećim prijevojem (falc). Vertikalni dio prijevoja je stožast, tako da u donjem ležajnom području traka ostane dilatacijski razmak 3-5 mm. Postava na glatku daščanu oplatu debljine min. 24 mm, vlaga do 20%, širina daske do 16 cm. (obuhvačeno zasebnom stavkom u tesarskim radovima).
D11: Debljina materjala 0,70 mm, Širina nabavnog materijala 500 mm. Težina: 1.89kg/m² prije falcanja, 2,3 kg/m² nakon falcanja. Dimenzija nakon postave: osno: 430 mm, širina ploče: 420 mm. Trake su jednostrano plastificirane, stražnja strana transparentni zapečeni zaštitni lak. Boja: prema odabiru projektanta. Prije izvedbe izvođač je dužan donijeti projektantu uzorak lima na odobrenje. Kvaliteta i metoda bojanja lima: metoda kontinuiranog premaza lima (eng. coil coating). Garancija na boja min. 40 godina.
D12: Kvaliteta falcanog spoja: H41 iz alu. legure EN AW 3005 ili jednakovrijedno prema EN 573-3 ili jednakovrijedno. Razred reakcije na požar ''A1'' sukladno EN 13501-1 ili jednakovrijedno. Deklaracija proizvoda za okoliš prema ISO 14025 ili jednakovrijedno i EN 15804: EPD-GDA-20130260-IBG1-DE ili jedankovrijedno. Referentni vijek trajanja prema ekološkoj deklaraciji proizvoda: = 70 godina. Minimalno jamstvo na materjal 40 godina.
D13: Pričvršćenje traka pomoću nerđajućih fiksnih (2/3) i kliznih učvršćivača (1/3) uključeni u cijeni. Koristiti pričvrsnice sustavnog rješenja sa užljebljenih čavala od nehrđajućeg čelika i/ili vijke. Na oplatu položiti razdjelni bitumenski sloj sloj, krovna membrana sa samoljepljivim preklopom debljine 1.5mm (obuhvaćeno posebnom stavkom u izolaterskim radovima). Izvedba prema detaljnim uputama proizvođača. Obavezna uporaba gela za falcanje za nagibe ≥ 7° (13%) uključen u cijeni. U stavku uključiti sve krovne površine. Obračun po m² neto gotove površine krovova.
C14: a. | D14: krovovi nagiba do 7° | E14: m2 | F14: 35 | G14: 92 | H14: =F14*G14 -> 3220
C15: b. | D15: krovovi nagiba iznad 7° | E15: m2 | F15: 682 | G15: 100 | H15: =F15*G15 -> 68200
A17: 06. | B17: 02. | D17: Dobava i ugradnja donjeg početka pokrova iznad visećih žljebova u ventiliranoj izvedbi uključivo: 1.početnu traku za falcani alu lim r.š. 25 cm, 1,00 mm, 2. uljevni lim (okapni lim) r.š. 33 cm, 0,70 mm, 3. perforirane rešetke za dovod zraka od alu lim r.š. 12.5 cm, 0,7 mm. Rupe perforacije su promjera 5 mm. Boje i kvalitete materijala kao i osnovna pozicija. U cijenu uključiti eventualno potrebni pomoćni i spojni materijal, montirati vjetrootporno i s omogućenim dilatacijskim radom. Izvesti sve strogo prema uputstvima proizvođača kao sistemsko rješenje. Obračun po m'.
E18: m' | F18: 48 | G18: 100 | H18: =F18*G18 -> 4800
A20: 06. | B20: 03. | D20: Dobava i ugradnja donjeg početka pokrova iznad upuštenih žljebova u ne-ventiliranoj izvedbi uključivo: 1.početnu traku za falcani alu lim r.š. 25 cm, 1,00 mm, 2. uljevni lim (okapni lim) r.š. 25 cm, 0,70 mm, Boje i kvalitete materijala kao i osnovna pozicija. U cijenu uključiti eventualno potrebni pomoćni i spojni materijal, montirati vjetrootporno i s omogućenim dilatacijskim radom. Izvesti sve strogo prema uputstvima proizvođača kao sistemsko rješenje. Obračun po m'.
E21: m' | F21: 75 | G21: 100 | H21: =F21*G21 -> 7500
A23: 06. | B23: 04. | D23: Dobava i montaža opšava spoja upuštenog žljeba s fasadom sastavljen od: 1. aluminijske dopunske trake R.Š. 25cm debljine 0,70 mm u boji i kvaliteti materijala kao osnovna pozicija. Falcani spoj svakih 2m. 2. početne aluminijske limove RŠ 12 x 2 debljine 1,00 mm. 3. perforirane rešetke za dovod zraka od alu lim r.š. 12.5 cm, 0,7 mm. Rupe perforacije su promjera 5 mm. Postaviti na daščanu podlogu zaštićena razdjelnim slojem kao i u stavci 06.01. Obračun po m'.
E24: m' | F24: 75 | G24: 108 | H24: =G24*F24 -> 8100
A26: 06. | B26: 05. | D26: Dobava i ugradnja opšava zabatnih djelova krova pokrovnim limom kao osnovna pozicija od alu trakam debljine 0,70 mm (postava bočno-vertikalno na strehu) boje i kvalitete materijala kao osnovna pozicija (stavka 1) R.Š 35cm, uključivo donje početno-okapne alu trake r.š.20cm iz aluminija 1,00 mm montirati vjetrootporno i s omogućenim dilatacijskim radom. Obračun po m'.
E27: m' | F27: 46 | G27: 70 | H27: =F27*G27 -> 3220
A29: 06. | B29: 06. | D29: Dobava i montaža tipskog samonosivog ventiliranog sljemenjaka /grebena (jet-odzračnik) za ventilirane krovove, polukružnog oblika s labirintom za izlaz zraka. Sastavljen od unutarnje polukružne rešetkaste perforacije i obostrane podložne brtve.
D30: Boja i kvalitete materijala kao osnovna pozicija. Moraju se poštovati smjernice za polaganje: Pričvrsni materijal (nehrđajući vijci 4,5/60 mm sa brtvenom podloškom). Duljine komada: 3000/1200 mm Presjek ventilacije: 250 cm²/m Debljina materijala: 1,00 mm Stručno ugraditi, uključiti bočne tipske završne elemente i obradu kutnih spojeva dva ili tri grebena. Nužna tesarska priprema koja obuhvaća izrezivanje potrebnih otvora u krovnoj oplati uz porubljivanje ventilacijskog otvora prema van te obostranu postavu rubnih letvi 5x8cm po cijeloj dužini obrađeni su u zasebnoj stavci tesarskih radova. Obračun po m'.
E31: m' | F31: 65 | G31: 125 | H31: =F31*G31 -> 8125
A33: 06. | B33: 07. | D33: Dobava i montaža neventiliranih grebena sistemom opšivanja grebene letve (opisana zasebno u tesarskim radovima) 5x5 cm, boje i kvalitete materijala kao osnovna pozicija. Voditi računa o dilatacijskom radu pokrovnih traka. Obračun po m'.
E34: m' | F34: 35 | G34: 50 | H34: =F34*G34 -> 1750
A36: 06. | B36: 08. | D36: Dobava i ugradnja krovnih uvala u ne-ventiliranoj izvedbi uključivo uvalni lim RŠ 50 s duplim prevojem. Kvaliteta i boja materijala kao i osnovna pozicija pokrova. U cijenu uključiti nosivi lim (s obje strane plohe po jedan) RŠ 10 iz aluminija 1,0 mm i eventualno potrebni pomoćni i spojni materijal, montirati vjetrootporno i s omogućenim dilatacijskim radom. Napomena: Prelaz zraka iz jedne krovne plohe u drugoj izvodi se skraćivanjem letvama u drvenoj potkonstrukciji. Obračun po m¹ uključivo sve elemente.
E37: m' | F37: 75 | G37: 55 | H37: =F37*G37 -> 4125
A39: 06. | B39: 09. | D39: Dobava i ugradnja lomova krovnih ploha . Spoj je sastavljen od nosivog početnog lima za falcanje debljine 1,0 mm, (RŠ) 15 cm, te uključuje falc gel i pričvrsnice za završetak donjih krovnih traka. Obračun se vrši po dužnom metru (m¹), uključujući sve potrebne elemente za potpunu izvedbu. Obračun po m'.
E40: m' | F40: 65 | G40: 40 | H40: =F40*G40 -> 2600
A42: 06. | B42: 10. | D42: Dobava i ugradnja opšava otvora za odimljavanje dim. 126x126cm od aluminijskim limom d=0.7mm, r.š. 40 boje i kvalitete kao i osnovna pozicija. Montirati stručno u utorima ispod pokrivnih kapa prozora. Sve prema uputama proizvođača.
E43: kom | F43: 1 | G43: 170 | H43: =G43*F43 -> 170
A45: 06. | B45: 11. | D45: Dobava i montaža cijevnog snjegobrana za falcani pokrov od alu lima, u boji kao osnovna pozicija (plastificirano). Sastoji se iz jednostrukih alu stezaljki s izduženom rupom (materjal EN AW 6060 T66) za falcani pokrov s 1 alu cijevi kružnog presjeka Ø 28x2 mm. Uključivo hvatača leda, dva kom po traci, odnosno 5 kom m1. Snjegobrani postavljaju se uzduž upuštenih žlejbova odnosno iznad donjeg početka krova strogo prema uputama proizvođaća. Na svaki falc postavlja se po jedna stezaljka. Obračun po m'.
E46: m' | F46: 125 | G46: 70 | H46: =G46*F46 -> 8750
A48: 06. | B48: 12. | D48: Dobava i ugradnja opšava dimnjaka 38x38 cm (uključiti kitne lajsne) aluminijskim limom RŠ 40 boje i kvalitete kao i osnovna pozicija. Lim uzdignut minimalno 15 cm. Uklljučiti sav spojni i brtveni materijal. Obračun po komadu.
E49: kom | F49: 7 | G49: 150 | H49: =F49*G49 -> 1050
A51: 06. | B51: 13. | D51: Dobava i ugradnja opšava oko ventilacijskih otvora LRH na falcanom krovu od aluminijskim limom 0.7mm RŠ 40cm u boji i kvalitete kao i osnovna pozicija. Specijalno ljepilo uključeno u stavci. Element uzdignuti minimalno 15 cm oko prodora. Uklljučiti sav spojni i brtveni materijal.
C52: a. | D52: krovna kapa LRH 51x164 cm | E52: kom | F52: 1 | G52: 165 | H52: =F52*G52 -> 165
C53: b. | D53: krovna kapa LRH 51x89 cm | E53: kom | F53: 1 | G53: 162 | H53: =F53*G53 -> 162
