Workbook
Name __xlnm.Print_Area_1: #REF!
Name __xlnm.Print_Area_1: #REF!
Name __xlnm.Print_Area_1: #REF!
Name __xlnm.Print_Area_1: #REF!
Name __xlnm.Print_Area_1: #REF!
Name __xlnm.Print_Area_2: #REF!
Name __xlnm.Print_Area_2: #REF!
Name __xlnm.Print_Area_2: #REF!
Name __xlnm.Print_Area_2: #REF!
Name __xlnm.Print_Area_2: #REF!
Name __xlnm.Print_Area_3: #REF!
Name __xlnm.Print_Area_3: #REF!
Name __xlnm.Print_Area_3: #REF!
Name __xlnm.Print_Area_3: #REF!
Name __xlnm.Print_Area_3: #REF!
Name __xlnm.Print_Area_4: #REF!
Name __xlnm.Print_Area_5: #REF!
Name __xlnm.Print_Area_6: #REF!
Name __xlnm.Print_Titles_1: #REF!
Name __xlnm.Print_Titles_2: #REF!
Name __xlnm.Print_Titles_3: #REF!
Name __xlnm.Print_Titles_4: #REF!
Name __xlnm.Print_Titles_5: #REF!
Name NOVO: #REF!
Name Print_Area_MI: #REF!
Name Print_Area_MI: #REF!
Name Print_Area_MI: #REF!
Name Print_Area_MI: #REF!
Name Print_Area_MI: #REF!

Sheet NASLOVNICA
C2: INVESTITOR: | D2: REPUBLIKA HRVATSKA
D3: SISAČKO-MOSLAVAČKA ŽUPANIJA
D4: Ulica Stjepana i Antuna Radića 36
D5: 44000, Sisak
D6: OIB: 82215698659
C8: GRAĐEVINA: | D8: Rekonstrukcija i dogradnja zgrade 3 (bivša stražarnica) u sklopu Domobranske vojarne u Sisku i prenamjena u RCK Tehnička škola Sisak
C11: LOKACIJA: | D11: Sisak, Lađarska ulica 28A
D12: k.č.718/1 k.o. Novi Sisak
C14: BR. PROJEKTA : | D14: TD 2/24
A30: TENDER TROŠKOVNIK
B41: GLAVNI PROJEKTANT:
B43: Mate Žagar, dipl.ing.građ.
D49: Zagreb, prosinac 2024. god
D50: revizija 1: siječanj 2025. god.

Sheet SVEUKUPNA REKAPITULACIJA
C3: SVEUKUPNA REKAPITULACIJA ZGRADA 3
B5: 1. | C5: GRAĐEVINSKO-OBRTNIČKI RADOVI | G5: ='1_Građevinsko Obrtnički'!G1186 -> 2475854
B6: 2. | C6: VODOVOD I KANALIZACIJA | G6: ='VIK-REK'!G13 -> 254911.89
B7: 3. | C7: STROJARSKE INSTALACIJE | G7: ='3_STROJARSTVO'!F842 -> 355220
B8: 4. | C8: ELEKTROINSTALACIJE | G8: ='4_ELEKTROINSTALACIJE'!F777 -> 356777.42
B9: 5. | C9: VATRODOJAVA | G9: ='5_VATRODOJAVA'!F172 -> 32830
C11: UKUPNO | G11: =SUM(G5:G9) -> 3475593.3
C12: PDV 25% | G12: =G11*0.25 -> 868898.33
C14: SVEUKUPNO | G14: =G11+G12 -> 4344491.6

Sheet OTU
A2: NAPOMENA !
A3: VAŽNA NAPOMENA UZ TROŠKOVNIKE (odnosi se na sve troškovnike):
A4: Odredba o normama U dokumentaciji su navedena tehnička pravila koja opisuju predmet nabave pomoću hrvatskih odnosno europskih odnosno međunarodnih normi. Ponuditelj treba ponuditi predmet nabave u skladu s normama iz dokumentacije o nabavi ili jednakovrijednim normama. Stoga za svaku navedenu normu navedenu pod dotičnom normizacijskom sustavu dozvoljeno je nuditi jednakovrijednu normu, tehničko odobrenje odnosno uputu iz odgovarajuće hrvatske, europske ili međunarodne nomenklature.
A5: Jedinična cijena U jediničnim cijenama za sve stavke troškovnika, ponuda mora sadržavati ukupne troškove materijala i rada do potpunog dovršenja cjelokupnog posla odnosno do pune funkcionalnosti. Jedinična cijena, također, uključuje sva potrebna ispitivanja, kontrole i mjerenja za sve izvedene radove, ugrađene materijale i opremu, u svrhu dokazivanja njihove kvalitete i kompletiranja tehničke dokumentacije potrebne za ishođenje dozvola, te se prilikom primopredaje građevine, uručuje Investitoru odnosno krajnjem korisniku. Navedena ispitivanja, kontrole i mjerenja izvode ovlaštene institucije, a odnose se na ispitivanje plinskih instalacija, ispitivanje vodonepropusnosti kanalizacije, uzimanje uzoraka i ispitivanje pitkosti vode, ispitivanje gromobranske instalacije, ispitivanje električne instalacije jake i slabe struje, pregled dimovodnih kanala, te ostala potrebna ispitivanja sukladno važećoj zakonskoj regulativi. Napomena: Sve predmetno je obuhvaćeno jediničnom cijenom i ne navodi se kao zasebna stavka!
A6: POSEBNI, OPĆI I TEHNIČKI UVJETI UGOVARANJA I IZVOĐENJA
A7: OPĆI UVJETI
A8: Sve radove izvođač mora izvoditi prema troškovniku, glavnom projektu (prema svim navedenim zakonima, pravilnicima i normama u programu kontrole i osiguranja kvalitete) i izvedbenom projektu solidno i stručno, prema pravilima dobrog zanata, a osobito prema:
A9: Zakon o prostornom uređenju (NN 153/13, 65/17, 114/18, 39/19, 98/19), Zakona o gradnji (NN 153/13, 20/17, 39/19,125/19), Zakon o državnom inspektoratu (NN 115/18, 117/21, 67/23), Zakon o građevnim proizvodima (NN 76/13, 30/14, 130/17, 32/19, 118/20), Zakon o tehničkim zahtjevima za proizvode i ocjenjivanju sukladnosti (NN 126/21), Zakon o zaštiti na radu (NN 71/14, 118/14, 154/14 , 94/18, 96/18), Zakon o zaštiti od buke (NN 30/09, 55/13, 153/13, 41/16, 114/18, 14/21), Zakon o zaštiti od požara (NN 92/10).
A10: Tehnički propis o građevnim proizvodima (NN 35/18, 104/19), Tehnički propis za građevinske konstrukcije (NN 17/17, 75/20, 7/22) , Tehnički propis o racionalnoj uporabi energije i toplinskoj zaštiti u zgradama (NN 128/15, 70/18, 73/18-ispravak, 86/18-ispravak, 102/20) ) s pripadajućim normama, te svim ostalim hrvatskim i europskim tehničkim propisima i normama i priznatim tehničkim pravilima.
A11: Specifikacije (tekstualni dio) i grafički prikazi predstavljaju cjelinu i što je makar jednom od njih naznačeno obaveza je za izvoditelja. Sve eventualne nejasnoće i nedefiniranosti izvođač radova treba utvrditi sa projektantom ili nadzornim inženjerom i otkloniti. Izvoditelj ima obavezu dati pismenu izjavu da je tehničku dokumentaciju razumio, da je izvršio provjeru usklađenosti i količina, da u njoj nema nedostataka, te da je prihvaća kao osnovu za izgradnju.
A12: Izvoditelj preuzima punu odgovornost za točnost, stabilnost i sigurnost svih operacija i načina gradnje. Izvoditelj će otkloniti sve nedostatke koje ustanovi Investitor, a prema opsegu radova predviđenih ugovorom i ovim uvjetima. Ovo pod uvjetom da izvoditelj neće biti odgovoran za nacrte ili specifikaciju trajnih ili privremenih radova koje nije primio, a nije bio u obvezi da ih sam izradi u skladu s ovim uvjetima i ugovorom.
A13: Prije dostave ponude i početka radova, izvoditelju se preporuča provjeriti na radilištu sve uvjete potrebne za rad te pregledati i detaljno proučiti sve podatke koje mu je Investitor stavio na raspolaganje i to o hidrološkim i podzemnim uvjetima, projektnu dokumentaciju, prema kojoj će izvoditi radove. Provjeriti sve izmjere vezane na raspoloživu projektnu dokumentaciju. Naročitu pažnju treba posvetiti usuglašenosti građevinskih i instalaterskih nacrta. O svim eventualnim primjedbama u odnosu na potpunost i tehničku ispravnost tehničke dokumentacije, dužan je izvoditelj pravovremeno u pisanom obliku izvijestiti Investitora prije početka radova i zatražiti potrebna objašnjenja i rješenja, jer u protivnom, troškovi koji bi uslijed toga nastupili, idu na teret Izvoditelja. Smatra se da je izvoditelj pregledao i ispitao radilište i njegovu okolinu kao i podatke u vezi s njim te da se zadovoljio (u onoj mjeri u kojoj je to provedivo, uzimajući u obzir trošak i vrijeme) prije podnošenja svoje Ponude u pogledu:
... A786: čišćenja po završenom radu

Sheet 1_NASLOV
C2: INVESTITOR: | D2: REPUBLIKA HRVATSKA
D3: SISAČKO-MOSLAVAČKA ŽUPANIJA
D4: Ulica Stjepana i Antuna Radića 36
D5: 44000, Sisak
D6: OIB: 82215698659
C8: GRAĐEVINA: | D8: Rekonstrukcija i dogradnja zgrade 3 (bivša stražarnica) u sklopu Domobranske vojarne u Sisku i prenamjena u RCK Tehnička škola Sisak
C11: LOKACIJA: | D11: Sisak, Lađarska ulica 28A
D12: k.č.718/1 k.o. Novi Sisak
C14: BR. PROJEKTA : | D14: TD 2/24
A30: 1_TROŠKOVNIK
A31: GRAĐEVINSKO-OBRTNIČKIH RADOVA
B41: PROJEKTANT:
B43: Jasenka Žagar, dipl.ing.arh.
D49: Zagreb, prosinac 2024. god
D50: revizija 1: siječanj 2025. god.

Sheet 1_Građevinsko Obrtnički
A1: Broj stavke | C1: OPIS STAVKE | D1: jed. mjere | E1: količina | F1: jedinična cijena | G1: ukupno
A3: A. | C3: GRAĐEVINSKI RADOVI
A5: A. | B5: I. | C5: SKELA I PRIPREMNI RADOVI
B7: 1. | C7: REKONSTRUKCIJA POSTOJEĆE ZGRADE
B8: 1.1. | C8: Doprema na gradilište, montaža, demontaža i odvoz s gradilišta cijevne fasadne skele izrađene od bešavnih cijevi ili tipskih montažnih elemenata, te i potrebnih spojnih sredstava i pribora, sa svim potrebnim ukrućenjima i sidrenjima. Skela obuhvaća cijelu dužinu pročelja sa istakama. Skelu je potrebno osigurati od prevrtanja sidrenjem u objekt, a od udara groma uzemljenjem. Potrebno je izvesti pomoćne željezne ili drvene ljestve - penjalice u svrhu osiguranja vertikalne komunikacije po skeli.
C9: Prije izvedbe skele izvođač je dužan izraditi projekt skele sa uključenim rješenjima statičke stabilnosti i osiguranja zaštite na radu što je u cijeni stavke.
C10: Obračun se vrši po m2 vertikalne projekcije površine skele. | D10: m2 | E10: 250 | F10: 15 | G10: =E10*F10 -> 3750
B12: 1.2. | C12: Ispitivanje vertikalnosti pročelja nakon postave skele i obijanja žbuke. Rad se izvodi u dogovoru s nadzornim inženjerom, a ustanovljene neravnine se moraju ucrtati i kotirati na nacrtu pročelja. Ispitivanje vertikalnosti na 16 pozicija (2-3 po plohi pročelja) visine 4,5 m. Obračun po kompletu ispitanosti vertikalnosti (m1=72).
D13: komplet | E13: 1 | F13: 1000 | G13: =E13*F13 -> 1000
B15: 1.3. | C15: Snimanje profilacija i uzimanje otisaka s očuvanih i očišćenih profilacija. Izmjere i uzorci uzimaju se s očuvanih površina i elemenata s kojih prethodno treba ukloniti sve slojeve prašine, smoga i drugih nečistoća, slojeve starih naliča, žbuke i sl. Prema otiscima izraditi šablone za izvedbu vučenih profila (po jednu radnu i jednu rezervnu) od čvrste i zdrave drvene građe ili metalne. Po potrebi izraditi i gipsane odljeve i nacrte 1:1. Za svaki vučeni profil izrađuje se komplet za oba sloja žbuke (za podložni i završni sloj žbuke) 1 komplet na 6-8 m. Izrada kalupa od prikladnih materijala, odljeva i drugog po potrebi za pojedine elemente koji se izvode u žbuci. Izrada kalupa, odljeva i sl. za elemente u štuko (ili drugoj masi) obuhvaćena je u restauratorskim radovima za svaki pojedini element. Točan položaj i broj snimaka i otisaka određuje nadzor nadležnog konzervatorskog zavoda. Uključivo ovjera konzervatorskog nadzora snimaka i šablona, nakon čega se može početi s obijanjem žbuke. Obračun po kompletu.
C16: Shema - detaljna skica plohe arhitektonske plastike | D16: komplet | E16: 1
C17: a) profilacija nadvoja iznad prozora od fasadne opeke r.š. do 30 cm (m1=16)
C18: b) profilacija pozorskih klupčica (m1=12)
C19: c) profilacija vertikalna uz fasadnu opeku okvira vrata prizemlja od fasadne opeke r.š. do 20 cm (m1=6) | D19: komplet | E19: 1
C20: Obračun po kompletu izvedenih radova. | D20: komplet | E20: 1 | F20: 5000 | G20: =E20*F20 -> 5000
B22: 2. | C22: DOGRADNJA
B23: 2.1. | C23: Doprema na gradilište, montaža, demontaža i odvoz s gradilišta cijevne fasadne skele izrađene od bešavnih cijevi ili tipskih montažnih elemenata, te i potrebnih spojnih sredstava i pribora, sa svim potrebnim ukrućenjima i sidrenjima. Skela obuhvaća cijelu dužinu pročelja sa istakama. Skelu je potrebno osigurati od prevrtanja sidrenjem u objekt, a od udara groma uzemljenjem. Potrebno je izvesti pomoćne željezne ili drvene ljestve - penjalice u svrhu osiguranja vertikalne komunikacije po skeli.
C24: Prije izvedbe skele izvođač je dužan izraditi projekt skele sa uključenim rješenjima statičke stabilnosti i osiguranja zaštite na radu što je u cijeni stavke.
C25: Obračun se vrši po m2 vertikalne projekcije površine skele. | D25: m2 | E25: 1400 | F25: 15 | G25: =E25*F25 -> 21000
B27: 2.2. | C27: Rušenje drveća i čišćenje parcele u zoni zahvata površine 3600 m2, od grmlja, drveća visine 8-12 m (kom 18), postojećeg zidanog opečnog potpornog zida debljine do 70 cm, visine 1,50 m i duljine 50 m, s utovarom i odvozom na mjesnu planirku.
C28: U dogovoru s konzervatorskim nadzorom odrediti koja se stabla mogu ukloniti.
C29: Čišćenje parcele u zoni zahvata, s utovarom i odvozom na mjesnu planirku; a) čišćenje parcele, uključivo uklanjanje niskog raslinja, m2=3600; b) uklanjanje drveća visine do 8 m, promjera do 60 cm, sa vađenjem panjeva, kom=8; c) uklanjanje drveća visine do 12 m, promjera do 100 cm, sa vađenjem panjeva, kom=10; d) uklanjanje postojećeg zidanog opečnog potpornog zida debljine do 70 cm, visine 1,50 m i duljine 50 m.
C30: Obračun po komadu kompletu srušenog izvedenih radova. | D30: komplet | E30: 1 | F30: 1000 | G30: =E30*F30 -> 1000
B32: 2.3. | C32: Iskolčenje građevine, tj, geodetski prijenos tlocrta vanjskih obrisa na terenu unutar građevne čestice sa izradom nacrta - situacija iskolčenja. Obuhvaća npr.: iskolčenje osi i poligonih točaka koje služe za rekonstrukciju osovine i visine; postavljanje poprečnih profila i drugo; tijekom rada izvođač obavlja pojedine izmjene pravca i visine koje su mu potrebne za izvođenje i obračun izvršenih radova; praćenje slijeganja dogradnje u odnosu na postojeću građevinu (broj repera 4, vrijeme praćenja 2 godine). U cijeni sav rad i materijal.
C33: Obuhvatiti sva geodetska mjerenja, kojima se podaci iz projekta prenose na teren, osiguranje iskolčenih osi trase, profiliranje, obnavljanje i održavanje iskolčenih oznaka na terenu za sve vrijeme građenja, odnosno do predaje radova investitoru.
C34: Iskolčenje građevine mora obaviti osoba ovlaštena za obavljanje poslova izmjere. Ispravnost iskolčenja građevine potvrđuje ovlaštena osoba (prethodni pasus) upisom u građevinski dnevnik prije početka radova iskopa.
C35: Tlocrtna površina građevine iznosi 930 m2. Obračun po kompletu iskolčenja građevine. | D35: komplet | E35: 1 | F35: 500 | G35: =E35*F35 -> 500
B37: 2.4. | C37: Izrada geodetskog elaborata izvedene građevine i parcele, te instalacija s uplanjenjem u katastar. Izvesti po ovlaštenoj osobi. | D37: komplet | E37: 1 | F37: 2500 | G37: =E37*F37 -> 2500
A39: A. | B39: I. | C39: SKELA I PRIPREMNI RADOVI UKUPNO | G39: =SUM(G10:G37) -> 34750
A42: A. | B42: II. | C42: KONZERVATORSKI ISTRAŽNI RADOVI
B44: 1. | C44: REKONSTRUKCIJA POSTOJEĆE ZGRADE
B45: 1.1. | C45: Konzervatorska istraživanja žbuke i boje zidova, te površina i elemenata pročelja nakon postave skele, a prije rušenja i demontaža, radi utvrđivanja izgleda pročelja u raznim povijesnim razdobljima, te radi utvrđivanja stanja obrada i konstrukcija. Prema odredbama nadležnog konzervatorskog zavoda otvoriti konzervatorske sonde na ravnim površinama pročelja, na vučenim profilacijama, te stolariji. Stavka uključuje izradu izvještaja nakon provedenih konzervatorskih istražnih radova s ucrtanim i opisanim pozicijama sondi. Obračun po broju sondi i kompletu elaborata istražnih radova.
C46: Sonda | D46: komada | E46: 10 | F46: 500 | G46: =F46*E46 -> 5000
C47: Izrada elaborata istražnih radova | D47: komplet | E47: 1 | F47: 3000 | G47: =F47*E47 -> 3000
B49: 1.2. | C49: Konzervatorska istraživanja slojeva, žbuke i boje, unutarnjih zidova, prije rušenja i demontaža, radi utvrđivanja izgleda pročelja u raznim povijesnim razdobljima, te radi utvrđivanja stanja obrada i konstrukcija. Prema odredbama nadležnog konzervatorskog zavoda otvoriti konzervatorske sonde na ravnim površinama unutarnjih zidova. Stavka uključuje izradu izvještaja s fotodokumentacijom nakon provedenih konzervatorskih istražnih radova s ucrtanim i opisanim pozicijama sondi. Obračun po broju sondi i kompletu elaborata istražnih radova.
C50: Sonda | D50: komada | E50: 5 | F50: 500 | G50: =E50*F50 -> 2500
C51: Izrada elaborata istražnih radova | D51: komplet | E51: 1 | F51: 3000 | G51: =E51*F51 -> 3000
A53: A. | B53: II. | C53: KONZERVATORSKI ISTRAŽNI RADOVI UKUPNO | G53: =SUM(G46:G51) -> 13500
A56: A. | B56: III. | C56: RUŠENJA I DEMONTAŽE
B58: 1. | C58: REKONSTRUKCIJA POSTOJEĆE ZGRADE
...

Sheet 2_NASLOV
B2: ARHINGTRADE d.o.o.
A3: Gajeva 47, 10000 Zagreb, tel. 01/49 22 345, fax. 01/49 22 332, e-mail arhingtrade@arhingtrad.tcloud.hr
A6: Investitor:
A7: SISAČKO-MOSLAVAČKA ŽUPANIJA
A8: Stjepana i Antuna Radića 36, 44 000 Sisak
A12: Građevina:
A13: ZGRADA 3 (BIVŠA STRAŽARNICA)
A14: U SKLOPU DOMOBRANSKE VOJARNE U SISKU
A15: na k.č.br. 718/1, k.o. Novi Sisak, Lađarska ulica 28A
A19: Vrsta i naziv projekta:
A20: TROŠKOVNIK
A21: INSTALACIJE VODOVODA I KANALIZACIJE
A23: Zajednička oznaka projekta: MŽ-02/24
... A26: revizija 1: siječanj 2025.

Sheet VIK-1
B3: TROŠKOVNIK VODOVODA I KANALIZACIJE
A5: I. | B5: RAZVOD UNUTAR OBJEKTA
A7: Red. broj | B7: Opis stavke | C7: Jed.mjera | D7: Količina | E7: Jed.cijena | F7: Iznos
A9: A/ | B9: VODOVOD
A11: 1. | B11: Nabava, dobava i ugradnja cijevi od tvrdog polietilena visoke gustoće PE-80 (PEHD), S 6,3/SDR 13,6 u kvaliteti prema odredbama normi HRN EN 12201 i HRN EN ISO 3126 ili jednakovrijedna za pogonski tlak 1.0 MPa. Montaža cijevi izvodi se elektrootpornim zavarivanjem elektrospojnicama uz obavezno korištenje alata za ispravljanje ovalnosti cijevi. Montaža uključuje potreban brtveni, spojni materijal i fazone. Uračunat pregled prije ugradnje, te ispitivanje spojeva.
B12: Cijevi se spajaju tipskim elektro-spojnicama sa dvostrukim naglavkom u svemu prema naputku proizvođača cijevi. Cijevi se polažu u rov na pripremljenu posteljicu sukladno normi HRN EN1610 ili jednakovrijedna
B13: Stavkom je obuhvaćena dobava, transport i ugradnja cijevi i fazonskih komada (lučnih i čvornih gdje se za njih ukaže potreba), te ispitivanje kao i sav spojni i brtveni materijal, sve za radni tlak PN 10 bara.
B14: Ø 50 mm | C14: m' | D14: 20 | E14: 23 | F14: =(D14*E14) -> 460
B15: Ø 32 mm | C15: m' | D15: 30 | E15: 15 | F15: =(D15*E15) -> 450
F16: =(D16*E16) -> 0
A17: 2. | B17: Nabava, dobava i ugradnja vodovodne PPR cijevi SDR 11, PN 10 sa spojnim i brtvenim materijalom za razvod tople, hladne vode i recirkulacijske vode unutar građevine. Cijevi se polažu u instalacijski kanal, šliceve izvedene u zidovima objekta, zidne usjeke i proboje kao i pod stropom građevine. U cijenu uključiti materijal za pričvršćivanje cijevi (obujmica sa vijkom) pomoću kliznih i čvrstih točaka, cijevi se pričvršćuju svakih cca 0,80m ovisno o profilu i uputama proizvođača. Cijevi se izoliraju izolacijom debljine 6mm. U projektu su navedene nazivne mjere cijevi. Kod dopreme cijevi i spojnih komada na gradilište izvođač je obavezan nadzornom inženjeru priložiti dokument, tj. ispitivanje od strane ZAVODA ZA JAVNO ZDRAVSTVO temeljem kojeg se jamči da su cijevi uporabljive za pitku vodu (tj. za ljudsku uporabu) kao i važeću atestnu dokumentaciju prema normi HRN EN ISO 15874-2 ili jednakovrijedna | F17: =(D17*E17) -> 0
B18: Obračun po m1 komplet dobavljene, ugrađene i ispitane cijevi na tlak od 10 bar-a sa fazonskim komadima. Sav ugrađeni materijal i pribor mora imati odgovarajuće ateste, a ugradnja se mora izvoditi isključivo po uputstvu proizvođača. | F18: =(D18*E18) -> 0
B20: Dimenzije cijevi date su sa unutarnjim promjerom cijevi. Učvršćenje cijevnih vodova za zidnu i stropnu konstrukciju izvesti pomoću obujmica.Stavkom je obuhvaćena dobava, transport u ugradnja cijevi i fazonskih komada po m1 ugrađene cijevi te ispitivanje. | F20: =(D20*E20) -> 0
B21: Ø 20 mm | C21: m' | D21: 140 | E21: 22 | F21: =(D21*E21) -> 3080
B22: Ø 15 mm | C22: m' | D22: 80 | E22: 20 | F22: =(D22*E22) -> 1600
B23: Ø 25 mm | C23: m' | D23: 40 | E23: 26 | F23: =(D23*E23) -> 1040
A25: 3. | B25: Dobava, donos i montaža metalnih cijevi izrađenih iz izvana i iznutra pocinčanog C-čelika sukladno HRN EN 10305 E220 ili jednakovrijedna sa spajanjem spojnim komadima iz galvanski pocinčanog C-čelika, za glavni hidrantski razvod-mokri. Stavka obuhvaća sve potrebne spojnice, redukcije, T-komade i potrebni pričvrsni i ovjesni materijal. | F25: =D25*E25 -> 0
B26: Cijevi izolirati uz prethodni premaz oštećenih i spojnih mjesta antikorozivnim premazom: | F26: =D26*E26 -> 0
B27: a) u zidu i podu – termoizlacijskim cijevima i trakom sa debljinom stijenki od 0,3 mm. | F27: =D27*E27 -> 0
B28: b) u kanalu s gotovim termoizolacijskim cijevima i oblogama sa debljinom stijenki 13 mm. | F28: =D28*E28 -> 0
B29: c) pod stropom – gotove termoizolacijske cijevi sa debljinom stijenki 19 mm. | F29: =D29*E29 -> 0
B30: Dimenzije cijevi date su sa unutarnjim promjerom cijevi. Učvršćenje cijevnih vodova za zidnu i stropnu konstrukciju izvesti pomoću obujmica.Stavkom je obuhvaćena dobava, transport u ugradnja cijevi i fazonskih komada po m1 ugrađene cijevi te ispitivanje.
B31: Ø 50 mm | C31: m' | D31: 100 | E31: 38 | F31: =D31*E31 -> 3800
A33: 4. | B33: Dobava, prijenos i ugradba mjedenih (ljevano željeznih) slobodno protočnih ventila - zasuna, komplet. Ventile montirati kod spoja i na mjestima označenim shemama. Ventile montirati na njima označenom mjestu. | F33: =(D33*E33) -> 0
B34: Ø 50 mm | C34: kom | D34: 1 | E34: 110 | F34: =(D34*E34) -> 110
B35: Ø 25 mm | C35: kom | D35: 1 | E35: 38 | F35: =(D35*E35) -> 38
A37: 5. | B37: Dobava, donos i ugradba mjedenog protočnog ventila sa ugradbenom kapom na navoj. Obračun po komadu komplet ugrađenog ventila sa kapom. | F37: =(D37*E37) -> 0
C38: kom | D38: 5 | E38: 35 | F38: =(D38*E38) -> 175
F39: =(D39*E39) -> 0
A40: 6. | B40: Dobava, prijenos i ugradba kutnih ventila za montažu ispod sanitarnih jedinica (UMIVAONIK-2, WC-1, PISOAR-1). Obračun po komadu ugrađenog ventila sa rozetom. Obračun po komadu ugrađenog ventila. | F40: =(D40*E40) -> 0
B41: Ø 15 mm | C41: kom | D41: 30 | E41: 20 | F41: =(D41*E41) -> 600
F42: =(D42*E42) -> 0
A43: 7. | B43: Dobava, prijenos i ugradba materijala za pričvršćenje i zavješenje cjevovoda, dvostruke i jednostruke obujmice, perforirana traka, vijci, matice, tipli i dr. | C43: kompl. | D43: 1 | E43: 300 | F43: =(D43*E43) -> 300
F44: =(D44*E44) -> 0
A45: 8. | B45: Ispitivanje instalacije na tlak od 15 bara i dezinfekcija cjevovoda otopinom klora. | F45: =(D45*E45) -> 0
B46: Obračun po komadu komplet ispitane instalacije. | C46: kom | D46: 1 | E46: 400 | F46: =(D46*E46) -> 400
A48: 9 | B48: Dobava, prijenos i ugradba požarnih hidranata s ormarićem ugrađenim na zid (nadžbukni crveni i kučište i vrata), vel. ormarića 500x500x140, 22,5 kg br. 4110. Ustavku je uključen ormarić s nastavkom Ø 2'', ventil s holenderom Ø 2'', gumirana cijev trevira, dužine 20 m, prifila 52 mm, art. 3100/T sa spojkom i mlaznicom art. br. 4360, te nosačima. Ormarić opremljen sa elktrogrijačem, spojen sa automatskim uključivanjem i isključivanjem, spojen na el.instalaciju. Obračun po komadu kompletno montiranog i opremljenog hidranta Hv Ø 2'' | F48: =D48*E48 -> 0
B49: INOX vratašca sa staklom. | C49: kom | D49: 5 | E49: 250 | F49: =D49*E49 -> 1250
A51: 10 | B51: Dobava, prijenos, ugradba i postavljanje ručnih vatrogasnih aparata sa zidnim nosačima S9. Sve komplet sa svim pomočnim materijalom i razmještajem. | C51: kom | D51: 10 | E51: 98 | F51: =D51*E51 -> 980
A53: 11 | B53: Izvedba predmeta opreme na hladnu i toplu vodu, sa ventilima Ø 20. Ø 25 i Ø 32, te priključka spremnika tople vode.
...

Sheet VIK-2
A3: II. | B3: RAZVOD IZVAN OBJEKTA
A5: Red. broj | B5: Opis stavke | C5: Oznaka | D5: Jed.mjera | E5: Količina | F5: Jed.cijena | G5: Iznos
A8: A/ | B8: DEMONTAŽE I RUŠENJA
A10: 1 | B10: Uklanjanje raznog otpada i demontaža dotrajalih sanitarija (umivaonici, wc školjke i pisoari). | D10: kom. | E10: 10 | F10: 100 | G10: =E10*F10 -> 1000
A11: 2 | B11: Demontaža postojećih unutarnjih instalacija vodovoda, odvodnje kao i svih objekata vezanih uz predmetne instalacije. Stavka uključuje sav potreban rad, alat, materijal, pomoćni i dodatni materijal i opremu. Obračun po komadu kompletu izvršene demontaže. | D11: kompl. | E11: 1 | F11: 100 | G11: =E11*F11 -> 100
A12: 3 | B12: Demontaža postojećih dvorišnih instalacija vodovoda, odvodnje, kao i svih objekata vezanih uz predmetne instalacije. Stavka uključuje sav potreban rad, alat, materijal, pomoćni i dodatni materijal i opremu. Obračun po komadu kompletu demontiranih instalacija: a) vodovodne instalacije do Φ50 mm, m1=100; b) odvodnja do Φ150 mm, m1=150 m. | D12: kompl. | E12: 1 | F12: 100 | G12: =E12*F12 -> 100
A13: 4 | B13: Vodonepropusno zatvaranje postojećeg kanala prema rijeci. Zatvaranje se vrši armiranim vodonepropusnim betonom. Klasa betona C25/30 prema normi HRN EN-206-1:2006 ili jednakovrijedno, armatura B500B prema normi HRN 1130 ili jednakovrijedno. i HRN EN 10080:2005 ili jednakovrijedno, 150kg/m³, v/c faktor max. 0,50, s dopuštenim prodorom vode 15mm. Ispitivanje vodonepropusnosti prema normi HRN EN 12390-8 ili jednakovrijedno. Radove uskladiti sa zahtjevima nadležnog Konzervatorskog odjela. Stavka uključuje sav potreban rad, alat, materijal, pomoćni i dodatni materijal i opremu. | D13: kom. | E13: 1
A15: A/ | B15: DEMONTAŽE I RUŠENJA UKUPNO: | G15: =SUM(G10:G12) -> 1200
A18: B/ | B18: VANJSKI RAZVOD VODOVODNIH INSTALACIJA
A20: 1 | B20: Strojno-ručni iskop rova u terenu za polaganje vodomjernog okna i vrtnog priključka, sukladno s normom HRN EN 1610 ili jednakovrijedno, od priključnog čvora do temelja. Iskop pravilno zasjecati, te postaviti razupiranja za spriječavanje urušavanje rova, a iskopani materijal odbacivati min. 1,0 m od ruba iskopa. Potrebno je ostaviti slobodnu površinu uz rov širine 0,50 m. Radovi moraju teći u potpunoj koordinaciji s montažom cijevi. Sve radove treba uključiti u jediničnu cijenu (kao utovar, potrebni prijevoz i sl.) Obračun po m³ uključujući sav rad, strojeve, alat, materijal, pomoćni i dodatni materijal i opremu.
A21: a) | B21: strojno 85% | D21: m3 | E21: 20.4 | F21: 40 | G21: =E21*F21 -> 816
A22: b) | B22: ručno 15% | D22: m3 | E22: 4.5 | F22: 100 | G22: =E22*F22 -> 450
A23: 2 | B23: Dobava materijala, izrada vodomjernog okna debljine stijenki 25 cm, tlocrtnih dimenzija 200x280 cm iz betona C25/30 prema normi HRN EN-206-1:2006 ili jednakovrijedno, armatura B500B prema normi HRN 1130 ili jednakovrijedno. i HRN EN 10080:2005 ili jednakovrijedno, 150kg/m³, u dvostranoj oplati, a nakon skidanja oplate okno iznutra ožbukati vodonepropusnom cem. žbukom omjera 1:2 i zagladiti do crnog sjaja. Na pokrovnoj ploči postaviti ljevani željezni poklopac, razred opterečenja B125 prema HRN EN 124 ili jednakovrijedno. Na svakih 25 cm ispod poklopca u stijenku ugraditi ljevanoželjezne penjalice. Sve ostalo prema nacrtima uz uputu nadzornog inženjera. Obračun po komadu gotovog okna. | C23: VMO | D23: kom. | E23: 1 | F23: 2500 | G23: =E23*F23 -> 2500
A24: 3 | B24: Dobava materijala, izrada okna vrtnog priključka debljine stijenki 15 cm, tlocrtnih dimenzija 100x100 cm iz betona C25/30 prema normi HRN EN-206-1:2006 ili jednakovrijedno, armatura B500B prema normi HRN 1130 ili jednakovrijedno i HRN EN 10080:2005 ili jednakovrijedno, 150kg/m³, u dvostranoj oplati, a nakon skidanja oplate okno iznutra ožbukati vodonepropusnom cem. žbukom omjera 1:2 i zagladiti do crnog sjaja. Na pokrovnoj ploči postaviti ljevani željezni poklopac, razred opterečenja B125 prema HRN EN 124 ili jednakovrijednoj. Sve ostalo prema nacrtima uz uputu nadzornog inženjera. Obračun po komadu gotovog okna. | C24: VP1,2 | D24: kom. | E24: 2 | F24: 800 | G24: =E24*F24 -> 1600
A25: 4 | B25: Strojno-ručni iskop rova u terenu za polaganje cijevi, sukladno s normom HRN EN 1610 ili jednakovrijednom, te postaviti razupiranja za spriječavanje urušavanje rova, a iskopani materijal odbacivati min. 1,0 m od ruba iskopa. Potrebno je ostaviti slobodnu površinu uz rov širine 0,50 m. Radovi moraju teći u potpunoj koordinaciji s montažom cijevi. Sve radove treba uključiti u jediničnu cijenu (kao utovar, potrebni prijevoz i sl.) Obračun po m³ uključujući sav rad, strojeve, alat, materijal, pomoćni i dodatni materijal i opremu.
A26: a) | B26: strojno 95% | D26: m3 | E26: 235 | F26: 20 | G26: =E26*F26 -> 4700
A27: b) | B27: ručno 5% | D27: m3 | E27: 15.5 | F27: 100 | G27: =E27*F27 -> 1550
A28: 5 | B28: Izvedba posteljice od pijeska granulacije 0-8mm, za polaganje vodovodnih cijevi. Sloj pijeska deb. 10 cm iznad i ispod cijevi razastirati ravnomjerno duž rova. Obračun po m3 uključujući trasnport, rad, alat, materijal, pomoćni i dodatni materijal i opremu. | D28: m3 | E28: =(E21+E22+E26+E27)*0.1 -> 27.54 | F28: 40 | G28: =E28*F28 -> 1101.6
A29: 6 | B29: Izrada i brtvljenje prodora u stjenci okna za prolaz vodovodnih cijevi, uključujući zaštitnu cijev, rad, građevinski i brtveni materijal do potpune pogonske gotovosti. | D29: kom. | E29: 7 | F29: 100 | G29: =E29*F29 -> 700
A30: 7 | B30: Zatrpavanje rovova materijalom od iskopa. Uz postavljanje zaštitnih elemenata i oznaka uključujući zaštite i oznake. Izvoditi u slojevima od 30 cm s nabijanjem. Kod zatrpavanja (kod cijevi) najprije upotrijebiti sitniji materijal. Obračun po m³ zatrpanog rova. Napomena: ukoliko se na lokaciji pokaže loša kvaliteta materijala iz iskopa, te se materijalom iskopa ne može postići potrebna čvrstoća terena ispod, potrebno je ugraditi zamjenski materijal. | D30: m3 | E30: 250 | F30: 20 | G30: =E30*F30 -> 5000
A31: 8 | B31: Dobava i ugradnja trake za označavananje vodovoda i žice za indikaciju trase vodovoda. | D31: m' | E31: 385 | F31: 1 | G31: =E31*F31 -> 385
A32: 9 | B32: Sanacija nogostupa nakon spoja sa postojećom uličnom vodovodnom cijevi. Sanacija se izvodi u slojevima kao i kod zatečenog stanja. | D32: m² | E32: 4 | F32: 200 | G32: =E32*F32 -> 800
A33: 10 | B33: Dobava i montaža lijevanoželjeznog priključnog voda DN 100 mm, PN16 u unaprijed iskopan rov i postavljenu posteljicu, te spoj s postojećim javnim vodovodom. Stavka uključuje sav potreban rad, alat, materijal, pomoćni i dodatni materijal i opremu. | D33: m' | E33: 6 | F33: 100 | G33: =E33*F33 -> 600
A34: 11 | B34: Izrada, dobava i montaža fazonskih komada i armatura u vodomjerno okno. U stavku uključeno spajanje fazonskih komada izvan okna, betonske oslonce, kao i sav spojni pribor, potreban rad, alat, materijal, pomoćni i dodatni materijal i opremu.
A35: a) | B35: FFG DN100, l=200mm | D35: kom. | E35: 1 | F35: 100 | G35: =E35*F35 -> 100
A36: b) | B36: FFG DN100, l=700mm | D36: kom. | E36: 1 | F36: 100 | G36: =E36*F36 -> 100
A37: c) | B37: Lijevanoželjezni nepovratni ventil DN100, PN16, prema normi HRN EN 12334 ili jednakovrijednoj | D37: kom. | E37: 1 | F37: 100 | G37: =E37*F37 -> 100
A38: d) | B38: Eliptični ventil DN100, PN16, prema normi HRN EN 1171 ili jednakovrijednoj | D38: kom. | E38: 2 | F38: 100 | G38: =E38*F38 -> 200
A39: e) | B39: Eliptični ventil DN50, PN10, prema normi HRN EN 1171 ili jednakovrijednoj | D39: kom. | E39: 2 | F39: 100 | G39: =E39*F39 -> 200
A40: f) | B40: Eliptični ventil DN32, PN10, prema normi HRN EN 1171 ili jednakovrijednoj | D40: kom. | E40: 2 | F40: 80 | G40: =E40*F40 -> 160
A41: g) | B41: Eliptični ventil DN32, PN10, prema normi HRN EN 1171 ili jednakovrijednoj | D41: kom. | E41: 2 | F41: 50 | G41: =E41*F41 -> 100
A42: h) | B42: Hvatač nečistoča DN100, PN16. | D42: kom. | E42: 1 | F42: 50 | G42: =E42*F42 -> 50
A43: i) | B43: MDK-A komad, DN100, PN16 | D43: kom. | E43: 1 | F43: 100 | G43: =E43*F43 -> 100
A44: j) | B44: T komad DN100/50 | D44: kom. | E44: 3 | F44: 100 | G44: =E44*F44 -> 300
A45: k) | B45: Q komad DN100, PN16 | D45: kom. | E45: 1 | F45: 100 | G45: =E45*F45 -> 100
A46: l) | B46: Redukcija DN50/32 | D46: kom. | E46: 1 | F46: 100 | G46: =E46*F46 -> 100
... A51: r) | B51: Obračunski vodomjer mjerno područje Qn=6,3m³/h; promjer DN25 PN10 sa spojnim i ovjesnim priborom | D51: kom. | E51: 1 | F51: 300 | G51: =E51*F51 -> 300
A52: 12 | B52: Nabava, doprema i ugradba vodovodnih polietilenskih cijevi PE 100, za radni tlak PN 16 bara, SDR 11, na dubini za sprječavanje smrzavanja. U cijenu je uračunat sav materijal potreban za montažu, uključivo brtve, sredstvo za podmazivanje, zasunske ventile na granama, materijal i oprema potrebni za zavarivanje, betonska uporišta, lučne komade, kao i sav ostali spojni pribor, potreban rad, alat, materijal, pomoćni i dodatni materijal i opremu do potpune funkcionalnosti i uporabljivosti instalacije.
A53: a) | B53: DN 125 mm | D53: m' | E53: 101.3 | F53: 65 | G53: =E53*F53 -> 6584.5
A54: b) | B54: DN 110 mm | D54: m' | E54: 96.3 | F54: 60 | G54: =E54*F54 -> 5778
...

Sheet VIK-REK
B7: REKAPITULACIJA INSTALACIJE VODOVODA I KANALIZACIJE
A9: I/ | B9: RAZVOD UNUTAR OBJEKTA | G9: ='VIK-1'!F210 -> 62421
A11: II/ | B11: RAZVOD IZVAN OBJEKTA | G11: ='VIK-2'!G124 -> 192490.89
B13: UKUPNO: | G13: =SUM(G9:G11) -> 254911.89
B14: PDV 25%: | G14: =G13*0.25 -> 63727.972
B16: SVEUKUPNO: | G16: =G13+G14 -> 318639.86

Sheet 3_NASLOV
B2: ARHINGTRADE d.o.o.
A3: Gajeva 47, 10000 Zagreb, tel.01/4922345,014922332, e-mail:info@arhingtrde.hr
A6: Investitor:
A7: SISAČKO-MOSLAVAČKA ŽUPANIJA
A8: Stjepana i Antuna Radića 36, 44000 Sisak
A9: OIB: 82215698659
A12: Građevina:
A13: ZGRADA 3 (BIVŠA STRAŽARNICA)
A14: U SKLOPU DOMOBRANSKE VOJARNE U SISKU Lađarska ulica 28A, 44000 Sisak na k.č.br. 718/1, k.o. Novi Sisak
A17: Zajednička oznaka projekta: MŽ-02/24
A18: Datum: prosinac 2024.
A19: Interni broj projekta: 02/24
A20: revizija 1: siječanj 2025.
A24: TROŠKOVNIK STROJARSKIH INSTALACIJA

Sheet 3_STROJARSTVO
B3: TROŠKOVNIK STROJARSKIH INSTALACIJA
B5: OPĆI UVJETI:
B6: Dimenzije za sve elemente opreme potrebno je provjeriti na licu mjesta.
B7: U jediničnim cijenama za sve stavke troškovnika, ponuda mora sadržavati dobavu, ukupne troškove materijala i rada do potpunog dovršenja cjelokupnog posla odnosno do pune funkcionalnosti.U slučaju odstupanja od projekta u tijeku izvođenja radova isporučitelj je dužan izraditi elaborat izvedenog stanja.
B8: Jedinična cijena, također, uključuje sva potrebna ispitivanja, kontrole i mjerenja za sve izvedene radove, ugrađene materijale i opremu, u svrhu dokazivanja njihove kvalitete i kompletiranja tehničke dokumentacije potrebne za ishođenje uporabne dozvole, te se prilikom primopredaje građevine, uručuje Investitoru odnosno krajnjem korisniku.prije oštećenja.
B9: Navedena ispitivanja, kontrole i mjerenja izvode ovlaštene institucije, a odnose se na ispitivanje klimatizacije i ventilacije,te ostala potrebna ispitivanja sukladno važećoj zakonskoj regulativi.
B10: Kao dokaz usklađenosti sa specificiranim materijalom u troškovniku, ponuditelj je dužan obvezno dostaviti prije isporuke sljedeće dokumente:
B11: katalog sa opisom i fotografijom svih ponuđenih proizvoda, iz kojeg su vidljive sve tražene karakteristike proizvoda predmeta nabave,
B12: Isporučitelj je dužan prilikom isporuke, montaže i razmještaja opreme u okviru ugovorene cijene, preuzeti nekretninu, te obavijestiti investitora o početku radova. Od tog trenutka pa do primopredaje opreme, isporučitelj je odgovoran za stvari i osobe koje se nalaze u građevini.
B13: Za sav materijal, opremu i uređaje isporučitelj je dužan prije isporuke dostaviti ateste i uvjerenja o kvaliteti, te garancijske listove i tehničku dokumentaciju sa podacima.
B14: Ukoliko isporučitelj isporuči robu na neodgovarajući način i od neodgovarajućih materijala,dužan je na svoj trošak izvesti iste iz materijala tražene kvalitete i na opisan
B15: način, uz prethodno otklanjanje nekvalitetnih dijelova.
... B26: Ovi opći uvjeti i grafički prilozi sastavni su dio opisa svake pojedine stavke troškovnika.
A29: Red. broj | B29: Opis stavke | C29: Jed.mjera | D29: Količina | E29: Jed.cijena | F29: Iznos
A31: S1. | B31: GRIJANJE I HLAĐENJE
A33: 1. | B33: Inverterski rashladnik vode sa stapnim kompresorima.
B34: Koristi prirodni radnim medij R290 (propan) s iznimno niskim GWP=3 i smanjenim utjecajem na okoliš.
B35: Struktura jedinice izrađena je od pocinčanog lima presvučenog poliesterskim prahom RAL 5017/7035 na 180 ° C, što je čini visoko otpornom na vremenske uvjete. Konstrukcija je nosivi okvir s uklonjivim oplatama obloženim prostirkom od poliuretana koja apsorbira zvuk. Svi vijci su od nehrđajućeg čelika.
B36: Kompresori su polu-hermetički klipni s dva kruga, frekventnim pretvaračem za svaki kompresor koji modulira radnu frekvenciju prema zahtjevu opterećenja. Inverterski kompresori promjenjive brzine povećavaju sezonsku učinkovitost i postižu stabilnu termodinamičku regulaciju u svim uvjetima opterećenja.
B37: Optimizirani su za upotrebu s propanom. Svi kompresori opremljeni su grijačem kućišta radilice, usisnim i dovodnim servisnim ventilima. Kompresori imaju ATEX certifikat ili jednakovrijedno.
B38: Brzina modulirajućeg kompresora varira, ovisno o ukupnom toplinskom opterećenju između 30 i 105 o / min. 30Hz i 65Hz.
B39: Zrakom hlađeni i grijani toplinski izmjenjivač uređaja napravljen je od bakrenih cijevi te aluminijskih mikro kanala koji povećavaju površinu izmjene zraka. Izmjenivač je optimiziran za rad uređaja u grijanju te ima povećanu širinu i nagib lamela kako bi se smanjilo stvaranje leda i olakšao odljev kondenzirane vode tijekom odmrzavanja. Bakrene cijevi su povećane debljine kako bi se osigurala veća pouzdanost i trajnost tijekom radnog vijeka.
B40: Na dnu zrakom hlađenog i grijanog izmjenivača se nalazi posuda za sakupljanje kondenzata koja olakšava odvod kondenzata tijekom odmrzavanja. Uređaj je standardno opremljen grijaćim kabelom montiranim na dno posude za kondenzat kako bi se spriječilo stvaranje leda.
B41: Vodeni izmjenjivač je također opremljen termostatom grijačem protiv smrzavanja koji ga štiti od stvaranja leda kada uređaj ne radi. Rad uređaja optimiziran je u načinu grijanja, gdje se voda i tekućine rashladnog sredstva izmjenjuju u protustruji unutar pločastog izmjenjivača topline.
B42: Svaki krug rashladnog sredstva osnovne jedinice sadrži: elektromagnetni ventil na dovodu tekuće faze, 4-smjerni prekretni ventil, servisni ventili prije i nakon kompresora, reciever tekuće faze radnog medija, priključci za punjenje radnog medija, kontrolno staklo, filter za isušivanje, elektronski ekspanzijski ventil, prekidači visokog i niskog tlaka te separator usisne tekućine.
B43: Rashladni krug zatvoren je u odjeljak koji sadrži certificirani osjetnik propuštanja i ventilacijski ventilator s ATEX-ovim certifikatom ili jednakovrijedno. Hidraulični modul, ako je prisutan, također je zatvoren u odjeljak koji sadrži certificirani osjetnik propuštanja i ventilator za usisavanje s ATEX-ovim certifikatom ili jednakovrijedno.
B44: Električna upravljačka ploča izrađena je u obojenoj pocinčanoj kutiji od lima sa prisilnom ventilacijom i zaštitom IP54. Električna ploča izrađena je prema standardu EN60204-1 ili jednakovrijedno. Električna ploča odvojena je od odjeljka kompresora.
B45: Za napajanje sigurnosnih uređaja (osjetnik curenja i ventilatori za usisavanje) potrebna je dodatna namjenska linija napajanja 230V / 50Hz. Rad ove linije mora biti zajamčen neprekidnim napajanjem.
... B77: Sve komponente se isporučuju sastavljene, tvornički ispitane i certificirane u jednom komadu.
C78: komplet | D78: 1 | E78: 50000 | F78: =E78*D78 -> 50000
A80: 2. | B80: Recirkulacijska jedinica za grijanje i hlađenje prostorija za ugradnju pod strop na visini 4,2 m od poda s centralnim izvorom topline i rashladne energije (2-cjevni sustav); izvedena kao krovna jednica; s visokoučinkovitim distributerom zraka.
B81: Jedinica se sastoji od sljedećih komponenata:
B82: - Krovne jedinice (s pristupom svim komponentama za servisiranje) dim.2795x1490x1439 mm(d x š x v) koja se sastoji od:
B83: -ventilatora s visokoučinkovitem EC motorom
B84: -visokoučinkovitog izmjenjivača za grijanje i hlađenje iz bakrenih cijevi
B85: -odvajača kondenzata
B86: -fitera
B87: -Elektroničke ploče na bočnoj strani kućista sa svim potrebnim električnim komponentama, upravljačkom jedinicom (pričvršćenom) i priključnim stezaljkama za sljedeće vanjske veze: -- Ventil za grijanje/hlađenje -- Pumpa za grijanje/hlađenje -- Kontakt za vrata
B89: - Potkrovna jedinica, sastoji se od:
B90: -Priključnog modula dim.110x1100x1300 mm(dxšxv)
...

Sheet 4_NASLOV
A2: ARHINGTRADE d.o.o.
A3: Gajeva 47, 10000 Zagreb, tel. 01/49 22 345, fax. 01/49 22 332, e-mail: info@arhingtrade.hr
A6: Investitor:
A7: SISAČKO-MOSLAVAČKA ŽUPANIJA Stjepana i Antuna Radića 36, 44000 Sisak OIB: 82215698659
A12: Građevina:
A13: ZGRADA 3 (BIVŠA STRAŽARNICA) U SKLOPU DOMOBRANSKE VOJARNE U SISKU Lađarska ulica 28A, 44000 Sisak na k.č.br. 718/1, k.o. Novi Sisak
A18: Zajednička oznaka projekta: MŽ-02/24
A19: Tehnički dnevnik: 02/24
A20: Zagreb, prosinac 2024.
A21: revizija 1: siječanj 2025.
A25: TROŠKOVNIK ELEKTROINSTALACIJA

Sheet 4_ELEKTROINSTALACIJE
A3: TROŠKOVNIK ELEKTROINSTALACIJA
B5: OPĆI POGODBENI I TEHNIČKI UVJETI ELEKTROINSTALACIJA
A7: 1. | B7: Ugovor za izvođenje sklapa se na osnovu ugovornog troškovnika. U cijenama troškovnika izvođač je dužan ponuditi kompletne stavke prema opisu, troškovniku, nacrtima, tehničkom opisu i uvjetima.
A9: 2. | B9: U cijenu stavke treba ukalkulirati sav materijal i rad (sa izradom šliceva i prodora kroz zidove i ploču) te potrebna mjerenja i ispitivanja.
B10: Izvođač radova dužan je po završetku radova dostaviti investitoru upute za rukovanje instalacijama i opremom.
A12: 3. | B12: Prije početka izvođenja radova, preporuča se obaviti pregled lokacije i o eventualnim odstupanjima projekta od stvarnog stanja upozoriti investitora.
A14: 4. | B14: Izvođač radova mora se prije početka izvođenja radova upoznati s projektnom dokumentacijom.
B15: Ako uoči neke nedostatke, treba odmah s uočenim nedostacima upoznati investitora i projektanta.
A17: 5. | B17: Prije početka radova treba odrediti točne trase kabela, kabelskih kanalica i većih komada opreme, a tek onda početi s polaganjem vodova i izvođenjem instalacija. Pritom paziti na propisani razmak u odnosu na druge instalacije i građevine.
A19: 6. | B19: Mijenjanje projekta od strane izvođača bez pismenih odobrenja investitora i nadzornog inženjera nije dozvoljeno.
A21: 7. | B21: Izvođač treba tijekom izvođenja radova na građevini voditi građevinski dnevnik u koji upisuje početak izvođenja radova na objektu, svakodnevno upisuje broj ljudi na radu i poslove koje su obavili.
B22: U građevinksi dnevnik nadzorni inženjer i investitor upisuju primjedbe na izvedene radove i eventualne promjene projekta.
A24: 8. | B24: Radi ispravnog odvijanja radova izvođač je dužan osigurati prostoriju za smještaj materijala i alata.
A26: 9. | B26: Prije stavljanja instalacije u pogon i tehničkog pregleda izvođač je dužan izvršiti slijedeća mjerenja i ispitivanja:
B28: Popis ispitivanja i atesta elektroenergetske instalacije niskog napona
B29: Provjera pregledom
B30: - Atest i certifikati ugrađene opreme i kabela
B31: - Atest o izvršenom mjerenju otpora izolacije
B32: - Atest o izvršenom mjerenju otpora uzemljenja metalnih masa
B33: - Atest o izvršenoj kontroli efikasnosti zaštite od indirektnog napona dodira
B34: - Atest o izvršenom mjerenju jakosti rasvjete
B35: - Atest o izvršenom funkcionalnom ispitivanju
B36: - Atest o funkcionalnom ispitivanju isklapanja glavnih prekidača
B37: - Reviziona knjiga sustava za zaštitu od djelovanaj munje
B38: - Ispitni listovi razvodnih ormara
B39: - Atest o ispitivanju protupanične rasvjete
... B49: - Atesti o izvršenom ispitivanju pozivne instalacije
A51: 10. | B51: Za sva mjerenja i ispitivanja koja su izvršena sastaviti odgovarajuće izvještaje.
A53: 11. | B53: Svaki izvođač ima pravo izbora kome će povjeriti ispitivanje kvalitete i funkcionalnosti električnih instalacija i opreme, no to svakako mora biti ovlaštena pravna osoba.
B54: Troškove ispitivanja snosi izvođač.
A56: 12. | B56: Izvođač za svoje radove daje garanciju.
B57: Garantni rok počinje teći od dana tehničkog prijema instalacije, odnosno od dana predaje instalacije na upotrebu investitoru odnosno korisniku.
B58: Izvođač je dužan otkloniti sve nedostatke u garantnom roku. Ako se izvođač ne odazove na poziv investitora da otkloni nedostatke, investitor će iste otkloniti po trećem licu na teret izvođača.
A60: 13. | B60: Sav korišteni materijal , oprema i proizvodi koji se upotrebljavaju kod izvođenja instalacija moraju odgovarati postojećim propisima i normama, kao i opisu u troškovniku.
B61: Radove treba izvesti točno prema nacrtima i tehničkom opisu, a po uputama projektanta i nadzornog inženjera. Radove izvesti stručno i solidno.
A63: 14. | B63: Tijekom izvođenja radova izvođač je dužan sva nastala odstupanja trasa od onih predviđenih projektom unesti u projekt, a po završetku radova treba predati investitoru projekt izvedenog stanja.
A65: 15. | B65: Stavljanje instalacije u uporabu dozvoljeno je tek nakon obavljenog tehničkog pregleda i dobivanja uporabne dozvole.
A67: 16. | B67: Ako troškovnikom i tehničkim opisom nije drugačije određeno, narudžba materijala i opreme obuhvaća dobavu, skladištenje i dopremu na gradilište.
A69: 17. | B69: Za sav ugrađeni materijal i proizvode treba osigurati i priložiti isprave o sukladnosti i druge dokaze kvalitete, te odgovarjauću atesnu i ispitnu dokumentaciju.
A71: 18. | B71: Nadzorni inženjer mora imati uvid u terminski plan.
...

Sheet 5_NASLOV
A2: ARHINGTRADE d.o.o.
A3: Gajeva 47, 10000 Zagreb, tel. 01/49 22 345, fax. 01/49 22 332, e-mail: info@arhingtrade.hr
A6: Investitor:
A7: SISAČKO-MOSLAVAČKA ŽUPANIJA Stjepana i Antuna Radića 36, 44000 Sisak OIB: 82215698659
A12: Građevina:
A13: ZGRADA 3 (BIVŠA STRAŽARNICA) U SKLOPU DOMOBRANSKE VOJARNE U SISKU Lađarska ulica 28A 44000 Sisak na k.č.br. 718/1, k.o. Novi Sisak
A18: Zajednička oznaka projekta: MŽ-02/24
A19: Tehnički dnevnik: 02/24
A20: Zagreb, prosinac 2024.
A21: revizija 1: siječanj 2025.
A25: TROŠKOVNIK SUSTAVA VATRODOJAVE

Sheet 5_VATRODOJAVA
A2: TROŠKOVNIK SUSTAVA VATRODOJAVE
B5: OPĆI POGODBENI I TEHNIČKI UVJETI
A6: 1. | B6: Ugovor za izvođenje sklapa se na osnovu ugovornog troškovnika. U cijenama troškovnika izvođač je dužan ponuditi kompletne stavke prema opisu, troškovniku, nacrtima, tehničkom opisu i uvjetima.
A7: 2. | B7: U cijenu stavke treba ukalkulirati sav materijal i rad (sa izradom šliceva i prodora kroz zidove i ploču) te potrebna mjerenja i ispitivanja.
B8: Izvođač radova dužan je po završetku radova dostaviti investitoru upute za rukovanje instalacijama i opremom.
A9: 3. | B9: Prije početka izvođenja radova, izvođač može obaviti pregled lokacije i o eventualnim odstupanjima projekta od stvarnog stanja upozoriti investitora.
A10: 4. | B10: Izvođač radova mora se prije početka izvođenja radova upoznati s projektnom dokumentacijom.
B11: Ako uoči neke nedostatke, treba odmah s uočenim nedostacima upoznati investitora i projektanta.
A12: 5. | B12: Prije početka radova treba odrediti točne trase kabela, kabelskih kanalica i većih komada opreme, a tek onda početi s polaganjem vodova i izvođenjem instalacija. Pritom paziti na propisani razmak u odnosu na druge instalacije i građevine.
A13: 6. | B13: Mijenjanje projekta od strane izvođača bez pismenih odobrenja investitora i nadzornog inženjera nije dozvoljeno.
A14: 7. | B14: Izvođač treba tijekom izvođenja radova na građevini voditi građevinski dnevnik u koji upisuje početak izvođenja radova na objektu, svakodnevno upisuje broj ljudi na radu i poslove koje su obavili.
B15: U građevinksi dnevnik nadzorni inženjer i investitor upisuju primjedbe na izvedene radove i eventualne promjene projekta.
A16: 8. | B16: Radi ispravnog odvijanja radova izvođač je dužan osigurati prostoriju za smještaj materijala i alata.
A17: 9. | B17: Sav korišteni materijal , oprema i proizvodi koji se upotrebljavaju kod izvođenja instalacija moraju odgovarati postojećim propisima i normama, kao i opisu u troškovniku.
B18: Radove treba izvesti točno prema nacrtima i tehničkom opisu, a po uputama projektanta i nadzornog inženjera. Radove izvesti stručno i solidno.
A19: 10. | B19: Tijekom izvođenja radova izvođač je dužan sva nastala odstupanja trasa od onih predviđenih projektom unesti u projekt, a po završetku radova treba predati investitoru projekt izvedenog stanja.
A20: 11. | B20: Stavljanje instalacije u uporabu dozvoljeno je tek nakon obavljenog tehničkog pregleda i dobivanja uporabne dozvole.
A21: 12. | B21: Ako troškovnikom i tehničkim opisom nije drugačije određeno, narudžba materijala i opreme obuhvaća dobavu, skladištenje i dopremu na gradilište.
A22: 13. | B22: Za sav ugrađeni materijal i proizvode treba osigurati i priložiti isprave o sukladnosti i druge dokaze kvalitete, te odgovarjauću atesnu i ispitnu dokumentaciju.
A23: 14. | B23: Nadzorni inženjer mora imati uvid u terminski plan.
B24: Za svako neopravdano produženje termina koje utvrdi nadzorni inženjer odredit će se kazna prema Ugovoru za izvođenje.
A25: 15. | B25: Izvođač daje jamstvo da, kod prenošenja dijela ugovora na jednog ili više kooperanata, preuzima sve ugovorne obveze iz ugovora zaključenog sa investitorom, te da će se istog pridržavati.
A26: 16. | B26: Ako drugačije nije dogovoreno, izvođač treba, bez posebnih zahtjeva, svakodenevno čistii radni prostor. Izvođač mora u toku gradnje iz gradilišta odvesti svu građevinsku šutu, sav otpadni materijal i nepotrebne uređaje.
A27: 17. | B27: Pri izvođenju radova izvođač je dužan voditi računa o već izvedenim radovima na građevini.
B28: Ako bi se izvedeni radovi drugih izvođača pri montaži instalacija vatrodojave i opreme nepotrebno i uslijed nemarnosti i nestručnosti oštetili, troškove štete snosit će izvođač vatrodojave.
A29: 18. | B29: Rušenje i retanje konstruktivnih elemenata ne smije se obaviti bez znanja i odobrenja nadzornog inženjera za građevinske radove.
A30: 19. | B30: Investitor je dužan tijekom izgradnje građevine osigurati stručni nadzor nad izvođenjem radova.
A31: 20. | B31: Cjelokupnu električnu instalaciju treba izvesti prema priloženim nacrtima, troškovniku, tehničkom opisu, ovim uvjetima i važećim propisima za izvođenje električnih instalacija, odnosno tehničkim propisima za niskonaponske električne instalacije (NN br. 05/10) i propisima RH.
A32: 21. | B32: Kod polaganja instalacije vatrodojavnog sustava treba se pridržavati važećih propisa za instalacije slabe struje kao i posebnih uputa proizvođača opreme.
A33: 22. | B33: Potrebno je izbjegavati blisko paralelno vođenje instalacija vatrodojavnog sustava i instalacija jake struje, a ako to nije moguće potrebno je osigurati razmake minimalno 10 cm. Križanje s vodovima jake struje nije poželjno, no ako se ono ne može izbjeći trase se moraju sjeći pod kutom od 90° i na razmaku po dubini najmanje 1 cm.
A34: 23. | B34: Cijevi koje se polažu kroz vanjske zidove objekta moraju biti od materijala koji su otporni na vlagu.
A35: 24. | B35: Kod probijanja zidova i bušenja armirano-betonske konstrukcije, odnosno stropova na kojima je trstika treba se posavjetovati sa stručnjacima - statičarima.
A36: 25. | B36: Kod probijanja zidova i bušenja stropova na kojima ima štukatura i ukrasnih motiva treba se posavjetovati sa stručnjacima - restauratorima
A37: 26. | B37: Kod probijanja zidova i bušenja armirano-betonske konstrukcije u prostoru u kojem su provedene propisane mjere zaštite od požara i eksplozije treba koristiti vatrootpornu masu za brtvljenje.
A38: 27. | B38: Polaganje vodova instalacije vatrodojavnog sustava potrebno je prilagoditi građevinskim rješenjima izvedbe objekta.
A39: 28. | B39: Polaganje vodova u cijevi treba biti izvedeno tako da se mogu bez teškoća izvući i ponovno uvući.
A40: 29. | B40: Horizontalno polaganje kabela niže od 2 metra treba izbjegavati, a u slučaju da to nije moguće treba ih mehanički zaštititi.
... A70: 59. | B70: Prije stavljanja instalacije u pogon i tehničkog pregleda izvođač je dužan izvršiti slijedeća mjerenja i ispitivanja:
B71: Potrebna ispitivanja
B72: - Atest o izvršenom ispitivanju sustava vatrodojave od ovlaštene institucije
...
